Workbook

Sheet population_bsl
A1: Gender | B1: Region | C1: Age | D1: 2011 | E1: 2012 | F1: 2013 | G1: 2014 | H1: 2015 | I1: 2016 | J1: 2017 | K1: 2018 | L1: 2019 | M1: 2020 | N1: 2021 | O1: 2022 | P1: 2023 | Q1: 2024 | R1: 2025 | S1: 2026 | T1: 2027 | U1: 2028 | V1: 2029 | W1: 2030 | X1: 2031 | Y1: 2032 | Z1: 2033 | AA1: 2034 | AB1: 2035 | AC1: 2036 | AD1: 2037 | AE1: 2038 | AF1: 2039 | AG1: 2040 | AH1: 2041 | AI1: 2042 | AJ1: 2043 | AK1: 2044 | AL1: 2045 | AM1: 2046 | AN1: 2047 | AO1: 2048 | AP1: 2049 | AQ1: 2050 | AR1: 2051 | AS1: 2052 | AT1: 2053 | AU1: 2054 | AV1: 2055 | AW1: 2056 | AX1: 2057 | AY1: 2058 | AZ1: 2059 | BA1: 2060
A2: Female | B2: HUA | C2: 0 | D2: 12251 | E2: 11982 | F2: 11943 | G2: 11843 | H2: 12399 | I2: 12203 | J2: 12482 | K2: 12172 | L2: 11529 | M2: 11017 | N2: 11280 | O2: 11760 | P2: 12274 | Q2: 12085 | R2: 12071 | S2: 12049 | T2: 12017 | U2: 11969 | V2: 11917 | W2: 11852 | X2: 11804 | Y2: 11756 | Z2: 11723 | AA2: 11699 | AB2: 11689 | AC2: 11683 | AD2: 11675 | AE2: 11684 | AF2: 11680 | AG2: 11664 | AH2: 11655 | AI2: 11647 | AJ2: 11630 | AK2: 11620 | AL2: 11607 | AM2: 11604 | AN2: 11601 | AO2: 11590 | AP2: 11567 | AQ2: 11552 | AR2: 11528 | AS2: 11498 | AT2: 11469 | AU2: 11429 | AV2: 11405 | AW2: 11374 | AX2: 11350 | AY2: 11321 | AZ2: 11297 | BA2: 11268
A3: Female | B3: HUA | C3: 1 | D3: 13251 | E3: 12515 | F3: 11971 | G3: 12403 | H3: 12281 | I3: 12998 | J3: 12612 | K3: 13162 | L3: 13174 | M3: 12819 | N3: 12724 | O3: 12916 | P3: 13305 | Q3: 12159 | R3: 12144 | S3: 12132 | T3: 12113 | U3: 12083 | V3: 12030 | W3: 11982 | X3: 11916 | Y3: 11869 | Z3: 11821 | AA3: 11787 | AB3: 11766 | AC3: 11755 | AD3: 11746 | AE3: 11742 | AF3: 11752 | AG3: 11746 | AH3: 11729 | AI3: 11726 | AJ3: 11719 | AK3: 11702 | AL3: 11690 | AM3: 11678 | AN3: 11677 | AO3: 11670 | AP3: 11663 | AQ3: 11638 | AR3: 11623 | AS3: 11600 | AT3: 11571 | AU3: 11541 | AV3: 11502 | AW3: 11478 | AX3: 11452 | AY3: 11426 | AZ3: 11397 | BA3: 11372
A4: Female | B4: HUA | C4: 2 | D4: 13859 | E4: 13422 | F4: 12469 | G4: 11933 | H4: 12385 | I4: 12285 | J4: 12927 | K4: 12662 | L4: 13191 | M4: 13257 | N4: 12930 | O4: 12782 | P4: 13088 | Q4: 12266 | R4: 12247 | S4: 12231 | T4: 12217 | U4: 12199 | V4: 12169 | W4: 12116 | X4: 12068 | Y4: 12004 | Z4: 11956 | AA4: 11906 | AB4: 11874 | AC4: 11852 | AD4: 11842 | AE4: 11833 | AF4: 11831 | AG4: 11841 | AH4: 11835 | AI4: 11817 | AJ4: 11812 | AK4: 11807 | AL4: 11788 | AM4: 11776 | AN4: 11765 | AO4: 11765 | AP4: 11757 | AQ4: 11750 | AR4: 11726 | AS4: 11711 | AT4: 11686 | AU4: 11658 | AV4: 11629 | AW4: 11590 | AX4: 11566 | AY4: 11541 | AZ4: 11514 | BA4: 11485
A5: Female | B5: HUA | C5: 3 | D5: 13733 | E5: 13910 | F5: 13347 | G5: 12455 | H5: 11889 | I5: 12370 | J5: 12257 | K5: 12925 | L5: 12701 | M5: 13218 | N5: 13318 | O5: 12971 | P5: 12580 | Q5: 12381 | R5: 12352 | S5: 12335 | T5: 12318 | U5: 12304 | V5: 12286 | W5: 12258 | X5: 12204 | Y5: 12156 | Z5: 12091 | AA5: 12044 | AB5: 11997 | AC5: 11963 | AD5: 11941 | AE5: 11929 | AF5: 11923 | AG5: 11919 | AH5: 11930 | AI5: 11923 | AJ5: 11907 | AK5: 11901 | AL5: 11894 | AM5: 11878 | AN5: 11864 | AO5: 11853 | AP5: 11855 | AQ5: 11844 | AR5: 11838 | AS5: 11814 | AT5: 11798 | AU5: 11773 | AV5: 11744 | AW5: 11717 | AX5: 11677 | AY5: 11654 | AZ5: 11627 | BA5: 11601
A6: Female | B6: HUA | C6: 4 | D6: 14096 | E6: 13744 | F6: 13880 | G6: 13313 | H6: 12425 | I6: 11872 | J6: 12299 | K6: 12287 | L6: 12914 | M6: 12698 | N6: 13282 | O6: 13297 | P6: 13022 | Q6: 13088 | R6: 12463 | S6: 12438 | T6: 12418 | U6: 12401 | V6: 12387 | W6: 12369 | X6: 12341 | Y6: 12286 | Z6: 12239 | AA6: 12174 | AB6: 12128 | AC6: 12080 | AD6: 12048 | AE6: 12025 | AF6: 12012 | AG6: 12006 | AH6: 12002 | AI6: 12016 | AJ6: 12007 | AK6: 11991 | AL6: 11987 | AM6: 11977 | AN6: 11964 | AO6: 11946 | AP6: 11937 | AQ6: 11939 | AR6: 11926 | AS6: 11922 | AT6: 11898 | AU6: 11879 | AV6: 11858 | AW6: 11827 | AX6: 11801 | AY6: 11756 | AZ6: 11736 | BA6: 11709
A7: Female | B7: HUA | C7: 5 | D7: 13851 | E7: 14244 | F7: 13754 | G7: 13871 | H7: 13339 | I7: 12503 | J7: 11887 | K7: 12384 | L7: 12390 | M7: 13017 | N7: 12835 | O7: 13382 | P7: 13437 | Q7: 13210 | R7: 13164 | S7: 12538 | T7: 12512 | U7: 12491 | V7: 12475 | W7: 12462 | X7: 12443 | Y7: 12416 | Z7: 12362 | AA7: 12315 | AB7: 12248 | AC7: 12205 | AD7: 12159 | AE7: 12123 | AF7: 12102 | AG7: 12090 | AH7: 12082 | AI7: 12079 | AJ7: 12092 | AK7: 12083 | AL7: 12069 | AM7: 12065 | AN7: 12054 | AO7: 12043 | AP7: 12024 | AQ7: 12015 | AR7: 12017 | AS7: 12004 | AT7: 11996 | AU7: 11977 | AV7: 11956 | AW7: 11936 | AX7: 11906 | AY7: 11879 | AZ7: 11833 | BA7: 11813
A8: Female | B8: HUA | C8: 6 | D8: 13661 | E8: 13827 | F8: 14205 | G8: 13631 | H8: 13780 | I8: 13259 | J8: 12470 | K8: 11876 | L8: 12331 | M8: 12360 | N8: 12981 | O8: 12808 | P8: 13632 | Q8: 13629 | R8: 13277 | S8: 13234 | T8: 12606 | U8: 12581 | V8: 12561 | W8: 12546 | X8: 12533 | Y8: 12514 | Z8: 12487 | AA8: 12433 | AB8: 12385 | AC8: 12318 | AD8: 12274 | AE8: 12229 | AF8: 12192 | AG8: 12173 | AH8: 12161 | AI8: 12150 | AJ8: 12149 | AK8: 12165 | AL8: 12153 | AM8: 12138 | AN8: 12135 | AO8: 12124 | AP8: 12117 | AQ8: 12097 | AR8: 12088 | AS8: 12091 | AT8: 12077 | AU8: 12066 | AV8: 12051 | AW8: 12029 | AX8: 12010 | AY8: 11979 | AZ8: 11952 | BA8: 11907
A9: Female | B9: HUA | C9: 7 | D9: 13279 | E9: 13430 | F9: 13791 | G9: 14169 | H9: 13559 | I9: 13749 | J9: 13235 | K9: 12448 | L9: 11893 | M9: 12343 | N9: 12383 | O9: 12999 | P9: 13376 | Q9: 13702 | R9: 13688 | S9: 13339 | T9: 13298 | U9: 12668 | V9: 12642 | W9: 12623 | X9: 12609 | Y9: 12597 | Z9: 12577 | AA9: 12550 | AB9: 12496 | AC9: 12449 | AD9: 12384 | AE9: 12337 | AF9: 12293 | AG9: 12257 | AH9: 12238 | AI9: 12225 | AJ9: 12217 | AK9: 12215 | AL9: 12232 | AM9: 12219 | AN9: 12204 | AO9: 12202 | AP9: 12191 | AQ9: 12185 | AR9: 12164 | AS9: 12155 | AT9: 12156 | AU9: 12145 | AV9: 12133 | AW9: 12121 | AX9: 12096 | AY9: 12078 | AZ9: 12047 | BA9: 12017
A10: Female | B10: HUA | C10: 8 | D10: 13748 | E10: 13199 | F10: 13454 | G10: 13770 | H10: 14145 | I10: 13584 | J10: 13771 | K10: 13285 | L10: 12478 | M10: 11966 | N10: 12454 | O10: 12426 | P10: 13420 | Q10: 13256 | R10: 13763 | S10: 13744 | T10: 13398 | U10: 13360 | V10: 12727 | W10: 12701 | X10: 12682 | Y10: 12668 | Z10: 12658 | AA10: 12637 | AB10: 12611 | AC10: 12559 | AD10: 12510 | AE10: 12444 | AF10: 12399 | AG10: 12355 | AH10: 12317 | AI10: 12301 | AJ10: 12287 | AK10: 12279 | AL10: 12278 | AM10: 12292 | AN10: 12279 | AO10: 12267 | AP10: 12265 | AQ10: 12255 | AR10: 12251 | AS10: 12229 | AT10: 12219 | AU10: 12220 | AV10: 12210 | AW10: 12199 | AX10: 12185 | AY10: 12159 | AZ10: 12142 | BA10: 12111
A11: Female | B11: HUA | C11: 9 | D11: 13755 | E11: 13723 | F11: 13249 | G11: 13478 | H11: 13808 | I11: 14254 | J11: 13658 | K11: 13870 | L11: 13437 | M11: 12631 | N11: 12137 | O11: 12640 | P11: 12675 | Q11: 13541 | R11: 13313 | S11: 13822 | T11: 13801 | U11: 13459 | V11: 13422 | W11: 12787 | X11: 12761 | Y11: 12742 | Z11: 12729 | AA11: 12719 | AB11: 12697 | AC11: 12670 | AD11: 12621 | AE11: 12571 | AF11: 12505 | AG11: 12457 | AH11: 12416 | AI11: 12377 | AJ11: 12363 | AK11: 12349 | AL11: 12338 | AM11: 12339 | AN11: 12350 | AO11: 12339 | AP11: 12325 | AQ11: 12326 | AR11: 12314 | AS11: 12310 | AT11: 12291 | AU11: 12281 | AV11: 12280 | AW11: 12269 | AX11: 12260 | AY11: 12246 | AZ11: 12222 | BA11: 12204
A12: Female | B12: HUA | C12: 10 | D12: 13907 | E12: 13665 | F12: 13796 | G12: 13275 | H12: 13523 | I12: 13837 | J12: 14326 | K12: 13780 | L12: 13995 | M12: 13548 | N12: 12798 | O12: 12220 | P12: 12852 | Q12: 12994 | R12: 13604 | S12: 13377 | T12: 13884 | U12: 13861 | V12: 13521 | W12: 13483 | X12: 12848 | Y12: 12824 | Z12: 12805 | AA12: 12794 | AB12: 12783 | AC12: 12760 | AD12: 12731 | AE12: 12684 | AF12: 12631 | AG12: 12565 | AH12: 12518 | AI12: 12477 | AJ12: 12438 | AK12: 12423 | AL12: 12410 | AM12: 12400 | AN12: 12399 | AO12: 12409 | AP12: 12399 | AQ12: 12387 | AR12: 12386 | AS12: 12377 | AT12: 12370 | AU12: 12352 | AV12: 12342 | AW12: 12343 | AX12: 12330 | AY12: 12321 | AZ12: 12308 | BA12: 12284
A13: Female | B13: HUA | C13: 11 | D13: 13353 | E13: 13580 | F13: 13735 | G13: 13895 | H13: 13342 | I13: 13631 | J13: 13981 | K13: 14510 | L13: 13921 | M13: 14158 | N13: 13807 | O13: 12987 | P13: 12414 | Q13: 13053 | R13: 13061 | S13: 13671 | T13: 13444 | U13: 13950 | V13: 13926 | W13: 13589 | X13: 13549 | Y13: 12912 | Z13: 12889 | AA13: 12870 | AB13: 12859 | AC13: 12848 | AD13: 12824 | AE13: 12796 | AF13: 12747 | AG13: 12695 | AH13: 12629 | AI13: 12582 | AJ13: 12542 | AK13: 12500 | AL13: 12484 | AM13: 12473 | AN13: 12463 | AO13: 12465 | AP13: 12473 | AQ13: 12461 | AR13: 12450 | AS13: 12448 | AT13: 12437 | AU13: 12429 | AV13: 12414 | AW13: 12403 | AX13: 12403 | AY13: 12390 | AZ13: 12383 | BA13: 12369
... A607: Male | B607: HUC | C607: 100 | D607: 197 | E607: 197 | F607: 197 | G607: 197 | H607: 197 | I607: 197 | J607: 197 | K607: 197 | L607: 197 | M607: 212 | N607: 244 | O607: 276 | P607: 285 | Q607: 298 | R607: 296 | S607: 309 | T607: 323 | U607: 331 | V607: 340 | W607: 352 | X607: 368 | Y607: 378 | Z607: 383 | AA607: 391 | AB607: 398 | AC607: 401 | AD607: 399 | AE607: 406 | AF607: 423 | AG607: 442 | AH607: 469 | AI607: 497 | AJ607: 534 | AK607: 565 | AL607: 605 | AM607: 617 | AN607: 640 | AO607: 678 | AP607: 718 | AQ607: 753 | AR607: 793 | AS607: 825 | AT607: 859 | AU607: 931 | AV607: 1012 | AW607: 1052 | AX607: 1066 | AY607: 1056 | AZ607: 1050 | BA607: 1045
C608: Total: | D608: =SUM(D1:D607) -> 9986215 | E608: =SUM(E1:E607) -> 9934708 | F608: =SUM(F1:F607) -> 9897854 | G608: =SUM(G1:G607) -> 9852719 | H608: =SUM(H1:H607) -> 9818229 | I608: =SUM(I1:I607) -> 9781950 | J608: =SUM(J1:J607) -> 9742084 | K608: =SUM(K1:K607) -> 9715772 | ... BA608: =SUM(BA1:BA607) -> 9119155

Sheet population_low
A1: Gender | B1: Region | C1: Age | D1: 2011 | E1: 2012 | F1: 2013 | G1: 2014 | H1: 2015 | I1: 2016 | J1: 2017 | K1: 2018 | L1: 2019 | M1: 2020 | N1: 2021 | O1: 2022 | P1: 2023 | Q1: 2024 | R1: 2025 | S1: 2026 | T1: 2027 | U1: 2028 | V1: 2029 | W1: 2030 | X1: 2031 | Y1: 2032 | Z1: 2033 | AA1: 2034 | AB1: 2035 | AC1: 2036 | AD1: 2037 | AE1: 2038 | AF1: 2039 | AG1: 2040 | AH1: 2041 | AI1: 2042 | AJ1: 2043 | AK1: 2044 | AL1: 2045 | AM1: 2046 | AN1: 2047 | AO1: 2048 | AP1: 2049 | AQ1: 2050 | AR1: 2051 | AS1: 2052 | AT1: 2053 | AU1: 2054 | AV1: 2055 | AW1: 2056 | AX1: 2057 | AY1: 2058 | AZ1: 2059 | BA1: 2060
A2: Female | B2: HUA | C2: 0 | D2: 12251 | E2: 11982 | F2: 11943 | G2: 11843 | H2: 12399 | I2: 12203 | J2: 12482 | K2: 12172 | L2: 11529 | M2: 10994.586 | N2: 11218.296 | O2: 11674.349 | P2: 12156.691 | Q2: 11942.558 | R2: 11893.957 | S2: 11836.845 | T2: 11764.165 | U2: 11670.021 | V2: 11577.797 | W2: 11466.323 | X2: 11372.563 | Y2: 11282.908 | Z2: 11211.237 | AA2: 11148.117 | AB2: 11103.157 | AC2: 11067.362 | AD2: 11031.604 | AE2: 11014.735 | AF2: 10987.719 | AG2: 10949.93 | AH2: 10921.842 | AI2: 10892.485 | AJ2: 10860.045 | AK2: 10829.939 | AL2: 10799.178 | AM2: 10777.183 | AN2: 10755.12 | AO2: 10725.356 | AP2: 10680.593 | AQ2: 10645.424 | AR2: 10598.507 | AS2: 10545.216 | AT2: 10492.758 | AU2: 10429.522 | AV2: 10379.802 | AW2: 10320.086 | AX2: 10265.768 | AY2: 10210.611 | AZ2: 10155.482 | BA2: 10097.602
A3: Female | B3: HUA | C3: 1 | D3: 13251 | E3: 12515 | F3: 11971 | G3: 12403 | H3: 12281 | I3: 12998 | J3: 12612 | K3: 13162 | L3: 13174 | M3: 12774.931 | N3: 12661.265 | O3: 12809.3 | P3: 13175.278 | Q3: 12016.756 | R3: 11979.334 | S3: 11932.096 | T3: 11877.87 | U3: 11807.063 | V3: 11707.956 | W3: 11620.085 | X3: 11506.456 | Y3: 11413.554 | Z3: 11323.801 | AA3: 11251.107 | AB3: 11190.758 | AC3: 11144.209 | AD3: 11105.498 | AE3: 11073.504 | AF3: 11057.49 | AG3: 11028.569 | AH3: 10989.257 | AI3: 10966.237 | AJ3: 10938.303 | AK3: 10905.312 | AL3: 10873.859 | AM3: 10843.473 | AN3: 10822.759 | AO3: 10796.929 | AP3: 10770.849 | AQ3: 10723.692 | AR3: 10687.932 | AS3: 10642.446 | AT3: 10588.988 | AU3: 10535.556 | AV3: 10473.237 | AW3: 10423.464 | AX3: 10367.715 | AY3: 10311.528 | AZ3: 10255.81 | BA3: 10200.25
A4: Female | B4: HUA | C4: 2 | D4: 13859 | E4: 13422 | F4: 12469 | G4: 11933 | H4: 12385 | I4: 12285 | J4: 12927 | K4: 12662 | L4: 13191 | M4: 13214.468 | N4: 12848.9 | O4: 12686.199 | P4: 12949.034 | Q4: 12120.85 | R4: 12082.69 | S4: 12044.19 | T4: 11994.862 | U4: 11941.483 | V4: 11870.524 | W4: 11770.698 | X4: 11682.659 | Y4: 11570.801 | Z4: 11476.713 | AA4: 11384.896 | AB4: 11313.942 | AC4: 11252.481 | AD4: 11206.211 | AE4: 11167.343 | AF4: 11137.148 | AG4: 11120.465 | AH4: 11091.464 | AI4: 11051.709 | AJ4: 11026.193 | AK4: 10999.5 | AL4: 10964.605 | AM4: 10932.566 | AN4: 10903.037 | AO4: 10883.176 | AP4: 10856.89 | AQ4: 10829.705 | AR4: 10783.396 | AS4: 10747.539 | AT4: 10700.151 | AU4: 10646.986 | AV4: 10594.396 | AW4: 10532.017 | AX4: 10481.631 | AY4: 10427.241 | AZ4: 10368.99 | BA4: 10313.168
A5: Female | B5: HUA | C5: 3 | D5: 13733 | E5: 13910 | F5: 13347 | G5: 12455 | H5: 11889 | I5: 12370 | J5: 12257 | K5: 12925 | L5: 12701 | M5: 13179.455 | N5: 13241.542 | O5: 12859.373 | P5: 12459.677 | Q5: 12226.149 | R5: 12185.824 | S5: 12149.554 | T5: 12109.981 | U5: 12060.519 | V5: 12007.01 | W5: 11937.839 | X5: 11836.839 | Y5: 11748.63 | Z5: 11635.602 | AA5: 11541.729 | AB5: 11453.164 | AC5: 11379.569 | AD5: 11317.938 | AE5: 11269.591 | AF5: 11232.894 | AG5: 11200.69 | AH5: 11184.828 | AI5: 11154.81 | AJ5: 11116.325 | AK5: 11090.335 | AL5: 11061.165 | AM5: 11028.995 | AN5: 10994.504 | AO5: 10964.917 | AP5: 10946.805 | AQ5: 10917.136 | AR5: 10890.778 | AS5: 10843.905 | AT5: 10807.56 | AU5: 10759.55 | AV5: 10705.42 | AW5: 10654.024 | AX5: 10590.649 | AY5: 10541.625 | AZ5: 10485.331 | BA5: 10426.815
A6: Female | B6: HUA | C6: 4 | D6: 14096 | E6: 13744 | F6: 13880 | G6: 13313 | H6: 12425 | I6: 11872 | J6: 12299 | K6: 12287 | L6: 12914 | M6: 12659.815 | N6: 13209.979 | O6: 13190.1 | P6: 12883.13 | Q6: 12939.279 | R6: 12287.06 | S6: 12250.633 | T6: 12211.338 | U6: 12171.686 | V6: 12122.671 | W6: 12068.475 | X6: 11999.158 | Y6: 11897.019 | Z6: 11809.62 | AA6: 11695.869 | AB6: 11603.309 | AC6: 11513.102 | AD6: 11441.229 | AE6: 11378.513 | AF6: 11329.054 | AG6: 11291.723 | AH6: 11259.412 | AI6: 11246.253 | AJ6: 11214.278 | AK6: 11175.181 | AL6: 11151.007 | AM6: 11118.959 | AN6: 11088.976 | AO6: 11050.71 | AP6: 11022.944 | AQ6: 11004.205 | AR6: 10973.179 | AS6: 10948.064 | AT6: 10901.142 | AU6: 10861.964 | AV6: 10817.018 | AW6: 10760.973 | AX6: 10710.415 | AY6: 10641.909 | AZ6: 10595.551 | BA6: 10539.125
A7: Female | B7: HUA | C7: 5 | D7: 13851 | E7: 14244 | F7: 13754 | G7: 13871 | H7: 13339 | I7: 12503 | J7: 11887 | K7: 12384 | L7: 12390 | M7: 12980.69 | N7: 12764.918 | O7: 13280.678 | P7: 13302.86 | Q7: 13046.613 | R7: 12995.355 | S7: 12342.041 | T7: 12305.161 | U7: 12264.262 | V7: 12225.532 | W7: 12177.398 | X7: 12122.117 | Y7: 12053.642 | Z7: 11951.778 | AA7: 11864.229 | AB7: 11748.419 | AC7: 11658.575 | AD7: 11569.592 | AE7: 11494.302 | AF7: 11432.807 | AG7: 11384.174 | AH7: 11344.849 | AI7: 11313.398 | AJ7: 11298.649 | AK7: 11266.622 | AL7: 11229.344 | AM7: 11205.094 | AN7: 11171.526 | AO7: 11143.893 | AP7: 11104.13 | AQ7: 11076.299 | AR7: 11056.962 | AS7: 11025.899 | AT7: 10997.035 | AU7: 10954.124 | AV7: 10913.043 | AW7: 10868.951 | AX7: 10813.206 | AY7: 10761.679 | AZ7: 10692.208 | BA7: 10645.279
A8: Female | B8: HUA | C8: 6 | D8: 13661 | E8: 13827 | F8: 14205 | G8: 13631 | H8: 13780 | I8: 13259 | J8: 12470 | K8: 11876 | L8: 12331 | M8: 12325.315 | N8: 12913.949 | O8: 12710.238 | P8: 13503.686 | Q8: 13470.623 | R8: 13094.22 | S8: 13045.957 | T8: 12390.585 | U8: 12354.653 | V8: 12314.684 | W8: 12276.873 | X8: 12228.647 | Y8: 12172.706 | Z8: 12104.667 | AA8: 12002.139 | AB8: 11913.495 | AC8: 11797.57 | AD8: 11706.622 | AE8: 11618.467 | AF8: 11541.56 | AG8: 11481.846 | AH8: 11433.111 | AI8: 11390.879 | AJ8: 11360.715 | AK8: 11348.647 | AL8: 11313.241 | AM8: 11275.541 | AN8: 11251.637 | AO8: 11218.032 | AP8: 11193.507 | AQ8: 11152.795 | AR8: 11124.929 | AS8: 11106.433 | AT8: 11073.889 | AU8: 11042.212 | AV8: 11002.923 | AW8: 10960.865 | AX8: 10917.101 | AY8: 10860.35 | AZ8: 10808.802 | BA8: 10739.656
A9: Female | B9: HUA | C9: 7 | D9: 13279 | E9: 13430 | F9: 13791 | G9: 14169 | H9: 13559 | I9: 13749 | J9: 13235 | K9: 12448 | L9: 11893 | M9: 12309.722 | N9: 12318.81 | O9: 12905.107 | P9: 13249.08 | Q9: 13551.363 | R9: 13510.637 | S9: 13137.364 | T9: 13091.102 | U9: 12433.684 | V9: 12396.739 | W9: 12357.707 | X9: 12320.83 | Y9: 12273.506 | Z9: 12216.526 | AA9: 12148.389 | AB9: 12045.762 | AC9: 11957.413 | AD9: 11843.307 | AE9: 11749.902 | AF9: 11662.052 | AG9: 11585.983 | AH9: 11526.17 | AI9: 11475.848 | AJ9: 11436.366 | AK9: 11405.749 | AL9: 11393.45 | AM9: 11357.063 | AN9: 11319.359 | AO9: 11295.781 | AP9: 11262.12 | AQ9: 11238.486 | AR9: 11196.837 | AS9: 11168.384 | AT9: 11147.983 | AU9: 11118.194 | AV9: 11085.547 | AW9: 11048.401 | AX9: 11003.555 | AY9: 10960.684 | AZ9: 10903.341 | BA9: 10849.019
A10: Female | B10: HUA | C10: 8 | D10: 13748 | E10: 13199 | F10: 13454 | G10: 13770 | H10: 14145 | I10: 13584 | J10: 13771 | K10: 13285 | L10: 12478 | M10: 11932.903 | N10: 12391.575 | O10: 12335.038 | P10: 13299.067 | Q10: 13109.181 | R10: 13594.036 | S10: 13547.622 | T10: 13178.045 | U10: 13134.757 | V10: 12473.756 | W10: 12437.35 | X10: 12398.278 | Y10: 12361.92 | Z10: 12315.364 | AA10: 12257.342 | AB10: 12190.074 | AC10: 12089.289 | AD10: 11998.909 | AE10: 11883.749 | AF10: 11792.132 | AG10: 11704.189 | AH10: 11625.581 | AI10: 11568.508 | AJ10: 11517.17 | AK10: 11477.067 | AL10: 11447.899 | AM10: 11432.154 | AN10: 11395.229 | AO10: 11360.81 | AP10: 11336.633 | AQ10: 11303.868 | AR10: 11282.047 | AS10: 11239.42 | AT10: 11209.511 | AU10: 11189.023 | AV10: 11160.129 | AW10: 11127.832 | AX10: 11089.339 | AY10: 11043.031 | AZ10: 11001.005 | BA10: 10943.607
A11: Female | B11: HUA | C11: 9 | D11: 13755 | E11: 13723 | F11: 13249 | G11: 13478 | H11: 13808 | I11: 14254 | J11: 13658 | K11: 13870 | L11: 13437 | M11: 12599.864 | N11: 12076.804 | O11: 12552.05 | P11: 12560.356 | Q11: 13399.477 | R11: 13149.064 | S11: 13635.788 | T11: 13587.236 | U11: 13221.735 | V11: 13179.444 | W11: 12516.396 | X11: 12479.96 | Y11: 12440.848 | Z11: 12405.413 | AA11: 12358.776 | AB11: 12299.722 | AC11: 12231.39 | AD11: 12133.378 | AE11: 12041.936 | AF11: 11926.11 | AG11: 11832.068 | AH11: 11746.325 | AI11: 11666.669 | AJ11: 11611.381 | AK11: 11559.397 | AL11: 11516.411 | AM11: 11489.059 | AN11: 11470.458 | AO11: 11435.346 | AP11: 11399.054 | AQ11: 11377.073 | AR11: 11342.436 | AS11: 11320.567 | AT11: 11280.125 | AU11: 11250.194 | AV11: 11227.839 | AW11: 11197.965 | AX11: 11166.932 | AY11: 11128.385 | AZ11: 11083.873 | BA11: 11040.903
A12: Female | B12: HUA | C12: 10 | D12: 13907 | E12: 13665 | F12: 13796 | G12: 13275 | H12: 13523 | I12: 13837 | J12: 14326 | K12: 13780 | L12: 13995 | M12: 13517.825 | N12: 12739.704 | O12: 12136.1 | P12: 12741.679 | Q12: 12857.611 | R12: 13445.756 | S12: 13196.348 | T12: 13680.989 | U12: 13630.303 | V12: 13266.883 | W12: 13223.629 | X12: 12560.489 | Y12: 12525.983 | Z12: 12486.825 | AA12: 12453.27 | AB12: 12405.567 | AC12: 12345.463 | AD12: 12275.653 | AE12: 12178.894 | AF12: 12084.461 | AG12: 11967.966 | AH12: 11874.75 | AI12: 11788.903 | AJ12: 11709.122 | AK12: 11652.813 | AL12: 11601.119 | AM12: 11559.006 | AN12: 11529.718 | AO12: 11510.126 | AP12: 11475.349 | AQ12: 11440.861 | AR12: 11416.969 | AS12: 11384.547 | AT12: 11360.971 | AU12: 11320.353 | AV12: 11290.376 | AW12: 11269.788 | AX12: 11238.069 | AY12: 11206.981 | AZ12: 11168.776 | BA12: 11124.213
A13: Female | B13: HUA | C13: 11 | D13: 13353 | E13: 13580 | F13: 13735 | G13: 13895 | H13: 13342 | I13: 13631 | J13: 13981 | K13: 14510 | L13: 13921 | M13: 14127.991 | N13: 13749.747 | O13: 12903.75 | P13: 12307.491 | Q13: 12922.12 | R13: 12907.896 | S13: 13496.476 | T13: 13247.076 | U13: 13730.62 | V13: 13678.787 | W13: 13318.405 | X13: 13273.205 | Y13: 12607.431 | Z13: 12574.434 | AA13: 12534.651 | AB13: 12501.597 | AC13: 12453.231 | AD13: 12392.632 | AE13: 12323.669 | AF13: 12225.425 | AG13: 12130.721 | AH13: 12014.108 | AI13: 11920.735 | AJ13: 11835.715 | AK13: 11752.99 | AL13: 11695.071 | AM13: 11645.179 | AN13: 11602.981 | AO13: 11576.401 | AP13: 11554.86 | AQ13: 11517.649 | AR13: 11483.512 | AS13: 11459.177 | AT13: 11424.86 | AU13: 11399.778 | AV13: 11361.89 | AW13: 11330.95 | AX13: 11309.412 | AY13: 11277.678 | AZ13: 11248.378 | BA13: 11208.669
... A607: Male | B607: HUC | C607: 100 | D607: 197 | E607: 197 | F607: 197 | G607: 197 | H607: 197 | I607: 197 | J607: 197 | K607: 197 | L607: 197 | M607: 212 | N607: 244 | O607: 276 | P607: 285 | Q607: 298 | R607: 296 | S607: 309 | T607: 323 | U607: 331 | V607: 340 | W607: 352 | X607: 368 | Y607: 378 | Z607: 383 | AA607: 391 | AB607: 397.68058 | AC607: 401 | AD607: 399 | AE607: 406 | AF607: 422.68966 | AG607: 441.37615 | AH607: 468.37633 | AI607: 496.37168 | AJ607: 533.36655 | AK607: 564.36158 | AL607: 604.0412 | AM607: 616.03744 | AN607: 638.71163 | AO607: 676.72496 | AP607: 716.42059 | AQ607: 751.44035 | AR607: 791.76672 | AS607: 823.46939 | AT607: 856.55183 | AU607: 928.52887 | AV607: 1009.2308 | AW607: 1048.6776 | AX607: 1062.4248 | AY607: 1051.2686 | AZ607: 1044.1143 | BA607: 1037.3637
C608: Total: | D608: =SUM(D1:D607) -> 9986215 | E608: =SUM(E1:E607) -> 9934708 | F608: =SUM(F1:F607) -> 9897854 | G608: =SUM(G1:G607) -> 9852719 | H608: =SUM(H1:H607) -> 9818229 | I608: =SUM(I1:I607) -> 9781950 | J608: =SUM(J1:J607) -> 9742084 | K608: =SUM(K1:K607) -> 9715772 | ... BA608: =SUM(BA1:BA607) -> 8686880.3

Sheet population_high
A1: Gender | B1: Region | C1: Age | D1: 2011 | E1: 2012 | F1: 2013 | G1: 2014 | H1: 2015 | I1: 2016 | J1: 2017 | K1: 2018 | L1: 2019 | M1: 2020 | N1: 2021 | O1: 2022 | P1: 2023 | Q1: 2024 | R1: 2025 | S1: 2026 | T1: 2027 | U1: 2028 | V1: 2029 | W1: 2030 | X1: 2031 | Y1: 2032 | Z1: 2033 | AA1: 2034 | AB1: 2035 | AC1: 2036 | AD1: 2037 | AE1: 2038 | AF1: 2039 | AG1: 2040 | AH1: 2041 | AI1: 2042 | AJ1: 2043 | AK1: 2044 | AL1: 2045 | AM1: 2046 | AN1: 2047 | AO1: 2048 | AP1: 2049 | AQ1: 2050 | AR1: 2051 | AS1: 2052 | AT1: 2053 | AU1: 2054 | AV1: 2055 | AW1: 2056 | AX1: 2057 | AY1: 2058 | AZ1: 2059 | BA1: 2060
A2: Female | B2: HUA | C2: 0 | D2: 12251 | E2: 11982 | F2: 11943 | G2: 11843 | H2: 12399 | I2: 12203 | J2: 12482 | K2: 12172 | L2: 11529 | M2: 11016.989 | N2: 11278.349 | O2: 11758.21 | P2: 12269.742 | Q2: 12083.46 | R2: 12067.555 | S2: 12048.615 | T2: 12016.769 | U2: 11965.166 | V2: 11916.216 | W2: 11848.534 | X2: 11799.708 | Y2: 11750.314 | Z2: 11719.497 | AA2: 11692.633 | AB2: 11681.47 | AC2: 11675.495 | AD2: 11666.709 | AE2: 11674.958 | AF2: 11669.977 | AG2: 11652.448 | AH2: 11643.093 | AI2: 11632.17 | AJ2: 11617.64 | AK2: 11604.996 | AL2: 11591.61 | AM2: 11588.722 | AN2: 11585.266 | AO2: 11574.615 | AP2: 11548.512 | AQ2: 11533.753 | AR2: 11507.92 | AS2: 11475.757 | AT2: 11445.924 | AU2: 11405.591 | AV2: 11381.41 | AW2: 11346.748 | AX2: 11319.792 | AY2: 11292.077 | AZ2: 11266.608 | BA2: 11236.191
A3: Female | B3: HUA | C3: 1 | D3: 13251 | E3: 12515 | F3: 11971 | G3: 12403 | H3: 12281 | I3: 12998 | J3: 12612 | K3: 13162 | L3: 13174 | M3: 12818.962 | N3: 12724.202 | O3: 12913.994 | P3: 13302.842 | Q3: 12154.658 | R3: 12142.318 | S3: 12128.374 | T3: 12112.127 | U3: 12082.522 | V3: 12025.868 | W3: 11981.171 | X3: 11912.142 | Y3: 11863.991 | Z3: 11814.829 | AA3: 11782.702 | AB3: 11759.344 | AC3: 11746.577 | AD3: 11737.85 | AE3: 11732.756 | AF3: 11742.252 | AG3: 11735.525 | AH3: 11716.402 | AI3: 11713.278 | AJ3: 11703.618 | AK3: 11688.508 | AL3: 11674.41 | AM3: 11661.983 | AN3: 11660.503 | AO3: 11653.305 | AP3: 11646.903 | AQ3: 11618.202 | AR3: 11603.671 | AS3: 11579.104 | AT3: 11547.311 | AU3: 11516.722 | AV3: 11477.359 | AW3: 11453.418 | AX3: 11423.129 | AY3: 11394.408 | AZ3: 11366.634 | BA3: 11340.426
A4: Female | B4: HUA | C4: 2 | D4: 13859 | E4: 13422 | F4: 12469 | G4: 11933 | H4: 12385 | I4: 12285 | J4: 12927 | K4: 12662 | L4: 13191 | M4: 13256.966 | N4: 12929.872 | O4: 12782.099 | P4: 13085.829 | Q4: 12263.879 | R4: 12242.506 | S4: 12229.157 | T4: 12213.175 | U4: 12197.626 | V4: 12168.266 | W4: 12111.55 | X4: 12066.827 | Y4: 11999.463 | Z4: 11950.542 | AA4: 11899.337 | AB4: 11869.178 | AC4: 11845.052 | AD4: 11832.675 | AE4: 11824.197 | AF4: 11821.071 | AG4: 11830.523 | AH4: 11823.77 | AI4: 11803.915 | AJ4: 11798.201 | AK4: 11790.765 | AL4: 11773.648 | AM4: 11759.504 | AN4: 11748.054 | AO4: 11747.55 | AP4: 11739.631 | AQ4: 11732.617 | AR4: 11705.153 | AS4: 11690.6 | AT4: 11664.007 | AU4: 11633.15 | AV4: 11603.53 | AW4: 11564.138 | AX4: 11540.141 | AY4: 11511.103 | AZ4: 11480.736 | BA4: 11452.932
A5: Female | B5: HUA | C5: 3 | D5: 13733 | E5: 13910 | F5: 13347 | G5: 12455 | H5: 11889 | I5: 12370 | J5: 12257 | K5: 12925 | L5: 12701 | M5: 13217.972 | N5: 13317.89 | O5: 12970.759 | P5: 12579.985 | Q5: 12378.816 | R5: 12349.742 | S5: 12330.343 | T5: 12315.985 | U5: 12299.966 | V5: 12284.398 | W5: 12257.006 | X5: 12199.234 | Y5: 12154.489 | Z5: 12086.07 | AA5: 12038.093 | AB5: 11990.135 | AC5: 11957.658 | AD5: 11933.488 | AE5: 11919.07 | AF5: 11913.549 | AG5: 11908.395 | AH5: 11918.82 | AI5: 11911.045 | AJ5: 11893.142 | AK5: 11886.704 | AL5: 11876.668 | AM5: 11862.816 | AN5: 11846.626 | AO5: 11835.158 | AP5: 11836.629 | AQ5: 11825.674 | AR5: 11819.638 | AS5: 11792.117 | AT5: 11776.568 | AU5: 11749.921 | AV5: 11718.031 | AW5: 11690.352 | AX5: 11649.934 | AY5: 11627.21 | AZ5: 11596.132 | BA5: 11566.11
A6: Female | B6: HUA | C6: 4 | D6: 14096 | E6: 13744 | F6: 13880 | G6: 13313 | H6: 12425 | I6: 11872 | J6: 12299 | K6: 12287 | L6: 12914 | M6: 12697.971 | N6: 13281.902 | O6: 13296.784 | P6: 13021.628 | Q6: 13087.859 | R6: 12460.673 | S6: 12435.587 | T6: 12413.164 | U6: 12398.797 | V6: 12383.03 | W6: 12367.152 | X6: 12339.727 | Y6: 12280.903 | Z6: 12237.134 | AA6: 12168.65 | AB6: 12121.639 | AC6: 12072.629 | AD6: 12042.119 | AE6: 12016.628 | AF6: 12001.448 | AG6: 11995.885 | AH6: 11990.702 | AI6: 12004.098 | AJ6: 11994.302 | AK6: 11976.352 | AL6: 11971.893 | AM6: 11958.83 | AN6: 11947.944 | AO6: 11927.733 | AP6: 11918.243 | AQ6: 11919.671 | AR6: 11907.001 | AS6: 11902.364 | AT6: 11875.087 | AU6: 11856.524 | AV6: 11833.815 | AW6: 11799.893 | AX6: 11773.184 | AY6: 11727.723 | AZ6: 11707.965 | BA6: 11676.841
A7: Female | B7: HUA | C7: 5 | D7: 13851 | E7: 14244 | F7: 13754 | G7: 13871 | H7: 13339 | I7: 12503 | J7: 11887 | K7: 12384 | L7: 12390 | M7: 13016.975 | N7: 12834.904 | O7: 13381.807 | P7: 13436.664 | Q7: 13209.492 | R7: 13163.741 | S7: 12535.521 | T7: 12509.716 | U7: 12485.982 | V7: 12472.604 | W7: 12457.805 | X7: 12440.904 | Y7: 12414.448 | Z7: 12356.565 | AA7: 12312.771 | AB7: 12242.237 | AC7: 12197.9 | AD7: 12151.117 | AE7: 12116.594 | AF7: 12093.045 | AG7: 12078.826 | AH7: 12071.239 | AI7: 12067.028 | AJ7: 12079.382 | AK7: 12069.563 | AL7: 12053.585 | AM7: 12049.106 | AN7: 12034.996 | AO7: 12026.398 | AP7: 12004.585 | AQ7: 11995.355 | AR7: 11996.741 | AS7: 11984.056 | AT7: 11975.403 | AU7: 11953.063 | AV7: 11932.483 | AW7: 11910.745 | AX7: 11877.76 | AY7: 11850.026 | AZ7: 11803.54 | BA7: 11783.729
A8: Female | B8: HUA | C8: 6 | D8: 13661 | E8: 13827 | F8: 14205 | G8: 13631 | H8: 13780 | I8: 13259 | J8: 12470 | K8: 11876 | L8: 12331 | M8: 12359.976 | N8: 12980.913 | O8: 12807.813 | P8: 13631.697 | Q8: 13628.537 | R8: 13276.367 | S8: 13233.613 | T8: 12603.36 | U8: 12578.547 | V8: 12555.791 | W8: 12543.402 | X8: 12528.571 | Y8: 12511.641 | Z8: 12485.162 | AA8: 12427.221 | AB8: 12382.403 | AC8: 12311.82 | AD8: 12266.442 | AE8: 12220.621 | AF8: 12185.053 | AG8: 12163.463 | AH8: 12149.208 | AI8: 12138.599 | AJ8: 12136.341 | AK8: 12151.667 | AL8: 12138.81 | AM8: 12122.11 | AN8: 12118.031 | AO8: 12104.174 | AP8: 12099.539 | AQ8: 12076.702 | AR8: 12067.455 | AS8: 12069.817 | AT8: 12056.095 | AU8: 12044.426 | AV8: 12026.049 | AW8: 12004.452 | AX8: 11983.658 | AY8: 11949.641 | AZ8: 11921.882 | BA8: 11876.339
A9: Female | B9: HUA | C9: 7 | D9: 13279 | E9: 13430 | F9: 13791 | G9: 14169 | H9: 13559 | I9: 13749 | J9: 13235 | K9: 12448 | L9: 11893 | M9: 12342.978 | N9: 12382.917 | O9: 12998.83 | P9: 13375.697 | Q9: 13701.584 | R9: 13687.422 | S9: 13338.232 | T9: 13297.475 | U9: 12665.191 | V9: 12639.37 | W9: 12617.593 | X9: 12606.193 | Y9: 12592.047 | Z9: 12574.379 | AA9: 12547.871 | AB9: 12489.886 | AC9: 12446.032 | AD9: 12377.401 | AE9: 12328.997 | AF9: 12284.125 | AG9: 12249.528 | AH9: 12227.9 | AI9: 12212.594 | AJ9: 12204.959 | AK9: 12201.977 | AL9: 12217.676 | AM9: 12204.081 | AN9: 12187.36 | AO9: 12184.238 | AP9: 12170.356 | AQ9: 12166.709 | AR9: 12142.851 | AS9: 12133.563 | AT9: 12133.909 | AU9: 12123.167 | AV9: 12110.48 | AW9: 12095.042 | AX9: 12070.432 | AY9: 12050.611 | AZ9: 12016.535 | BA9: 11985.758
A10: Female | B10: HUA | C10: 8 | D10: 13748 | E10: 13199 | F10: 13454 | G10: 13770 | H10: 14145 | I10: 13584 | J10: 13771 | K10: 13285 | L10: 12478 | M10: 11965.977 | N10: 12453.922 | O10: 12425.833 | P10: 13419.726 | Q10: 13255.303 | R10: 13762.189 | S10: 13743.293 | T10: 13397.09 | U10: 13359.329 | V10: 12724.01 | W10: 12698.186 | X10: 12676.389 | Y10: 12665.271 | Z10: 12652.795 | AA10: 12634.105 | AB10: 12608.567 | AC10: 12552.536 | AD10: 12506.657 | AE10: 12436.982 | AF10: 12390.538 | AG10: 12345.631 | AH10: 12308.99 | AI10: 12290.323 | AJ10: 12273.985 | AK10: 12266.306 | AL10: 12264.601 | AM10: 12276.695 | AN10: 12263.343 | AO10: 12249.616 | AP10: 12246.453 | AQ10: 12233.545 | AR10: 12231.886 | AS10: 12207.005 | AT10: 12196.681 | AU10: 12197.006 | AV10: 12187.247 | AW10: 12175.514 | AX10: 12158.076 | AY10: 12132.426 | AZ10: 12113.577 | BA10: 12079.47
A11: Female | B11: HUA | C11: 9 | D11: 13755 | E11: 13723 | F11: 13249 | G11: 13478 | H11: 13808 | I11: 14254 | J11: 13658 | K11: 13870 | L11: 13437 | M11: 12630.981 | N11: 12136.925 | O11: 12639.846 | P11: 12674.74 | Q11: 13540.628 | R11: 13312.203 | S11: 13821.079 | T11: 13800.166 | U11: 13457.945 | V11: 13421.182 | W11: 12783.831 | X11: 12758.001 | Y11: 12736.185 | Z11: 12726.057 | AA11: 12713.552 | AB11: 12693.843 | AC11: 12667.278 | AD11: 12614.204 | AE11: 12567.304 | AF11: 12497.573 | AG11: 12448.109 | AH11: 12406.152 | AI11: 12368.485 | AJ11: 12351.781 | AK11: 12335.392 | AL11: 12324.694 | AM11: 12324.965 | AN11: 12334.039 | AO11: 12322.666 | AP11: 12307.205 | AQ11: 12306.435 | AR11: 12291.79 | AS11: 12290.121 | AT11: 12268.19 | AU11: 12257.85 | AV11: 12256.161 | AW11: 12245.388 | AX11: 12235.608 | AY11: 12218.144 | AZ11: 12194.474 | BA11: 12174.603
A12: Female | B12: HUA | C12: 10 | D12: 13907 | E12: 13665 | F12: 13796 | G12: 13275 | H12: 13523 | I12: 13837 | J12: 14326 | K12: 13780 | L12: 13995 | M12: 13547.983 | N12: 12797.933 | O12: 12219.855 | P12: 12851.762 | Q12: 12993.64 | R12: 13603.537 | S12: 13376.096 | T12: 13882.962 | U12: 13859.74 | V12: 13519.795 | W12: 13482.029 | X12: 12844.648 | Y12: 12820.81 | Z12: 12798.975 | AA12: 12790.839 | AB12: 12777.304 | AC12: 12756.577 | AD12: 12728.284 | AE12: 12676.871 | AF12: 12626.952 | AG12: 12557.166 | AH12: 12508.665 | AI12: 12466.674 | AJ12: 12428.982 | AK12: 12411.245 | AL12: 12395.805 | AM12: 12386.084 | AN12: 12384.336 | AO12: 12392.387 | AP12: 12381.974 | AQ12: 12368.491 | AR12: 12365.703 | AS12: 12354.009 | AT12: 12349.667 | AU12: 12328.102 | AV12: 12317.746 | AW12: 12318.317 | AX12: 12305.535 | AY12: 12295.736 | AZ12: 12279.219 | BA12: 12255.532
A13: Female | B13: HUA | C13: 11 | D13: 13353 | E13: 13580 | F13: 13735 | G13: 13895 | H13: 13342 | I13: 13631 | J13: 13981 | K13: 14510 | L13: 13921 | M13: 14157.984 | N13: 13806.941 | O13: 12986.866 | P13: 12413.771 | Q13: 13052.67 | R13: 13060.549 | S13: 13670.439 | T13: 13442.983 | U13: 13948.839 | V13: 13924.307 | W13: 13587.639 | X13: 13547.871 | Y13: 12908.452 | Z13: 12885.615 | AA13: 12863.752 | AB13: 12855.617 | AC13: 12842.044 | AD13: 12820.31 | AE13: 12792.992 | AF13: 12739.836 | AG13: 12690.301 | AH13: 12620.757 | AI13: 12572.221 | AJ13: 12531.197 | AK13: 12490.482 | AL13: 12471.694 | AM13: 12458.221 | AN13: 12448.479 | AO13: 12449.707 | AP13: 12455.735 | AQ13: 12443.286 | AR13: 12430.76 | AS13: 12426.976 | AT13: 12413.264 | AU13: 12407.893 | AV13: 12389.299 | AW13: 12377.93 | AX13: 12377.487 | AY13: 12364.975 | AZ13: 12357.155 | BA13: 12339.023
... A607: Male | B607: HUC | C607: 100 | D607: 197 | E607: 197 | F607: 197 | G607: 197 | H607: 197 | I607: 197 | J607: 197 | K607: 197 | L607: 197 | M607: 212 | N607: 244 | O607: 276 | P607: 285 | Q607: 298 | R607: 296.24958 | S607: 309.25307 | T607: 323.25923 | U607: 331.52249 | V607: 340.79688 | W607: 352.80549 | X607: 368.80998 | Y607: 378.80028 | Z607: 383.76396 | AA607: 391.98862 | AB607: 398.94425 | AC607: 401.90621 | AD607: 399.84311 | AE607: 406.84451 | AF607: 424.06442 | AG607: 443.03902 | AH607: 469.82534 | AI607: 498.02941 | AJ607: 534.83048 | AK607: 565.83859 | AL607: 605.86213 | AM607: 618.02356 | AN607: 641.16753 | AO607: 679.75194 | AP607: 720.60872 | AQ607: 756.58471 | AR607: 797.44507 | AS607: 830.56492 | AT607: 865.70719 | AU607: 939.27785 | AV607: 1022.151 | AW607: 1063.8332 | AX607: 1079.1253 | AY607: 1069.4156 | AZ607: 1063.5686 | BA607: 1057.6372
C608: Total: | D608: =SUM(D1:D607) -> 9986215 | E608: =SUM(E1:E607) -> 9934708 | F608: =SUM(F1:F607) -> 9897854 | G608: =SUM(G1:G607) -> 9852719 | H608: =SUM(H1:H607) -> 9818229 | I608: =SUM(I1:I607) -> 9781950 | J608: =SUM(J1:J607) -> 9742084 | K608: =SUM(K1:K607) -> 9715772 | ... BA608: =SUM(BA1:BA607) -> 9492669.7

Sheet HU_gdp_basepop_baseprod
A1: Year | B1: Value | F1: HU_projected_gdp_growth
A2: 1995 | B2: 49.625
A3: 1996 | B3: 51.401
A4: 1997 | B4: 56.591
A5: 1998 | B5: 56.639
A6: 1999 | B6: 58.284
A7: 2000 | B7: 62.092
A8: 2001 | B8: 69.866
A9: 2002 | B9: 79.723
A10: 2003 | B10: 80.504
A11: 2004 | B11: 85.303
A12: 2005 | B12: 88.815
A13: 2006 | B13: 86.428
... A28: 2021 | B28: 113.21
A29: 2022 | B29: 118.487 | F29: 0.026220697
A30: 2023 | B30: 121.59381 | E30: =B29*(1+F29) -> 121.59381 | F30: 0.027162977
A31: 2024 | B31: 124.89666 | E31: =E30*(1+F30) -> 124.89666 | F31: 0.026969373
A32: 2025 | B32: 128.26505 | E32: =E31*(1+F31) -> 128.26505 | F32: 0.026814979
A33: 2026 | B33: 131.70447 | E33: =E32*(1+F32) -> 131.70447 | F33: 0.026618014
A34: 2027 | B34: 135.21018 | E34: =E33*(1+F33) -> 135.21018 | F34: 0.026323083
A35: 2028 | B35: 138.76933 | E35: =E34*(1+F34) -> 138.76933 | F35: 0.026096196
A36: 2029 | B36: 142.39068 | E36: =E35*(1+F35) -> 142.39068 | F36: 0.02528574
A37: 2030 | B37: 145.99114 | E37: =E36*(1+F36) -> 145.99114 | F37: 0.024551167
A38: 2031 | B38: 149.57539 | E38: =E37*(1+F37) -> 149.57539 | F38: 0.024114878
A39: 2032 | B39: 153.18238 | E39: =E38*(1+F38) -> 153.18238 | F39: 0.023733478
A40: 2033 | B40: 156.81793 | E40: =E39*(1+F39) -> 156.81793 | F40: 0.022892236
A41: 2034 | B41: 160.40785 | E41: =E40*(1+F40) -> 160.40785 | F41: 0.022511634
A42: 2035 | B42: 164.01889 | E42: =E41*(1+F41) -> 164.01889 | F42: 0.022075337
... A47: 2040 | B47: 182.21441 | E47: =E46*(1+F46) -> 182.21441 | F47: 0.019802968

Sheet HU_gdp_basepop_highprod
A1: Year | B1: Value | F1: HU_projected_gdp_growth
A2: 1995 | B2: 49.625
A3: 1996 | B3: 51.401
A4: 1997 | B4: 56.591
A5: 1998 | B5: 56.639
A6: 1999 | B6: 58.284
A7: 2000 | B7: 62.092
A8: 2001 | B8: 69.866
A9: 2002 | B9: 79.723
A10: 2003 | B10: 80.504
A11: 2004 | B11: 85.303
A12: 2005 | B12: 88.815
A13: 2006 | B13: 86.428
... A28: 2021 | B28: 113.21
A29: 2022 | B29: 118.487 | F29: 0.034183324
A30: 2023 | B30: 122.53728 | E30: =B29*(1+F29) -> 122.53728 | F30: 0.035084524
A31: 2024 | B31: 126.83644 | E31: =E30*(1+F30) -> 126.83644 | F31: 0.034833733
A32: 2025 | B32: 131.25463 | E32: =E31*(1+F31) -> 131.25463 | F32: 0.034466486
A33: 2026 | B33: 135.77851 | E33: =E32*(1+F32) -> 135.77851 | F33: 0.034176311
A34: 2027 | B34: 140.41892 | E34: =E33*(1+F33) -> 140.41892 | F34: 0.033840152
A35: 2028 | B35: 145.17072 | E35: =E34*(1+F34) -> 145.17072 | F35: 0.034041827
A36: 2029 | B36: 150.1126 | E36: =E35*(1+F35) -> 150.1126 | F36: 0.033801473
A37: 2030 | B37: 155.18662 | E37: =E36*(1+F36) -> 155.18662 | F37: 0.033223709
A38: 2031 | B38: 160.3425 | E38: =E37*(1+F37) -> 160.3425 | F38: 0.032748316
A39: 2032 | B39: 165.59345 | E39: =E38*(1+F38) -> 165.59345 | F39: 0.032247327
A40: 2033 | B40: 170.93339 | E40: =E39*(1+F39) -> 170.93339 | F40: 0.031069121
A41: 2034 | B41: 176.24414 | E41: =E40*(1+F40) -> 176.24414 | F41: 0.030383065
A42: 2035 | B42: 181.59898 | E42: =E41*(1+F41) -> 181.59898 | F42: 0.029679551
... A47: 2040 | B47: 208.83121 | E47: =E46*(1+F46) -> 208.83121 | F47: 0.026159132

Sheet HU_gdp_highpop_baseprod_green
A1: Year | B1: Value
A2: 1995 | B2: 49.625
A3: 1996 | B3: 51.401
A4: 1997 | B4: 56.591
A5: 1998 | B5: 56.639
A6: 1999 | B6: 58.284
A7: 2000 | B7: 62.092
A8: 2001 | B8: 69.866
A9: 2002 | B9: 79.723
A10: 2003 | B10: 80.504
A11: 2004 | B11: 85.303
A12: 2005 | B12: 88.815
A13: 2006 | B13: 86.428
... A28: 2021 | B28: 113.21
A29: 2022 | B29: 118.487 | F29: 0.047362563
A30: 2023 | B30: 124.09885 | E30: =B29*(1+F29) -> 124.09885 | F30: 0.039119204
A31: 2024 | B31: 128.9535 | E31: =E30*(1+F30) -> 128.9535 | F31: 0.033368762
A32: 2025 | B32: 133.25651 | E32: =E31*(1+F31) -> 133.25651 | F32: 0.029763389
A33: 2026 | B33: 137.22268 | E33: =E32*(1+F32) -> 137.22268 | F33: 0.027730687
A34: 2027 | B34: 141.02796 | E34: =E33*(1+F33) -> 141.02796 | F34: 0.026496237
A35: 2028 | B35: 144.76467 | E35: =E34*(1+F34) -> 144.76467 | F35: 0.026111553
A36: 2029 | B36: 148.5447 | E36: =E35*(1+F35) -> 148.5447 | F36: 0.025467157
A37: 2030 | B37: 152.32771 | E37: =E36*(1+F36) -> 152.32771 | F37: 0.024738759
A38: 2031 | B38: 156.09611 | E38: =E37*(1+F37) -> 156.09611 | F38: 0.024310325
A39: 2032 | B39: 159.89086 | E39: =E38*(1+F38) -> 159.89086 | F39: 0.024397024
A40: 2033 | B40: 163.79172 | E40: =E39*(1+F39) -> 163.79172 | F40: 0.024055326
A41: 2034 | B41: 167.73178 | E41: =E40*(1+F40) -> 167.73178 | F41: 0.024007935
A42: 2035 | B42: 171.75867 | E42: =E41*(1+F41) -> 171.75867 | F42: 0.023803719
... A47: 2040 | B47: 192.65245 | E47: =E46*(1+F46) -> 192.65245 | F47: 0.021527636

Sheet HU_gdp_basepop_baseprod_green
A1: Year | B1: Value
A2: 1995 | B2: 49.625
A3: 1996 | B3: 51.401
A4: 1997 | B4: 56.591
A5: 1998 | B5: 56.639
A6: 1999 | B6: 58.284
A7: 2000 | B7: 62.092
A8: 2001 | B8: 69.866
A9: 2002 | B9: 79.723
A10: 2003 | B10: 80.504
A11: 2004 | B11: 85.303
A12: 2005 | B12: 88.815
A13: 2006 | B13: 86.428
... A28: 2021 | B28: 113.21
A29: 2022 | B29: 118.487 | F29: 0.046678557
A30: 2023 | B30: 124.0178 | E30: =B29*(1+F29) -> 124.0178 | F30: 0.038438281
A31: 2024 | B31: 128.78483 | E31: =E30*(1+F30) -> 128.78483 | F31: 0.032581723
A32: 2025 | B32: 132.98087 | E32: =E31*(1+F31) -> 132.98087 | F32: 0.028940507
A33: 2026 | B33: 136.8294 | E33: =E32*(1+F32) -> 136.8294 | F33: 0.026852167
A34: 2027 | B34: 140.50356 | E34: =E33*(1+F33) -> 140.50356 | F34: 0.02565182
A35: 2028 | B35: 144.10774 | E35: =E34*(1+F34) -> 144.10774 | F35: 0.0252611
A36: 2029 | B36: 147.74806 | E36: =E35*(1+F35) -> 147.74806 | F36: 0.024516431
A37: 2030 | B37: 151.37031 | E37: =E36*(1+F36) -> 151.37031 | F37: 0.023802144
A38: 2031 | B38: 154.97325 | E38: =E37*(1+F37) -> 154.97325 | F38: 0.02337112
A39: 2032 | B39: 158.59515 | E39: =E38*(1+F38) -> 158.59515 | F39: 0.023443971
A40: 2033 | B40: 162.31325 | E40: =E39*(1+F39) -> 162.31325 | F40: 0.023015658
A41: 2034 | B41: 166.04899 | E41: =E40*(1+F40) -> 166.04899 | F41: 0.023012675
A42: 2035 | B42: 169.87023 | E42: =E41*(1+F41) -> 169.87023 | F42: 0.02281418
... A47: 2040 | B47: 189.6754 | E47: =E46*(1+F46) -> 189.6754 | F47: 0.020561264

Sheet HU_gdp_basepop_highprod_green
A1: Year | B1: Value
A2: 1995 | B2: 49.625
A3: 1996 | B3: 51.401
A4: 1997 | B4: 56.591
A5: 1998 | B5: 56.639
A6: 1999 | B6: 58.284
A7: 2000 | B7: 62.092
A8: 2001 | B8: 69.866
A9: 2002 | B9: 79.723
A10: 2003 | B10: 80.504
A11: 2004 | B11: 85.303
A12: 2005 | B12: 88.815
A13: 2006 | B13: 86.428
... A28: 2021 | B28: 113.21
A29: 2022 | B29: 118.487 | F29: 0.054503498
A30: 2023 | B30: 124.94496 | E30: =B29*(1+F29) -> 124.94496 | F30: 0.046083314
A31: 2024 | B31: 130.70283 | E31: =E30*(1+F30) -> 130.70283 | F31: 0.040207775
A32: 2025 | B32: 135.9581 | E32: =E31*(1+F31) -> 135.9581 | F32: 0.036724317
A33: 2026 | B33: 140.95107 | E33: =E32*(1+F32) -> 140.95107 | F33: 0.034784789
A34: 2027 | B34: 145.85403 | E34: =E33*(1+F33) -> 145.85403 | F34: 0.033603356
A35: 2028 | B35: 150.75521 | E35: =E34*(1+F34) -> 150.75521 | F35: 0.033097322
A36: 2029 | B36: 155.7448 | E36: =E35*(1+F35) -> 155.7448 | F36: 0.032371195
A37: 2030 | B37: 160.78645 | E37: =E36*(1+F36) -> 160.78645 | F37: 0.031634273
A38: 2031 | B38: 165.87281 | E38: =E37*(1+F37) -> 165.87281 | F38: 0.031080582
A39: 2032 | B39: 171.02824 | E39: =E38*(1+F38) -> 171.02824 | F39: 0.03082276
A40: 2033 | B40: 176.2998 | E40: =E39*(1+F39) -> 176.2998 | F40: 0.030489847
A41: 2034 | B41: 181.67515 | E41: =E40*(1+F40) -> 181.67515 | F41: 0.030549342
A42: 2035 | B42: 187.22521 | E42: =E41*(1+F41) -> 187.22521 | F42: 0.030319664
... A47: 2040 | B47: 216.56375 | E47: =E46*(1+F46) -> 216.56375 | F47: 0.027293819

Sheet HU_gdp_lowpop_baseprod_green
A1: Year | B1: Value
A2: 1995 | B2: 49.625
A3: 1996 | B3: 51.401
A4: 1997 | B4: 56.591
A5: 1998 | B5: 56.639
A6: 1999 | B6: 58.284
A7: 2000 | B7: 62.092
A8: 2001 | B8: 69.866
A9: 2002 | B9: 79.723
A10: 2003 | B10: 80.504
A11: 2004 | B11: 85.303
A12: 2005 | B12: 88.815
A13: 2006 | B13: 86.428
... A28: 2021 | B28: 113.21
A29: 2022 | B29: 118.487 | F29: 0.04598876
A30: 2023 | B30: 123.93607 | E30: =B29*(1+F29) -> 123.93607 | F30: 0.037756465
A31: 2024 | B31: 128.61546 | E31: =E30*(1+F30) -> 128.61546 | F31: 0.031802446
A32: 2025 | B32: 132.70574 | E32: =E31*(1+F31) -> 132.70574 | F32: 0.028115118
A33: 2026 | B33: 136.43678 | E33: =E32*(1+F32) -> 136.43678 | F33: 0.02596437
A34: 2027 | B34: 139.97928 | E34: =E33*(1+F33) -> 139.97928 | F34: 0.024706079
A35: 2028 | B35: 143.43762 | E35: =E34*(1+F34) -> 143.43762 | F35: 0.024390677
A36: 2029 | B36: 146.93616 | E36: =E35*(1+F35) -> 146.93616 | F36: 0.023580569
A37: 2030 | B37: 150.40099 | E37: =E36*(1+F36) -> 150.40099 | F37: 0.022841311
A38: 2031 | B38: 153.83635 | E38: =E37*(1+F37) -> 153.83635 | F38: 0.022445322
A39: 2032 | B39: 157.28926 | E39: =E38*(1+F38) -> 157.28926 | F39: 0.022543335
A40: 2033 | B40: 160.83508 | E40: =E39*(1+F39) -> 160.83508 | F40: 0.021937975
A41: 2034 | B41: 164.36348 | E41: =E40*(1+F40) -> 164.36348 | F41: 0.021967263
A42: 2035 | B42: 167.97409 | E42: =E41*(1+F41) -> 167.97409 | F42: 0.021783226
... A47: 2040 | B47: 186.6059 | E47: =E46*(1+F46) -> 186.6059 | F47: 0.019441174

Sheet HU_wage_basepop_baseprod
A1: Year | B1: Value
A2: 2000 | B2: 94.248199
A3: 2001 | B3: 94.248199
A4: 2002 | B4: 94.248199
A5: 2003 | B5: 94.248199
A6: 2004 | B6: 94.248199
A7: 2005 | B7: 94.248199
A8: 2006 | B8: 94.248199
A9: 2007 | B9: 94.248199
A10: 2008 | B10: 94.248199
A11: 2009 | B11: 94.248199
A12: 2010 | B12: 94.248199
A13: 2011 | B13: 94.248199
... A23: 2021 | B23: 132.02655
A24: 2022 | B24: 134.31987 | F24: 0.030787325
A25: 2023 | B25: 138.45522 | E25: =B24*(1+F24) -> 138.45522 | F25: 0.031401085
A26: 2024 | B26: 142.80286 | E26: =B25*(1+F25) -> 142.80286 | F26: 0.031913798
A27: 2025 | B27: 137.23588 | E27: =B26*(1+F26) -> 147.36025 | F27: 0.032233188
A28: 2026 | B28: 142.32515 | E28: =B27*(1+F27) -> 141.65943 | F28: 0.032422071
A29: 2027 | B29: 147.54573 | E29: =B28*(1+F28) -> 146.93963 | F29: 0.032476404
A30: 2028 | B30: 152.89351 | E30: =B29*(1+F29) -> 152.33748 | F30: 0.032437861
A31: 2029 | B31: 158.36822 | E31: =B30*(1+F30) -> 157.85305 | F31: 0.032336197
A32: 2030 | B32: 163.97071 | E32: =B31*(1+F31) -> 163.48925 | F32: 0.032170849
A33: 2031 | B33: 169.70164 | E33: =B32*(1+F32) -> 169.24578 | F33: 0.031935637
A34: 2032 | B34: 175.55056 | E34: =B33*(1+F33) -> 175.12117 | F34: 0.031657403
A35: 2033 | B35: 181.51536 | E35: =B34*(1+F34) -> 181.10804 | F35: 0.031394774
A36: 2034 | B36: 187.60578 | E36: =B35*(1+F35) -> 187.214 | F36: 0.031063358
... A42: 2040 | B42: 226.49601 | E42: =B41*(1+F41) -> 226.179 | F42: 0.028940978

Sheet HU_wage_basepop_highprod
A1: Year | B1: Value
A2: 2000 | B2: 94.248199
A3: 2001 | B3: 94.248199
A4: 2002 | B4: 94.248199
A5: 2003 | B5: 94.248199
A6: 2004 | B6: 94.248199
A7: 2005 | B7: 94.248199
A8: 2006 | B8: 94.248199
A9: 2007 | B9: 94.248199
A10: 2008 | B10: 94.248199
A11: 2009 | B11: 94.248199
A12: 2010 | B12: 94.248199
A13: 2011 | B13: 94.248199
... A23: 2021 | B23: 132.02655
A24: 2022 | B24: 134.31987 | F24: 0.03253857
A25: 2023 | B25: 138.69045 | E25: =B24*(1+F24) -> 138.69045 | F25: 0.035137407
A26: 2024 | B26: 143.56367 | E26: =E25*(1+F25) -> 143.56367 | F26: 0.037203719
A27: 2025 | B27: 148.90477 | E27: =E26*(1+F26) -> 148.90477 | F27: 0.038714716
A28: 2026 | B28: 154.66958 | E28: =E27*(1+F27) -> 154.66958 | F28: 0.039796231
A29: 2027 | B29: 160.82484 | E29: =E28*(1+F28) -> 160.82484 | F29: 0.040503772
A30: 2028 | B30: 167.33886 | E30: =E29*(1+F29) -> 167.33886 | F30: 0.040930219
A31: 2029 | B31: 174.18807 | E31: =E30*(1+F30) -> 174.18807 | F31: 0.041162454
A32: 2030 | B32: 181.35808 | E32: =E31*(1+F31) -> 181.35808 | F32: 0.04120806
A33: 2031 | B33: 188.8315 | E33: =E32*(1+F32) -> 188.8315 | F33: 0.041082949
A34: 2032 | B34: 196.58925 | E34: =E33*(1+F33) -> 196.58925 | F34: 0.040832251
A35: 2033 | B35: 204.61643 | E35: =E34*(1+F34) -> 204.61643 | F35: 0.040522769
A36: 2034 | B36: 212.90806 | E36: =E35*(1+F35) -> 212.90806 | F36: 0.040098595
A37: 2035 | B37: 221.44537 | E37: =E36*(1+F36) -> 221.44537 | F37: 0.039626845
... A42: 2040 | B42: 267.5498 | E42: =E41*(1+F41) -> 267.5498 | F42: 0.036855944

Sheet HU_wage_highpop_baseprod_green
A1: Year | B1: Value
A2: 2000 | B2: 94.248199
A3: 2001 | B3: 94.248199
A4: 2002 | B4: 94.248199
A5: 2003 | B5: 94.248199
A6: 2004 | B6: 94.248199
A7: 2005 | B7: 94.248199
A8: 2006 | B8: 94.248199
A9: 2007 | B9: 94.248199
A10: 2008 | B10: 94.248199
A11: 2009 | B11: 94.248199
A12: 2010 | B12: 94.248199
A13: 2011 | B13: 94.248199
... A23: 2021 | B23: 132.02655
A24: 2022 | B24: 134.31987 | F24: 0.029048201
A25: 2023 | B25: 138.22162 | E25: =B24*(1+F24) -> 138.22162 | F25: 0.030544532
A26: 2024 | B26: 142.44354 | E26: =E25*(1+F25) -> 142.44354 | F26: 0.03148435
A27: 2025 | B27: 146.92828 | E27: =E26*(1+F26) -> 146.92828 | F27: 0.032031697
A28: 2026 | B28: 151.63464 | E28: =E27*(1+F27) -> 151.63464 | F28: 0.03234455
A29: 2027 | B29: 156.53919 | E29: =E28*(1+F28) -> 156.53919 | F29: 0.032488353
A30: 2028 | B30: 161.62489 | E30: =E29*(1+F29) -> 161.62489 | F30: 0.032504219
A31: 2029 | B31: 166.87839 | E31: =E30*(1+F30) -> 166.87839 | F31: 0.032434528
A32: 2030 | B32: 172.29101 | E32: =E31*(1+F31) -> 172.29101 | F32: 0.032260299
A33: 2031 | B33: 177.84917 | E33: =E32*(1+F32) -> 177.84917 | F33: 0.03199053
A34: 2032 | B34: 183.53866 | E34: =E33*(1+F33) -> 183.53866 | F34: 0.031695444
A35: 2033 | B35: 189.35599 | E35: =E34*(1+F34) -> 189.35599 | F35: 0.031435179
A36: 2034 | B36: 195.30843 | E36: =E35*(1+F35) -> 195.30843 | F36: 0.031108874
A37: 2035 | B37: 201.38426 | E37: =E36*(1+F36) -> 201.38426 | F37: 0.030783098
... A42: 2040 | B42: 233.56449 | E42: =E41*(1+F41) -> 233.56449 | F42: 0.029088247

Sheet HU_wage_basepop_baseprod_green
A1: Year | B1: Value
A2: 2000 | B2: 94.248199
A3: 2001 | B3: 94.248199
A4: 2002 | B4: 94.248199
A5: 2003 | B5: 94.248199
A6: 2004 | B6: 94.248199
A7: 2005 | B7: 94.248199
A8: 2006 | B8: 94.248199
A9: 2007 | B9: 94.248199
A10: 2008 | B10: 94.248199
A11: 2009 | B11: 94.248199
A12: 2010 | B12: 94.248199
A13: 2011 | B13: 94.248199
... A23: 2021 | B23: 132.02655
A24: 2022 | B24: 134.31987 | F24: 0.029058342
A25: 2023 | B25: 138.22298 | E25: =B24*(1+F24) -> 138.22298 | F25: 0.030535334
A26: 2024 | B26: 142.44367 | E26: =E25*(1+F25) -> 142.44367 | F26: 0.031478864
A27: 2025 | B27: 146.92763 | E27: =E26*(1+F26) -> 146.92763 | F27: 0.032030132
A28: 2026 | B28: 151.63374 | E28: =E27*(1+F27) -> 151.63374 | F28: 0.032345269
A29: 2027 | B29: 156.53838 | E29: =E28*(1+F28) -> 156.53838 | F29: 0.032478763
A30: 2028 | B30: 161.62255 | E30: =E29*(1+F29) -> 161.62255 | F30: 0.032487026
A31: 2029 | B31: 166.87319 | E31: =E30*(1+F30) -> 166.87319 | F31: 0.03242813
A32: 2030 | B32: 172.28457 | E32: =E31*(1+F31) -> 172.28457 | F32: 0.032265543
A33: 2031 | B33: 177.84343 | E33: =E32*(1+F32) -> 177.84343 | F33: 0.03199446
A34: 2032 | B34: 183.53343 | E34: =E33*(1+F33) -> 183.53343 | F34: 0.031693277
A35: 2033 | B35: 189.35021 | E35: =E34*(1+F34) -> 189.35021 | F35: 0.031443129
A36: 2034 | B36: 195.30397 | E36: =E35*(1+F35) -> 195.30397 | F36: 0.031113195
A37: 2035 | B37: 201.3805 | E37: =E36*(1+F36) -> 201.3805 | F37: 0.030787656
... A42: 2040 | B42: 233.57583 | E42: =E41*(1+F41) -> 233.57583 | F42: 0.029137364

Sheet HU_wage_basepop_highprod_green
A1: Year | B1: Value
A2: 2000 | B2: 94.248199
A3: 2001 | B3: 94.248199
A4: 2002 | B4: 94.248199
A5: 2003 | B5: 94.248199
A6: 2004 | B6: 94.248199
A7: 2005 | B7: 94.248199
A8: 2006 | B8: 94.248199
A9: 2007 | B9: 94.248199
A10: 2008 | B10: 94.248199
A11: 2009 | B11: 94.248199
A12: 2010 | B12: 94.248199
A13: 2011 | B13: 94.248199
... A23: 2021 | B23: 132.02655
A24: 2022 | B24: 134.31987 | F24: 0.030831564
A25: 2023 | B25: 138.46116 | E25: =B24*(1+F24) -> 138.46116 | F25: 0.034293209
A26: 2024 | B26: 143.20944 | E26: =E25*(1+F25) -> 143.20944 | F26: 0.036771149
A27: 2025 | B27: 148.47541 | E27: =E26*(1+F26) -> 148.47541 | F27: 0.038501437
A28: 2026 | B28: 154.19193 | E28: =E27*(1+F27) -> 154.19193 | F28: 0.03971115
A29: 2027 | B29: 160.31507 | E29: =E28*(1+F28) -> 160.31507 | F29: 0.04051429
A30: 2028 | B30: 166.81012 | E30: =E29*(1+F29) -> 166.81012 | F30: 0.041019067
A31: 2029 | B31: 173.65252 | E31: =E30*(1+F30) -> 173.65252 | F31: 0.041272849
A32: 2030 | B32: 180.81965 | E32: =E31*(1+F31) -> 180.81965 | F32: 0.041313928
A33: 2031 | B33: 188.29002 | E33: =E32*(1+F32) -> 188.29002 | F33: 0.041129226
A34: 2032 | B34: 196.03424 | E34: =E33*(1+F33) -> 196.03424 | F34: 0.040841039
A35: 2033 | B35: 204.04049 | E35: =E34*(1+F34) -> 204.04049 | F35: 0.040546204
A36: 2034 | B36: 212.31355 | E36: =E35*(1+F35) -> 212.31355 | F36: 0.040137268
A37: 2035 | B37: 220.83524 | E37: =E36*(1+F36) -> 220.83524 | F37: 0.039693848
... A42: 2040 | B42: 266.97227 | E42: =E41*(1+F41) -> 266.97227 | F42: 0.037085553

Sheet HU_wage_lowpop_baseprod_green
A1: Year | B1: Value
A2: 2000 | B2: 94.248199
A3: 2001 | B3: 94.248199
A4: 2002 | B4: 94.248199
A5: 2003 | B5: 94.248199
A6: 2004 | B6: 94.248199
A7: 2005 | B7: 94.248199
A8: 2006 | B8: 94.248199
A9: 2007 | B9: 94.248199
A10: 2008 | B10: 94.248199
A11: 2009 | B11: 94.248199
A12: 2010 | B12: 94.248199
A13: 2011 | B13: 94.248199
... A23: 2021 | B23: 132.02655
A24: 2022 | B24: 134.31987 | F24: 0.02906899
A25: 2023 | B25: 138.22441 | E25: =B24*(1+F24) -> 138.22441 | F25: 0.030528208
A26: 2024 | B26: 142.44416 | E26: =E25*(1+F25) -> 142.44416 | F26: 0.031475995
A27: 2025 | B27: 146.92773 | E27: =E26*(1+F26) -> 146.92773 | F27: 0.032030773
A28: 2026 | B28: 151.63394 | E28: =E27*(1+F27) -> 151.63394 | F28: 0.032344538
A29: 2027 | B29: 156.53847 | E29: =E28*(1+F28) -> 156.53847 | F29: 0.032476246
A30: 2028 | B30: 161.62225 | E30: =E29*(1+F29) -> 161.62225 | F30: 0.03246764
A31: 2029 | B31: 166.86974 | E31: =E30*(1+F30) -> 166.86974 | F31: 0.032419457
A32: 2030 | B32: 172.27957 | E32: =E31*(1+F31) -> 172.27957 | F32: 0.032275161
A33: 2031 | B33: 177.83992 | E33: =E32*(1+F32) -> 177.83992 | F33: 0.031999174
A34: 2032 | B34: 183.53065 | E34: =E33*(1+F33) -> 183.53065 | F34: 0.031688254
A35: 2033 | B35: 189.34641 | E35: =E34*(1+F34) -> 189.34641 | F35: 0.031456592
A36: 2034 | B36: 195.30261 | E36: =E35*(1+F35) -> 195.30261 | F36: 0.031115539
A37: 2035 | B37: 201.37955 | E37: =E36*(1+F36) -> 201.37955 | F37: 0.030793052
... A42: 2040 | B42: 233.58588 | E42: =E41*(1+F41) -> 233.58588 | F42: 0.029165906

Sheet HU_emp_basepop_baseprod
A1: year | B1: employed_share | E1: emplpyed quantity | F1: pop
A2: 2011 | B2: 0.48918823
A3: 2012 | B3: 0.48918823
A4: 2013 | B4: 0.48918823
A5: 2014 | B5: 0.48918823
A6: 2015 | B6: 0.48918823 | N6: year | O6: =population_bsl!N1 -> 2021 | P6: =population_bsl!O1 -> 2022 | Q6: =population_bsl!P1 -> 2023 | R6: =population_bsl!Q1 -> 2024 | S6: =population_bsl!R1 -> 2025 | T6: =population_bsl!S1 -> 2026 | U6: =population_bsl!T1 -> 2027 | V6: =population_bsl!U1 -> 2028 | ... AH6: =population_bsl!AG1 -> 2040
A7: 2016 | B7: 0.48918823 | N7: pop_bsl | O7: =population_bsl!N608 -> 9652763 | P7: =population_bsl!O608 -> 9611159 | Q7: =population_bsl!P608 -> 9604280 | R7: =population_bsl!Q608 -> 9715366 | S7: =population_bsl!R608 -> 9699245 | T7: =population_bsl!S608 -> 9683729 | U7: =population_bsl!T608 -> 9668350 | V7: =population_bsl!U608 -> 9652870 | ... AH7: =population_bsl!AG608 -> 9443179
A8: 2017 | B8: 0.48918823 | N8: pop_low | O8: =population_low!N608 -> 9629536.8 | P8: =population_low!O608 -> 9578149.9 | Q8: =population_low!P608 -> 9561319.7 | R8: =population_low!Q608 -> 9662718.3 | S8: =population_low!R608 -> 9637564.1 | T8: =population_low!S608 -> 9612781.2 | U8: =population_low!T608 -> 9587993 | V8: =population_low!U608 -> 9562961.5 | ... AH8: =population_low!AG608 -> 9229346.8
A9: 2018 | B9: 0.48918823 | N9: pop_high | O9: =population_high!N608 -> 9713695.7 | P9: =population_high!O608 -> 9679333.5 | Q9: =population_high!P608 -> 9679928.4 | R9: =population_high!Q608 -> 9799444 | S9: =population_high!R608 -> 9790873 | T9: =population_high!S608 -> 9783012.2 | U9: =population_high!T608 -> 9775340.1 | V9: =population_high!U608 -> 9767628.3 | ... AH9: =population_high!AG608 -> 9653661.9
A10: 2019 | B10: 0.48918823
A11: 2020 | B11: 0.48918823 | N11: {=TRANSPOSE(N6:AH9)} -> year | O11: pop_bsl | P11: pop_low | Q11: pop_high
A12: 2021 | B12: 0.48918823 | E12: 4722018 | F12: 9652763 | N12: 2021 | O12: 9652763 | P12: 9629536.8 | Q12: 9713695.7
A13: 2022 | B13: 0.48909252 | E13: 4700746 | F13: 9611159 | N13: 2022 | O13: 9611159 | P13: 9578149.9 | Q13: 9679333.5
A14: 2023 | B14: 0.4873521 | E14: 4680666 | F14: 9604280 | N14: 2023 | O14: 9604280 | P14: 9561319.7 | Q14: 9679928.4
A15: 2024 | B15: 0.47971677 | E15: 4660624 | F15: 9715366 | N15: 2024 | O15: 9715366 | P15: 9662718.3 | Q15: 9799444
A16: 2025 | B16: 0.47852137 | E16: 4641296 | F16: 9699245 | N16: 2025 | O16: 9699245 | P16: 9637564.1 | Q16: 9790873
A17: 2026 | B17: 0.47726325 | E17: 4621688 | F17: 9683729 | N17: 2026 | O17: 9683729 | P17: 9612781.2 | Q17: 9783012.2
A18: 2027 | B18: 0.47604121 | E18: 4602533 | F18: 9668350 | N18: 2027 | O18: 9668350 | P18: 9587993 | Q18: 9775340.1
A19: 2028 | B19: 0.47485629 | E19: 4583726 | F19: 9652870 | N19: 2028 | O19: 9652870 | P19: 9562961.5 | Q19: 9767628.3
A20: 2029 | B20: 0.47326445 | E20: 4560912 | F20: 9637132 | N20: 2029 | O20: 9637132 | P20: 9537517.3 | Q20: 9759714.4
A21: 2030 | B21: 0.47120668 | E21: 4533503 | F21: 9621050 | N21: 2030 | O21: 9621050 | P21: 9511564.8 | Q21: 9751491.7
A22: 2031 | B22: 0.46899516 | E22: 4504494 | F22: 9604564 | N22: 2031 | O22: 9604564 | P22: 9485054.1 | Q22: 9742912.8
A23: 2032 | B23: 0.46683501 | E23: 4475860 | F23: 9587670 | N23: 2032 | O23: 9587670 | P23: 9458012.3 | Q23: 9733934.2
... A31: 2040 | B31: 0.44542341 | E31: 4206213 | F31: 9443179 | N31: 2040 | O31: 9443179 | P31: 9229346.8 | Q31: 9653661.9

Sheet HU_emp_basepop_highprod
A1: year | B1: employed_share | E1: emplpyed quantity | F1: pop
A2: 2011 | B2: 0.48918833
A3: 2012 | B3: 0.48918833
A4: 2013 | B4: 0.48918833
A5: 2014 | B5: 0.48918833
A6: 2015 | B6: 0.48918833
A7: 2016 | B7: 0.48918833
A8: 2017 | B8: 0.48918833
A9: 2018 | B9: 0.48918833
A10: 2019 | B10: 0.48918833
A11: 2020 | B11: 0.48918833
A12: 2021 | B12: 0.48918833 | E12: 4722019 | F12: 9652763
A13: 2022 | B13: 0.48911801 | E13: 4700991 | F13: 9611159
A14: 2023 | B14: 0.48742009 | E14: 4681319 | F14: 9604280
A15: 2024 | B15: 0.47983596 | E15: 4661782 | F15: 9715366
A16: 2025 | B16: 0.47870035 | E16: 4643032 | F16: 9699245
A17: 2026 | B17: 0.4775239 | E17: 4624212 | F17: 9683729
A18: 2027 | B18: 0.47631519 | E18: 4605182 | F18: 9668350
A19: 2028 | B19: 0.47516138 | E19: 4586671 | F19: 9652870
A20: 2029 | B20: 0.47359723 | E20: 4564119 | F20: 9637132
A21: 2030 | B21: 0.47153928 | E21: 4536703 | F21: 9621050
A22: 2031 | B22: 0.46931677 | E22: 4507583 | F22: 9604564
A23: 2032 | B23: 0.46714781 | E23: 4478859 | F23: 9587670
... A31: 2040 | B31: 0.44495397 | E31: 4201780 | F31: 9443179

Sheet HU_emp_highpop_baseprod_green
A1: year | B1: employed_share | E1: emplpyed quantity | F1: pop_high
A2: 2011 | B2: 0.48611961
A3: 2012 | B3: 0.48611961
A4: 2013 | B4: 0.48611961
A5: 2014 | B5: 0.48611961
A6: 2015 | B6: 0.48611961
A7: 2016 | B7: 0.48611961
A8: 2017 | B8: 0.48611961
A9: 2018 | B9: 0.48611961
A10: 2019 | B10: 0.48611961
A11: 2020 | B11: 0.48611961
A12: 2021 | B12: 0.48611961 | E12: 4722018 | F12: 9713695.7
A13: 2022 | B13: 0.48616395 | E13: 4705743 | F13: 9679333.5
A14: 2023 | B14: 0.48465668 | E14: 4691442 | F14: 9679928.4
A15: 2024 | B15: 0.47733504 | E15: 4677618 | F15: 9799444
A16: 2025 | B16: 0.47645384 | E16: 4664899 | F16: 9790873
A17: 2026 | B17: 0.47560577 | E17: 4652857 | F17: 9783012.2
A18: 2027 | B18: 0.47480967 | E18: 4641426 | F18: 9775340.1
A19: 2028 | B19: 0.47415717 | E19: 4631391 | F19: 9767628.3
A20: 2029 | B20: 0.47311999 | E20: 4617516 | F20: 9759714.4
A21: 2030 | B21: 0.47158395 | E21: 4598647 | F21: 9751491.7
A22: 2031 | B22: 0.46990845 | E22: 4578277 | F22: 9742912.8
A23: 2032 | B23: 0.4683279 | E23: 4558673 | F23: 9733934.2
... A31: 2040 | B31: 0.45038308 | E31: 4347846 | F31: 9653661.9

Sheet HU_emp_basepop_baseprod_green
A1: year | B1: employed_share | E1: emplpyed quantity | F1: pop
A2: 2011 | B2: 0.48918823
A3: 2012 | B3: 0.48918823
A4: 2013 | B4: 0.48918823
A5: 2014 | B5: 0.48918823
A6: 2015 | B6: 0.48918823
A7: 2016 | B7: 0.48918823
A8: 2017 | B8: 0.48918823
A9: 2018 | B9: 0.48918823
A10: 2019 | B10: 0.48918823
A11: 2020 | B11: 0.48918823
A12: 2021 | B12: 0.48918823 | E12: 4722018 | F12: 9652763
A13: 2022 | B13: 0.48914517 | E13: 4701252 | F13: 9611159
A14: 2023 | B14: 0.48751609 | E14: 4682241 | F14: 9604280
A15: 2024 | B15: 0.48001156 | E15: 4663488 | F15: 9715366
A16: 2025 | B16: 0.47897213 | E16: 4645668 | F16: 9699245
A17: 2026 | B17: 0.47794295 | E17: 4628270 | F17: 9683729
A18: 2027 | B18: 0.47708627 | E18: 4612637 | F18: 9668350
A19: 2028 | B19: 0.47642401 | E19: 4598859 | F19: 9652870
A20: 2029 | B20: 0.4753382 | E20: 4580897 | F20: 9637132
A21: 2030 | B21: 0.4737168 | E21: 4557653 | F21: 9621050
A22: 2031 | B22: 0.47195916 | E22: 4532962 | F22: 9604564
A23: 2032 | B23: 0.47030853 | E23: 4509163 | F23: 9587670
... A31: 2040 | B31: 0.45126657 | E31: 4261391 | F31: 9443179

Sheet HU_emp_basepop_highprod_green
A1: year | B1: employed_share | E1: emplpyed quantity | F1: pop
A2: 2011 | B2: 0.48918833
A3: 2012 | B3: 0.48918833
A4: 2013 | B4: 0.48918833
A5: 2014 | B5: 0.48918833
A6: 2015 | B6: 0.48918833
A7: 2016 | B7: 0.48918833
A8: 2017 | B8: 0.48918833
A9: 2018 | B9: 0.48918833
A10: 2019 | B10: 0.48918833
A11: 2020 | B11: 0.48918833
A12: 2021 | B12: 0.48918833 | E12: 4722019 | F12: 9652763
A13: 2022 | B13: 0.48916598 | E13: 4701452 | F13: 9611159
A14: 2023 | B14: 0.48756315 | E14: 4682693 | F14: 9604280
A15: 2024 | B15: 0.48008505 | E15: 4664202 | F15: 9715366
A16: 2025 | B16: 0.479071 | E16: 4646627 | F16: 9699245
A17: 2026 | B17: 0.47806553 | E17: 4629457 | F17: 9683729
A18: 2027 | B18: 0.47716984 | E18: 4613445 | F18: 9668350
A19: 2028 | B19: 0.4763865 | E19: 4598497 | F19: 9652870
A20: 2029 | B20: 0.47517643 | E20: 4579338 | F20: 9637132
A21: 2030 | B21: 0.47342993 | E21: 4554893 | F21: 9621050
A22: 2031 | B22: 0.47154436 | E22: 4528978 | F22: 9604564
A23: 2032 | B23: 0.46974447 | E23: 4503755 | F23: 9587670
... A31: 2040 | B31: 0.44970502 | E31: 4246645 | F31: 9443179

Sheet HU_emp_lowpop_baseprod_green
A1: year | B1: employed_share | E1: emplpyed quantity | F1: pop_low
A2: 2011 | B2: 0.49036813
A3: 2012 | B3: 0.49036813
A4: 2013 | B4: 0.49036813
A5: 2014 | B5: 0.49036813
A6: 2015 | B6: 0.49036813
A7: 2016 | B7: 0.49036813
A8: 2017 | B8: 0.49036813
A9: 2018 | B9: 0.49036813
A10: 2019 | B10: 0.49036813
A11: 2020 | B11: 0.49036813
A12: 2021 | B12: 0.49036813 | E12: 4722018 | F12: 9629536.8
