Workbook

Sheet W1fa-comp
A1: ='W1fa-sel'!A1 -> REGRESSOR | B1: ='W1fa-sel'!B1 -> COEFFICIENT | D1: ='W1fa-sel_orig'!A1 -> REGRESSOR | E1: ='W1fa-sel_orig'!B1 -> COEFFICIENT | G1: comp
A2: ='W1fa-sel'!A2 -> labStatusC3StudentL1 | B2: ='W1fa-sel'!B2 -> -0.91632643 | D2: ='W1fa-sel_orig'!A2 -> 2.L1les_c3 | E2: ='W1fa-sel_orig'!B2 -> -0.91632643 | G2: =B2-E2 -> 0
A3: ='W1fa-sel'!A3 -> labStatusC3NotEmployedL1 | B3: ='W1fa-sel'!B3 -> -1.2525569 | D3: ='W1fa-sel_orig'!A3 -> 3.L1les_c3 | E3: ='W1fa-sel_orig'!B3 -> -1.2525569 | G3: =B3-E3 -> 0
A4: ='W1fa-sel'!A4 -> demAge | B4: ='W1fa-sel'!B4 -> 0.10930382 | D4: ='W1fa-sel_orig'!A4 -> dag | E4: ='W1fa-sel_orig'!B4 -> 0.10930382 | G4: =B4-E4 -> -1.6653345e-16
A5: ='W1fa-sel'!A5 -> demAgeSq | B5: ='W1fa-sel'!B5 -> -0.0018005293 | D5: ='W1fa-sel_orig'!A5 -> dagsq | E5: ='W1fa-sel_orig'!B5 -> -0.0018005293 | G5: =B5-E5 -> 1.7347235e-18
A6: ='W1fa-sel'!A6 -> eduHighestC4Medium | B6: ='W1fa-sel'!B6 -> -0.62383639 | D6: ='W1fa-sel_orig'!A6 -> 2.deh_c4 | E6: ='W1fa-sel_orig'!B6 -> -0.62383639 | G6: =B6-E6 -> -1.2212453e-15
A7: ='W1fa-sel'!A7 -> eduHighestC4Low | B7: ='W1fa-sel'!B7 -> -1.3754651 | D7: ='W1fa-sel_orig'!A7 -> 3.deh_c4 | E7: ='W1fa-sel_orig'!B7 -> -1.3754651 | G7: =B7-E7 -> 0
A8: ='W1fa-sel'!A8 -> eduHighestC4Medium_demAge | B8: ='W1fa-sel'!B8 -> 0.0097372249 | D8: ='W1fa-sel_orig'!A8 -> 2.deh_c4#c.dag | E8: ='W1fa-sel_orig'!B8 -> 0.0097372249 | G8: =B8-E8 -> 2.2551405e-17
A9: ='W1fa-sel'!A9 -> eduHighestC4Low_demAge | B9: ='W1fa-sel'!B9 -> 0.019542708 | D9: ='W1fa-sel_orig'!A9 -> 3.deh_c4#c.dag | E9: ='W1fa-sel_orig'!B9 -> 0.019542708 | G9: =B9-E9 -> 0
A10: ='W1fa-sel'!A10 -> eduHighestParentC3Medium | B10: ='W1fa-sel'!B10 -> 0.037092352 | D10: ='W1fa-sel_orig'!A10 -> 2.dehmf_c3 | E10: ='W1fa-sel_orig'!B10 -> 0.037092352 | G10: =B10-E10 -> -3.0531133e-16
A11: ='W1fa-sel'!A11 -> eduHighestParentC3Low | B11: ='W1fa-sel'!B11 -> -0.02390819 | D11: ='W1fa-sel_orig'!A11 -> 3.dehmf_c3 | E11: ='W1fa-sel_orig'!B11 -> -0.02390819 | G11: =B11-E11 -> -2.810252e-16
A12: ='W1fa-sel'!A12 -> demPartnerStatusPartnered | B12: ='W1fa-sel'!B12 -> -0.23181046 | D12: ='W1fa-sel_orig'!A12 -> mar | E12: ='W1fa-sel_orig'!B12 -> -0.23181046 | G12: =B12-E12 -> 0
A13: ='W1fa-sel'!A13 -> demDChild | B13: ='W1fa-sel'!B13 -> -0.31875706 | D13: ='W1fa-sel_orig'!A13 -> child | E13: ='W1fa-sel_orig'!B13 -> -0.31875706 | G13: =B13-E13 -> 0
... A33: ='W1fa-sel'!A33 -> Constant | B33: ='W1fa-sel'!B33 -> -0.46035827 | D33: ='W1fa-sel_orig'!A33 -> Constant | E33: ='W1fa-sel_orig'!B33 -> -0.46035827 | G33: =B33-E33 -> 4.6629367e-15

Sheet W1ma-comp
A1: ='W1ma-sel'!A1 -> REGRESSOR | B1: ='W1ma-sel'!B1 -> COEFFICIENT | D1: ='W1ma-sel'!A1 -> REGRESSOR | E1: ='W1ma-sel'!B1 -> COEFFICIENT | G1: comp
A2: ='W1ma-sel'!A2 -> labStatusC3StudentL1 | B2: ='W1ma-sel'!B2 -> -0.96830341 | D2: ='W1ma-sel'!A2 -> labStatusC3StudentL1 | E2: ='W1ma-sel'!B2 -> -0.96830341 | G2: =B2-E2 -> 0
A3: ='W1ma-sel'!A3 -> labStatusC3NotEmployedL1 | B3: ='W1ma-sel'!B3 -> -0.92025867 | D3: ='W1ma-sel'!A3 -> labStatusC3NotEmployedL1 | E3: ='W1ma-sel'!B3 -> -0.92025867 | G3: =B3-E3 -> 0
A4: ='W1ma-sel'!A4 -> demAge | B4: ='W1ma-sel'!B4 -> 0.092226677 | D4: ='W1ma-sel'!A4 -> demAge | E4: ='W1ma-sel'!B4 -> 0.092226677 | G4: =B4-E4 -> 0
A5: ='W1ma-sel'!A5 -> demAgeSq | B5: ='W1ma-sel'!B5 -> -0.0016780219 | D5: ='W1ma-sel'!A5 -> demAgeSq | E5: ='W1ma-sel'!B5 -> -0.0016780219 | G5: =B5-E5 -> 0
A6: ='W1ma-sel'!A6 -> eduHighestC4Medium | B6: ='W1ma-sel'!B6 -> -0.59930774 | D6: ='W1ma-sel'!A6 -> eduHighestC4Medium | E6: ='W1ma-sel'!B6 -> -0.59930774 | G6: =B6-E6 -> 0
A7: ='W1ma-sel'!A7 -> eduHighestC4Low | B7: ='W1ma-sel'!B7 -> -1.350879 | D7: ='W1ma-sel'!A7 -> eduHighestC4Low | E7: ='W1ma-sel'!B7 -> -1.350879 | G7: =B7-E7 -> 0
A8: ='W1ma-sel'!A8 -> eduHighestC4Medium_demAge | B8: ='W1ma-sel'!B8 -> 0.01124915 | D8: ='W1ma-sel'!A8 -> eduHighestC4Medium_demAge | E8: ='W1ma-sel'!B8 -> 0.01124915 | G8: =B8-E8 -> 0
A9: ='W1ma-sel'!A9 -> eduHighestC4Low_demAge | B9: ='W1ma-sel'!B9 -> 0.022697016 | D9: ='W1ma-sel'!A9 -> eduHighestC4Low_demAge | E9: ='W1ma-sel'!B9 -> 0.022697016 | G9: =B9-E9 -> 0
A10: ='W1ma-sel'!A10 -> eduHighestParentC3Medium | B10: ='W1ma-sel'!B10 -> 0.069201601 | D10: ='W1ma-sel'!A10 -> eduHighestParentC3Medium | E10: ='W1ma-sel'!B10 -> 0.069201601 | G10: =B10-E10 -> 0
A11: ='W1ma-sel'!A11 -> eduHighestParentC3Low | B11: ='W1ma-sel'!B11 -> 0.073676503 | D11: ='W1ma-sel'!A11 -> eduHighestParentC3Low | E11: ='W1ma-sel'!B11 -> 0.073676503 | G11: =B11-E11 -> 0
A12: ='W1ma-sel'!A12 -> demPartnerStatusPartnered | B12: ='W1ma-sel'!B12 -> 0.091560656 | D12: ='W1ma-sel'!A12 -> demPartnerStatusPartnered | E12: ='W1ma-sel'!B12 -> 0.091560656 | G12: =B12-E12 -> 0
A13: ='W1ma-sel'!A13 -> demDChild | B13: ='W1ma-sel'!B13 -> -0.07748175 | D13: ='W1ma-sel'!A13 -> demDChild | E13: ='W1ma-sel'!B13 -> -0.07748175 | G13: =B13-E13 -> 0
... A33: ='W1ma-sel'!A33 -> Constant | B33: ='W1ma-sel'!B33 -> -0.68633511 | D33: ='W1ma-sel'!A33 -> Constant | E33: ='W1ma-sel'!B33 -> -0.68633511 | G33: =B33-E33 -> 0

Sheet W1fb-comp
A1: ='W1fb-sel'!A1 -> REGRESSOR | B1: ='W1fb-sel'!B1 -> COEFFICIENT | D1: ='W1fb-sel_orig'!A1 -> REGRESSOR | E1: ='W1fb-sel_orig'!B1 -> COEFFICIENT | G1: comp
A2: ='W1fb-sel'!A2 -> demAge | B2: ='W1fb-sel'!B2 -> 0.15250301 | D2: ='W1fb-sel_orig'!A2 -> dag | E2: ='W1fb-sel_orig'!B2 -> 0.15250301 | G2: =B2-E2 -> 0
A3: ='W1fb-sel'!A3 -> demAgeSq | B3: ='W1fb-sel'!B3 -> -0.0018789539 | D3: ='W1fb-sel_orig'!A3 -> dagsq | E3: ='W1fb-sel_orig'!B3 -> -0.0018789539 | G3: =B3-E3 -> 0
A4: ='W1fb-sel'!A4 -> eduHighestC4Medium | B4: ='W1fb-sel'!B4 -> -0.34491004 | D4: ='W1fb-sel_orig'!A4 -> 2.deh_c4 | E4: ='W1fb-sel_orig'!B4 -> -0.34491004 | G4: =B4-E4 -> 0
A5: ='W1fb-sel'!A5 -> eduHighestC4Low | B5: ='W1fb-sel'!B5 -> -0.77460153 | D5: ='W1fb-sel_orig'!A5 -> 3.deh_c4 | E5: ='W1fb-sel_orig'!B5 -> -0.77460153 | G5: =B5-E5 -> 0
A6: ='W1fb-sel'!A6 -> eduHighestC4Medium_demAge | B6: ='W1fb-sel'!B6 -> 0.0086512476 | D6: ='W1fb-sel_orig'!A6 -> 2.deh_c4#c.dag | E6: ='W1fb-sel_orig'!B6 -> 0.0086512476 | G6: =B6-E6 -> 0
A7: ='W1fb-sel'!A7 -> eduHighestC4Low_demAge | B7: ='W1fb-sel'!B7 -> 0.015629343 | D7: ='W1fb-sel_orig'!A7 -> 3.deh_c4#c.dag | E7: ='W1fb-sel_orig'!B7 -> 0.015629343 | G7: =B7-E7 -> 0
A8: ='W1fb-sel'!A8 -> eduHighestParentC3Medium | B8: ='W1fb-sel'!B8 -> 0.1332376 | D8: ='W1fb-sel_orig'!A8 -> 2.dehmf_c3 | E8: ='W1fb-sel_orig'!B8 -> 0.1332376 | G8: =B8-E8 -> 0
A9: ='W1fb-sel'!A9 -> eduHighestParentC3Low | B9: ='W1fb-sel'!B9 -> 0.12734034 | D9: ='W1fb-sel_orig'!A9 -> 3.dehmf_c3 | E9: ='W1fb-sel_orig'!B9 -> 0.12734034 | G9: =B9-E9 -> 0
A10: ='W1fb-sel'!A10 -> demPartnerStatusPartnered | B10: ='W1fb-sel'!B10 -> -0.052543122 | D10: ='W1fb-sel_orig'!A10 -> mar | E10: ='W1fb-sel_orig'!B10 -> -0.052543122 | G10: =B10-E10 -> 0
A11: ='W1fb-sel'!A11 -> demDChild | B11: ='W1fb-sel'!B11 -> -0.12044651 | D11: ='W1fb-sel_orig'!A11 -> child | E11: ='W1fb-sel_orig'!B11 -> -0.12044651 | G11: =B11-E11 -> 0
A12: ='W1fb-sel'!A12 -> healthDsblLongtermFlag | B12: ='W1fb-sel'!B12 -> -0.79677687 | D12: ='W1fb-sel_orig'!A12 -> dlltsd01 | E12: ='W1fb-sel_orig'!B12 -> -0.79677687 | G12: =B12-E12 -> 0
A13: ='W1fb-sel'!A13 -> healthPhysicalPcsL1 | B13: ='W1fb-sel'!B13 -> 0.0052448758 | D13: ='W1fb-sel_orig'!A13 -> dhe_pcs_L1 | E13: ='W1fb-sel_orig'!B13 -> 0.0052448758 | G13: =B13-E13 -> 0
... A31: ='W1fb-sel'!A31 -> Constant | B31: ='W1fb-sel'!B31 -> -1.9006756 | D31: ='W1fb-sel_orig'!A31 -> Constant | E31: ='W1fb-sel_orig'!B31 -> -1.9006756 | G31: =B31-E31 -> 0

Sheet W1mb-comp
A1: ='W1mb-sel'!A1 -> REGRESSOR | B1: ='W1mb-sel'!B1 -> COEFFICIENT | D1: ='W1mb-sel_orig'!A1 -> REGRESSOR | E1: ='W1mb-sel_orig'!B1 -> COEFFICIENT | G1: comp
A2: ='W1mb-sel'!A2 -> demAge | B2: ='W1mb-sel'!B2 -> 0.13037744 | D2: ='W1mb-sel_orig'!A2 -> dag | E2: ='W1mb-sel_orig'!B2 -> 0.13037744 | G2: =B2-E2 -> 0
A3: ='W1mb-sel'!A3 -> demAgeSq | B3: ='W1mb-sel'!B3 -> -0.0016715073 | D3: ='W1mb-sel_orig'!A3 -> dagsq | E3: ='W1mb-sel_orig'!B3 -> -0.0016715073 | G3: =B3-E3 -> 0
A4: ='W1mb-sel'!A4 -> eduHighestC4Medium | B4: ='W1mb-sel'!B4 -> -0.24263388 | D4: ='W1mb-sel_orig'!A4 -> 2.deh_c4 | E4: ='W1mb-sel_orig'!B4 -> -0.24263388 | G4: =B4-E4 -> 0
A5: ='W1mb-sel'!A5 -> eduHighestC4Low | B5: ='W1mb-sel'!B5 -> -0.70361218 | D5: ='W1mb-sel_orig'!A5 -> 3.deh_c4 | E5: ='W1mb-sel_orig'!B5 -> -0.70361218 | G5: =B5-E5 -> 0
A6: ='W1mb-sel'!A6 -> eduHighestC4Medium_demAge | B6: ='W1mb-sel'!B6 -> 0.0079120636 | D6: ='W1mb-sel_orig'!A6 -> 2.deh_c4#c.dag | E6: ='W1mb-sel_orig'!B6 -> 0.0079120636 | G6: =B6-E6 -> 0
A7: ='W1mb-sel'!A7 -> eduHighestC4Low_demAge | B7: ='W1mb-sel'!B7 -> 0.015069055 | D7: ='W1mb-sel_orig'!A7 -> 3.deh_c4#c.dag | E7: ='W1mb-sel_orig'!B7 -> 0.015069055 | G7: =B7-E7 -> 0
A8: ='W1mb-sel'!A8 -> eduHighestParentC3Medium | B8: ='W1mb-sel'!B8 -> 0.13765043 | D8: ='W1mb-sel_orig'!A8 -> 2.dehmf_c3 | E8: ='W1mb-sel_orig'!B8 -> 0.13765043 | G8: =B8-E8 -> 0
A9: ='W1mb-sel'!A9 -> eduHighestParentC3Low | B9: ='W1mb-sel'!B9 -> 0.13895488 | D9: ='W1mb-sel_orig'!A9 -> 3.dehmf_c3 | E9: ='W1mb-sel_orig'!B9 -> 0.13895488 | G9: =B9-E9 -> 0
A10: ='W1mb-sel'!A10 -> demPartnerStatusPartnered | B10: ='W1mb-sel'!B10 -> 0.13249974 | D10: ='W1mb-sel_orig'!A10 -> mar | E10: ='W1mb-sel_orig'!B10 -> 0.13249974 | G10: =B10-E10 -> 0
A11: ='W1mb-sel'!A11 -> demDChild | B11: ='W1mb-sel'!B11 -> 0.00525531 | D11: ='W1mb-sel_orig'!A11 -> child | E11: ='W1mb-sel_orig'!B11 -> 0.00525531 | G11: =B11-E11 -> 0
A12: ='W1mb-sel'!A12 -> healthDsblLongtermFlag | B12: ='W1mb-sel'!B12 -> -0.9038271 | D12: ='W1mb-sel_orig'!A12 -> dlltsd01 | E12: ='W1mb-sel_orig'!B12 -> -0.9038271 | G12: =B12-E12 -> 0
A13: ='W1mb-sel'!A13 -> healthPhysicalPcsL1 | B13: ='W1mb-sel'!B13 -> 0.0036367173 | D13: ='W1mb-sel_orig'!A13 -> dhe_pcs_L1 | E13: ='W1mb-sel_orig'!B13 -> 0.0036367173 | G13: =B13-E13 -> 0
... A31: ='W1mb-sel'!A31 -> Constant | B31: ='W1mb-sel'!B31 -> -1.5287501 | D31: ='W1mb-sel_orig'!A31 -> Constant | E31: ='W1mb-sel_orig'!B31 -> -1.5287501 | G31: =B31-E31 -> 0

Sheet Info
A1: Description: | B1: This file contains regression estimates from the first stage of the Heckman selection model used to estimates wages.
A2: Authors: | B2: Patryk Bronka, Justin Van de Ven, Daria Popova, Aleksandra Kolndrekaj, Ashley Burdett
A3: Last edit: 19 May 2026 (DP)
A5: Process: | B5: Description:
A6: W1fa-sel | B6: First stage Heckman selection estimates for women that do not have an observed wage in the previous year
A7: W1ma-sel | B7: First stage Heckman selection estimates for women that do not have an observed wage in the previous year
A8: W1fb-sel | B8: First stage Heckman selection estimates for women that have an observed wage in the previous year
A9: W1mb-sel | B9: First stage Heckman selection estimates for men that have an observed wage in the previous year
A11: Notes: | B11: Estimated on panel data unlike the labour supply estimates
B12: Predicted wages used as input into union parameters and income process estimates
B13: Two-step Heckman command is used which does not permit weights

Sheet W1fa-sel_orig
A1: REGRESSOR | B1: COEFFICIENT | C1: 2.L1les_c3 | D1: 3.L1les_c3 | E1: dag | F1: dagsq | G1: 2.deh_c4 | H1: 3.deh_c4 | I1: 2.deh_c4#c.dag | J1: 3.deh_c4#c.dag | K1: 2.dehmf_c3 | L1: 3.dehmf_c3 | M1: mar | N1: child | O1: dlltsd01 | P1: dhe_pcs_L1 | Q1: dhe_mcs_L1 | R1: drgn1 | S1: 2.drgn1 | T1: 4.drgn1 | U1: 5.drgn1 | V1: 6.drgn1 | W1: 7.drgn1 | X1: 9.drgn1 | Y1: 10.drgn1 | Z1: 1drgn1 | AA1: 12.drgn1 | AB1: 13.drgn1 | AC1: y2020 | AD1: y2021 | AE1: 2.dot | AF1: 3.dot | AG1: 4.dot | AH1: Constant
A2: 2.L1les_c3 | B2: -0.91632643 | C2: 0.0018440613 | D2: 0.0011590531 | E2: 5.6926033e-05 | F2: -4.6317181e-07 | G2: 0.00030455872 | H2: 0.00041616822 | I2: -8.2858177e-06 | J2: -1.090373e-05 | K2: 2.1557553e-05 | L2: 1.7812116e-05 | M2: 5.5976833e-05 | N2: 3.4036048e-05 | O2: 4.860501e-06 | P2: 1.414367e-06 | Q2: 8.487742e-07 | R2: -6.1954695e-05 | S2: -3.8208045e-05 | T2: -3.3639575e-05 | U2: -3.5809529e-05 | V2: -3.5223545e-05 | W2: -3.5639559e-05 | X2: -1.6737617e-05 | Y2: -3.7438245e-05 | Z2: -3.692573e-05 | AA2: -6.8086331e-05 | AB2: -7.4377266e-05 | AC2: 1.7820729e-06 | AD2: -6.7850657e-07 | AE2: -2.6470739e-05 | AF2: -8.7085972e-05 | AG2: -1.2025198e-06 | AH2: -0.002750099
A3: 3.L1les_c3 | B3: -1.2525569 | C3: 0.0011590531 | D3: 0.0012126414 | E3: 1.4639582e-05 | F3: -1.0409824e-07 | G3: 9.3653653e-05 | H3: 8.4237937e-05 | I3: -4.9195952e-06 | J3: -5.5131612e-06 | K3: -2.2672594e-05 | L3: -3.0208749e-05 | M3: 1.0428691e-05 | N3: -3.0404641e-05 | O3: -3.3827781e-05 | P3: 2.2537224e-06 | Q3: 1.2458268e-06 | R3: -6.7297918e-05 | S3: -2.8577574e-05 | T3: -4.6248393e-05 | U3: -4.6857512e-05 | V3: -3.5419869e-05 | W3: -3.2242616e-05 | X3: -1.0602849e-05 | Y3: -3.9407214e-05 | Z3: -4.5838303e-05 | AA3: -3.8464997e-05 | AB3: -6.720708e-05 | AC3: 1.56094e-05 | AD3: 9.0049524e-06 | AE3: -4.1553749e-05 | AF3: -4.3607069e-05 | AG3: -3.7076572e-07 | AH3: -0.0015349063
A4: dag | B4: 0.10930382 | C4: 5.6926033e-05 | D4: 1.4639582e-05 | E4: 1.9324138e-05 | F4: -2.0124958e-07 | G4: 0.00011210194 | H4: 6.2813892e-05 | I4: -2.3442554e-06 | J4: -1.2502327e-06 | K4: -3.6640582e-06 | L4: -7.6265466e-06 | M4: -2.2308507e-05 | N4: -2.0763157e-05 | O4: -2.7066164e-05 | P4: 1.507698e-07 | Q4: 2.2717694e-07 | R4: 4.2885349e-06 | S4: 3.4363803e-06 | T4: 6.4273253e-06 | U4: 3.74169e-06 | V4: 2.4395899e-06 | W4: 2.863142e-06 | X4: 3.4290818e-06 | Y4: 6.8888014e-06 | Z4: 5.0957062e-06 | AA4: 2.601902e-06 | AB4: 1.593674e-06 | AC4: 2.1038687e-06 | AD4: -3.0456758e-07 | AE4: -4.0934549e-06 | AF4: -1.272287e-05 | AG4: -1.8732446e-06 | AH4: -0.0004301722
A5: dagsq | B5: -0.0018005293 | C5: -4.6317181e-07 | D5: -1.0409824e-07 | E5: -2.0124958e-07 | F5: 2.2885869e-09 | G5: -6.518297e-07 | H5: -5.6203592e-08 | I5: 1.1794439e-08 | J5: -1.3436107e-09 | K5: 3.2061447e-08 | L5: 4.2252423e-08 | M5: 2.2177347e-07 | N5: 2.9171666e-07 | O5: 3.2661499e-07 | P5: -4.4610899e-10 | Q5: -3.605892e-09 | R5: -2.8852646e-08 | S5: -2.9880313e-08 | T5: -5.656426e-08 | U5: -2.8813413e-08 | V5: -1.6740078e-08 | W5: -2.5966232e-08 | X5: -4.0555355e-08 | Y5: -8.3709394e-08 | Z5: -4.4523128e-08 | AA5: -2.8757965e-08 | AB5: -3.8497152e-09 | AC5: -3.3620783e-08 | AD5: -1.1903547e-08 | AE5: 1.007099e-07 | AF5: 1.5125013e-07 | AG5: 4.7706274e-08 | AH5: 4.0260586e-06
A6: 2.deh_c4 | B6: -0.62383639 | C6: 0.00030455872 | D6: 9.3653653e-05 | E6: 0.00011210194 | F6: -6.518297e-07 | G6: 0.0034042638 | H6: 0.0025495641 | I6: -7.3612803e-05 | J6: -5.4043835e-05 | K6: -7.9757688e-05 | L6: -0.00010231662 | M6: 3.4905455e-05 | N6: -0.00013273846 | O6: -5.7954379e-05 | P6: 1.0854719e-06 | Q6: 5.4672082e-07 | R6: 1.9134007e-05 | S6: 2.3588738e-06 | T6: -9.224521e-06 | U6: -1.6940205e-05 | V6: -6.9860664e-07 | W6: -8.4074696e-06 | X6: 1.4827142e-05 | Y6: -1.8106914e-05 | Z6: -7.5786921e-06 | AA6: -9.2353199e-06 | AB6: -3.7741531e-06 | AC6: 8.6546024e-06 | AD6: -8.4576084e-06 | AE6: 0.00010270089 | AF6: 3.6551333e-05 | AG6: 3.139982e-05 | AH6: -0.0037549709
A7: 3.deh_c4 | B7: -1.3754651 | C7: 0.00041616822 | D7: 8.4237937e-05 | E7: 6.2813892e-05 | F7: -5.6203592e-08 | G7: 0.0025495641 | H7: 0.0078182288 | I7: -5.4434978e-05 | J7: -0.00015687271 | K7: -0.00013518895 | L7: -0.00016224572 | M7: 4.4492519e-05 | N7: -0.00012999113 | O7: -0.00010502528 | P7: -4.6123368e-07 | Q7: -7.6337069e-07 | R7: 4.7052542e-05 | S7: -1.6476872e-05 | T7: 1.132229e-05 | U7: 7.163457e-06 | V7: 5.7348181e-06 | W7: -2.2558314e-05 | X7: 5.3081061e-06 | Y7: -2.9894511e-05 | Z7: -1.9553332e-05 | AA7: 6.1223552e-06 | AB7: -6.0433385e-05 | AC7: 4.4661125e-07 | AD7: 5.2719339e-06 | AE7: 5.8678562e-05 | AF7: -5.3195926e-05 | AG7: 4.5197207e-05 | AH7: -0.002666986
A8: 2.deh_c4#c.dag | B8: 0.0097372249 | C8: -8.2858177e-06 | D8: -4.9195952e-06 | E8: -2.3442554e-06 | F8: 1.1794439e-08 | G8: -7.3612803e-05 | H8: -5.4434978e-05 | I8: 1.8109908e-06 | J8: 1.3121915e-06 | K8: 1.5117233e-07 | L8: -2.7906065e-07 | M8: -5.9166359e-07 | N8: 2.5392477e-06 | O8: 6.6855463e-07 | P8: -1.7020164e-09 | Q8: 3.657087e-09 | R8: -9.0898276e-07 | S8: -3.7014507e-07 | T8: -3.8317615e-07 | U8: -1.8547857e-07 | V8: -5.0729389e-07 | W8: -4.3990891e-07 | X8: -2.8895601e-07 | Y8: 2.807439e-07 | Z8: -3.9733399e-07 | AA8: -6.1316559e-08 | AB8: -2.2187075e-07 | AC8: 1.1518726e-07 | AD8: 4.4802298e-07 | AE8: -1.5708258e-06 | AF8: -9.769195e-07 | AG8: -5.7801596e-07 | AH8: 7.9207172e-05
A9: 3.deh_c4#c.dag | B9: 0.019542708 | C9: -1.090373e-05 | D9: -5.5131612e-06 | E9: -1.2502327e-06 | F9: -1.3436107e-09 | G9: -5.4043835e-05 | H9: -0.00015687271 | I9: 1.3121915e-06 | J9: 3.5083041e-06 | K9: 1.4775815e-06 | L9: 9.1302172e-08 | M9: -4.4690914e-07 | N9: 2.4184071e-06 | O9: 1.3228411e-06 | P9: 4.2771684e-08 | Q9: 3.4412411e-08 | R9: -1.0744514e-06 | S9: 2.5039719e-07 | T9: -5.4891261e-07 | U9: -5.0899824e-07 | V9: -5.2883267e-07 | W9: 1.7226204e-08 | X9: 4.0176828e-07 | Y9: 8.4304037e-07 | Z9: 3.3851937e-08 | AA9: 1.3047483e-07 | AB9: 5.1316588e-07 | AC9: 7.4119518e-07 | AD9: 7.7098204e-07 | AE9: -1.3834848e-06 | AF9: 8.4849623e-07 | AG9: -7.6038166e-07 | AH9: 5.4762473e-05
A10: 2.dehmf_c3 | B10: 0.037092352 | C10: 2.1557553e-05 | D10: -2.2672594e-05 | E10: -3.6640582e-06 | F10: 3.2061447e-08 | G10: -7.9757688e-05 | H10: -0.00013518895 | I10: 1.5117233e-07 | J10: 1.4775815e-06 | K10: 0.0011949606 | L10: 0.0010879594 | M10: -1.7991304e-05 | N10: -1.8306275e-05 | O10: -5.6951206e-06 | P10: 5.5278397e-07 | Q10: -3.0117341e-07 | R10: -4.0383365e-05 | S10: -3.650179e-05 | T10: -3.1219277e-05 | U10: -1.9716569e-05 | V10: -4.278692e-05 | W10: -3.2143558e-05 | X10: -2.3755713e-05 | Y10: -3.9117548e-05 | Z10: -4.1870109e-05 | AA10: -3.4860721e-05 | AB10: -3.9094855e-05 | AC10: -2.8266242e-07 | AD10: -8.3860336e-06 | AE10: -6.5683977e-08 | AF10: 2.3764761e-05 | AG10: 5.639223e-05 | AH10: -0.00088958666
A11: 3.dehmf_c3 | B11: -0.02390819 | C11: 1.7812116e-05 | D11: -3.0208749e-05 | E11: -7.6265466e-06 | F11: 4.2252423e-08 | G11: -0.00010231662 | H11: -0.00016224572 | I11: -2.7906065e-07 | J11: 9.1302172e-08 | K11: 0.0010879594 | L11: 0.0013150953 | M11: 1.2070746e-06 | N11: -1.3765364e-05 | O11: -4.4107964e-06 | P11: 8.3016188e-07 | Q11: -3.6868089e-07 | R11: -6.4119023e-05 | S11: -5.4839383e-05 | T11: -5.8504925e-05 | U11: -4.4274639e-05 | V11: -6.3183697e-05 | W11: -3.0573194e-05 | X11: -1.7907205e-05 | Y11: -3.1619884e-05 | Z11: -8.0517728e-05 | AA11: -3.7392671e-05 | AB11: -0.00011005045 | AC11: 1.727202e-05 | AD11: 1.6911473e-05 | AE11: -7.4640793e-05 | AF11: 1.8190878e-06 | AG11: 3.8490697e-05 | AH11: -0.00075628739
A12: mar | B12: -0.23181046 | C12: 5.5976833e-05 | D12: 1.0428691e-05 | E12: -2.2308507e-05 | F12: 2.2177347e-07 | G12: 3.4905455e-05 | H12: 4.4492519e-05 | I12: -5.9166359e-07 | J12: -4.4690914e-07 | K12: -1.7991304e-05 | L12: 1.2070746e-06 | M12: 0.00037725293 | N12: -5.9780858e-05 | O12: 7.6314004e-05 | P12: -3.9754134e-07 | Q12: -1.4224058e-06 | R12: -1.8933576e-05 | S12: -1.7935582e-05 | T12: -2.6168468e-05 | U12: -2.5625322e-05 | V12: -4.5062646e-06 | W12: -2.8135472e-05 | X12: -1.9055983e-05 | Y12: -3.2939204e-05 | Z12: -2.1894435e-05 | AA12: -1.5509663e-05 | AB12: 1.2636452e-05 | AC12: 4.8050214e-06 | AD12: 1.0006497e-05 | AE12: -2.9910834e-05 | AF12: 9.9458632e-05 | AG12: 3.1735273e-05 | AH12: 0.00039044257
A13: child | B13: -0.31875706 | C13: 3.4036048e-05 | D13: -3.0404641e-05 | E13: -2.0763157e-05 | F13: 2.9171666e-07 | G13: -0.00013273846 | H13: -0.00012999113 | I13: 2.5392477e-06 | J13: 2.4184071e-06 | K13: -1.8306275e-05 | L13: -1.3765364e-05 | M13: -5.9780858e-05 | N13: 0.00038574453 | O13: 5.4287675e-05 | P13: -6.2907445e-07 | Q13: -8.7375113e-07 | R13: 8.8563355e-06 | S13: 3.4024887e-06 | T13: 4.784502e-06 | U13: 1.0351616e-05 | V13: 3.0152751e-06 | W13: -1.2249525e-06 | X13: 2.7604382e-06 | Y13: 9.7915982e-06 | Z13: 7.5680248e-06 | AA13: 7.3886883e-06 | AB13: -5.2064251e-06 | AC13: 1.6490355e-05 | AD13: 2.3541689e-05 | AE13: -2.3915904e-05 | AF13: -4.0890784e-05 | AG13: -2.0840919e-05 | AH13: 0.00026624542
... A33: Constant | B33: -0.46035827 | C33: -0.002750099 | D33: -0.0015349063 | E33: -0.0004301722 | F33: 4.0260586e-06 | G33: -0.0037549709 | H33: -0.002666986 | I33: 7.9207172e-05 | J33: 5.4762473e-05 | K33: -0.00088958666 | L33: -0.00075628739 | M33: 0.00039044257 | N33: 0.00026624542 | O33: -0.00017983462 | P33: -4.5143397e-05 | Q33: -3.0446257e-05 | R33: -0.00070069109 | S33: -0.0006837128 | T33: -0.00068476169 | U33: -0.00064842734 | V33: -0.00058771624 | W33: -0.00060095626 | X33: -0.00066428381 | Y33: -0.00071167734 | Z33: -0.00070990874 | AA33: -0.00066615583 | AB33: -0.0005778421 | AC33: -0.00018092438 | AD33: -0.00015206962 | AE33: -0.00029177828 | AF33: -0.00024282349 | AG33: -0.00044350409 | AH33: 0.016788939

Sheet W1ma-sel_orig
A1: REGRESSOR | B1: COEFFICIENT | C1: 2.L1les_c3 | D1: 3.L1les_c3 | E1: dag | F1: dagsq | G1: 2.deh_c4 | H1: 3.deh_c4 | I1: 2.deh_c4#c.dag | J1: 3.deh_c4#c.dag | K1: 2.dehmf_c3 | L1: 3.dehmf_c3 | M1: mar | N1: child | O1: dlltsd01 | P1: dhe_pcs_L1 | Q1: dhe_mcs_L1 | R1: drgn1 | S1: 2.drgn1 | T1: 4.drgn1 | U1: 5.drgn1 | V1: 6.drgn1 | W1: 7.drgn1 | X1: 9.drgn1 | Y1: 10.drgn1 | Z1: 1drgn1 | AA1: 12.drgn1 | AB1: 13.drgn1 | AC1: y2020 | AD1: y2021 | AE1: 2.dot | AF1: 3.dot | AG1: 4.dot | AH1: Constant
A2: 2.L1les_c3 | B2: -0.96830341 | C2: 0.0018440827 | D2: 0.00094474921 | E2: 8.6985376e-05 | F2: -7.8012449e-07 | G2: 0.00037806583 | H2: 0.00045794877 | I2: -9.8483068e-06 | J2: -1.1839932e-05 | K2: 5.7692009e-05 | L2: 5.4806183e-05 | M2: 8.9096943e-05 | N2: 3.7381632e-05 | O2: -3.4521599e-05 | P2: 2.3135413e-06 | Q2: 1.967632e-06 | R2: -5.86164e-05 | S2: -4.7836833e-05 | T2: -4.8532098e-05 | U2: -2.6673922e-05 | V2: -3.4288932e-05 | W2: -3.1382368e-05 | X2: 1.1377952e-05 | Y2: -4.1613615e-05 | Z2: -6.0631976e-05 | AA2: -7.9831145e-05 | AB2: -6.0192193e-05 | AC2: -1.1776525e-05 | AD2: 9.515814e-07 | AE2: -4.9775765e-05 | AF2: -0.00013290921 | AG2: -3.4196347e-05 | AH2: -0.0032733581
A3: 3.L1les_c3 | B3: -0.92025867 | C3: 0.00094474921 | D3: 0.0010068785 | E3: 2.8469682e-05 | F3: -2.6905636e-07 | G3: 3.7619333e-05 | H3: -2.2889261e-05 | I3: -4.4142008e-06 | J3: -4.0429314e-06 | K3: -2.2356067e-05 | L3: -4.4523557e-05 | M3: 6.3347981e-05 | N3: 5.7004624e-05 | O3: -8.8891766e-05 | P3: 2.98993e-06 | Q3: 2.9093063e-06 | R3: -7.7329348e-05 | S3: -6.0085138e-05 | T3: -8.0590023e-05 | U3: -5.398013e-05 | V3: -4.1056256e-05 | W3: -3.2086219e-05 | X3: -1.0809321e-06 | Y3: -5.2895055e-05 | Z3: -7.9441605e-05 | AA3: -5.4505562e-05 | AB3: -8.6320243e-05 | AC3: 4.6645499e-06 | AD3: -2.8541027e-06 | AE3: -4.9019405e-05 | AF3: -0.0001188761 | AG3: -3.7019625e-05 | AH3: -0.0016321721
A4: dag | B4: 0.092226677 | C4: 8.6985376e-05 | D4: 2.8469682e-05 | E4: 2.3398687e-05 | F4: -2.3501853e-07 | G4: 0.00014611358 | H4: 0.0001021632 | I4: -2.9042579e-06 | J4: -1.9664897e-06 | K4: -7.7821729e-06 | L4: -8.1164995e-06 | M4: -3.085446e-05 | N4: -5.4863772e-06 | O4: -3.133162e-05 | P4: 2.0238053e-07 | Q4: 5.7573707e-07 | R4: 1.2808333e-06 | S4: 4.9668398e-06 | T4: 5.9983498e-06 | U4: 7.7989136e-06 | V4: 2.9316221e-06 | W4: 7.7070361e-06 | X4: 8.4016904e-06 | Y4: 7.6264037e-06 | Z4: 6.6420371e-06 | AA4: 9.1864769e-07 | AB4: 1.2958088e-06 | AC4: 2.1929108e-06 | AD4: 3.7100435e-06 | AE4: -3.0596988e-06 | AF4: -1.6871841e-05 | AG4: -1.2205541e-06 | AH4: -0.00056724572
A5: dagsq | B5: -0.0016780219 | C5: -7.8012449e-07 | D5: -2.6905636e-07 | E5: -2.3501853e-07 | F5: 2.5804538e-09 | G5: -8.7871494e-07 | H5: -3.2482864e-07 | I5: 1.5693409e-08 | J5: 4.0315682e-09 | K5: 4.8929511e-08 | L5: -3.8089985e-09 | M5: 2.1467071e-07 | N5: 1.2544792e-07 | O5: 3.7120937e-07 | P5: -4.8153531e-10 | Q5: -7.4937189e-09 | R5: 1.1103258e-08 | S5: -4.3222092e-08 | T5: -4.0194401e-08 | U5: -8.0726768e-08 | V5: -2.8845542e-08 | W5: -7.9170147e-08 | X5: -9.8375642e-08 | Y5: -9.2051979e-08 | Z5: -5.2505213e-08 | AA5: -1.2390316e-08 | AB5: 1.1929487e-08 | AC5: -4.4086021e-08 | AD5: -6.3321459e-08 | AE5: 8.9481529e-08 | AF5: 2.0031428e-07 | AG5: 4.2221904e-08 | AH5: 5.2573016e-06
A6: 2.deh_c4 | B6: -0.59930774 | C6: 0.00037806583 | D6: 3.7619333e-05 | E6: 0.00014611358 | F6: -8.7871494e-07 | G6: 0.0043813908 | H6: 0.0034790145 | I6: -8.797214e-05 | J6: -6.7669742e-05 | K6: -0.00018725201 | L6: -0.00021434561 | M6: 9.6154651e-06 | N6: -0.00016891965 | O6: -0.00011503531 | P6: 5.8286907e-07 | Q6: 1.3544824e-07 | R6: 2.4206633e-06 | S6: 4.557187e-06 | T6: -1.8138483e-06 | U6: -4.0957873e-05 | V6: -4.0828027e-05 | W6: 1.532719e-05 | X6: -2.8237194e-05 | Y6: -4.0722011e-05 | Z6: -3.2448806e-05 | AA6: -4.2591545e-05 | AB6: -2.3602252e-05 | AC6: 2.9643159e-06 | AD6: 2.8273554e-05 | AE6: 0.00012062362 | AF6: 9.0127735e-06 | AG6: 4.206101e-05 | AH6: -0.0048078074
A7: 3.deh_c4 | B7: -1.350879 | C7: 0.00045794877 | D7: -2.2889261e-05 | E7: 0.0001021632 | F7: -3.2482864e-07 | G7: 0.0034790145 | H7: 0.0091399196 | I7: -6.7966965e-05 | J7: -0.00017320284 | K7: -0.00023564891 | L7: -0.00037112065 | M7: -3.5484431e-05 | N7: -0.00021450232 | O7: -0.00027059584 | P7: -1.6428435e-06 | Q7: -9.7638561e-07 | R7: 2.4604587e-05 | S7: -1.3094004e-05 | T7: 1.1878961e-05 | U7: -6.6531782e-05 | V7: -5.9371734e-05 | W7: -1.0509456e-05 | X7: -3.2061616e-05 | Y7: -5.3669787e-05 | Z7: -9.0819267e-05 | AA7: -2.1060418e-05 | AB7: -0.00012044986 | AC7: -1.1831631e-05 | AD7: 1.5436382e-05 | AE7: 0.00021313583 | AF7: 0.00011267784 | AG7: 2.0083459e-05 | AH7: -0.0037688205
A8: 2.deh_c4#c.dag | B8: 0.01124915 | C8: -9.8483068e-06 | D8: -4.4142008e-06 | E8: -2.9042579e-06 | F8: 1.5693409e-08 | G8: -8.797214e-05 | H8: -6.7966965e-05 | I8: 2.047093e-06 | J8: 1.5199591e-06 | K8: 2.6168133e-06 | L8: 2.2526195e-06 | M8: 1.6652487e-07 | N8: 3.0175114e-06 | O8: 1.4116647e-06 | P8: 5.1099055e-08 | Q8: 2.7642573e-09 | R8: -5.2390666e-07 | S8: -8.9506922e-07 | T8: -1.1277796e-06 | U8: -3.0005217e-07 | V8: 6.1121492e-08 | W8: -1.2008582e-06 | X8: 2.6041448e-08 | Y8: 1.2409673e-07 | Z8: -1.0437364e-06 | AA8: 1.0091839e-07 | AB8: -5.5918912e-07 | AC8: 6.470718e-08 | AD8: -4.3801795e-07 | AE8: -1.731908e-06 | AF8: -7.3029034e-07 | AG8: -5.9333636e-07 | AH8: 9.3219528e-05
A9: 3.deh_c4#c.dag | B9: 0.022697016 | C9: -1.1839932e-05 | D9: -4.0429314e-06 | E9: -1.9664897e-06 | F9: 4.0315682e-09 | G9: -6.7669742e-05 | H9: -0.00017320284 | I9: 1.5199591e-06 | J9: 3.732575e-06 | K9: 3.8822166e-06 | L9: 3.9430548e-06 | M9: 1.3828101e-06 | N9: 3.3229435e-06 | O9: 3.5837529e-06 | P9: 1.2409377e-07 | Q9: 2.7792267e-08 | R9: -1.0876863e-06 | S9: -4.3494711e-07 | T9: -1.4783092e-06 | U9: -7.2537236e-09 | V9: 1.8915412e-08 | W9: -5.7574133e-07 | X9: 3.5476353e-07 | Y9: 5.4713644e-07 | Z9: -2.5044222e-07 | AA9: -2.3695575e-07 | AB9: 1.0995889e-07 | AC9: 7.9752748e-07 | AD9: 4.3559697e-07 | AE9: -4.1865543e-06 | AF9: -2.7131344e-06 | AG9: -4.2265358e-07 | AH9: 7.0362197e-05
A10: 2.dehmf_c3 | B10: 0.069201601 | C10: 5.7692009e-05 | D10: -2.2356067e-05 | E10: -7.7821729e-06 | F10: 4.8929511e-08 | G10: -0.00018725201 | H10: -0.00023564891 | I10: 2.6168133e-06 | J10: 3.8822166e-06 | K10: 0.0015439239 | L10: 0.0013991324 | M10: -1.775303e-05 | N10: -3.4146915e-05 | O10: -7.9918241e-06 | P10: 1.0539512e-06 | Q10: -7.8258316e-07 | R10: -2.6927295e-05 | S10: 1.9546015e-06 | T10: -1.9219438e-05 | U10: -2.1535731e-05 | V10: -1.7736541e-05 | W10: 1.1817741e-05 | X10: 6.3213685e-07 | Y10: -1.2886389e-05 | Z10: -1.949292e-05 | AA10: 1.4015359e-05 | AB10: 1.0085046e-05 | AC10: 2.2942334e-05 | AD10: 1.8445664e-05 | AE10: 3.462163e-06 | AF10: 2.925214e-05 | AG10: 9.0739014e-05 | AH10: -0.0010889454
A11: 3.dehmf_c3 | B11: 0.073676503 | C11: 5.4806183e-05 | D11: -4.4523557e-05 | E11: -8.1164995e-06 | F11: -3.8089985e-09 | G11: -0.00021434561 | H11: -0.00037112065 | I11: 2.2526195e-06 | J11: 3.9430548e-06 | K11: 0.0013991324 | L11: 0.0017331581 | M11: 6.4808084e-06 | N11: -3.8987429e-05 | O11: -7.29761e-06 | P11: 1.5789831e-06 | Q11: -1.104154e-06 | R11: -6.8298455e-05 | S11: -4.6473134e-06 | T11: -3.4020565e-05 | U11: -3.3954738e-05 | V11: -3.8496809e-05 | W11: 1.315895e-05 | X11: 3.284625e-05 | Y11: 1.7346212e-05 | Z11: -3.1508006e-05 | AA11: 2.9279943e-05 | AB11: -4.5593e-05 | AC11: 5.3934472e-05 | AD11: 5.7996683e-05 | AE11: -0.00010667079 | AF11: 1.8318518e-05 | AG11: 9.1711608e-05 | AH11: -0.001005694
A12: mar | B12: 0.091560656 | C12: 8.9096943e-05 | D12: 6.3347981e-05 | E12: -3.085446e-05 | F12: 2.1467071e-07 | G12: 9.6154651e-06 | H12: -3.5484431e-05 | I12: 1.6652487e-07 | J12: 1.3828101e-06 | K12: -1.775303e-05 | L12: 6.4808084e-06 | M12: 0.00070425939 | N12: -0.00021350562 | O12: 5.0812379e-05 | P12: -3.7979661e-07 | Q12: -1.7824567e-06 | R12: -2.3274271e-05 | S12: -2.168819e-05 | T12: -2.9295498e-05 | U12: -2.0601918e-05 | V12: -2.5739807e-05 | W12: -2.4444572e-05 | X12: -2.6260661e-05 | Y12: -3.8895085e-05 | Z12: -4.5112156e-05 | AA12: -1.6108627e-05 | AB12: 2.6945424e-05 | AC12: 1.7215351e-05 | AD12: 2.46242e-05 | AE12: 1.1666393e-05 | AF12: 0.00010927355 | AG12: 3.5749413e-05 | AH12: 0.00061203349
A13: child | B13: -0.07748175 | C13: 3.7381632e-05 | D13: 5.7004624e-05 | E13: -5.4863772e-06 | F13: 1.2544792e-07 | G13: -0.00016891965 | H13: -0.00021450232 | I13: 3.0175114e-06 | J13: 3.3229435e-06 | K13: -3.4146915e-05 | L13: -3.8987429e-05 | M13: -0.00021350562 | N13: 0.00055695499 | O13: 3.1732013e-05 | P13: 7.8423457e-07 | Q13: -1.4305101e-07 | R13: -1.4218962e-05 | S13: -9.2739432e-06 | T13: -7.8697901e-06 | U13: -2.5839863e-06 | V13: -2.8733344e-06 | W13: -1.8408121e-05 | X13: -1.1087513e-05 | Y13: 4.545107e-06 | Z13: 7.8581353e-06 | AA13: -5.8749718e-06 | AB13: 4.634853e-07 | AC13: 2.3952378e-07 | AD13: 2.7347113e-06 | AE13: -9.7488005e-05 | AF13: -8.672481e-05 | AG13: -2.6711488e-05 | AH13: -7.824273e-05
... A33: Constant | B33: -0.68633511 | C33: -0.0032733581 | D33: -0.0016321721 | E33: -0.00056724572 | F33: 5.2573016e-06 | G33: -0.0048078074 | H33: -0.0037688205 | I33: 9.3219528e-05 | J33: 7.0362197e-05 | K33: -0.0010889454 | L33: -0.001005694 | M33: 0.00061203349 | N33: -7.824273e-05 | O33: -0.00020379921 | P33: -7.7689272e-05 | Q33: -5.550471e-05 | R33: -0.00098560309 | S33: -0.0010393991 | T33: -0.00099666668 | U33: -0.0010012045 | V33: -0.00085517709 | W33: -0.0010466703 | X33: -0.0010960251 | Y33: -0.0010934212 | Z33: -0.0011004447 | AA33: -0.00097725227 | AB33: -0.00098873175 | AC33: -0.00022315344 | AD33: -0.00026297342 | AE33: -0.00049467722 | AF33: -0.00017845056 | AG33: -0.00061511595 | AH33: 0.023884228

Sheet W1fb-sel_orig
A1: REGRESSOR | B1: COEFFICIENT | C1: dag | D1: dagsq | E1: 2.deh_c4 | F1: 3.deh_c4 | G1: 2.deh_c4#c.dag | H1: 3.deh_c4#c.dag | I1: 2.dehmf_c3 | J1: 3.dehmf_c3 | K1: mar | L1: child | M1: dlltsd01 | N1: dhe_pcs_L1 | O1: dhe_mcs_L1 | P1: drgn1 | Q1: 2.drgn1 | R1: 4.drgn1 | S1: 5.drgn1 | T1: 6.drgn1 | U1: 7.drgn1 | V1: 9.drgn1 | W1: 10.drgn1 | X1: 1drgn1 | Y1: 12.drgn1 | Z1: 13.drgn1 | AA1: y2020 | AB1: y2021 | AC1: 2.dot | AD1: 3.dot | AE1: 4.dot | AF1: Constant
A2: dag | B2: 0.15250301 | C2: 1.2467462e-05 | D2: -1.3260796e-07 | E2: 5.462984e-05 | F2: -1.4586195e-05 | G2: -1.0834197e-06 | H2: 2.9777902e-07 | I2: -2.3424536e-06 | J2: -5.3512002e-06 | K2: -1.0965496e-05 | L2: -1.4019759e-05 | M2: -9.0746633e-06 | N2: 5.5505782e-08 | O2: 1.0269686e-07 | P2: -1.303514e-06 | Q2: 8.5036473e-07 | R2: 2.2459171e-07 | S2: -9.4316382e-07 | T2: -5.3216583e-07 | U2: 1.0201993e-07 | V2: 5.0130961e-07 | W2: 9.5761388e-07 | X2: 1.7228508e-06 | Y2: -2.7452137e-07 | Z2: 3.4840091e-07 | AA2: 7.7610222e-07 | AB2: 1.342878e-06 | AC2: 9.7415356e-08 | AD2: -4.8900566e-06 | AE2: -7.000232e-07 | AF2: -0.00026209823
A3: dagsq | B3: -0.0018789539 | C3: -1.3260796e-07 | D3: 1.5049231e-09 | E3: -2.6387618e-07 | F3: 5.1423111e-07 | G3: 4.3536099e-09 | H3: -1.1103244e-08 | I3: 1.7529954e-08 | J3: 2.6323455e-08 | K3: 1.1084789e-07 | L3: 1.8284558e-07 | M3: 1.0165671e-07 | N3: 9.7028686e-11 | O3: -1.6569728e-09 | P3: 2.5645688e-08 | Q3: -2.6877083e-09 | R3: 6.8626207e-09 | S3: 1.5163363e-08 | T3: 1.142129e-08 | U3: -8.1860865e-10 | V3: -8.5533025e-09 | W3: -1.296738e-08 | X3: -1.2261627e-08 | Y3: 3.8879674e-09 | Z3: 9.063982e-09 | AA3: -1.3803098e-08 | AB3: -2.2934295e-08 | AC3: 2.926001e-08 | AD3: 5.609563e-08 | AE3: 1.8639844e-08 | AF3: 2.5778719e-06
A4: 2.deh_c4 | B4: -0.34491004 | C4: 5.462984e-05 | D4: -2.6387618e-07 | E4: 0.0023249158 | F4: 0.0014397897 | G4: -4.7682476e-05 | H4: -2.9681772e-05 | I4: -7.9048712e-05 | J4: -9.4443032e-05 | K4: 3.6000886e-05 | L4: -7.0718275e-05 | M4: -1.6874884e-05 | N4: 8.444437e-07 | O4: 2.083255e-07 | P4: -1.1595324e-06 | Q4: -1.6590597e-05 | R4: -2.7480917e-05 | S4: -5.5448372e-05 | T4: -2.9003639e-05 | U4: -3.4005873e-05 | V4: -3.0501389e-05 | W4: -3.2263428e-05 | X4: -2.7006323e-05 | Y4: -2.865107e-05 | Z4: -8.9789581e-06 | AA4: 1.229963e-05 | AB4: 1.5982996e-05 | AC4: 7.2833203e-05 | AD4: 6.2260505e-06 | AE4: 1.0008065e-05 | AF4: -0.0019301614
A5: 3.deh_c4 | B5: -0.77460153 | C5: -1.4586195e-05 | D5: 5.1423111e-07 | E5: 0.0014397897 | F5: 0.010358174 | G5: -3.0174407e-05 | H5: -0.0001888874 | I5: -0.00010085806 | J5: -0.00011748602 | K5: 7.4158247e-05 | L5: -3.1166097e-05 | M5: -4.1769768e-05 | N5: 1.0298596e-06 | O5: -3.8383571e-07 | P5: 6.8280202e-06 | Q5: 7.8569375e-06 | R5: -2.9475183e-05 | S5: -2.6207293e-05 | T5: -3.7805045e-05 | U5: -4.9007454e-05 | V5: -2.9906075e-05 | W5: -2.4845454e-05 | X5: -4.4191674e-05 | Y5: -3.3908915e-05 | Z5: -2.5499613e-05 | AA5: 2.7395211e-05 | AB5: -6.5091643e-06 | AC5: -1.9799002e-06 | AD5: -7.7753394e-05 | AE5: -1.8469955e-05 | AF5: -0.00050732374
A6: 2.deh_c4#c.dag | B6: 0.0086512476 | C6: -1.0834197e-06 | D6: 4.3536099e-09 | E6: -4.7682476e-05 | F6: -3.0174407e-05 | G6: 1.0722059e-06 | H6: 6.842921e-07 | I6: 5.9496103e-07 | J6: 4.2189032e-07 | K6: -6.0049209e-07 | L6: 1.404926e-06 | M6: 5.1667877e-08 | N6: 2.852255e-10 | O6: -1.884415e-09 | P6: -6.2962365e-07 | Q6: -1.9747011e-07 | R6: -5.2569456e-08 | S6: 5.1538815e-07 | T6: 6.2567489e-08 | U6: 1.7096491e-07 | V6: 2.9300133e-07 | W6: 1.8529849e-07 | X6: -5.6793391e-08 | Y6: 9.8658511e-08 | Z6: -2.0068369e-07 | AA6: -1.4864043e-07 | AB6: -1.9174057e-07 | AC6: -1.221796e-06 | AD6: -2.1937737e-07 | AE6: -2.3481999e-07 | AF6: 3.8187593e-05
A7: 3.deh_c4#c.dag | B7: 0.015629343 | C7: 2.9777902e-07 | D7: -1.1103244e-08 | E7: -2.9681772e-05 | F7: -0.0001888874 | G7: 6.842921e-07 | H7: 3.6522827e-06 | I7: 1.071197e-06 | J7: 3.4368361e-07 | K7: -1.3795177e-06 | L7: 6.3106617e-07 | M7: 1.3530584e-07 | N7: 3.4848345e-09 | O7: 7.9799409e-09 | P7: -7.2180838e-07 | Q7: -4.8624384e-07 | R7: -1.2433948e-07 | S7: -1.1507666e-07 | T7: 6.026131e-08 | U7: 2.962512e-07 | V7: 2.1486027e-07 | W7: 1.9543863e-07 | X7: 1.2762541e-07 | Y7: 3.4272216e-07 | Z7: -2.9448182e-07 | AA7: -2.265585e-07 | AB7: 4.8158499e-07 | AC7: 9.1309419e-09 | AD7: 1.5246585e-06 | AE7: 5.5382988e-07 | AF7: 9.5670405e-06
A8: 2.dehmf_c3 | B8: 0.1332376 | C8: -2.3424536e-06 | D8: 1.7529954e-08 | E8: -7.9048712e-05 | F8: -0.00010085806 | G8: 5.9496103e-07 | H8: 1.071197e-06 | I8: 0.00086985419 | J8: 0.00079883961 | K8: -1.163602e-05 | L8: -7.1754439e-06 | M8: 4.8695692e-06 | N8: 3.8680097e-07 | O8: 6.1540419e-08 | P8: -2.145397e-05 | Q8: -3.1924626e-05 | R8: -2.2578691e-05 | S8: -2.8291511e-05 | T8: -3.3729273e-05 | U8: -1.58325e-05 | V8: -2.4157872e-05 | W8: -3.6207688e-05 | X8: -3.1682616e-05 | Y8: -3.2438332e-05 | Z8: -3.6266138e-05 | AA8: -4.7357013e-07 | AB8: -2.4987667e-06 | AC8: 9.5757851e-07 | AD8: 1.6987617e-05 | AE8: 6.6874508e-05 | AF8: -0.00068271479
A9: 3.dehmf_c3 | B9: 0.12734034 | C9: -5.3512002e-06 | D9: 2.6323455e-08 | E9: -9.4443032e-05 | F9: -0.00011748602 | G9: 4.2189032e-07 | H9: 3.4368361e-07 | I9: 0.00079883961 | J9: 0.00093498346 | K9: -7.0230072e-06 | L9: 1.0265142e-07 | M9: 2.7330133e-06 | N9: 5.5442523e-07 | O9: 9.3161339e-08 | P9: -3.2911916e-05 | Q9: -4.2402984e-05 | R9: -3.8029839e-05 | S9: -3.9638924e-05 | T9: -5.0113034e-05 | U9: -1.8048654e-05 | V9: -1.8209841e-05 | W9: -2.6768715e-05 | X9: -5.2224409e-05 | Y9: -3.4614264e-05 | Z9: -7.8800894e-05 | AA9: 1.1262204e-05 | AB9: 1.2770713e-05 | AC9: -4.6079382e-05 | AD9: -3.21174e-06 | AE9: 5.5250672e-05 | AF9: -0.00057981049
A10: mar | B10: -0.052543122 | C10: -1.0965496e-05 | D10: 1.1084789e-07 | E10: 3.6000886e-05 | F10: 7.4158247e-05 | G10: -6.0049209e-07 | H10: -1.3795177e-06 | I10: -1.163602e-05 | J10: -7.0230072e-06 | K10: 0.00020533761 | L10: -3.9875469e-05 | M10: 1.7832296e-05 | N10: -2.5243528e-07 | O10: -8.9360738e-07 | P10: -1.3458211e-05 | Q10: -1.5396594e-05 | R10: -1.7011203e-05 | S10: -2.3360277e-05 | T10: -1.1625482e-05 | U10: -1.7274984e-05 | V10: -1.4250079e-05 | W10: -2.4574456e-05 | X10: -1.3664722e-05 | Y10: -1.0120243e-05 | Z10: 1.3416048e-06 | AA10: 7.1605758e-06 | AB10: 5.7355433e-06 | AC10: -2.3664856e-06 | AD10: 5.6501227e-05 | AE10: 3.3247437e-05 | AF10: 0.00020196464
A11: child | B11: -0.12044651 | C11: -1.4019759e-05 | D11: 1.8284558e-07 | E11: -7.0718275e-05 | F11: -3.1166097e-05 | G11: 1.404926e-06 | H11: 6.3106617e-07 | I11: -7.1754439e-06 | J11: 1.0265142e-07 | K11: -3.9875469e-05 | L11: 0.00023833737 | M11: -1.3021062e-05 | N11: -2.9334725e-07 | O11: -1.7417053e-07 | P11: -9.6503863e-07 | Q11: -4.7893358e-06 | R11: -4.2868149e-06 | S11: 4.6332129e-06 | T11: -5.4707292e-06 | U11: -3.7414052e-06 | V11: -2.2930927e-06 | W11: 5.6655515e-07 | X11: -3.4092331e-06 | Y11: -1.327766e-06 | Z11: -1.2050659e-05 | AA11: 1.8962149e-06 | AB11: 6.6859483e-06 | AC11: -2.0417194e-05 | AD11: -2.8348343e-05 | AE11: -6.6509624e-06 | AF11: 0.00019847153
A12: dlltsd01 | B12: -0.79677687 | C12: -9.0746633e-06 | D12: 1.0165671e-07 | E12: -1.6874884e-05 | F12: -4.1769768e-05 | G12: 5.1667877e-08 | H12: 1.3530584e-07 | I12: 4.8695692e-06 | J12: 2.7330133e-06 | K12: 1.7832296e-05 | L12: -1.3021062e-05 | M12: 0.00074641136 | N12: 5.7270352e-06 | O12: 2.2031482e-06 | P12: 1.0065612e-06 | Q12: -7.6708029e-06 | R12: -6.7866648e-06 | S12: -6.1114469e-06 | T12: -6.7159721e-06 | U12: 3.6430123e-06 | V12: -2.9192589e-07 | W12: -1.1540079e-05 | X12: -1.486795e-05 | Y12: -5.5102205e-06 | Z12: -2.4303815e-05 | AA12: -2.8169914e-06 | AB12: -6.8462166e-06 | AC12: 2.2960862e-05 | AD12: 1.4519327e-05 | AE12: -4.1623471e-07 | AF12: -0.00026124884
A13: dhe_pcs_L1 | B13: 0.0052448758 | C13: 5.5505782e-08 | D13: 9.7028686e-11 | E13: 8.444437e-07 | F13: 1.0298596e-06 | G13: 2.852255e-10 | H13: 3.4848345e-09 | I13: 3.8680097e-07 | J13: 5.5442523e-07 | K13: -2.5243528e-07 | L13: -2.9334725e-07 | M13: 5.7270352e-06 | N13: 5.5658055e-07 | O13: 5.337395e-08 | P13: 2.5732404e-07 | Q13: 2.2945938e-07 | R13: 1.7491491e-07 | S13: -6.5932776e-08 | T13: 2.4006275e-07 | U13: -1.5967083e-07 | V13: -1.3583282e-07 | W13: -6.1607931e-09 | X13: 1.6814609e-07 | Y13: -2.3412114e-07 | Z13: -9.0612738e-08 | AA13: 2.8079647e-07 | AB13: 6.6354693e-09 | AC13: 1.3585987e-06 | AD13: 9.7885895e-07 | AE13: 7.32551e-07 | AF13: -3.5393143e-05
... A31: Constant | B31: -1.9006756 | C31: -0.00026209823 | D31: 2.5778719e-06 | E31: -0.0019301614 | F31: -0.00050732374 | G31: 3.8187593e-05 | H31: 9.5670405e-06 | I31: -0.00068271479 | J31: -0.00057981049 | K31: 0.00020196464 | L31: 0.00019847153 | M31: -0.00026124884 | N31: -3.5393143e-05 | O31: -2.4521984e-05 | P31: -0.00042919582 | Q31: -0.00044019358 | R31: -0.00043456501 | S31: -0.00038444239 | T31: -0.00038642497 | U31: -0.00039281144 | V31: -0.00040297086 | W31: -0.00042152053 | X31: -0.00046009932 | Y31: -0.00038982444 | Z31: -0.00039761887 | AA31: -0.00011415654 | AB31: -0.00011680379 | AC31: -0.00032752235 | AD31: -0.00027710723 | AE31: -0.00032986776 | AF31: 0.010083039

Sheet W1mb-sel_orig
A1: REGRESSOR | B1: COEFFICIENT | C1: dag | D1: dagsq | E1: 2.deh_c4 | F1: 3.deh_c4 | G1: 2.deh_c4#c.dag | H1: 3.deh_c4#c.dag | I1: 2.dehmf_c3 | J1: 3.dehmf_c3 | K1: mar | L1: child | M1: dlltsd01 | N1: dhe_pcs_L1 | O1: dhe_mcs_L1 | P1: drgn1 | Q1: 2.drgn1 | R1: 4.drgn1 | S1: 5.drgn1 | T1: 6.drgn1 | U1: 7.drgn1 | V1: 9.drgn1 | W1: 10.drgn1 | X1: 1drgn1 | Y1: 12.drgn1 | Z1: 13.drgn1 | AA1: y2020 | AB1: y2021 | AC1: 2.dot | AD1: 3.dot | AE1: 4.dot | AF1: Constant
A2: dag | B2: 0.13037744 | C2: 1.3289841e-05 | D2: -1.3517544e-07 | E2: 7.097732e-05 | F2: 1.1178667e-05 | G2: -1.3799272e-06 | H2: -2.0157042e-07 | I2: -4.0560689e-06 | J2: -4.3515786e-06 | K2: -1.2535136e-05 | L2: -1.1331331e-05 | M2: -6.4173497e-06 | N2: 3.6824432e-08 | O2: 1.8748021e-07 | P2: -1.7915886e-06 | Q2: 5.0262646e-07 | R2: 4.8937773e-07 | S2: 7.41334e-07 | T2: 1.2920827e-06 | U2: 1.7084762e-06 | V2: 1.1061955e-06 | W2: 2.6216047e-06 | X2: 9.2272939e-07 | Y2: -9.5333559e-07 | Z2: 1.8860915e-06 | AA2: 2.4223535e-07 | AB2: 3.9235823e-07 | AC2: 3.3927376e-07 | AD2: -2.4714635e-06 | AE2: -4.3163372e-09 | AF2: -0.00029859566
A3: dagsq | B3: -0.0016715073 | C3: -1.3517544e-07 | D3: 1.4816945e-09 | E3: -3.4967813e-07 | F3: 3.1061545e-07 | G3: 6.1315027e-09 | H3: -6.7757691e-09 | I3: 2.0897153e-08 | J3: -8.1042921e-09 | K3: 9.6938672e-08 | L3: 1.5411192e-07 | M3: 7.6891727e-08 | N3: 6.9303542e-10 | O3: -2.5967612e-09 | P3: 2.6810878e-08 | Q3: -1.0686495e-09 | R3: -2.4951128e-09 | S3: -6.2380854e-09 | T3: -1.2412612e-08 | U3: -1.9149115e-08 | V3: -1.6710308e-08 | W3: -3.2677642e-08 | X3: -4.2967679e-09 | Y3: 8.2698116e-09 | Z3: -1.2533469e-08 | AA3: -9.7855812e-09 | AB3: -1.209039e-08 | AC3: 2.5987652e-08 | AD3: 2.8334017e-08 | AE3: 2.0952159e-08 | AF3: 2.7991032e-06
A4: 2.deh_c4 | B4: -0.24263388 | C4: 7.097732e-05 | D4: -3.4967813e-07 | E4: 0.0029332667 | F4: 0.0019172919 | G4: -5.7774168e-05 | H4: -3.7608388e-05 | I4: -0.00015712698 | J4: -0.00016121444 | K4: 4.1636345e-05 | L4: -7.5504468e-05 | M4: -2.6965389e-05 | N4: 8.7861842e-07 | O4: -4.2485936e-07 | P4: -2.2195471e-05 | Q4: -3.1767731e-05 | R4: -5.3242333e-05 | S4: -6.5983216e-05 | T4: -4.2811693e-05 | U4: -3.4508515e-05 | V4: -4.8064227e-05 | W4: -3.8579388e-05 | X4: -5.2132115e-05 | Y4: -4.0355657e-05 | Z4: -4.0093074e-05 | AA4: 8.7364937e-06 | AB4: 1.6729349e-05 | AC4: 8.5791709e-05 | AD4: -1.4771385e-05 | AE4: 5.6378254e-05 | AF4: -0.0024906185
A5: 3.deh_c4 | B5: -0.70361218 | C5: 1.1178667e-05 | D5: 3.1061545e-07 | E5: 0.0019172919 | F5: 0.0088330808 | G5: -3.790558e-05 | H5: -0.00015966962 | I5: -0.00019592485 | J5: -0.00025201007 | K5: 2.1026345e-05 | L5: -7.9638353e-05 | M5: -5.7311561e-05 | N5: 7.2232549e-07 | O5: -1.2660596e-06 | P5: -3.0945848e-05 | Q5: -2.3319264e-05 | R5: -3.1471729e-05 | S5: -6.3035355e-05 | T5: -4.6705587e-05 | U5: -2.4124492e-05 | V5: -3.4961989e-05 | W5: -3.5704218e-05 | X5: -8.9409123e-05 | Y5: -1.1583204e-05 | Z5: -9.9455723e-05 | AA5: 2.034777e-05 | AB5: 1.5143393e-05 | AC5: 4.4192667e-05 | AD5: -3.2124755e-05 | AE5: 5.3407642e-05 | AF5: -0.0011239293
A6: 2.deh_c4#c.dag | B6: 0.0079120636 | C6: -1.3799272e-06 | D6: 6.1315027e-09 | E6: -5.7774168e-05 | F6: -3.790558e-05 | G6: 1.2406106e-06 | H6: 8.1161408e-07 | I6: 2.1604425e-06 | J6: 1.6542988e-06 | K6: -7.1506111e-07 | L6: 1.4970004e-06 | M6: 4.0976457e-08 | N6: 1.2451399e-08 | O6: 2.5059534e-09 | P6: -6.5562357e-08 | Q6: 1.3161728e-07 | R6: 4.6176389e-07 | S6: 6.2695242e-07 | T6: 2.3924061e-07 | U6: 2.4905194e-07 | V6: 5.9397536e-07 | W6: 2.0487265e-07 | X6: 2.084714e-07 | Y6: 3.271822e-07 | Z6: 3.4994905e-07 | AA6: -1.3100822e-07 | AB6: -2.7223607e-07 | AC6: -1.0994019e-06 | AD6: 2.7786918e-07 | AE6: -8.2441943e-07 | AF6: 4.7290042e-05
A7: 3.deh_c4#c.dag | B7: 0.015069055 | C7: -2.0157042e-07 | D7: -6.7757691e-09 | E7: -3.7608388e-05 | F7: -0.00015966962 | G7: 8.1161408e-07 | H7: 3.0740373e-06 | I7: 2.9312668e-06 | J7: 2.7094948e-06 | K7: -4.2855767e-07 | L7: 1.5304803e-06 | M7: 2.6870329e-07 | N7: 2.3778035e-08 | O7: 1.6090195e-08 | P7: 1.3979802e-07 | Q7: 5.162453e-08 | R7: 9.1794997e-09 | S7: 3.4561044e-07 | T7: 2.3578548e-07 | U7: 3.8477726e-08 | V7: 3.2899492e-07 | W7: 1.6489257e-07 | X7: 8.7735892e-07 | Y7: -4.9960163e-08 | Z7: 9.1815624e-07 | AA7: -8.9914625e-08 | AB7: 5.5780058e-08 | AC7: -6.462879e-07 | AD7: 5.0303299e-07 | AE7: -8.888433e-07 | AF7: 2.0233677e-05
A8: 2.dehmf_c3 | B8: 0.13765043 | C8: -4.0560689e-06 | D8: 2.0897153e-08 | E8: -0.00015712698 | F8: -0.00019592485 | G8: 2.1604425e-06 | H8: 2.9312668e-06 | I8: 0.0010709748 | J8: 0.00098778386 | K8: -2.4246086e-05 | L8: -3.3862519e-06 | M8: 6.111942e-06 | N8: 3.1509808e-07 | O8: -7.8073802e-08 | P8: -2.6439778e-05 | Q8: -2.0756179e-05 | R8: -3.6182545e-05 | S8: -2.1329766e-05 | T8: -2.7301992e-05 | U8: -1.8407243e-05 | V8: -2.0684611e-05 | W8: -2.0867327e-05 | X8: -2.1872524e-05 | Y8: -1.2663889e-05 | Z8: -1.7480805e-05 | AA8: 4.9529935e-06 | AB8: -7.5441733e-07 | AC8: 1.4791924e-05 | AD8: 1.3479603e-05 | AE8: 4.193948e-05 | AF8: -0.00078144117
A9: 3.dehmf_c3 | B9: 0.13895488 | C9: -4.3515786e-06 | D9: -8.1042921e-09 | E9: -0.00016121444 | F9: -0.00025201007 | G9: 1.6542988e-06 | H9: 2.7094948e-06 | I9: 0.00098778386 | J9: 0.0011472301 | K9: -1.9635791e-05 | L9: -2.8860283e-07 | M9: -4.7060042e-06 | N9: 4.4824228e-07 | O9: -1.6816291e-07 | P9: -4.2767061e-05 | Q9: -3.5556347e-05 | R9: -4.1650917e-05 | S9: -3.6169233e-05 | T9: -4.1499322e-05 | U9: -2.4816159e-05 | V9: -1.2271476e-05 | W9: -1.0451645e-05 | X9: -3.518115e-05 | Y9: -1.3825955e-05 | Z9: -6.3783934e-05 | AA9: 1.817214e-05 | AB9: 1.6683405e-05 | AC9: -3.893656e-05 | AD9: -7.5192314e-06 | AE9: 3.4179129e-05 | AF9: -0.00070878894
A10: mar | B10: 0.13249974 | C10: -1.2535136e-05 | D10: 9.6938672e-08 | E10: 4.1636345e-05 | F10: 2.1026345e-05 | G10: -7.1506111e-07 | H10: -4.2855767e-07 | I10: -2.4246086e-05 | J10: -1.9635791e-05 | K10: 0.00030838594 | L10: -0.00011834057 | M10: 5.1999072e-06 | N10: -1.3881398e-07 | O10: -1.1192347e-06 | P10: -1.2212072e-05 | Q10: -1.322594e-05 | R10: -1.8001256e-05 | S10: -2.2932475e-05 | T10: -1.67319e-05 | U10: -1.7238622e-05 | V10: -1.7150707e-05 | W10: -2.1706844e-05 | X10: -1.8398437e-05 | Y10: -7.1515821e-06 | Z10: -3.2774045e-06 | AA10: 4.7738527e-06 | AB10: 5.528166e-06 | AC10: 3.3062882e-06 | AD10: 5.2572547e-05 | AE10: 1.3094058e-05 | AF10: 0.00027106457
A11: child | B11: 0.00525531 | C11: -1.1331331e-05 | D11: 1.5411192e-07 | E11: -7.5504468e-05 | F11: -7.9638353e-05 | G11: 1.4970004e-06 | H11: 1.5304803e-06 | I11: -3.3862519e-06 | J11: -2.8860283e-07 | K11: -0.00011834057 | L11: 0.00030056707 | M11: 2.6416934e-06 | N11: -2.1561908e-07 | O11: 7.1402256e-08 | P11: -2.586781e-06 | Q11: -4.4274267e-06 | R11: -4.2569869e-07 | S11: 5.9866008e-06 | T11: -4.7254682e-06 | U11: -5.0166317e-06 | V11: -1.7865791e-06 | W11: 2.691596e-07 | X11: 3.8410525e-06 | Y11: 1.048295e-06 | Z11: -1.1043823e-05 | AA11: 1.8825684e-06 | AB11: 2.25191e-06 | AC11: -4.9368205e-05 | AD11: -3.7787849e-05 | AE11: -7.9350965e-06 | AF11: 0.00016732118
A12: dlltsd01 | B12: -0.9038271 | C12: -6.4173497e-06 | D12: 7.6891727e-08 | E12: -2.6965389e-05 | F12: -5.7311561e-05 | G12: 4.0976457e-08 | H12: 2.6870329e-07 | I12: 6.111942e-06 | J12: -4.7060042e-06 | K12: 5.1999072e-06 | L12: 2.6416934e-06 | M12: 0.001199841 | N12: 6.9112956e-06 | O12: 2.5134234e-06 | P12: -1.8323357e-05 | Q12: -2.4310943e-05 | R12: -1.9001901e-05 | S12: -2.2258569e-05 | T12: -3.1841356e-06 | U12: -5.7567466e-06 | V12: -9.5252976e-06 | W12: -2.2815402e-05 | X12: -1.7270194e-05 | Y12: -1.4507626e-05 | Z12: -2.7997234e-05 | AA12: 7.4141818e-07 | AB12: -3.3743603e-07 | AC12: 9.8539862e-06 | AD12: 1.691028e-05 | AE12: 3.4720819e-06 | AF12: -0.00039468515
A13: dhe_pcs_L1 | B13: 0.0036367173 | C13: 3.6824432e-08 | D13: 6.9303542e-10 | E13: 8.7861842e-07 | F13: 7.2232549e-07 | G13: 1.2451399e-08 | H13: 2.3778035e-08 | I13: 3.1509808e-07 | J13: 4.4824228e-07 | K13: -1.3881398e-07 | L13: -2.1561908e-07 | M13: 6.9112956e-06 | N13: 8.5599836e-07 | O13: 6.8153402e-08 | P13: 6.8661471e-07 | Q13: 4.0158239e-07 | R13: 3.0455047e-07 | S13: 5.484283e-07 | T13: 8.342229e-07 | U13: 4.0723354e-07 | V13: 5.2716072e-08 | W13: 4.0002324e-07 | X13: 7.5683233e-07 | Y13: 2.4756896e-07 | Z13: 3.4309997e-07 | AA13: 4.0185402e-07 | AB13: 2.0319066e-07 | AC13: 1.6806704e-06 | AD13: 2.7787454e-07 | AE13: 7.2509077e-07 | AF13: -5.3735573e-05
... A31: Constant | B31: -1.5287501 | C31: -0.00029859566 | D31: 2.7991032e-06 | E31: -0.0024906185 | F31: -0.0011239293 | G31: 4.7290042e-05 | H31: 2.0233677e-05 | I31: -0.00078144117 | J31: -0.00070878894 | K31: 0.00027106457 | L31: 0.00016732118 | M31: -0.00039468515 | N31: -5.3735573e-05 | O31: -3.5960596e-05 | P31: -0.00047509858 | Q31: -0.00048124709 | R31: -0.00044735426 | S31: -0.00047861489 | T31: -0.00050267421 | U31: -0.00050364375 | V31: -0.00046319785 | W31: -0.00051901733 | X31: -0.00052676817 | Y31: -0.00045229685 | Z31: -0.00049167576 | AA31: -0.00012207131 | AB31: -0.00012129317 | AC31: -0.00039462469 | AD31: -0.00028148291 | AE31: -0.00035609659 | AF31: 0.01310397

Sheet W1fa-sel
A1: REGRESSOR | B1: COEFFICIENT | C1: labStatusC3StudentL1 | D1: labStatusC3NotEmployedL1 | E1: demAge | F1: demAgeSq | G1: eduHighestC4Medium | H1: eduHighestC4Low | I1: eduHighestC4Medium_demAge | J1: eduHighestC4Low_demAge | K1: eduHighestParentC3Medium | L1: eduHighestParentC3Low | M1: demPartnerStatusPartnered | N1: demDChild | O1: healthDsblLongtermFlag | P1: healthPhysicalPcsL1 | Q1: healthMentalMcsL1 | R1: demRgnUKC | S1: demRgnUKD | T1: demRgnUKE | U1: demRgnUKF | V1: demRgnUKG | W1: demRgnUKH | X1: demRgnUKJ | Y1: demRgnUKK | Z1: demRgnUKL | AA1: demRgnUKM | AB1: demRgnUKN | AC1: demYear2020 | AD1: demYear2021 | AE1: demEthnC4Asian | AF1: demEthnC4Black | AG1: demEthnC4Other | AH1: Constant
A2: labStatusC3StudentL1 | B2: -0.91632643 | C2: 0.0018440613 | D2: 0.0011590531 | E2: 5.6926033e-05 | F2: -4.6317181e-07 | G2: 0.00030455872 | H2: 0.00041616822 | I2: -8.2858177e-06 | J2: -1.090373e-05 | K2: 2.1557553e-05 | L2: 1.7812116e-05 | M2: 5.5976833e-05 | N2: 3.4036048e-05 | O2: 4.8605009e-06 | P2: 1.414367e-06 | Q2: 8.487742e-07 | R2: -6.1954695e-05 | S2: -3.8208045e-05 | T2: -3.3639575e-05 | U2: -3.5809529e-05 | V2: -3.5223545e-05 | W2: -3.5639559e-05 | X2: -1.6737617e-05 | Y2: -3.7438245e-05 | Z2: -3.692573e-05 | AA2: -6.8086331e-05 | AB2: -7.4377266e-05 | AC2: 1.7820729e-06 | AD2: -6.7850657e-07 | AE2: -2.6470739e-05 | AF2: -8.7085972e-05 | AG2: -1.2025198e-06 | AH2: -0.002750099
A3: labStatusC3NotEmployedL1 | B3: -1.2525569 | C3: 0.0011590531 | D3: 0.0012126414 | E3: 1.4639582e-05 | F3: -1.0409824e-07 | G3: 9.3653653e-05 | H3: 8.4237937e-05 | I3: -4.9195952e-06 | J3: -5.5131612e-06 | K3: -2.2672594e-05 | L3: -3.0208749e-05 | M3: 1.0428691e-05 | N3: -3.0404641e-05 | O3: -3.3827781e-05 | P3: 2.2537224e-06 | Q3: 1.2458268e-06 | R3: -6.7297918e-05 | S3: -2.8577574e-05 | T3: -4.6248393e-05 | U3: -4.6857512e-05 | V3: -3.5419869e-05 | W3: -3.2242616e-05 | X3: -1.0602849e-05 | Y3: -3.9407214e-05 | Z3: -4.5838303e-05 | AA3: -3.8464997e-05 | AB3: -6.720708e-05 | AC3: 1.56094e-05 | AD3: 9.0049524e-06 | AE3: -4.1553749e-05 | AF3: -4.3607069e-05 | AG3: -3.7076572e-07 | AH3: -0.0015349063
A4: demAge | B4: 0.10930382 | C4: 5.6926033e-05 | D4: 1.4639582e-05 | E4: 1.9324138e-05 | F4: -2.0124958e-07 | G4: 0.00011210194 | H4: 6.2813892e-05 | I4: -2.3442554e-06 | J4: -1.2502327e-06 | K4: -3.6640582e-06 | L4: -7.6265466e-06 | M4: -2.2308507e-05 | N4: -2.0763157e-05 | O4: -2.7066164e-05 | P4: 1.507698e-07 | Q4: 2.2717694e-07 | R4: 4.2885349e-06 | S4: 3.4363803e-06 | T4: 6.4273253e-06 | U4: 3.74169e-06 | V4: 2.4395899e-06 | W4: 2.863142e-06 | X4: 3.4290818e-06 | Y4: 6.8888014e-06 | Z4: 5.0957062e-06 | AA4: 2.601902e-06 | AB4: 1.593674e-06 | AC4: 2.1038687e-06 | AD4: -3.0456758e-07 | AE4: -4.0934549e-06 | AF4: -1.272287e-05 | AG4: -1.8732446e-06 | AH4: -0.0004301722
A5: demAgeSq | B5: -0.0018005293 | C5: -4.6317181e-07 | D5: -1.0409824e-07 | E5: -2.0124958e-07 | F5: 2.2885869e-09 | G5: -6.518297e-07 | H5: -5.6203592e-08 | I5: 1.1794439e-08 | J5: -1.3436107e-09 | K5: 3.2061447e-08 | L5: 4.2252423e-08 | M5: 2.2177347e-07 | N5: 2.9171666e-07 | O5: 3.2661499e-07 | P5: -4.4610899e-10 | Q5: -3.605892e-09 | R5: -2.8852646e-08 | S5: -2.9880313e-08 | T5: -5.656426e-08 | U5: -2.8813413e-08 | V5: -1.6740078e-08 | W5: -2.5966232e-08 | X5: -4.0555355e-08 | Y5: -8.3709394e-08 | Z5: -4.4523128e-08 | AA5: -2.8757965e-08 | AB5: -3.8497152e-09 | AC5: -3.3620783e-08 | AD5: -1.1903547e-08 | AE5: 1.007099e-07 | AF5: 1.5125013e-07 | AG5: 4.7706274e-08 | AH5: 4.0260586e-06
A6: eduHighestC4Medium | B6: -0.62383639 | C6: 0.00030455872 | D6: 9.3653653e-05 | E6: 0.00011210194 | F6: -6.518297e-07 | G6: 0.0034042638 | H6: 0.0025495641 | I6: -7.3612803e-05 | J6: -5.4043835e-05 | K6: -7.9757688e-05 | L6: -0.00010231662 | M6: 3.4905455e-05 | N6: -0.00013273846 | O6: -5.7954379e-05 | P6: 1.0854719e-06 | Q6: 5.4672082e-07 | R6: 1.9134007e-05 | S6: 2.3588738e-06 | T6: -9.224521e-06 | U6: -1.6940205e-05 | V6: -6.9860664e-07 | W6: -8.4074696e-06 | X6: 1.4827142e-05 | Y6: -1.8106914e-05 | Z6: -7.5786921e-06 | AA6: -9.2353199e-06 | AB6: -3.7741531e-06 | AC6: 8.6546024e-06 | AD6: -8.4576084e-06 | AE6: 0.00010270089 | AF6: 3.6551333e-05 | AG6: 3.139982e-05 | AH6: -0.0037549709
A7: eduHighestC4Low | B7: -1.3754651 | C7: 0.00041616822 | D7: 8.4237937e-05 | E7: 6.2813892e-05 | F7: -5.6203592e-08 | G7: 0.0025495641 | H7: 0.0078182288 | I7: -5.4434978e-05 | J7: -0.00015687271 | K7: -0.00013518895 | L7: -0.00016224572 | M7: 4.4492519e-05 | N7: -0.00012999113 | O7: -0.00010502528 | P7: -4.6123368e-07 | Q7: -7.6337069e-07 | R7: 4.7052542e-05 | S7: -1.6476872e-05 | T7: 1.132229e-05 | U7: 7.163457e-06 | V7: 5.7348181e-06 | W7: -2.2558314e-05 | X7: 5.3081061e-06 | Y7: -2.9894511e-05 | Z7: -1.9553332e-05 | AA7: 6.1223552e-06 | AB7: -6.0433385e-05 | AC7: 4.4661125e-07 | AD7: 5.2719339e-06 | AE7: 5.8678562e-05 | AF7: -5.3195926e-05 | AG7: 4.5197207e-05 | AH7: -0.002666986
A8: eduHighestC4Medium_demAge | B8: 0.0097372249 | C8: -8.2858177e-06 | D8: -4.9195952e-06 | E8: -2.3442554e-06 | F8: 1.1794439e-08 | G8: -7.3612803e-05 | H8: -5.4434978e-05 | I8: 1.8109908e-06 | J8: 1.3121915e-06 | K8: 1.5117233e-07 | L8: -2.7906065e-07 | M8: -5.9166359e-07 | N8: 2.5392477e-06 | O8: 6.6855463e-07 | P8: -1.7020164e-09 | Q8: 3.657087e-09 | R8: -9.0898276e-07 | S8: -3.7014507e-07 | T8: -3.8317615e-07 | U8: -1.8547857e-07 | V8: -5.0729389e-07 | W8: -4.3990891e-07 | X8: -2.8895601e-07 | Y8: 2.807439e-07 | Z8: -3.9733399e-07 | AA8: -6.1316559e-08 | AB8: -2.2187075e-07 | AC8: 1.1518726e-07 | AD8: 4.4802298e-07 | AE8: -1.5708258e-06 | AF8: -9.769195e-07 | AG8: -5.7801596e-07 | AH8: 7.9207172e-05
A9: eduHighestC4Low_demAge | B9: 0.019542708 | C9: -1.090373e-05 | D9: -5.5131612e-06 | E9: -1.2502327e-06 | F9: -1.3436107e-09 | G9: -5.4043835e-05 | H9: -0.00015687271 | I9: 1.3121915e-06 | J9: 3.5083041e-06 | K9: 1.4775815e-06 | L9: 9.1302172e-08 | M9: -4.4690914e-07 | N9: 2.4184071e-06 | O9: 1.3228411e-06 | P9: 4.2771684e-08 | Q9: 3.4412411e-08 | R9: -1.0744514e-06 | S9: 2.5039719e-07 | T9: -5.4891261e-07 | U9: -5.0899824e-07 | V9: -5.2883267e-07 | W9: 1.7226204e-08 | X9: 4.0176828e-07 | Y9: 8.4304037e-07 | Z9: 3.3851937e-08 | AA9: 1.3047483e-07 | AB9: 5.1316588e-07 | AC9: 7.4119518e-07 | AD9: 7.7098204e-07 | AE9: -1.3834848e-06 | AF9: 8.4849623e-07 | AG9: -7.6038166e-07 | AH9: 5.4762473e-05
A10: eduHighestParentC3Medium | B10: 0.037092352 | C10: 2.1557553e-05 | D10: -2.2672594e-05 | E10: -3.6640582e-06 | F10: 3.2061447e-08 | G10: -7.9757688e-05 | H10: -0.00013518895 | I10: 1.5117233e-07 | J10: 1.4775815e-06 | K10: 0.0011949606 | L10: 0.0010879594 | M10: -1.7991304e-05 | N10: -1.8306275e-05 | O10: -5.6951206e-06 | P10: 5.5278397e-07 | Q10: -3.0117341e-07 | R10: -4.0383365e-05 | S10: -3.650179e-05 | T10: -3.1219277e-05 | U10: -1.9716569e-05 | V10: -4.278692e-05 | W10: -3.2143558e-05 | X10: -2.3755713e-05 | Y10: -3.9117548e-05 | Z10: -4.1870109e-05 | AA10: -3.4860721e-05 | AB10: -3.9094855e-05 | AC10: -2.8266242e-07 | AD10: -8.3860336e-06 | AE10: -6.5683977e-08 | AF10: 2.3764761e-05 | AG10: 5.639223e-05 | AH10: -0.00088958666
A11: eduHighestParentC3Low | B11: -0.02390819 | C11: 1.7812116e-05 | D11: -3.0208749e-05 | E11: -7.6265466e-06 | F11: 4.2252423e-08 | G11: -0.00010231662 | H11: -0.00016224572 | I11: -2.7906065e-07 | J11: 9.1302172e-08 | K11: 0.0010879594 | L11: 0.0013150953 | M11: 1.2070746e-06 | N11: -1.3765364e-05 | O11: -4.4107964e-06 | P11: 8.3016188e-07 | Q11: -3.6868089e-07 | R11: -6.4119023e-05 | S11: -5.4839383e-05 | T11: -5.8504925e-05 | U11: -4.4274639e-05 | V11: -6.3183697e-05 | W11: -3.0573194e-05 | X11: -1.7907205e-05 | Y11: -3.1619884e-05 | Z11: -8.0517728e-05 | AA11: -3.7392671e-05 | AB11: -0.00011005045 | AC11: 1.727202e-05 | AD11: 1.6911473e-05 | AE11: -7.4640793e-05 | AF11: 1.8190878e-06 | AG11: 3.8490697e-05 | AH11: -0.00075628739
A12: demPartnerStatusPartnered | B12: -0.23181046 | C12: 5.5976833e-05 | D12: 1.0428691e-05 | E12: -2.2308507e-05 | F12: 2.2177347e-07 | G12: 3.4905455e-05 | H12: 4.4492519e-05 | I12: -5.9166359e-07 | J12: -4.4690914e-07 | K12: -1.7991304e-05 | L12: 1.2070746e-06 | M12: 0.00037725293 | N12: -5.9780858e-05 | O12: 7.6314004e-05 | P12: -3.9754134e-07 | Q12: -1.4224058e-06 | R12: -1.8933576e-05 | S12: -1.7935582e-05 | T12: -2.6168468e-05 | U12: -2.5625322e-05 | V12: -4.5062646e-06 | W12: -2.8135472e-05 | X12: -1.9055983e-05 | Y12: -3.2939204e-05 | Z12: -2.1894435e-05 | AA12: -1.5509663e-05 | AB12: 1.2636452e-05 | AC12: 4.8050214e-06 | AD12: 1.0006497e-05 | AE12: -2.9910834e-05 | AF12: 9.9458632e-05 | AG12: 3.1735273e-05 | AH12: 0.00039044257
A13: demDChild | B13: -0.31875706 | C13: 3.4036048e-05 | D13: -3.0404641e-05 | E13: -2.0763157e-05 | F13: 2.9171666e-07 | G13: -0.00013273846 | H13: -0.00012999113 | I13: 2.5392477e-06 | J13: 2.4184071e-06 | K13: -1.8306275e-05 | L13: -1.3765364e-05 | M13: -5.9780858e-05 | N13: 0.00038574453 | O13: 5.4287675e-05 | P13: -6.2907445e-07 | Q13: -8.7375113e-07 | R13: 8.8563355e-06 | S13: 3.4024887e-06 | T13: 4.784502e-06 | U13: 1.0351616e-05 | V13: 3.0152751e-06 | W13: -1.2249525e-06 | X13: 2.7604382e-06 | Y13: 9.7915982e-06 | Z13: 7.5680248e-06 | AA13: 7.3886883e-06 | AB13: -5.2064251e-06 | AC13: 1.6490355e-05 | AD13: 2.3541689e-05 | AE13: -2.3915904e-05 | AF13: -4.0890784e-05 | AG13: -2.0840919e-05 | AH13: 0.00026624542
... A33: Constant | B33: -0.46035827 | C33: -0.002750099 | D33: -0.0015349063 | E33: -0.0004301722 | F33: 4.0260586e-06 | G33: -0.0037549709 | H33: -0.002666986 | I33: 7.9207172e-05 | J33: 5.4762473e-05 | K33: -0.00088958666 | L33: -0.00075628739 | M33: 0.00039044257 | N33: 0.00026624542 | O33: -0.00017983462 | P33: -4.5143397e-05 | Q33: -3.0446257e-05 | R33: -0.00070069109 | S33: -0.0006837128 | T33: -0.00068476169 | U33: -0.00064842734 | V33: -0.00058771624 | W33: -0.00060095626 | X33: -0.00066428381 | Y33: -0.00071167734 | Z33: -0.00070990874 | AA33: -0.00066615583 | AB33: -0.0005778421 | AC33: -0.00018092438 | AD33: -0.00015206962 | AE33: -0.00029177828 | AF33: -0.00024282349 | AG33: -0.00044350409 | AH33: 0.016788939

Sheet W1ma-sel
A1: REGRESSOR | B1: COEFFICIENT | C1: labStatusC3StudentL1 | D1: labStatusC3NotEmployedL1 | E1: demAge | F1: demAgeSq | G1: eduHighestC4Medium | H1: eduHighestC4Low | I1: eduHighestC4Medium_demAge | J1: eduHighestC4Low_demAge | K1: eduHighestParentC3Medium | L1: eduHighestParentC3Low | M1: demPartnerStatusPartnered | N1: demDChild | O1: healthDsblLongtermFlag | P1: healthPhysicalPcsL1 | Q1: healthMentalMcsL1 | R1: demRgnUKC | S1: demRgnUKD | T1: demRgnUKE | U1: demRgnUKF | V1: demRgnUKG | W1: demRgnUKH | X1: demRgnUKJ | Y1: demRgnUKK | Z1: demRgnUKL | AA1: demRgnUKM | AB1: demRgnUKN | AC1: demYear2020 | AD1: demYear2021 | AE1: demEthnC4Asian | AF1: demEthnC4Black | AG1: demEthnC4Other | AH1: Constant
