Workbook

Sheet W1mb-comp
A1: =W1mb!A1 -> REGRESSOR | B1: =W1mb!B1 -> COEFFICIENT | D1: =W1mb_orig!A1 -> REGRESSOR | E1: =W1mb_orig!B1 -> COEFFICIENT | G1: comp
A2: =W1mb!A2 -> labWageHrlyLogL1 | B2: =W1mb!B2 -> 0.49300454 | D2: =W1mb_orig!A2 -> lwage_hour_L1 | E2: =W1mb_orig!B2 -> 0.49300454 | G2: =B2-E2 -> 0
A3: =W1mb!A3 -> demAge | B3: =W1mb!B3 -> 0.014027119 | D3: =W1mb_orig!A3 -> dag | E3: =W1mb_orig!B3 -> 0.014027119 | G3: =B3-E3 -> 0
A4: =W1mb!A4 -> demAgeSq | B4: =W1mb!B4 -> -0.00012132579 | D4: =W1mb_orig!A4 -> dagsq | E4: =W1mb_orig!B4 -> -0.00012132579 | G4: =B4-E4 -> 0
A5: =W1mb!A5 -> eduHighestC4Medium | B5: =W1mb!B5 -> -0.138502 | D5: =W1mb_orig!A5 -> 2.deh_c4 | E5: =W1mb_orig!B5 -> -0.138502 | G5: =B5-E5 -> 0
A6: =W1mb!A6 -> eduHighestC4Low | B6: =W1mb!B6 -> -0.32111242 | D6: =W1mb_orig!A6 -> 3.deh_c4 | E6: =W1mb_orig!B6 -> -0.32111242 | G6: =B6-E6 -> 0
A7: =W1mb!A7 -> eduHighestC4Medium_demAge | B7: =W1mb!B7 -> -0.0010218866 | D7: =W1mb_orig!A7 -> 2.deh_c4#c.dag | E7: =W1mb_orig!B7 -> -0.0010218866 | G7: =B7-E7 -> 0
A8: =W1mb!A8 -> eduHighestC4Low_demAge | B8: =W1mb!B8 -> 0.00072577805 | D8: =W1mb_orig!A8 -> 3.deh_c4#c.dag | E8: =W1mb_orig!B8 -> 0.00072577805 | G8: =B8-E8 -> 0
A9: =W1mb!A9 -> eduHighestParentC3Medium | B9: =W1mb!B9 -> -0.040476858 | D9: =W1mb_orig!A9 -> 2.dehmf_c3 | E9: =W1mb_orig!B9 -> -0.040476858 | G9: =B9-E9 -> 0
A10: =W1mb!A10 -> eduHighestParentC3Low | B10: =W1mb!B10 -> -0.058158253 | D10: =W1mb_orig!A10 -> 3.dehmf_c3 | E10: =W1mb_orig!B10 -> -0.058158253 | G10: =B10-E10 -> 0
A11: =W1mb!A11 -> healthDsblLongtermFlag | B11: =W1mb!B11 -> 0.096810663 | D11: =W1mb_orig!A11 -> dlltsd01 | E11: =W1mb_orig!B11 -> 0.096810663 | G11: =B11-E11 -> 0
A12: =W1mb!A12 -> healthPhysicalPcsL1 | B12: =W1mb!B12 -> 0.0025798739 | D12: =W1mb_orig!A12 -> dhe_pcs_L1 | E12: =W1mb_orig!B12 -> 0.0025798739 | G12: =B12-E12 -> 0
A13: =W1mb!A13 -> healthMentalMcsL1 | B13: =W1mb!B13 -> 0.00098098486 | D13: =W1mb_orig!A13 -> dhe_mcs_L1 | E13: =W1mb_orig!B13 -> 0.00098098486 | G13: =B13-E13 -> 0
... A33: =W1mb!A33 -> InvMillsRatio | B33: =W1mb!B33 -> -0.47303313 | D33: =W1mb_orig!A33 -> InvMillsRatio | E33: =W1mb_orig!B33 -> -0.47303313 | G33: =B33-E33 -> 0

Sheet W1fb-comp
A1: =W1fb!A1 -> REGRESSOR | B1: =W1fb!B1 -> COEFFICIENT | D1: =W1fb_orig!A1 -> REGRESSOR | E1: =W1fb_orig!B1 -> COEFFICIENT | G1: comp
A2: =W1fb!A2 -> labWageHrlyLogL1 | B2: =W1fb!B2 -> 0.49533268 | D2: =W1fb_orig!A2 -> lwage_hour_L1 | E2: =W1fb_orig!B2 -> 0.49533268 | G2: =B2-E2 -> 0
A3: =W1fb!A3 -> demAge | B3: =W1fb!B3 -> 0.018875826 | D3: =W1fb_orig!A3 -> dag | E3: =W1fb_orig!B3 -> 0.018875826 | G3: =B3-E3 -> 0
A4: =W1fb!A4 -> demAgeSq | B4: =W1fb!B4 -> -0.00019845606 | D4: =W1fb_orig!A4 -> dagsq | E4: =W1fb_orig!B4 -> -0.00019845606 | G4: =B4-E4 -> 0
A5: =W1fb!A5 -> eduHighestC4Medium | B5: =W1fb!B5 -> -0.1854536 | D5: =W1fb_orig!A5 -> 2.deh_c4 | E5: =W1fb_orig!B5 -> -0.1854536 | G5: =B5-E5 -> 0
A6: =W1fb!A6 -> eduHighestC4Low | B6: =W1fb!B6 -> -0.25259229 | D6: =W1fb_orig!A6 -> 3.deh_c4 | E6: =W1fb_orig!B6 -> -0.25259229 | G6: =B6-E6 -> 0
A7: =W1fb!A7 -> eduHighestC4Medium_demAge | B7: =W1fb!B7 -> 0.00067196544 | D7: =W1fb_orig!A7 -> 2.deh_c4#c.dag | E7: =W1fb_orig!B7 -> 0.00067196544 | G7: =B7-E7 -> 0
A8: =W1fb!A8 -> eduHighestC4Low_demAge | B8: =W1fb!B8 -> 0.00032000856 | D8: =W1fb_orig!A8 -> 3.deh_c4#c.dag | E8: =W1fb_orig!B8 -> 0.00032000856 | G8: =B8-E8 -> 0
A9: =W1fb!A9 -> eduHighestParentC3Medium | B9: =W1fb!B9 -> -0.017792177 | D9: =W1fb_orig!A9 -> 2.dehmf_c3 | E9: =W1fb_orig!B9 -> -0.017792177 | G9: =B9-E9 -> 0
A10: =W1fb!A10 -> eduHighestParentC3Low | B10: =W1fb!B10 -> -0.037895449 | D10: =W1fb_orig!A10 -> 3.dehmf_c3 | E10: =W1fb_orig!B10 -> -0.037895449 | G10: =B10-E10 -> 0
A11: =W1fb!A11 -> healthDsblLongtermFlag | B11: =W1fb!B11 -> -0.024303523 | D11: =W1fb_orig!A11 -> dlltsd01 | E11: =W1fb_orig!B11 -> -0.024303523 | G11: =B11-E11 -> 0
A12: =W1fb!A12 -> healthPhysicalPcsL1 | B12: =W1fb!B12 -> 0.0021306048 | D12: =W1fb_orig!A12 -> dhe_pcs_L1 | E12: =W1fb_orig!B12 -> 0.0021306048 | G12: =B12-E12 -> 0
A13: =W1fb!A13 -> healthMentalMcsL1 | B13: =W1fb!B13 -> 0.00095961862 | D13: =W1fb_orig!A13 -> dhe_mcs_L1 | E13: =W1fb_orig!B13 -> 0.00095961862 | G13: =B13-E13 -> 0
... A33: =W1fb!A33 -> InvMillsRatio | B33: =W1fb!B33 -> -0.097049415 | D33: =W1fb_orig!A33 -> InvMillsRatio | E33: =W1fb_orig!B33 -> -0.097049415 | G33: =B33-E33 -> 0

Sheet W1ma-comp
A1: =W1ma!A1 -> REGRESSOR | B1: =W1ma!B1 -> COEFFICIENT | D1: =W1ma_orig!A1 -> REGRESSOR | E1: =W1ma_orig!B1 -> COEFFICIENT | G1: comp
A2: =W1ma!A2 -> dag | B2: =W1ma!B2 -> 0.0009163482 | D2: =W1ma_orig!A2 -> dag | E2: =W1ma_orig!B2 -> 0.0009163482 | G2: =B2-E2 -> 0
A3: =W1ma!A3 -> dagsq | B3: =W1ma!B3 -> 0.00035692656 | D3: =W1ma_orig!A3 -> dagsq | E3: =W1ma_orig!B3 -> 0.00035692656 | G3: =B3-E3 -> 0
A4: =W1ma!A4 -> 2.deh_c4 | B4: =W1ma!B4 -> 0.065472386 | D4: =W1ma_orig!A4 -> 2.deh_c4 | E4: =W1ma_orig!B4 -> 0.065472386 | G4: =B4-E4 -> 0
A5: =W1ma!A5 -> 3.deh_c4 | B5: =W1ma!B5 -> 0.44366923 | D5: =W1ma_orig!A5 -> 3.deh_c4 | E5: =W1ma_orig!B5 -> 0.44366923 | G5: =B5-E5 -> 0
A6: =W1ma!A6 -> 2.deh_c4#c.dag | B6: =W1ma!B6 -> -0.0069624467 | D6: =W1ma_orig!A6 -> 2.deh_c4#c.dag | E6: =W1ma_orig!B6 -> -0.0069624467 | G6: =B6-E6 -> 0
A7: =W1ma!A7 -> 3.deh_c4#c.dag | B7: =W1ma!B7 -> -0.018357135 | D7: =W1ma_orig!A7 -> 3.deh_c4#c.dag | E7: =W1ma_orig!B7 -> -0.018357135 | G7: =B7-E7 -> 0
A8: =W1ma!A8 -> 2.dehmf_c3 | B8: =W1ma!B8 -> -0.065260141 | D8: =W1ma_orig!A8 -> 2.dehmf_c3 | E8: =W1ma_orig!B8 -> -0.065260141 | G8: =B8-E8 -> 0
A9: =W1ma!A9 -> 3.dehmf_c3 | B9: =W1ma!B9 -> -0.096501293 | D9: =W1ma_orig!A9 -> 3.dehmf_c3 | E9: =W1ma_orig!B9 -> -0.096501293 | G9: =B9-E9 -> 0
A10: =W1ma!A10 -> dlltsd01 | B10: =W1ma!B10 -> 0.58017381 | D10: =W1ma_orig!A10 -> dlltsd01 | E10: =W1ma_orig!B10 -> 0.58017381 | G10: =B10-E10 -> 0
A11: =W1ma!A11 -> dhe_pcs_L1 | B11: =W1ma!B11 -> 0.0035515033 | D11: =W1ma_orig!A11 -> dhe_pcs_L1 | E11: =W1ma_orig!B11 -> 0.0035515033 | G11: =B11-E11 -> 0
A12: =W1ma!A12 -> dhe_mcs_L1 | B12: =W1ma!B12 -> 0.0030084742 | D12: =W1ma_orig!A12 -> dhe_mcs_L1 | E12: =W1ma_orig!B12 -> 0.0030084742 | G12: =B12-E12 -> 0
A13: =W1ma!A13 -> drgn1 | B13: =W1ma!B13 -> -0.11193482 | D13: =W1ma_orig!A13 -> drgn1 | E13: =W1ma_orig!B13 -> -0.11193482 | G13: =B13-E13 -> 0
... A32: =W1ma!A32 -> InvMillsRatio | B32: =W1ma!B32 -> -0.5650019 | D32: =W1ma_orig!A32 -> InvMillsRatio | E32: =W1ma_orig!B32 -> -0.5650019 | G32: =B32-E32 -> 0

Sheet W1fa-comp
A1: =W1fa!A1 -> REGRESSOR | B1: =W1fa!B1 -> COEFFICIENT | D1: =W1fa_orig!A1 -> REGRESSOR | E1: =W1fa_orig!B1 -> COEFFICIENT | G1: comp
A2: =W1fa!A2 -> demAge | B2: =W1fa!B2 -> 0.022841137 | D2: =W1fa_orig!A2 -> dag | E2: =W1fa_orig!B2 -> 0.022841137 | G2: =B2-E2 -> -7.3205331e-16
A3: =W1fa!A3 -> demAgeSq | B3: =W1fa!B3 -> -6.9930275e-05 | D3: =W1fa_orig!A3 -> dagsq | E3: =W1fa_orig!B3 -> -6.9930275e-05 | G3: =B3-E3 -> 7.2641546e-18
A4: =W1fa!A4 -> eduHighestC4Medium | B4: =W1fa!B4 -> -0.025850532 | D4: =W1fa_orig!A4 -> 2.deh_c4 | E4: =W1fa_orig!B4 -> -0.025850532 | G4: =B4-E4 -> -8.895662e-15
A5: =W1fa!A5 -> eduHighestC4Low | B5: =W1fa!B5 -> 0.11019045 | D5: =W1fa_orig!A5 -> 3.deh_c4 | E5: =W1fa_orig!B5 -> 0.11019045 | G5: =B5-E5 -> -7.3552275e-15
A6: =W1fa!A6 -> eduHighestC4Medium_demAge | B6: =W1fa!B6 -> -0.0035824293 | D6: =W1fa_orig!A6 -> 2.deh_c4#c.dag | E6: =W1fa_orig!B6 -> -0.0035824293 | G6: =B6-E6 -> 1.3964524e-16
A7: =W1fa!A7 -> eduHighestC4Low_demAge | B7: =W1fa!B7 -> -0.0053851444 | D7: =W1fa_orig!A7 -> 3.deh_c4#c.dag | E7: =W1fa_orig!B7 -> -0.0053851444 | G7: =B7-E7 -> 2.4286129e-17
A8: =W1fa!A8 -> eduHighestParentC3Medium | B8: =W1fa!B8 -> -0.006140817 | D8: =W1fa_orig!A8 -> 2.dehmf_c3 | E8: =W1fa_orig!B8 -> -0.006140817 | G8: =B8-E8 -> 1.1666015e-15
A9: =W1fa!A9 -> eduHighestParentC3Low | B9: =W1fa!B9 -> 0.012292336 | D9: =W1fa_orig!A9 -> 3.dehmf_c3 | E9: =W1fa_orig!B9 -> 0.012292336 | G9: =B9-E9 -> -5.1347815e-16
A10: =W1fa!A10 -> healthDsblLongtermFlag | B10: =W1fa!B10 -> 0.065577021 | D10: =W1fa_orig!A10 -> dlltsd01 | E10: =W1fa_orig!B10 -> 0.065577021 | G10: =B10-E10 -> -5.2874372e-15
A11: =W1fa!A11 -> healthPhysicalPcsL1 | B11: =W1fa!B11 -> 0.00061052362 | D11: =W1fa_orig!A11 -> dhe_pcs_L1 | E11: =W1fa_orig!B11 -> 0.00061052362 | G11: =B11-E11 -> 2.3960868e-17
A12: =W1fa!A12 -> healthMentalMcsL1 | B12: =W1fa!B12 -> 0.0023398658 | D12: =W1fa_orig!A12 -> dhe_mcs_L1 | E12: =W1fa_orig!B12 -> 0.0023398658 | G12: =B12-E12 -> -2.3852448e-17
A13: =W1fa!A13 -> demRgnUKC | B13: =W1fa!B13 -> -0.16278083 | D13: =W1fa_orig!A13 -> drgn1 | E13: =W1fa_orig!B13 -> -0.16278083 | G13: =B13-E13 -> -6.3837824e-16
... A32: =W1fa!A32 -> InvMillsRatio | B32: =W1fa!B32 -> -0.35606 | D32: =W1fa_orig!A32 -> InvMillsRatio | E32: =W1fa_orig!B32 -> -0.35606 | G32: =B32-E32 -> 8.3266727e-15

Sheet Info
A1: Description: | B1: This file contains regression estimates used to calculate potential wages for males and females in the simulation.
A2: Authors: | B2: Patryk Bronka, Justin Van de Ven, Daria Popova, Aleksandra Kolndrekaj, Ashley Burdett
A3: Last edit: 19 May 2026 (DP)
A5: Process: | B5: Description:
A6: W1fa | B6: Second stage Heckman selection estimates using women that do not have an observed wage in the previous year
A7: W1ma | B7: Second stage Heckman selection estimates using men that do not have an observed wage in the previous year
A8: W1fb | B8: Second stage Heckman selection estimates using women that have an observed wage in the previous year
A9: W1mb | B9: Second stage Heckman selection estimates using men that have an observed wage in the previous year
A11: Notes: | B11: Estimation sample: UK_ipop.dta. Two-step Heckman command is used which does not permit weights
B12: Conditions for processes are defined as globals in master.do
B13: Predicted wages sre saved in dataset UK_ipop2.dta and used as input into union parameters and income process estimates

Sheet W1fa_orig
A1: REGRESSOR | B1: COEFFICIENT | C1: dag | D1: dagsq | E1: 2.deh_c4 | F1: 3.deh_c4 | G1: 2.deh_c4#c.dag | H1: 3.deh_c4#c.dag | I1: 2.dehmf_c3 | J1: 3.dehmf_c3 | K1: dlltsd01 | L1: dhe_pcs_L1 | M1: dhe_mcs_L1 | N1: drgn1 | O1: 2.drgn1 | P1: 4.drgn1 | Q1: 5.drgn1 | R1: 6.drgn1 | S1: 7.drgn1 | T1: 9.drgn1 | U1: 10.drgn1 | V1: 1drgn1 | W1: 12.drgn1 | X1: 13.drgn1 | Y1: pt | Z1: real_wage_growth | AA1: y2020 | AB1: y2021 | AC1: 2.dot | AD1: 3.dot | AE1: 4.dot | AF1: Constant | AG1: InvMillsRatio
A2: dag | B2: 0.022841137 | C2: 2.5594038e-05 | D2: -3.1148086e-07 | E2: 0.00010857467 | F2: -7.8453479e-06 | G2: -2.8222258e-06 | H2: -4.6056271e-07 | I2: -1.21692e-05 | J2: -1.3574482e-05 | K2: -4.6379219e-05 | L2: 3.4981069e-07 | M2: 1.9065953e-07 | N2: -5.7918025e-06 | O2: -3.2772627e-06 | P2: -3.5486378e-06 | Q2: -5.671167e-06 | R2: -5.7925169e-06 | S2: -4.0178519e-06 | T2: 2.4343356e-06 | U2: 3.3983083e-06 | V2: -1.6227024e-07 | W2: -9.4075853e-07 | X2: 1.4370108e-06 | Y2: -9.0069531e-06 | Z2: 0.00017441339 | AA2: 2.4919396e-06 | AB2: -1.0877633e-05 | AC2: -1.9895946e-05 | AD2: -3.5587712e-06 | AE2: -6.0283285e-06 | AF2: -0.0006894042 | AG2: 3.9510369e-05
A3: dagsq | B3: -6.9930275e-05 | C3: -3.1148086e-07 | D3: 4.1387074e-09 | E3: -4.5607565e-07 | F3: 1.1638725e-06 | G3: 1.3592023e-08 | H3: -1.7369972e-08 | I3: 1.2867597e-07 | J3: 9.8282248e-08 | K3: 7.9375057e-07 | L3: -3.7786541e-09 | M3: -4.4371493e-09 | N3: 1.6691236e-07 | O3: 9.4439832e-08 | P3: 1.1123424e-07 | Q3: 1.2123888e-07 | R3: 1.2968955e-07 | S3: 8.8971803e-08 | T3: -2.0418626e-08 | U3: -3.399708e-08 | V3: 5.521424e-08 | W3: 6.1799877e-08 | X3: 7.1714838e-08 | Y3: 9.4792728e-08 | Z3: -2.9809559e-06 | AA3: 7.5669648e-09 | AB3: 1.7422158e-07 | AC3: 4.0111487e-07 | AD3: 6.8291372e-08 | AE3: 1.3466747e-07 | AF3: 9.0394288e-06 | AG3: -7.7795217e-07
A4: 2.deh_c4 | B4: -0.025850532 | C4: 0.00010857467 | D4: -4.5607565e-07 | E4: 0.0040907251 | F4: 0.0029858464 | G4: -9.5528586e-05 | H4: -6.3060826e-05 | I4: -0.00011631931 | J4: -0.00010839305 | K4: 0.00041071129 | L4: -1.335822e-06 | M4: -1.4671696e-06 | N4: 0.00011774062 | O4: 5.1169973e-05 | P4: 2.5635402e-05 | Q4: 5.8559461e-06 | R4: 4.0659942e-05 | S4: 4.1031483e-05 | T4: 2.6531888e-05 | U4: -2.7479192e-05 | V4: 1.379642e-05 | W4: 3.5151756e-05 | X4: 0.0001004328 | Y4: -0.00010338354 | Z4: -0.00011411676 | AA4: 9.0193526e-05 | AB4: 3.5052887e-05 | AC4: 0.00025246925 | AD4: 3.8851168e-05 | AE4: 4.5724872e-05 | AF4: -0.0027923718 | AG4: -0.00052372902
A5: 3.deh_c4 | B5: 0.11019045 | C5: -7.8453479e-06 | D5: 1.1638725e-06 | E5: 0.0029858464 | F5: 0.018382863 | G5: -6.3838831e-05 | H5: -0.00038162963 | I5: -0.0002290304 | J5: -0.0001499659 | K5: 0.001002465 | L5: -2.0770385e-06 | M5: -4.2899679e-06 | N5: 0.00026462502 | O5: 7.2695443e-05 | P5: 0.00010883086 | Q5: 0.0001579874 | R5: 0.00013680863 | S5: -7.2293467e-05 | T5: 5.7048808e-06 | U5: -6.1529426e-05 | V5: -2.6357036e-05 | W5: 9.6915982e-05 | X5: 0.00012125593 | Y5: -0.00010856821 | Z5: -0.0018073873 | AA5: 0.00014013022 | AB5: 0.00017775543 | AC5: 0.00033394151 | AD5: -0.00027730118 | AE5: 0.00011595833 | AF5: 0.0014871879 | AG5: -0.0011006878
A6: 2.deh_c4#c.dag | B6: -0.0035824293 | C6: -2.8222258e-06 | D6: 1.3592023e-08 | E6: -9.5528586e-05 | F6: -6.3838831e-05 | G6: 2.620688e-06 | H6: 1.6554426e-06 | I6: 7.0579911e-07 | J6: -5.6182933e-07 | K6: -4.9994197e-06 | L6: 5.0631631e-08 | M6: 5.6198048e-08 | N6: -2.950774e-06 | O6: -1.5900131e-06 | P6: -1.1919572e-06 | Q6: -9.3093905e-07 | R6: -1.4995101e-06 | S6: -1.7027109e-06 | T6: -4.3855804e-07 | U6: 3.4574118e-07 | V6: -1.1986049e-06 | W6: -7.1133223e-07 | X6: -2.5319581e-06 | Y6: 1.5894219e-06 | Z6: 5.1506846e-06 | AA6: -1.5773498e-06 | AB6: -6.7826958e-07 | AC6: -3.0561522e-06 | AD6: -2.0151827e-06 | AE6: -5.9482011e-07 | AF6: 6.9137988e-05 | AG6: 4.8585536e-06
A7: 3.deh_c4#c.dag | B7: -0.0053851444 | C7: -4.6056271e-07 | D7: -1.7369972e-08 | E7: -6.3060826e-05 | F7: -0.00038162963 | G7: 1.6554426e-06 | H7: 8.8865295e-06 | I7: 3.421149e-06 | J7: -5.8877219e-07 | K7: -1.3140103e-05 | L7: 3.696934e-08 | M7: 1.04207e-07 | N7: -3.5119642e-06 | O7: -2.9301183e-07 | P7: -1.9660577e-06 | Q7: -3.6686077e-06 | R7: -2.4671892e-06 | S7: 1.6718371e-06 | T7: 1.3387971e-06 | U7: 1.7160084e-06 | V7: 1.8895052e-08 | W7: -1.3466636e-07 | X7: -2.8834247e-06 | Y7: 1.515216e-06 | Z7: 4.8249476e-05 | AA7: -2.3332452e-06 | AB7: -3.5494105e-06 | AC7: -3.3313695e-06 | AD7: 5.0036814e-06 | AE7: -6.7468246e-07 | AF7: -2.2333112e-05 | AG7: 9.5000458e-06
A8: 2.dehmf_c3 | B8: -0.006140817 | C8: -1.21692e-05 | D8: 1.2867597e-07 | E8: -0.00011631931 | F8: -0.0002290304 | G8: 7.0579911e-07 | H8: 3.421149e-06 | I8: 0.0013583508 | J8: 0.001209772 | K8: 6.7125935e-06 | L8: 5.3615182e-07 | M8: 1.6592201e-07 | N8: -3.0101509e-05 | O8: -5.5599993e-05 | P8: -5.5140349e-05 | Q8: -3.5465645e-05 | R8: -6.8038889e-05 | S8: -5.3840739e-05 | T8: -3.9598286e-05 | U8: -5.4705457e-05 | V8: -5.7203845e-05 | W8: -6.3381973e-05 | X8: -6.0750115e-05 | Y8: 4.1241072e-06 | Z8: 7.9919908e-05 | AA8: -2.3824103e-06 | AB8: -2.1706387e-05 | AC8: 2.0866351e-06 | AD8: 7.3858696e-05 | AE8: 7.8689789e-05 | AF8: -0.00096858626 | AG8: -1.7419858e-06
A9: 3.dehmf_c3 | B9: 0.012292336 | C9: -1.3574482e-05 | D9: 9.8282248e-08 | E9: -0.00010839305 | F9: -0.0001499659 | G9: -5.6182933e-07 | H9: -5.8877219e-07 | I9: 0.001209772 | J9: 0.0015851387 | K9: 4.1129524e-05 | L9: 9.9976181e-07 | M9: 1.7998367e-07 | N9: -5.6285121e-05 | O9: -7.3368949e-05 | P9: -8.4884574e-05 | Q9: -7.9841156e-05 | R9: -0.00010450619 | S9: -5.0697028e-05 | T9: -2.5202221e-05 | U9: -3.6762482e-05 | V9: -0.00011041689 | W9: -6.3848067e-05 | X9: -0.00017198724 | Y9: 1.4239779e-05 | Z9: 0.00092876109 | AA9: -1.0338855e-05 | AB9: -4.924031e-05 | AC9: -0.00011677517 | AD9: 2.348961e-05 | AE9: 6.0660003e-05 | AF9: -0.001699195 | AG9: -5.0274268e-05
A10: dlltsd01 | B10: 0.065577021 | C10: -4.6379219e-05 | D10: 7.9375057e-07 | E10: 0.00041071129 | F10: 0.001002465 | G10: -4.9994197e-06 | H10: -1.3140103e-05 | I10: 6.7125935e-06 | J10: 4.1129524e-05 | K10: 0.0028858643 | L10: 8.3868847e-06 | M10: 4.5280206e-06 | N10: 0.00011508114 | O10: 6.9831475e-05 | P10: 7.0299591e-05 | Q10: 8.3948561e-05 | R10: 9.2099892e-05 | S10: 8.3785012e-05 | T10: 5.1769629e-05 | U10: -6.8495593e-05 | V10: 1.3737634e-05 | W10: 9.4230396e-05 | X10: 2.6094441e-05 | Y10: 7.0607196e-07 | Z10: -0.00099751188 | AA10: 3.7226962e-05 | AB10: 9.5705012e-05 | AC10: 0.00030425187 | AD10: -2.6359513e-05 | AE10: 6.3266311e-05 | AF10: 0.0014472454 | AG10: -0.00086915216
A11: dhe_pcs_L1 | B11: 0.00061052362 | C11: 3.4981069e-07 | D11: -3.7786541e-09 | E11: -1.335822e-06 | F11: -2.0770385e-06 | G11: 5.0631631e-08 | H11: 3.696934e-08 | I11: 5.3615182e-07 | J11: 9.9976181e-07 | K11: 8.3868847e-06 | L11: 1.3294298e-06 | M11: 1.2197239e-07 | N11: -1.3201037e-06 | O11: 2.3682951e-07 | P11: -3.0860932e-07 | Q11: -1.6865672e-07 | R11: -7.6721867e-08 | S11: -7.0738149e-07 | T11: -4.5609604e-07 | U11: 3.2102552e-07 | V11: -9.7588253e-07 | W11: -7.3065405e-07 | X11: -7.5841251e-07 | Y11: -1.3650828e-07 | Z11: 2.1190374e-05 | AA11: -6.6090805e-07 | AB11: -1.8060251e-06 | AC11: 2.5911939e-07 | AD11: 1.0549619e-06 | AE11: 8.9106011e-07 | AF11: -0.00011253481 | AG11: 6.599717e-06
A12: dhe_mcs_L1 | B12: 0.0023398658 | C12: 1.9065953e-07 | D12: -4.4371493e-09 | E12: -1.4671696e-06 | F12: -4.2899679e-06 | G12: 5.6198048e-08 | H12: 1.04207e-07 | I12: 1.6592201e-07 | J12: 1.7998367e-07 | K12: 4.5280206e-06 | L12: 1.2197239e-07 | M12: 8.6610455e-07 | N12: -2.3072897e-07 | O12: 1.349504e-07 | P12: -5.4283658e-07 | Q12: 3.3240669e-07 | R12: 2.1970105e-07 | S12: -4.2634094e-07 | T12: -5.3305473e-07 | U12: 5.0749527e-09 | V12: -2.3001978e-07 | W12: -1.7736378e-07 | X12: -2.0275921e-06 | Y12: -1.0973893e-07 | Z12: 4.9905363e-05 | AA12: -3.9307612e-07 | AB12: -3.9203722e-07 | AC12: -1.5532463e-06 | AD12: -8.5377911e-07 | AE12: 1.7076449e-06 | AF12: -9.9861906e-05 | AG12: 2.2768445e-06
A13: drgn1 | B13: -0.16278083 | C13: -5.7918025e-06 | D13: 1.6691236e-07 | E13: 0.00011774062 | F13: 0.00026462502 | G13: -2.950774e-06 | H13: -3.5119642e-06 | I13: -3.0101509e-05 | J13: -5.6285121e-05 | K13: 0.00011508114 | L13: -1.3201037e-06 | M13: -2.3072897e-07 | N13: 0.0040120362 | O13: 0.00086540724 | P13: 0.00086499312 | Q13: 0.00085339069 | R13: 0.00081951472 | S13: 0.00085088477 | T13: 0.00084958695 | U13: 0.00088119088 | V13: 0.00091036053 | W13: 0.00091104757 | X13: 0.00093090092 | Y13: 7.9569868e-06 | Z13: -0.00063238411 | AA13: -6.7108691e-06 | AB13: 2.2358398e-05 | AC13: 0.00043622006 | AD13: 0.00063088082 | AE13: 0.0003927945 | AF13: -1.1266709e-05 | AG13: -0.00019296468
... A32: InvMillsRatio | B32: -0.35606 | C32: 3.9510369e-05 | D32: -7.7795217e-07 | E32: -0.00052372902 | F32: -0.0011006878 | G32: 4.8585536e-06 | H32: 9.5000458e-06 | I32: -1.7419858e-06 | J32: -5.0274268e-05 | K32: -0.00086915216 | L32: 6.599717e-06 | M32: 2.2768445e-06 | N32: -0.00019296468 | O32: -0.00010527581 | P32: -0.00013251041 | Q32: -8.8872281e-05 | R32: -9.902232e-05 | S32: -9.1064789e-05 | T32: -5.5775987e-05 | U32: -7.4146929e-06 | V32: -7.092005e-05 | W32: -0.00011352316 | X32: -9.6757644e-05 | Y32: -7.1510382e-05 | Z32: 0.00094814762 | AA32: -7.1475859e-05 | AB32: -6.9607561e-05 | AC32: -0.00032126988 | AD32: 2.1803563e-05 | AE32: -0.00010689875 | AF32: -0.0025381961 | AG32: 0.0011347806

Sheet W1ma_orig
A1: REGRESSOR | B1: COEFFICIENT | C1: dag | D1: dagsq | E1: 2.deh_c4 | F1: 3.deh_c4 | G1: 2.deh_c4#c.dag | H1: 3.deh_c4#c.dag | I1: 2.dehmf_c3 | J1: 3.dehmf_c3 | K1: dlltsd01 | L1: dhe_pcs_L1 | M1: dhe_mcs_L1 | N1: drgn1 | O1: 2.drgn1 | P1: 4.drgn1 | Q1: 5.drgn1 | R1: 6.drgn1 | S1: 7.drgn1 | T1: 9.drgn1 | U1: 10.drgn1 | V1: 1drgn1 | W1: 12.drgn1 | X1: 13.drgn1 | Y1: pt | Z1: real_wage_growth | AA1: y2020 | AB1: y2021 | AC1: 2.dot | AD1: 3.dot | AE1: 4.dot | AF1: Constant | AG1: InvMillsRatio
A2: dag | B2: 0.0009163482 | C2: 5.49098e-05 | D2: -7.1120255e-07 | E2: 0.00010266666 | F2: -0.00011641101 | G2: -3.2817445e-06 | H2: 4.0724371e-07 | I2: -5.0516222e-06 | J2: -2.7850298e-06 | K2: -0.00029186574 | L2: 2.1476898e-06 | M2: 1.7593706e-06 | N2: -4.3457675e-05 | O2: -6.3377912e-06 | P2: -1.8144176e-05 | Q2: 1.7233309e-05 | R2: 2.975493e-06 | S2: 5.7265887e-06 | T2: 1.7396805e-05 | U2: 1.1909999e-05 | V2: -2.1396109e-06 | W2: -8.3894877e-06 | X2: -1.2335866e-05 | Y2: 1.9563924e-05 | Z2: 0.00032823314 | AA2: -8.9738747e-06 | AB2: -8.4605985e-06 | AC2: -1.4806619e-05 | AD2: -1.2257222e-05 | AE2: -1.9741871e-05 | AF2: -0.0016719174 | AG2: 0.00026132113
A3: dagsq | B3: 0.00035692656 | C3: -7.1120255e-07 | D3: 9.6530052e-09 | E3: -1.4134986e-07 | F3: 2.8809719e-06 | G3: 1.5405467e-08 | H3: -3.3985642e-08 | I3: -2.8650201e-08 | J3: -1.332823e-07 | K3: 4.3121016e-06 | L3: -2.8547024e-08 | M3: -2.5754691e-08 | N3: 6.6745723e-07 | O3: 1.4150306e-07 | P3: 3.2174048e-07 | Q3: -2.1494206e-07 | R3: -9.9150126e-09 | S3: -5.2040253e-08 | T3: -2.4072113e-07 | U3: -1.5409222e-07 | V3: 8.2640601e-08 | W3: 1.4879591e-07 | X3: 2.7299441e-07 | Y3: -2.4673997e-07 | Z3: -4.7770658e-06 | AA3: 1.4156556e-07 | AB3: 1.4056253e-07 | AC3: 2.6255259e-07 | AD3: 1.9574619e-07 | AE3: 3.2469179e-07 | AF3: 2.2065932e-05 | AG3: -3.8664739e-06
A4: 2.deh_c4 | B4: 0.065472386 | C4: 0.00010266666 | D4: -1.4134986e-07 | E4: 0.0051866639 | F4: 0.0039805258 | G4: -0.00011572307 | H4: -8.1860652e-05 | I4: -0.00024752382 | J4: -0.00028305573 | K4: 0.00082107782 | L4: -3.3043329e-06 | M4: -4.5830951e-06 | N4: 9.9881825e-05 | O4: 6.4563066e-05 | P4: 3.0780679e-05 | Q4: -7.7731173e-05 | R4: 6.03326e-06 | S4: -8.4401161e-06 | T4: -5.848731e-05 | U4: -5.424114e-05 | V4: -5.6201276e-06 | W4: 1.8023033e-06 | X4: 6.3489909e-05 | Y4: -7.0754392e-05 | Z4: 0.00054824931 | AA4: 4.6781051e-05 | AB4: 2.1629213e-05 | AC4: 0.00010874999 | AD4: 1.8690057e-05 | AE4: 8.6396117e-05 | AF4: -0.0035469488 | AG4: -0.00068571383
A5: 3.deh_c4 | B5: 0.44366923 | C5: -0.00011641101 | D5: 2.8809719e-06 | E5: 0.0039805258 | F5: 0.017354985 | G5: -7.9805011e-05 | H5: -0.00034544743 | I5: -0.00046594554 | J5: -0.00056095074 | K5: 0.0021619173 | L5: -1.3035199e-05 | M5: -9.0577376e-06 | N5: 0.00038909873 | O5: 6.3642353e-05 | P5: 0.00025740225 | Q5: -0.00019228514 | R5: -3.0066726e-05 | S5: -3.0891823e-05 | T5: -7.0806237e-05 | U5: -4.3906181e-05 | V5: -0.00015197699 | W5: 0.00015356429 | X5: 2.472569e-05 | Y5: -6.0156623e-05 | Z5: -0.00068445545 | AA5: 3.8640012e-05 | AB5: 0.00011867552 | AC5: 0.00024896431 | AD5: 0.00010498033 | AE5: 0.00019136304 | AF5: 0.0031250688 | AG5: -0.0020679527
A6: 2.deh_c4#c.dag | B6: -0.0069624467 | C6: -3.2817445e-06 | D6: 1.5405467e-08 | E6: -0.00011572307 | F6: -7.9805011e-05 | G6: 3.0477449e-06 | H6: 1.9700619e-06 | I6: 3.0127387e-06 | J6: 2.7002485e-06 | K6: -9.1238886e-06 | L6: 1.142007e-07 | M6: 1.0121359e-07 | N6: -1.4380543e-06 | O6: -2.3675065e-06 | P6: -1.6376691e-06 | Q6: -7.7273939e-07 | R6: -1.7142015e-06 | S6: -1.121856e-06 | T6: -2.8247943e-07 | U6: -7.0208741e-08 | V6: -2.1538138e-06 | W6: -5.50057e-07 | X6: -2.3173544e-06 | Y6: 1.193525e-06 | Z6: -1.039403e-05 | AA6: -6.6611092e-07 | AB6: -7.4434422e-07 | AC6: -1.1517131e-06 | AD6: -1.9118047e-06 | AE6: -2.4217297e-07 | AF6: 9.6449823e-05 | AG6: 4.7477193e-06
A7: 3.deh_c4#c.dag | B7: -0.018357135 | C7: 4.0724371e-07 | D7: -3.3985642e-08 | E7: -8.1860652e-05 | F7: -0.00034544743 | G7: 1.9700619e-06 | H7: 7.8823623e-06 | I7: 7.3876385e-06 | J7: 5.752569e-06 | K7: -2.5951362e-05 | L7: 2.8816017e-07 | M7: 1.4824498e-07 | N7: -6.6203743e-06 | O7: -2.059887e-06 | P7: -5.6944963e-06 | Q7: 3.0005823e-07 | R7: -1.4090433e-06 | S7: -8.9503281e-07 | T7: -1.3416484e-07 | U7: -4.8882297e-07 | V7: 1.9658917e-07 | W7: -3.0832202e-06 | X7: -3.4818033e-06 | Y7: 1.0974609e-06 | Z7: 2.2795176e-05 | AA7: -1.8625923e-07 | AB7: -3.2559453e-06 | AC7: -5.873821e-06 | AD7: -3.9916321e-06 | AE7: -2.8977984e-06 | AF7: -2.4813036e-05 | AG7: 2.240881e-05
A8: 2.dehmf_c3 | B8: -0.065260141 | C8: -5.0516222e-06 | D8: -2.8650201e-08 | E8: -0.00024752382 | F8: -0.00046594554 | G8: 3.0127387e-06 | H8: 7.3876385e-06 | I8: 0.0018388484 | J8: 0.0016420827 | K8: -0.00012870896 | L8: 2.3606913e-06 | M8: -3.8553759e-07 | N8: -7.2511109e-05 | O8: -7.4290028e-06 | P8: -7.2733196e-05 | Q8: -3.0418732e-05 | R8: -3.2453258e-05 | S8: -3.9868629e-05 | T8: -1.7375481e-05 | U8: -2.8130346e-05 | V8: -4.8610464e-05 | W8: 4.8136908e-06 | X8: -9.3338498e-06 | Y8: -9.7136147e-06 | Z8: 0.00091678158 | AA8: -2.5666118e-05 | AB8: -5.9608137e-05 | AC8: 1.8992132e-05 | AD8: 7.5088743e-05 | AE8: 0.0001560939 | AF8: -0.0024314614 | AG8: 0.00012446107
A9: 3.dehmf_c3 | B9: -0.096501293 | C9: -2.7850298e-06 | D9: -1.332823e-07 | E9: -0.00028305573 | F9: -0.00056095074 | G9: 2.7002485e-06 | H9: 5.752569e-06 | I9: 0.0016420827 | J9: 0.0021402943 | K9: -0.00010364543 | L9: 3.4425168e-06 | M9: -8.4776176e-07 | N9: -0.00011310974 | O9: -1.2597175e-05 | P9: -8.0397435e-05 | Q9: -5.8585522e-05 | R9: -5.3982335e-05 | S9: -3.6138839e-05 | T9: 2.5397494e-05 | U9: 3.0788531e-05 | V9: -7.3196121e-05 | W9: 2.7056995e-05 | X9: -0.00010091302 | Y9: 3.9033224e-06 | Z9: 0.0018191504 | AA9: -2.4492052e-05 | AB9: -4.8600545e-05 | AC9: -0.00015176703 | AD9: 4.6777972e-05 | AE9: 0.00013693126 | AF9: -0.0032809466 | AG9: 8.5185327e-05
A10: dlltsd01 | B10: 0.58017381 | C10: -0.00029186574 | D10: 4.3121016e-06 | E10: 0.00082107782 | F10: 0.0021619173 | G10: -9.1238886e-06 | H10: -2.5951362e-05 | I10: -0.00012870896 | J10: -0.00010364543 | K10: 0.0075623959 | L10: -1.6927997e-06 | M10: -4.6277892e-06 | N10: 0.00052326807 | O10: 8.9556646e-05 | P10: 0.00024881114 | Q10: -0.00012238678 | R10: 4.2212296e-05 | S10: 5.1628312e-05 | T10: -0.00015525381 | U10: -0.00012999914 | V10: 0.00011661366 | W10: 0.00013315537 | X10: 0.00010834436 | Y10: -1.8482363e-05 | Z10: -0.0025455763 | AA10: 8.6400606e-05 | AB10: 0.00014542989 | AC10: 3.1606507e-05 | AD10: -1.5760429e-05 | AE10: 0.00018954878 | AF10: 0.0094455552 | AG10: -0.0030798723
A11: dhe_pcs_L1 | B11: 0.0035515033 | C11: 2.1476898e-06 | D11: -2.8547024e-08 | E11: -3.3043329e-06 | F11: -1.3035199e-05 | G11: 1.142007e-07 | H11: 2.8816017e-07 | I11: 2.3606913e-06 | J11: 3.4425168e-06 | K11: -1.6927997e-06 | L11: 2.5107339e-06 | M11: 2.6628497e-07 | N11: -1.2073852e-06 | O11: 1.2184454e-07 | P11: 7.8081849e-07 | Q11: 2.7225798e-06 | R11: 2.3135861e-06 | S11: 4.5818603e-07 | T11: 1.2038742e-06 | U11: 2.645265e-06 | V11: 3.2673164e-06 | W11: -6.7460191e-07 | X11: 1.15223e-06 | Y11: 1.2616947e-06 | Z11: 1.435719e-05 | AA11: 3.619581e-07 | AB11: 3.7622556e-07 | AC11: 3.1881971e-06 | AD11: -6.992348e-07 | AE11: -9.1716027e-07 | AF11: -0.0002220042 | AG11: 2.1052627e-05
A12: dhe_mcs_L1 | B12: 0.0030084742 | C12: 1.7593706e-06 | D12: -2.5754691e-08 | E12: -4.5830951e-06 | F12: -9.0577376e-06 | G12: 1.0121359e-07 | H12: 1.4824498e-07 | I12: -3.8553759e-07 | J12: -8.4776176e-07 | K12: -4.6277892e-06 | L12: 2.6628497e-07 | M12: 1.4565733e-06 | N12: -1.2445354e-06 | O12: 9.1867461e-08 | P12: -6.6600029e-07 | Q12: -2.3396728e-07 | R12: 9.0958611e-07 | S12: -5.702708e-07 | T12: -2.432539e-07 | U12: 5.3644773e-07 | V12: 1.0440223e-06 | W12: -1.2544323e-06 | X12: -2.8700486e-06 | Y12: 6.5829381e-07 | Z12: 5.2254324e-05 | AA12: -2.2486712e-07 | AB12: -2.1591181e-07 | AC12: -2.8864387e-07 | AD12: -2.3691359e-06 | AE12: -4.3070136e-07 | AF12: -0.00017304739 | AG12: 1.2429692e-05
A13: drgn1 | B13: -0.11193482 | C13: -4.3457675e-05 | D13: 6.6745723e-07 | E13: 9.9881825e-05 | F13: 0.00038909873 | G13: -1.4380543e-06 | H13: -6.6203743e-06 | I13: -7.2511109e-05 | J13: -0.00011310974 | K13: 0.00052326807 | L13: -1.2073852e-06 | M13: -1.2445354e-06 | N13: 0.0049431397 | O13: 0.0011978926 | P13: 0.001221165 | Q13: 0.001202841 | R13: 0.0011086413 | S13: 0.0012078791 | T13: 0.0011977476 | U13: 0.0012490158 | V13: 0.0012979972 | W13: 0.001290967 | X13: 0.0013310189 | Y13: -4.7128245e-07 | Z13: -0.0010133277 | AA13: 4.449855e-05 | AB13: 3.3326797e-05 | AC13: 0.00057645475 | AD13: 0.00087166417 | AE13: 0.00061432908 | AF13: 0.00086350086 | AG13: -0.00043156768
... A32: InvMillsRatio | B32: -0.5650019 | C32: 0.00026132113 | D32: -3.8664739e-06 | E32: -0.00068571383 | F32: -0.0020679527 | G32: 4.7477193e-06 | H32: 2.240881e-05 | I32: 0.00012446107 | J32: 8.5185327e-05 | K32: -0.0030798723 | L32: 2.1052627e-05 | M32: 1.2429692e-05 | N32: -0.00043156768 | O32: -0.00011972232 | P32: -0.00023458934 | Q32: 0.0001233179 | R32: -1.8687961e-05 | S32: 6.4186089e-06 | T32: 0.0001199811 | U32: 7.5018201e-05 | V32: -5.3222249e-05 | W32: -0.0001125475 | X32: -0.00017623051 | Y32: -4.559386e-05 | Z32: 0.0015369738 | AA32: -6.804132e-05 | AB32: -6.9361948e-05 | AC32: 8.9325954e-06 | AD32: 2.381323e-05 | AE32: -0.00016683617 | AF32: -0.0093178342 | AG32: 0.0028603152

Sheet W1fb_orig
A1: REGRESSOR | B1: COEFFICIENT | C1: lwage_hour_L1 | D1: dag | E1: dagsq | F1: 2.deh_c4 | G1: 3.deh_c4 | H1: 2.deh_c4#c.dag | I1: 3.deh_c4#c.dag | J1: 2.dehmf_c3 | K1: 3.dehmf_c3 | L1: dlltsd01 | M1: dhe_pcs_L1 | N1: dhe_mcs_L1 | O1: drgn1 | P1: 2.drgn1 | Q1: 4.drgn1 | R1: 5.drgn1 | S1: 6.drgn1 | T1: 7.drgn1 | U1: 9.drgn1 | V1: 10.drgn1 | W1: 1drgn1 | X1: 12.drgn1 | Y1: 13.drgn1 | Z1: pt | AA1: real_wage_growth | AB1: y2020 | AC1: y2021 | AD1: 2.dot | AE1: 3.dot | AF1: 4.dot | AG1: Constant | AH1: InvMillsRatio
A2: lwage_hour_L1 | B2: 0.49533268 | C2: 9.0878276e-06 | D2: -6.1418547e-07 | E2: 6.4425993e-09 | F2: 2.8873123e-06 | G2: 5.1064827e-06 | H2: -5.2372668e-09 | I2: -1.9475077e-08 | J2: -1.085703e-07 | K2: 2.741415e-07 | L2: 1.6671705e-06 | M2: -4.63612e-08 | N2: -2.2995696e-08 | O2: 1.1376488e-06 | P2: 1.1479415e-06 | Q2: 1.3419214e-06 | R2: 1.2156581e-06 | S2: 8.3981733e-07 | T2: 6.5917181e-07 | U2: 5.6168814e-07 | V2: 1.3291804e-06 | W2: 1.2120336e-06 | X2: 5.358021e-07 | Y2: 5.604381e-07 | Z2: 1.0785693e-06 | AA2: -3.3677841e-06 | AB2: -9.3906358e-08 | AC2: 1.6740331e-08 | AD2: 5.5590216e-07 | AE2: 5.950363e-07 | AF2: 4.293649e-07 | AG2: -3.0398963e-06 | AH2: -2.9150539e-06
A3: dag | B3: 0.018875826 | C3: -6.1418547e-07 | D3: 8.4751578e-06 | E3: -1.0345066e-07 | F3: -1.7636169e-05 | G3: -4.3251185e-05 | H3: 4.4993238e-07 | I3: 9.0125793e-07 | J3: 5.5001559e-06 | K3: 5.4546003e-06 | L3: -5.1033204e-05 | M3: 2.3060209e-07 | N3: 2.012241e-07 | O3: 3.0447228e-06 | P3: 2.299163e-06 | Q3: 3.9012631e-06 | R3: 4.347938e-06 | S3: 2.4645034e-06 | T3: 1.2636546e-06 | U3: 8.5303956e-07 | V3: 3.3612853e-06 | W3: 3.0935505e-06 | X3: 2.2502138e-06 | Y3: 3.4714202e-06 | Z3: -1.6090422e-06 | AA3: 8.6395558e-06 | AB3: 1.3521298e-06 | AC3: -2.6285066e-07 | AD3: -9.2760756e-06 | AE3: -5.4743891e-06 | AF3: -2.1526627e-06 | AG3: -0.00022116715 | AH3: 0.00018482006
A4: dagsq | B4: -0.00019845606 | C4: 6.4425993e-09 | D4: -1.0345066e-07 | E4: 1.2756394e-09 | F4: 2.5997558e-07 | G4: 5.7194857e-07 | H4: -6.5433271e-09 | I4: -1.2017174e-08 | J4: -6.9341675e-08 | K4: -7.1402744e-08 | L4: 6.3458014e-07 | M4: -2.8010631e-09 | N4: -2.5479255e-09 | O4: -3.7578136e-08 | P4: -2.8364162e-08 | Q4: -4.8072485e-08 | R4: -5.4161315e-08 | S4: -3.0601707e-08 | T4: -1.6073799e-08 | U4: -1.0990334e-08 | V4: -4.2493046e-08 | W4: -3.8144049e-08 | X4: -2.8410164e-08 | Y4: -4.2183217e-08 | Z4: 1.9037293e-08 | AA4: -1.1937223e-07 | AB4: -1.6794893e-08 | AC4: 3.6072571e-09 | AD4: 1.1777217e-07 | AE4: 6.7762593e-08 | AF4: 2.7671134e-08 | AG4: 2.7045266e-06 | AH4: -2.2998787e-06
A5: 2.deh_c4 | B5: -0.1854536 | C5: 2.8873123e-06 | D5: -1.7636169e-05 | E5: 2.5997558e-07 | F5: 0.00029868244 | G5: 0.00025958701 | H5: -6.6242495e-06 | I5: -5.545747e-06 | J5: -2.4377554e-05 | K5: -2.5907479e-05 | L5: 0.00014831512 | M5: -6.3837755e-07 | N5: -5.7975506e-07 | O5: -1.0039613e-05 | P5: -9.3542837e-06 | Q5: -1.4591549e-05 | R5: -1.7894274e-05 | S5: -1.0753489e-05 | T5: -7.8202659e-06 | U5: -5.4789772e-06 | V5: -1.333987e-05 | W5: -1.1686377e-05 | X5: -1.0172855e-05 | Y5: -1.2040102e-05 | Z5: 1.6004704e-06 | AA5: 1.5818733e-05 | AB5: -3.8423617e-06 | AC5: -6.9602652e-07 | AD5: 3.2198416e-05 | AE5: 1.4203853e-05 | AF5: 6.738826e-06 | AG5: 0.00038159553 | AH5: -0.00054706174
A6: 3.deh_c4 | B6: -0.25259229 | C6: 5.1064827e-06 | D6: -4.3251185e-05 | E6: 5.7194857e-07 | F6: 0.00025958701 | G6: 0.0014851846 | H6: -6.0425167e-06 | I6: -2.8554368e-05 | J6: -3.9772084e-05 | K6: -4.2323131e-05 | L6: 0.00027683273 | M6: -1.1355375e-06 | N6: -1.0635437e-06 | O6: -1.6757876e-05 | P6: -1.2024398e-05 | Q6: -2.3918466e-05 | R6: -2.6815506e-05 | S6: -1.7267408e-05 | T6: -1.020246e-05 | U6: -6.092836e-06 | V6: -2.0580678e-05 | W6: -2.1559952e-05 | X6: -1.5994347e-05 | Y6: -2.1819726e-05 | Z6: 3.5297199e-06 | AA6: -1.5808815e-05 | AB6: -6.5497039e-06 | AC6: 2.5060117e-07 | AD6: 4.7840281e-05 | AE6: 1.8243251e-05 | AF6: 7.3461249e-06 | AG6: 0.0010249279 | AH6: -0.0010032262
A7: 2.deh_c4#c.dag | B7: 0.00067196544 | C7: -5.2372668e-09 | D7: 4.4993238e-07 | E7: -6.5433271e-09 | F7: -6.6242495e-06 | G7: -6.0425167e-06 | H7: 1.5624255e-07 | I7: 1.3523748e-07 | J7: 4.8462173e-07 | K7: 4.7913432e-07 | L7: -3.7041618e-06 | M7: 1.7410933e-08 | N7: 1.4670265e-08 | O7: 2.0838191e-07 | P7: 1.9148101e-07 | Q7: 3.1119185e-07 | R7: 3.8227484e-07 | S7: 2.1986859e-07 | T7: 1.431023e-07 | U7: 1.0011914e-07 | V7: 2.9082092e-07 | W7: 2.3980372e-07 | X7: 2.0608153e-07 | Y7: 2.7041809e-07 | Z7: -7.7726785e-08 | AA7: 2.6197062e-08 | AB7: 9.6028488e-08 | AC7: 4.1026323e-09 | AD7: -7.5303115e-07 | AE7: -3.5872677e-07 | AF7: -1.6006899e-07 | AG7: -1.0575182e-05 | AH7: 1.3612719e-05
A8: 3.deh_c4#c.dag | B8: 0.00032000856 | C8: -1.9475077e-08 | D8: 9.0125793e-07 | E8: -1.2017174e-08 | F8: -5.545747e-06 | G8: -2.8554368e-05 | H8: 1.3523748e-07 | I8: 5.7231009e-07 | J8: 7.471656e-07 | K8: 7.1617508e-07 | L8: -5.8489017e-06 | M8: 2.6190481e-08 | N8: 2.2727548e-08 | O8: 3.1819348e-07 | P8: 2.3865952e-07 | Q8: 4.5817739e-07 | R8: 5.1741767e-07 | S8: 3.1005759e-07 | T8: 1.6838431e-07 | U8: 9.978593e-08 | V8: 4.2188798e-07 | W8: 3.9620596e-07 | X8: 3.1202406e-07 | Y8: 4.012226e-07 | Z8: -1.3977097e-07 | AA8: 1.0401385e-06 | AB8: 1.3934181e-07 | AC8: -2.9459756e-08 | AD8: -1.0091794e-06 | AE8: -3.8591458e-07 | AF8: -1.4225237e-07 | AG8: -2.2355228e-05 | AH8: 2.1124486e-05
A9: 2.dehmf_c3 | B9: -0.017792177 | C9: -1.085703e-07 | D9: 5.5001559e-06 | E9: -6.9341675e-08 | F9: -2.4377554e-05 | G9: -3.9772084e-05 | H9: 4.8462173e-07 | I9: 7.471656e-07 | J9: 8.6888605e-05 | K9: 8.1401923e-05 | L9: -3.8839961e-05 | M9: 2.2108063e-07 | N9: 1.484035e-07 | O9: 2.0551819e-07 | P9: -8.3891223e-07 | Q9: 1.2936893e-06 | R9: 7.586417e-07 | S9: -4.4200806e-07 | T9: -5.3081171e-08 | U9: -1.4781542e-06 | V9: -1.1281958e-07 | W9: -5.330614e-07 | X9: -1.0200157e-06 | Y9: -5.5578654e-07 | Z9: -1.2484553e-06 | AA9: -1.3873975e-06 | AB9: 1.1123985e-06 | AC9: -8.8880083e-08 | AD9: -7.2337489e-06 | AE9: -2.664295e-06 | AF9: 3.6418641e-06 | AG9: -0.0002135441 | AH9: 0.00014646686
A10: 3.dehmf_c3 | B10: -0.037895449 | C10: 2.741415e-07 | D10: 5.4546003e-06 | E10: -7.1402744e-08 | F10: -2.5907479e-05 | G10: -4.2323131e-05 | H10: 4.7913432e-07 | I10: 7.1617508e-07 | J10: 8.1401923e-05 | K10: 9.3141509e-05 | L10: -3.9968651e-05 | M10: 2.4812554e-07 | N10: 1.7008313e-07 | O10: -5.614031e-07 | P10: -1.6814775e-06 | Q10: 1.036168e-07 | R10: -7.5506871e-08 | S10: -1.8922917e-06 | T10: -1.16239e-07 | U10: -8.3176902e-07 | V10: 8.5833388e-07 | W10: -1.9868011e-06 | X10: -1.2069468e-06 | Y10: -4.2721166e-06 | Z10: -9.5829253e-07 | AA10: 3.0019552e-05 | AB10: 1.0069003e-06 | AC10: -1.2568428e-06 | AD10: -1.1155603e-05 | AE10: -4.7424161e-06 | AF10: 2.8335407e-06 | AG10: -0.00024300914 | AH10: 0.00014985427
A11: dlltsd01 | B11: -0.024303523 | C11: 1.6671705e-06 | D11: -5.1033204e-05 | E11: 6.3458014e-07 | F11: 0.00014831512 | G11: 0.00027683273 | H11: -3.7041618e-06 | I11: -5.8489017e-06 | J11: -3.8839961e-05 | K11: -3.9968651e-05 | L11: 0.00048687029 | M11: -1.0416558e-06 | N11: -1.1983189e-06 | O11: -2.3468537e-05 | P11: -1.8079454e-05 | Q11: -2.9287165e-05 | R11: -3.2896912e-05 | S11: -1.9536465e-05 | T11: -9.8996598e-06 | U11: -6.9942015e-06 | V11: -2.569963e-05 | W11: -2.3146611e-05 | X11: -1.7423115e-05 | Y11: -2.745859e-05 | Z11: 8.2380513e-06 | AA11: -5.7194581e-05 | AB11: -9.0713409e-06 | AC11: 2.22462e-06 | AD11: 6.5349077e-05 | AE11: 3.7096841e-05 | AF11: 1.5323092e-05 | AG11: 0.0013313217 | AH11: -0.0012916848
A12: dhe_pcs_L1 | B12: 0.0021306048 | C12: -4.63612e-08 | D12: 2.3060209e-07 | E12: -2.8010631e-09 | F12: -6.3837755e-07 | G12: -1.1355375e-06 | H12: 1.7410933e-08 | I12: 2.6190481e-08 | J12: 2.2108063e-07 | K12: 2.4812554e-07 | L12: -1.0416558e-06 | M12: 6.3314008e-08 | N12: 1.284322e-08 | O12: 1.3075213e-07 | P12: 8.6359095e-08 | Q12: 1.450759e-07 | R12: 1.390353e-07 | S12: 1.0644073e-07 | T12: 3.6748919e-08 | U12: 2.7995986e-08 | V12: 1.0509836e-07 | W12: 1.2245434e-07 | X12: 6.1264098e-08 | Y12: 1.1329555e-07 | Z12: -4.3607499e-08 | AA12: 8.2103168e-07 | AB12: 4.8687779e-08 | AC12: -5.9617843e-08 | AD12: -1.5895031e-07 | AE12: -6.9384498e-08 | AF12: -1.8916676e-09 | AG12: -1.0232863e-05 | AH12: 5.8994767e-06
A13: dhe_mcs_L1 | B13: 0.00095961862 | C13: -2.2995696e-08 | D13: 2.012241e-07 | E13: -2.5479255e-09 | F13: -5.7975506e-07 | G13: -1.0635437e-06 | H13: 1.4670265e-08 | I13: 2.2727548e-08 | J13: 1.484035e-07 | K13: 1.7008313e-07 | L13: -1.1983189e-06 | M13: 1.284322e-08 | N13: 4.5837406e-08 | O13: 9.2669496e-08 | P13: 6.2727567e-08 | Q13: 1.1098612e-07 | R13: 1.2129728e-07 | S13: 9.122432e-08 | T13: 2.7274929e-08 | U13: 1.5264473e-08 | V13: 8.4669364e-08 | W13: 8.4381902e-08 | X13: 4.1740081e-08 | Y13: 2.165364e-08 | Z13: -6.4603099e-08 | AA13: 1.850582e-06 | AB13: 3.6611939e-08 | AC13: -3.8061279e-08 | AD13: -2.4427535e-07 | AE13: -1.6930721e-07 | AF13: -5.5142822e-09 | AG13: -9.2152307e-06 | AH13: 5.1218384e-06
... A33: InvMillsRatio | B33: -0.097049415 | C33: -2.9150539e-06 | D33: 0.00018482006 | E33: -2.2998787e-06 | F33: -0.00054706174 | G33: -0.0010032262 | H33: 1.3612719e-05 | I33: 2.1124486e-05 | J33: 0.00014646686 | K33: 0.00014985427 | L33: -0.0012916848 | M33: 5.8994767e-06 | N33: 5.1218384e-06 | O33: 8.7824913e-05 | P33: 6.5251032e-05 | Q33: 0.00010779216 | R33: 0.00012006516 | S33: 7.1069788e-05 | T33: 3.9693207e-05 | U33: 2.6666394e-05 | V33: 9.3185309e-05 | W33: 8.2473764e-05 | X33: 6.5315546e-05 | Y33: 9.4579242e-05 | Z33: -4.3427726e-05 | AA33: 0.00011503367 | AB33: 3.4318084e-05 | AC33: -4.0411766e-06 | AD33: -0.00023231559 | AE33: -0.00013277044 | AF33: -5.6471895e-05 | AG33: -0.0049039683 | AH33: 0.0047321301

Sheet W1mb_orig
A1: REGRESSOR | B1: COEFFICIENT | C1: lwage_hour_L1 | D1: dag | E1: dagsq | F1: 2.deh_c4 | G1: 3.deh_c4 | H1: 2.deh_c4#c.dag | I1: 3.deh_c4#c.dag | J1: 2.dehmf_c3 | K1: 3.dehmf_c3 | L1: dlltsd01 | M1: dhe_pcs_L1 | N1: dhe_mcs_L1 | O1: drgn1 | P1: 2.drgn1 | Q1: 4.drgn1 | R1: 5.drgn1 | S1: 6.drgn1 | T1: 7.drgn1 | U1: 9.drgn1 | V1: 10.drgn1 | W1: 1drgn1 | X1: 12.drgn1 | Y1: 13.drgn1 | Z1: pt | AA1: real_wage_growth | AB1: y2020 | AC1: y2021 | AD1: 2.dot | AE1: 3.dot | AF1: 4.dot | AG1: Constant | AH1: InvMillsRatio
A2: lwage_hour_L1 | B2: 0.49300454 | C2: 9.5003456e-06 | D2: -4.7582805e-07 | E2: 4.4137732e-09 | F2: 2.3361141e-06 | G2: 4.9685491e-06 | H2: 2.0286271e-08 | I2: 2.5779259e-09 | J2: 6.3971114e-07 | K2: 1.0156497e-06 | L2: -9.0162463e-07 | M2: -5.6357926e-08 | N2: -3.223533e-08 | O2: 1.70609e-06 | P2: 1.4936559e-06 | Q2: 1.9012014e-06 | R2: 1.8201939e-06 | S2: 1.2383711e-06 | T2: 1.2091885e-06 | U2: 9.3379928e-07 | V2: 2.0732113e-06 | W2: 2.1208649e-06 | X2: 1.3414711e-06 | Y2: 2.1301139e-06 | Z2: 1.7380831e-06 | AA2: -1.827443e-06 | AB2: -7.3740589e-08 | AC2: -8.5602598e-09 | AD2: 2.091211e-06 | AE2: 1.6915559e-06 | AF2: 1.0055577e-06 | AG2: -1.0211905e-05 | AH2: 4.8900118e-06
A3: dag | B3: 0.014027119 | C3: -4.7582805e-07 | D3: 1.1949252e-05 | E3: -1.4824898e-07 | F3: -1.4388106e-05 | G3: -5.210258e-05 | H3: 4.9296612e-07 | I3: 1.1513308e-06 | J3: 8.1481047e-06 | K3: 8.7539345e-06 | L3: -8.4292617e-05 | M3: 2.3134752e-07 | N3: 4.0516533e-07 | O3: 2.5549611e-06 | P3: 7.4282519e-06 | Q3: 7.40872e-06 | R3: 8.898648e-06 | S3: 4.716747e-06 | T3: 8.0359521e-06 | U3: 5.7755483e-06 | V3: 1.0999514e-05 | W3: 5.910908e-06 | X3: 6.0815001e-06 | Y3: 8.4790223e-06 | Z3: -2.4789133e-07 | AA3: 4.2236507e-06 | AB3: -1.1334625e-06 | AC3: -1.938696e-06 | AD3: -5.1263228e-06 | AE3: -1.2039353e-05 | AF3: -4.0635951e-06 | AG3: -0.00030553716 | AH3: 0.00026962757
A4: dagsq | B4: -0.00012132579 | C4: 4.4137732e-09 | D4: -1.4824898e-07 | E4: 1.8652809e-09 | F4: 2.6400216e-07 | G4: 7.3133209e-07 | H4: -8.1029411e-09 | I4: -1.6207545e-08 | J4: -1.0857082e-07 | K4: -1.2060629e-07 | L4: 1.0780199e-06 | M4: -2.8010196e-09 | N4: -5.2281094e-09 | O4: -3.3171065e-08 | P4: -9.4956896e-08 | Q4: -9.5058312e-08 | R4: -1.1409868e-07 | S4: -6.0339666e-08 | T4: -1.0325378e-07 | U4: -7.5095975e-08 | V4: -1.4162249e-07 | W4: -7.5404209e-08 | X4: -7.8939828e-08 | Y4: -1.0777612e-07 | Z4: 2.161003e-09 | AA4: -7.2506404e-08 | AB4: 1.4351018e-08 | AC4: 2.5423253e-08 | AD4: 6.8331839e-08 | AE4: 1.5305716e-07 | AF4: 5.4438189e-08 | AG4: 3.7926814e-06 | AH4: -3.4471098e-06
A5: 2.deh_c4 | B5: -0.138502 | C5: 2.3361141e-06 | D5: -1.4388106e-05 | E5: 2.6400216e-07 | F5: 0.00046605525 | G5: 0.00038385707 | H5: -1.0301232e-05 | I5: -8.2755107e-06 | J5: -4.0028394e-05 | K5: -4.1001915e-05 | L5: 0.00018968147 | M5: -4.3114892e-07 | N5: -8.9921177e-07 | O5: -1.1011514e-05 | P5: -2.1603543e-05 | Q5: -2.3812585e-05 | R5: -2.7894746e-05 | S5: -1.6199006e-05 | T5: -2.4281314e-05 | U5: -2.0271625e-05 | V5: -2.9617073e-05 | W5: -1.9503198e-05 | X5: -1.9581511e-05 | Y5: -2.4924274e-05 | Z5: 2.2948394e-07 | AA5: 4.0528827e-05 | AB5: 2.4314697e-06 | AC5: 3.6593015e-06 | AD5: 1.9556163e-05 | AE5: 2.2815158e-05 | AF5: 1.6343731e-05 | AG5: 0.00023160209 | AH5: -0.00061252846
A6: 3.deh_c4 | B6: -0.32111242 | C6: 4.9685491e-06 | D6: -5.210258e-05 | E6: 7.3133209e-07 | F6: 0.00038385707 | G6: 0.0016752198 | H6: -9.1313058e-06 | I6: -3.2822274e-05 | J6: -6.7919245e-05 | K6: -7.6809235e-05 | L6: 0.00042145875 | M6: -1.0571014e-06 | N6: -2.1328356e-06 | O6: -1.6959412e-05 | P6: -3.8671812e-05 | Q6: -3.9948729e-05 | R6: -4.8987818e-05 | S6: -3.0872292e-05 | T6: -4.2302761e-05 | U6: -3.4802099e-05 | V6: -5.9066013e-05 | W6: -3.6955608e-05 | X6: -3.3070604e-05 | Y6: -5.2832196e-05 | Z6: -4.5155502e-06 | AA6: 5.7674489e-05 | AB6: 6.8217561e-06 | AC6: 8.3076688e-06 | AD6: 2.5636137e-05 | AE6: 5.1520512e-05 | AF6: 2.4788295e-05 | AG6: 0.0011418801 | AH6: -0.0013504109
A7: 2.deh_c4#c.dag | B7: -0.0010218866 | C7: 2.0286271e-08 | D7: 4.9296612e-07 | E7: -8.1029411e-09 | F7: -1.0301232e-05 | G7: -9.1313058e-06 | H7: 2.452951e-07 | I7: 2.0787855e-07 | J7: 8.8078064e-07 | K7: 8.4763023e-07 | L7: -5.6895203e-06 | M7: 1.7149584e-08 | N7: 2.5353148e-08 | O7: 2.4158699e-07 | P7: 5.6085223e-07 | Q7: 5.9516517e-07 | R7: 6.9210032e-07 | S7: 3.6984248e-07 | T7: 6.2096635e-07 | U7: 5.1061546e-07 | V7: 7.9075383e-07 | W7: 4.5329383e-07 | X7: 4.9400139e-07 | Y7: 6.6412709e-07 | Z7: -3.3414574e-08 | AA7: -5.8631124e-07 | AB7: -7.0211942e-08 | AC7: -1.1862112e-07 | AD7: -3.8865056e-07 | AE7: -6.7394226e-07 | AF7: -3.6506685e-07 | AG7: -1.0389418e-05 | AH7: 1.8209258e-05
A8: 3.deh_c4#c.dag | B8: 0.00072577805 | C8: 2.5779259e-09 | D8: 1.1513308e-06 | E8: -1.6207545e-08 | F8: -8.2755107e-06 | G8: -3.2822274e-05 | H8: 2.0787855e-07 | I8: 6.756356e-07 | J8: 1.3553898e-06 | K8: 1.3946515e-06 | L8: -9.5185738e-06 | M8: 2.8616941e-08 | N8: 4.5558839e-08 | O8: 3.3488424e-07 | P8: 8.3688333e-07 | Q8: 8.4378331e-07 | R8: 1.0079785e-06 | S8: 6.0127181e-07 | T8: 9.0368882e-07 | U8: 7.2532929e-07 | V8: 1.2694524e-06 | W8: 7.4584248e-07 | X8: 7.2881346e-07 | Y8: 1.0823782e-06 | Z8: 4.7773157e-08 | AA8: -3.0259818e-07 | AB8: -1.4131032e-07 | AC8: -2.0630035e-07 | AD8: -5.1130868e-07 | AE8: -1.1483844e-06 | AF8: -5.0743697e-07 | AG8: -2.6849589e-05 | AH8: 3.026926e-05
A9: 2.dehmf_c3 | B9: -0.040476858 | C9: 6.3971114e-07 | D9: 8.1481047e-06 | E9: -1.0857082e-07 | F9: -4.0028394e-05 | G9: -6.7919245e-05 | H9: 8.8078064e-07 | I9: 1.3553898e-06 | J9: 0.0001515293 | K9: 0.00014306401 | L9: -7.3524073e-05 | M9: 2.3427004e-07 | N9: 3.4201101e-07 | O9: -6.2154099e-07 | P9: 3.0110594e-06 | Q9: 9.3460994e-07 | R9: 4.5045471e-06 | S9: 2.5224124e-08 | T9: 4.4312246e-06 | U9: 2.3590023e-06 | V9: 6.2505046e-06 | W9: 1.9108497e-06 | X9: 3.4920984e-06 | Y9: 4.6010715e-06 | Z9: -4.3700642e-07 | AA9: 1.0219407e-05 | AB9: -9.0756409e-07 | AC9: -2.6855439e-06 | AD9: -2.5649816e-06 | AE9: -9.2527667e-06 | AF9: 2.1227159e-07 | AG9: -0.00034702981 | AH9: 0.00023892658
A10: 3.dehmf_c3 | B10: -0.058158253 | C10: 1.0156497e-06 | D10: 8.7539345e-06 | E10: -1.2060629e-07 | F10: -4.1001915e-05 | G10: -7.6809235e-05 | H10: 8.4763023e-07 | I10: 1.3946515e-06 | J10: 0.00014306401 | K10: 0.00016356514 | L10: -7.9186928e-05 | M10: 2.6929842e-07 | N10: 3.7617345e-07 | O10: -2.7338726e-06 | P10: 1.3025885e-06 | Q10: 2.9294851e-07 | R10: 2.8512001e-06 | S10: -2.2522538e-06 | T10: 3.9522855e-06 | U10: 3.6116545e-06 | V10: 8.2634841e-06 | W10: -7.1011759e-08 | X10: 3.2139605e-06 | Y10: -1.8379173e-06 | Z10: 7.8335027e-08 | AA10: 6.5716404e-05 | AB10: -1.0540094e-06 | AC10: -4.5481111e-06 | AD10: -9.3737177e-06 | AE10: -1.219711e-05 | AF10: -7.9362283e-07 | AG10: -0.00041203043 | AH10: 0.00025325144
A11: dlltsd01 | B11: 0.096810663 | C11: -9.0162463e-07 | D11: -8.4292617e-05 | E11: 1.0780199e-06 | F11: 0.00018968147 | G11: 0.00042145875 | H11: -5.6895203e-06 | I11: -9.5185738e-06 | J11: -7.3524073e-05 | K11: -7.9186928e-05 | L11: 0.0010594591 | M11: -8.9278826e-07 | N11: -2.9736492e-06 | O11: -2.9821691e-05 | P11: -6.8238397e-05 | Q11: -6.7500907e-05 | R11: -8.0020891e-05 | S11: -4.0969657e-05 | T11: -7.0384696e-05 | U11: -5.218989e-05 | V11: -9.6551694e-05 | W11: -5.3652081e-05 | X11: -5.6459914e-05 | Y11: -7.6430393e-05 | Z11: 6.068524e-06 | AA11: -2.6312024e-05 | AB11: 9.8646748e-06 | AC11: 1.6376937e-05 | AD11: 3.9832661e-05 | AE11: 9.9654605e-05 | AF11: 3.4298134e-05 | AG11: 0.0021366979 | AH11: -0.0022738302
A12: dhe_pcs_L1 | B12: 0.0025798739 | C12: -5.6357926e-08 | D12: 2.3134752e-07 | E12: -2.8010196e-09 | F12: -4.3114892e-07 | G12: -1.0571014e-06 | H12: 1.7149584e-08 | I12: 2.8616941e-08 | J12: 2.3427004e-07 | K12: 2.6929842e-07 | L12: -8.9278826e-07 | M12: 1.2789613e-07 | N12: 2.0840843e-08 | O12: 1.0556159e-07 | P12: 2.1274466e-07 | Q12: 2.1007466e-07 | R12: 2.5611194e-07 | S12: 1.9789246e-07 | T12: 2.3758973e-07 | U12: 1.4749939e-07 | V12: 2.8005156e-07 | W12: 2.192394e-07 | X12: 1.5098996e-07 | Y12: 2.2957996e-07 | Z12: 2.5811084e-08 | AA12: 1.1659314e-06 | AB12: -2.3826071e-09 | AC12: -1.0889379e-07 | AD12: 1.1247801e-07 | AE12: -2.3371661e-07 | AF12: 4.986085e-09 | AG12: -1.47037e-05 | AH12: 6.1689329e-06
A13: dhe_mcs_L1 | B13: 0.00098098486 | C13: -3.223533e-08 | D13: 4.0516533e-07 | E13: -5.2281094e-09 | F13: -8.9921177e-07 | G13: -2.1328356e-06 | H13: 2.5353148e-08 | I13: 4.5558839e-08 | J13: 3.4201101e-07 | K13: 3.7617345e-07 | L13: -2.9736492e-06 | M13: 2.0840843e-08 | N13: 9.6017169e-08 | O13: 1.3546204e-07 | P13: 2.8593481e-07 | Q13: 2.7766747e-07 | R13: 3.5032096e-07 | S13: 2.3473182e-07 | T13: 3.164747e-07 | U13: 2.1507725e-07 | V13: 4.0171003e-07 | W13: 2.3100333e-07 | X13: 2.0677185e-07 | Y13: 2.4799626e-07 | Z13: -7.7082006e-09 | AA13: 2.5916484e-06 | AB13: -2.5664575e-08 | AC13: -1.3257623e-07 | AD13: -1.8582865e-07 | AE13: -5.284572e-07 | AF13: -1.3908011e-07 | AG13: -1.7457716e-05 | AH13: 1.0535196e-05
... A33: InvMillsRatio | B33: -0.47303313 | C33: 4.8900118e-06 | D33: 0.00026962757 | E33: -3.4471098e-06 | F33: -0.00061252846 | G33: -0.0013504109 | H33: 1.8209258e-05 | I33: 3.026926e-05 | J33: 0.00023892658 | K33: 0.00025325144 | L33: -0.0022738302 | M33: 6.1689329e-06 | N33: 1.0535196e-05 | O33: 8.5588517e-05 | P33: 0.00021036856 | Q33: 0.00021102735 | R33: 0.00024872801 | S33: 0.00013154618 | T33: 0.00022512429 | U33: 0.00016163588 | V33: 0.00030221616 | W33: 0.00016813372 | X33: 0.00017646646 | Y33: 0.00023752944 | Z33: -5.015605e-05 | AA33: 1.8816439e-05 | AB33: -3.0524705e-05 | AC33: -4.9890246e-05 | AD33: -0.00012069429 | AE33: -0.00031404141 | AF33: -0.00010994444 | AG33: -0.0070176941 | AH33: 0.0073072744

Sheet W1fa
A1: REGRESSOR | B1: COEFFICIENT | C1: demAge | D1: demAgeSq | E1: eduHighestC4Medium | F1: eduHighestC4Low | G1: eduHighestC4Medium_demAge | H1: eduHighestC4Low_demAge | I1: eduHighestParentC3Medium | J1: eduHighestParentC3Low | K1: healthDsblLongtermFlag | L1: healthPhysicalPcsL1 | M1: healthMentalMcsL1 | N1: demRgnUKC | O1: demRgnUKD | P1: demRgnUKE | Q1: demRgnUKF | R1: demRgnUKG | S1: demRgnUKH | T1: demRgnUKJ | U1: demRgnUKK | V1: demRgnUKL | W1: demRgnUKM | X1: demRgnUKN | Y1: labPt | Z1: realWageGrowth | AA1: demYear2020 | AB1: demYear2021 | AC1: demEthnC4Asian | AD1: demEthnC4Black | AE1: demEthnC4Other | AF1: Constant | AG1: InvMillsRatio
A2: demAge | B2: 0.022841137 | C2: 2.5594038e-05 | D2: -3.1148086e-07 | E2: 0.00010857467 | F2: -7.8453479e-06 | G2: -2.8222258e-06 | H2: -4.6056271e-07 | I2: -1.21692e-05 | J2: -1.3574482e-05 | K2: -4.6379219e-05 | L2: 3.4981069e-07 | M2: 1.9065953e-07 | N2: -5.7918025e-06 | O2: -3.2772627e-06 | P2: -3.5486378e-06 | Q2: -5.671167e-06 | R2: -5.7925169e-06 | S2: -4.0178519e-06 | T2: 2.4343356e-06 | U2: 3.3983083e-06 | V2: -1.6227024e-07 | W2: -9.4075853e-07 | X2: 1.4370108e-06 | Y2: -9.0069531e-06 | Z2: 0.00017441339 | AA2: 2.4919396e-06 | AB2: -1.0877633e-05 | AC2: -1.9895946e-05 | AD2: -3.5587712e-06 | AE2: -6.0283285e-06 | AF2: -0.0006894042 | AG2: 3.9510369e-05
A3: demAgeSq | B3: -6.9930275e-05 | C3: -3.1148086e-07 | D3: 4.1387074e-09 | E3: -4.5607565e-07 | F3: 1.1638725e-06 | G3: 1.3592023e-08 | H3: -1.7369972e-08 | I3: 1.2867597e-07 | J3: 9.8282248e-08 | K3: 7.9375057e-07 | L3: -3.7786541e-09 | M3: -4.4371493e-09 | N3: 1.6691236e-07 | O3: 9.4439832e-08 | P3: 1.1123424e-07 | Q3: 1.2123888e-07 | R3: 1.2968955e-07 | S3: 8.8971803e-08 | T3: -2.0418626e-08 | U3: -3.399708e-08 | V3: 5.521424e-08 | W3: 6.1799877e-08 | X3: 7.1714838e-08 | Y3: 9.4792728e-08 | Z3: -2.9809559e-06 | AA3: 7.5669648e-09 | AB3: 1.7422158e-07 | AC3: 4.0111487e-07 | AD3: 6.8291372e-08 | AE3: 1.3466747e-07 | AF3: 9.0394288e-06 | AG3: -7.7795217e-07
A4: eduHighestC4Medium | B4: -0.025850532 | C4: 0.00010857467 | D4: -4.5607565e-07 | E4: 0.0040907251 | F4: 0.0029858464 | G4: -9.5528586e-05 | H4: -6.3060826e-05 | I4: -0.00011631931 | J4: -0.00010839305 | K4: 0.00041071129 | L4: -1.335822e-06 | M4: -1.4671696e-06 | N4: 0.00011774062 | O4: 5.1169973e-05 | P4: 2.5635402e-05 | Q4: 5.8559461e-06 | R4: 4.0659942e-05 | S4: 4.1031483e-05 | T4: 2.6531888e-05 | U4: -2.7479192e-05 | V4: 1.379642e-05 | W4: 3.5151756e-05 | X4: 0.0001004328 | Y4: -0.00010338354 | Z4: -0.00011411676 | AA4: 9.0193526e-05 | AB4: 3.5052887e-05 | AC4: 0.00025246925 | AD4: 3.8851168e-05 | AE4: 4.5724872e-05 | AF4: -0.0027923718 | AG4: -0.00052372902
A5: eduHighestC4Low | B5: 0.11019045 | C5: -7.8453479e-06 | D5: 1.1638725e-06 | E5: 0.0029858464 | F5: 0.018382863 | G5: -6.3838831e-05 | H5: -0.00038162963 | I5: -0.0002290304 | J5: -0.0001499659 | K5: 0.001002465 | L5: -2.0770385e-06 | M5: -4.2899679e-06 | N5: 0.00026462502 | O5: 7.2695443e-05 | P5: 0.00010883086 | Q5: 0.0001579874 | R5: 0.00013680863 | S5: -7.2293467e-05 | T5: 5.7048808e-06 | U5: -6.1529426e-05 | V5: -2.6357036e-05 | W5: 9.6915982e-05 | X5: 0.00012125593 | Y5: -0.00010856821 | Z5: -0.0018073873 | AA5: 0.00014013022 | AB5: 0.00017775543 | AC5: 0.00033394151 | AD5: -0.00027730118 | AE5: 0.00011595833 | AF5: 0.0014871879 | AG5: -0.0011006878
A6: eduHighestC4Medium_demAge | B6: -0.0035824293 | C6: -2.8222258e-06 | D6: 1.3592023e-08 | E6: -9.5528586e-05 | F6: -6.3838831e-05 | G6: 2.620688e-06 | H6: 1.6554426e-06 | I6: 7.0579911e-07 | J6: -5.6182933e-07 | K6: -4.9994197e-06 | L6: 5.0631631e-08 | M6: 5.6198048e-08 | N6: -2.950774e-06 | O6: -1.5900131e-06 | P6: -1.1919572e-06 | Q6: -9.3093905e-07 | R6: -1.4995101e-06 | S6: -1.7027109e-06 | T6: -4.3855804e-07 | U6: 3.4574118e-07 | V6: -1.1986049e-06 | W6: -7.1133223e-07 | X6: -2.5319581e-06 | Y6: 1.5894219e-06 | Z6: 5.1506846e-06 | AA6: -1.5773498e-06 | AB6: -6.7826958e-07 | AC6: -3.0561522e-06 | AD6: -2.0151827e-06 | AE6: -5.9482011e-07 | AF6: 6.9137988e-05 | AG6: 4.8585536e-06
A7: eduHighestC4Low_demAge | B7: -0.0053851444 | C7: -4.6056271e-07 | D7: -1.7369972e-08 | E7: -6.3060826e-05 | F7: -0.00038162963 | G7: 1.6554426e-06 | H7: 8.8865295e-06 | I7: 3.421149e-06 | J7: -5.8877219e-07 | K7: -1.3140103e-05 | L7: 3.696934e-08 | M7: 1.04207e-07 | N7: -3.5119642e-06 | O7: -2.9301183e-07 | P7: -1.9660577e-06 | Q7: -3.6686077e-06 | R7: -2.4671892e-06 | S7: 1.6718371e-06 | T7: 1.3387971e-06 | U7: 1.7160084e-06 | V7: 1.8895052e-08 | W7: -1.3466636e-07 | X7: -2.8834247e-06 | Y7: 1.515216e-06 | Z7: 4.8249476e-05 | AA7: -2.3332452e-06 | AB7: -3.5494105e-06 | AC7: -3.3313695e-06 | AD7: 5.0036814e-06 | AE7: -6.7468246e-07 | AF7: -2.2333112e-05 | AG7: 9.5000458e-06
A8: eduHighestParentC3Medium | B8: -0.006140817 | C8: -1.21692e-05 | D8: 1.2867597e-07 | E8: -0.00011631931 | F8: -0.0002290304 | G8: 7.0579911e-07 | H8: 3.421149e-06 | I8: 0.0013583508 | J8: 0.001209772 | K8: 6.7125935e-06 | L8: 5.3615182e-07 | M8: 1.6592201e-07 | N8: -3.0101509e-05 | O8: -5.5599993e-05 | P8: -5.5140349e-05 | Q8: -3.5465645e-05 | R8: -6.8038889e-05 | S8: -5.3840739e-05 | T8: -3.9598286e-05 | U8: -5.4705457e-05 | V8: -5.7203845e-05 | W8: -6.3381973e-05 | X8: -6.0750115e-05 | Y8: 4.1241072e-06 | Z8: 7.9919908e-05 | AA8: -2.3824103e-06 | AB8: -2.1706387e-05 | AC8: 2.0866351e-06 | AD8: 7.3858696e-05 | AE8: 7.8689789e-05 | AF8: -0.00096858626 | AG8: -1.7419858e-06
A9: eduHighestParentC3Low | B9: 0.012292336 | C9: -1.3574482e-05 | D9: 9.8282248e-08 | E9: -0.00010839305 | F9: -0.0001499659 | G9: -5.6182933e-07 | H9: -5.8877219e-07 | I9: 0.001209772 | J9: 0.0015851387 | K9: 4.1129524e-05 | L9: 9.9976181e-07 | M9: 1.7998367e-07 | N9: -5.6285121e-05 | O9: -7.3368949e-05 | P9: -8.4884574e-05 | Q9: -7.9841156e-05 | R9: -0.00010450619 | S9: -5.0697028e-05 | T9: -2.5202221e-05 | U9: -3.6762482e-05 | V9: -0.00011041689 | W9: -6.3848067e-05 | X9: -0.00017198724 | Y9: 1.4239779e-05 | Z9: 0.00092876109 | AA9: -1.0338855e-05 | AB9: -4.924031e-05 | AC9: -0.00011677517 | AD9: 2.348961e-05 | AE9: 6.0660003e-05 | AF9: -0.001699195 | AG9: -5.0274268e-05
A10: healthDsblLongtermFlag | B10: 0.065577021 | C10: -4.6379219e-05 | D10: 7.9375057e-07 | E10: 0.00041071129 | F10: 0.001002465 | G10: -4.9994197e-06 | H10: -1.3140103e-05 | I10: 6.7125935e-06 | J10: 4.1129524e-05 | K10: 0.0028858643 | L10: 8.3868847e-06 | M10: 4.5280206e-06 | N10: 0.00011508114 | O10: 6.9831475e-05 | P10: 7.0299591e-05 | Q10: 8.3948561e-05 | R10: 9.2099892e-05 | S10: 8.3785012e-05 | T10: 5.1769629e-05 | U10: -6.8495593e-05 | V10: 1.3737634e-05 | W10: 9.4230396e-05 | X10: 2.6094441e-05 | Y10: 7.0607196e-07 | Z10: -0.00099751188 | AA10: 3.7226962e-05 | AB10: 9.5705012e-05 | AC10: 0.00030425187 | AD10: -2.6359513e-05 | AE10: 6.3266311e-05 | AF10: 0.0014472454 | AG10: -0.00086915216
A11: healthPhysicalPcsL1 | B11: 0.00061052362 | C11: 3.4981069e-07 | D11: -3.7786541e-09 | E11: -1.335822e-06 | F11: -2.0770385e-06 | G11: 5.0631631e-08 | H11: 3.696934e-08 | I11: 5.3615182e-07 | J11: 9.9976181e-07 | K11: 8.3868847e-06 | L11: 1.3294298e-06 | M11: 1.2197239e-07 | N11: -1.3201037e-06 | O11: 2.3682951e-07 | P11: -3.0860932e-07 | Q11: -1.6865672e-07 | R11: -7.6721867e-08 | S11: -7.0738149e-07 | T11: -4.5609604e-07 | U11: 3.2102552e-07 | V11: -9.7588253e-07 | W11: -7.3065405e-07 | X11: -7.5841251e-07 | Y11: -1.3650828e-07 | Z11: 2.1190374e-05 | AA11: -6.6090805e-07 | AB11: -1.8060251e-06 | AC11: 2.5911939e-07 | AD11: 1.0549619e-06 | AE11: 8.9106011e-07 | AF11: -0.00011253481 | AG11: 6.599717e-06
A12: healthMentalMcsL1 | B12: 0.0023398658 | C12: 1.9065953e-07 | D12: -4.4371493e-09 | E12: -1.4671696e-06 | F12: -4.2899679e-06 | G12: 5.6198048e-08 | H12: 1.04207e-07 | I12: 1.6592201e-07 | J12: 1.7998367e-07 | K12: 4.5280206e-06 | L12: 1.2197239e-07 | M12: 8.6610455e-07 | N12: -2.3072897e-07 | O12: 1.349504e-07 | P12: -5.4283658e-07 | Q12: 3.3240669e-07 | R12: 2.1970105e-07 | S12: -4.2634094e-07 | T12: -5.3305473e-07 | U12: 5.0749527e-09 | V12: -2.3001978e-07 | W12: -1.7736378e-07 | X12: -2.0275921e-06 | Y12: -1.0973893e-07 | Z12: 4.9905363e-05 | AA12: -3.9307612e-07 | AB12: -3.9203722e-07 | AC12: -1.5532463e-06 | AD12: -8.5377911e-07 | AE12: 1.7076449e-06 | AF12: -9.9861906e-05 | AG12: 2.2768445e-06
A13: demRgnUKC | B13: -0.16278083 | C13: -5.7918025e-06 | D13: 1.6691236e-07 | E13: 0.00011774062 | F13: 0.00026462502 | G13: -2.950774e-06 | H13: -3.5119642e-06 | I13: -3.0101509e-05 | J13: -5.6285121e-05 | K13: 0.00011508114 | L13: -1.3201037e-06 | M13: -2.3072897e-07 | N13: 0.0040120362 | O13: 0.00086540724 | P13: 0.00086499312 | Q13: 0.00085339069 | R13: 0.00081951472 | S13: 0.00085088477 | T13: 0.00084958695 | U13: 0.00088119088 | V13: 0.00091036053 | W13: 0.00091104757 | X13: 0.00093090092 | Y13: 7.9569868e-06 | Z13: -0.00063238411 | AA13: -6.7108691e-06 | AB13: 2.2358398e-05 | AC13: 0.00043622006 | AD13: 0.00063088082 | AE13: 0.0003927945 | AF13: -1.1266709e-05 | AG13: -0.00019296468
... A32: InvMillsRatio | B32: -0.35606 | C32: 3.9510369e-05 | D32: -7.7795217e-07 | E32: -0.00052372902 | F32: -0.0011006878 | G32: 4.8585536e-06 | H32: 9.5000458e-06 | I32: -1.7419858e-06 | J32: -5.0274268e-05 | K32: -0.00086915216 | L32: 6.599717e-06 | M32: 2.2768445e-06 | N32: -0.00019296468 | O32: -0.00010527581 | P32: -0.00013251041 | Q32: -8.8872281e-05 | R32: -9.902232e-05 | S32: -9.1064789e-05 | T32: -5.5775987e-05 | U32: -7.4146929e-06 | V32: -7.092005e-05 | W32: -0.00011352316 | X32: -9.6757644e-05 | Y32: -7.1510382e-05 | Z32: 0.00094814762 | AA32: -7.1475859e-05 | AB32: -6.9607561e-05 | AC32: -0.00032126988 | AD32: 2.1803563e-05 | AE32: -0.00010689875 | AF32: -0.0025381961 | AG32: 0.0011347806

Sheet W1ma
A1: REGRESSOR | B1: COEFFICIENT | C1: demAge | D1: demAgeSq | E1: eduHighestC4Medium | F1: eduHighestC4Low | G1: eduHighestC4Medium_demAge | H1: eduHighestC4Low_demAge | I1: eduHighestParentC3Medium | J1: eduHighestParentC3Low | K1: healthDsblLongtermFlag | L1: healthPhysicalPcsL1 | M1: healthMentalMcsL1 | N1: demRgnUKC | O1: demRgnUKD | P1: demRgnUKE | Q1: demRgnUKF | R1: demRgnUKG | S1: demRgnUKH | T1: demRgnUKJ | U1: demRgnUKK | V1: demRgnUKL | W1: demRgnUKM | X1: demRgnUKN | Y1: labPt | Z1: realWageGrowth | AA1: demYear2020 | AB1: demYear2021 | AC1: demEthnC4Asian | AD1: demEthnC4Black | AE1: demEthnC4Other | AF1: Constant | AG1: InvMillsRatio
A2: demAge | B2: 0.0009163482 | C2: 5.49098e-05 | D2: -7.1120255e-07 | E2: 0.00010266666 | F2: -0.00011641101 | G2: -3.2817445e-06 | H2: 4.0724371e-07 | I2: -5.0516222e-06 | J2: -2.7850298e-06 | K2: -0.00029186574 | L2: 2.1476898e-06 | M2: 1.7593706e-06 | N2: -4.3457675e-05 | O2: -6.3377912e-06 | P2: -1.8144176e-05 | Q2: 1.7233309e-05 | R2: 2.975493e-06 | S2: 5.7265887e-06 | T2: 1.7396805e-05 | U2: 1.1909999e-05 | V2: -2.1396109e-06 | W2: -8.3894877e-06 | X2: -1.2335866e-05 | Y2: 1.9563924e-05 | Z2: 0.00032823314 | AA2: -8.9738747e-06 | AB2: -8.4605985e-06 | AC2: -1.4806619e-05 | AD2: -1.2257222e-05 | AE2: -1.9741871e-05 | AF2: -0.0016719174 | AG2: 0.00026132113
A3: demAgeSq | B3: 0.00035692656 | C3: -7.1120255e-07 | D3: 9.6530052e-09 | E3: -1.4134986e-07 | F3: 2.8809719e-06 | G3: 1.5405467e-08 | H3: -3.3985642e-08 | I3: -2.8650201e-08 | J3: -1.332823e-07 | K3: 4.3121016e-06 | L3: -2.8547024e-08 | M3: -2.5754691e-08 | N3: 6.6745723e-07 | O3: 1.4150306e-07 | P3: 3.2174048e-07 | Q3: -2.1494206e-07 | R3: -9.9150126e-09 | S3: -5.2040253e-08 | T3: -2.4072113e-07 | U3: -1.5409222e-07 | V3: 8.2640601e-08 | W3: 1.4879591e-07 | X3: 2.7299441e-07 | Y3: -2.4673997e-07 | Z3: -4.7770658e-06 | AA3: 1.4156556e-07 | AB3: 1.4056253e-07 | AC3: 2.6255259e-07 | AD3: 1.9574619e-07 | AE3: 3.2469179e-07 | AF3: 2.2065932e-05 | AG3: -3.8664739e-06
