Workbook

Sheet H1_comp
A1: ='H1'!A1 -> REGRESSOR | B1: ='H1'!B1 -> COEFFICIENT | D1: =H1_orig!A1 -> REGRESSOR | E1: =H1_orig!B1 -> COEFFICIENT | G1: comp
A2: ='H1'!A2 -> eduSampleFlag_Poor | B2: ='H1'!B2 -> 0.072841292 | D2: =H1_orig!A2 -> Ded_Poor | E2: =H1_orig!B2 -> 0.072841292 | G2: =B2-E2 -> -1.3766169e-11
A3: ='H1'!A3 -> demMaleFlag_Poor | B3: ='H1'!B3 -> -0.34580773 | D3: =H1_orig!A3 -> Dgn_Poor | E3: =H1_orig!B3 -> -0.34580773 | G3: =B3-E3 -> 1.286321e-11
A4: ='H1'!A4 -> demAge_Poor | B4: ='H1'!B4 -> -0.015830927 | D4: =H1_orig!A4 -> Dag_Poor | E4: =H1_orig!B4 -> -0.015830927 | G4: =B4-E4 -> 4.8507032e-13
A5: ='H1'!A5 -> demAgeSq_Poor | B5: ='H1'!B5 -> 0.00016030202 | D5: =H1_orig!A5 -> Dag_sq_Poor | E5: =H1_orig!B5 -> 0.00016030202 | G5: =B5-E5 -> -3.4142882e-15
A6: ='H1'!A6 -> healthPhysicalPcsL1_Poor | B6: ='H1'!B6 -> 0.12325572 | D6: =H1_orig!A6 -> L_Dhe_pcs_Poor | E6: =H1_orig!B6 -> 0.12325572 | G6: =B6-E6 -> -5.74088e-12
A7: ='H1'!A7 -> healthMentalMcsL1_Poor | B7: ='H1'!B7 -> 0.068845052 | D7: =H1_orig!A7 -> L_Dhe_mcs_Poor | E7: =H1_orig!B7 -> 0.068845052 | G7: =B7-E7 -> -2.9698882e-12
A8: ='H1'!A8 -> eduHighestC4Medium_Poor | B8: ='H1'!B8 -> -0.10917815 | D8: =H1_orig!A8 -> Deh_c4_Medium_Poor | E8: =H1_orig!B8 -> -0.10917815 | G8: =B8-E8 -> 1.2192636e-11
A9: ='H1'!A9 -> eduHighestC4Low_Poor | B9: ='H1'!B9 -> -0.2491453 | D9: =H1_orig!A9 -> Deh_c4_Low_Poor | E9: =H1_orig!B9 -> -0.2491453 | G9: =B9-E9 -> 1.8143487e-11
A10: ='H1'!A10 -> labStatusC4NotEmployedL1_Poor | B10: ='H1'!B10 -> -0.38112638 | D10: =H1_orig!A10 -> L_Les_c4_NotEmployed_Poor | E10: =H1_orig!B10 -> -0.38112638 | G10: =B10-E10 -> 1.4193702e-11
A11: ='H1'!A11 -> labStatusC4RetiredL1_Poor | B11: ='H1'!B11 -> -0.23624978 | D11: =H1_orig!A11 -> L_Les_c4_Retired_Poor | E11: =H1_orig!B11 -> -0.23624978 | G11: =B11-E11 -> 3.7587156e-12
A12: ='H1'!A12 -> yHhQuintilesMonthC5Q2L1_Poor | B12: ='H1'!B12 -> 0.2015064 | D12: =H1_orig!A12 -> L_Ydses_c5_Q2_Poor | E12: =H1_orig!B12 -> 0.2015064 | G12: =B12-E12 -> -5.2517712e-12
A13: ='H1'!A13 -> yHhQuintilesMonthC5Q3L1_Poor | B13: ='H1'!B13 -> 0.33579278 | D13: =H1_orig!A13 -> L_Ydses_c5_Q3_Poor | E13: =H1_orig!B13 -> 0.33579278 | G13: =B13-E13 -> -9.0871755e-12
... A121: ='H1'!A121 -> Constant_VeryGood | B121: ='H1'!B121 -> -12.783532 | D121: =H1_orig!A121 -> Constant_VeryGood | E121: =H1_orig!B121 -> -12.783532 | G121: =B121-E121 -> 2.2986679e-09

Sheet H2_comp
A1: ='H2'!A1 -> REGRESSOR | B1: ='H2'!B1 -> COEFFICIENT | D1: =H2_orig!A1 -> REGRESSOR | E1: =H2_orig!B1 -> COEFFICIENT | G1: comp
A2: ='H2'!A2 -> demMaleFlag | B2: ='H2'!B2 -> -0.030671029 | D2: =H2_orig!A2 -> Dgn | E2: =H2_orig!B2 -> -0.030671029 | G2: =B2-E2 -> 2.289835e-16
A3: ='H2'!A3 -> demAge | B3: ='H2'!B3 -> 0.12827825 | D3: =H2_orig!A3 -> Dag | E3: =H2_orig!B3 -> 0.12827825 | G3: =B3-E3 -> 0
A4: ='H2'!A4 -> demAgeSq | B4: ='H2'!B4 -> -0.0015703749 | D4: =H2_orig!A4 -> Dag_sq | E4: =H2_orig!B4 -> -0.0015703749 | G4: =B4-E4 -> 2.1684043e-18
A5: ='H2'!A5 -> eduHighestC4Medium | B5: ='H2'!B5 -> 0.22297852 | D5: =H2_orig!A5 -> Deh_c4_Medium | E5: =H2_orig!B5 -> 0.22297852 | G5: =B5-E5 -> 0
A6: ='H2'!A6 -> eduHighestC4Low | B6: ='H2'!B6 -> 0.35541844 | D6: =H2_orig!A6 -> Deh_c4_Low | E6: =H2_orig!B6 -> 0.35541844 | G6: =B6-E6 -> 0
A7: ='H2'!A7 -> yHhQuintilesMonthC5Q2L1 | B7: ='H2'!B7 -> -0.26674911 | D7: =H2_orig!A7 -> L_Ydses_c5_Q2 | E7: =H2_orig!B7 -> -0.26674911 | G7: =B7-E7 -> 0
A8: ='H2'!A8 -> yHhQuintilesMonthC5Q3L1 | B8: ='H2'!B8 -> -0.49654491 | D8: =H2_orig!A8 -> L_Ydses_c5_Q3 | E8: =H2_orig!B8 -> -0.49654491 | G8: =B8-E8 -> 0
A9: ='H2'!A9 -> yHhQuintilesMonthC5Q4L1 | B9: ='H2'!B9 -> -0.6516426 | D9: =H2_orig!A9 -> L_Ydses_c5_Q4 | E9: =H2_orig!B9 -> -0.6516426 | G9: =B9-E9 -> 0
A10: ='H2'!A10 -> yHhQuintilesMonthC5Q5L1 | B10: ='H2'!B10 -> -0.82343239 | D10: =H2_orig!A10 -> L_Ydses_c5_Q5 | E10: =H2_orig!B10 -> -0.82343239 | G10: =B10-E10 -> 0
A11: ='H2'!A11 -> healthPhysicalPcsL1 | B11: ='H2'!B11 -> -0.02061903 | D11: =H2_orig!A11 -> L_Dhe_pcs | E11: =H2_orig!B11 -> -0.02061903 | G11: =B11-E11 -> 0
A12: ='H2'!A12 -> healthMentalMcsL1 | B12: ='H2'!B12 -> -0.011959765 | D12: =H2_orig!A12 -> L_Dhe_mcs | E12: =H2_orig!B12 -> -0.011959765 | G12: =B12-E12 -> 0
A13: ='H2'!A13 -> healthDsblLongtermFlagL1 | B13: ='H2'!B13 -> 2.4323872 | D13: =H2_orig!A13 -> L_Dlltsd01 | E13: =H2_orig!B13 -> 2.4323872 | G13: =B13-E13 -> 0
... A34: ='H2'!A34 -> Constant | B34: ='H2'!B34 -> -2.8048153 | D34: =H2_orig!A34 -> Constant | E34: =H2_orig!B34 -> -2.8048153 | G34: =B34-E34 -> 5.3290705e-15

Sheet Info
A1: Description: | B1: Model parameters governing projection self-reported health status
A2: Authors: | B2: Justin van de Ven, Daria Popova, Aleksandra Kolndrekaj, Ashley Burdett
A3: Last edit: 15 April 2026 (DP)
A5: Process: | B5: Description:
A6: H1 | B6: Self rated health (5 cat)
B7: Covariates that satisfy the parallel lines assumption have one estimate for all categories of the dependent variable and are present once in the table
B8: Covariates that do not satisfy the parallel lines assumption have an estimate for each estimated category of the dependent variable. These covariates have the dependent variable category appended to their name.
A9: H1_raw | B9: elf rated health (5 cat) - unformatted output
A10: H2 | B10: Prob. long-term sick or disabled
A15: Notes: | B15: Estimation sample: UK_ipop.dta with grossing up weight dwt
B16: Conditions for processes are defined as globals in master.do
B17: Combined former processes H1a and H1b

Sheet Gof
A1: Goodness of fit
A3: H1 - Self-rated health
A4: Pseudo R-squared | B4: 0.22382378 | E4: Chi^2 | F4: 79974.113
A5: N | B5: 320018 | E5: Log likelihood | F5: -362352.42
A7: H2 - Disabled or long term sick
A8: Pseudo R-squared | B8: 0.66472305 | E8: Chi^2 | F8: 30439.35
A9: N | B9: 335251 | E9: Log likelihood | F9: -21195947

Sheet H1_orig_raw
A1: CATEGORY | B1: REGRESSOR | C1: COEFFICIENT
A2: Poor | B2: Ded | C2: 0.072841292
A3: Poor | B3: Dgn | C3: -0.34580773
A4: Poor | B4: Dag | C4: -0.015830927
A5: Poor | B5: Dag_sq | C5: 0.00016030202
A6: Poor | B6: L_Dhe_pcs | C6: 0.12325572
A7: Poor | B7: L_Dhe_mcs | C7: 0.068845052
A8: Poor | B8: 0b.Deh_c4_Medium | C8: 0
A9: Poor | B9: 1.Deh_c4_Medium | C9: -0.10917815
A10: Poor | B10: 0b.Deh_c4_Low | C10: 0
A11: Poor | B11: 1.Deh_c4_Low | C11: -0.2491453
A12: Poor | B12: 0b.Deh_c4_Na | C12: 0
A13: Poor | B13: 1o.Deh_c4_Na | C13: 0
... A161: VeryGood | B161: _cons | C161: -12.783532

Sheet H1_orig
A1: REGRESSOR | B1: COEFFICIENT | C1: Ded_Poor | D1: Dgn_Poor | E1: Dag_Poor | F1: Dag_sq_Poor | G1: L_Dhe_pcs_Poor | H1: L_Dhe_mcs_Poor | I1: Deh_c4_Medium_Poor | J1: Deh_c4_Low_Poor | K1: L_Les_c4_NotEmployed_Poor | L1: L_Les_c4_Retired_Poor | M1: L_Ydses_c5_Q2_Poor | N1: L_Ydses_c5_Q3_Poor | O1: L_Ydses_c5_Q4_Poor | P1: L_Ydses_c5_Q5_Poor | Q1: L_Dhhtp_c4_CoupleChildren_Poor | R1: L_Dhhtp_c4_SingleNoChildren_Poor | S1: L_Dhhtp_c4_SingleChildren_ | T1: L_Dlltsd01_Poor | U1: demRgnUKC_ | V1: demRgnUKD_ | W1: demRgnUKE_Poor | X1: demRgnUKF_Poor | Y1: demRgnUKG_Poor | Z1: demRgnUKH_Poor | AA1: demRgnUKJ_Poor | AB1: demRgnUKK_Poor | AC1: demRgnUKL_ | AD1: demRgnUKM_ | AE1: demRgnUKN_Poor | AF1: Year_transformed_Poor | AG1: Y2020_ | AH1: Y2021_Poor | AI1: demEthnC4Asian_Poor | AJ1: demEthnC4Black_ | AK1: demEthnC4Other_ | AL1: Constant_Poor | AM1: Ded_Fair | AN1: Dgn_Fair | AO1: Dag_Fair | AP1: Dag_sq_Fair | AQ1: L_Dhe_pcs_Fair | AR1: L_Dhe_mcs_Fair | AS1: Deh_c4_Medium_Fair | AT1: Deh_c4_Low_Fair | AU1: L_Les_c4_NotEmployed_Fair | AV1: L_Les_c4_Retired_Fair | AW1: L_Ydses_c5_Q2_Fair | AX1: L_Ydses_c5_Q3_Fair | AY1: L_Ydses_c5_Q4_Fair | AZ1: L_Ydses_c5_Q5_Fair | BA1: L_Dhhtp_c4_CoupleChildren_Fair | BB1: L_Dhhtp_c4_SingleNoChildren_Fair | BC1: L_Dlltsd01_Fair | BD1: demRgnUKE_Fair | BE1: demRgnUKF_Fair | BF1: demRgnUKG_Fair | BG1: demRgnUKH_Fair | BH1: demRgnUKJ_Fair | BI1: demRgnUKK_Fair | BJ1: demRgnUKN_Fair | BK1: Year_transformed_Fair | BL1: Y2021_Fair | BM1: demEthnC4Asian_Fair | BN1: Constant_Fair | BO1: Ded_Good | BP1: Dgn_Good | BQ1: Dag_Good | BR1: Dag_sq_Good | BS1: L_Dhe_pcs_Good | BT1: L_Dhe_mcs_Good | BU1: Deh_c4_Medium_Good | BV1: Deh_c4_Low_Good | BW1: L_Les_c4_NotEmployed_Good | BX1: L_Les_c4_Retired_Good | BY1: L_Ydses_c5_Q2_Good | BZ1: L_Ydses_c5_Q3_Good | CA1: L_Ydses_c5_Q4_Good | CB1: L_Ydses_c5_Q5_Good | CC1: L_Dhhtp_c4_CoupleChildren_Good | CD1: L_Dhhtp_c4_SingleNoChildren_Good | CE1: L_Dlltsd01_Good | CF1: demRgnUKE_Good | CG1: demRgnUKF_Good | CH1: demRgnUKG_Good | CI1: demRgnUKH_Good | CJ1: demRgnUKJ_Good | CK1: demRgnUKK_Good | CL1: demRgnUKN_Good | CM1: Year_transformed_Good | CN1: Y2021_Good | CO1: demEthnC4Asian_Good | CP1: Constant_Good | CQ1: Ded_VeryGood | CR1: Dgn_VeryGood | CS1: Dag_VeryGood | CT1: Dag_sq_VeryGood | CU1: L_Dhe_pcs_VeryGood | CV1: L_Dhe_mcs_VeryGood | CW1: Deh_c4_Medium_VeryGood | CX1: Deh_c4_Low_VeryGood | CY1: L_Les_c4_NotEmployed_VeryGood | CZ1: L_Les_c4_Retired_VeryGood | DA1: L_Ydses_c5_Q2_VeryGood | DB1: L_Ydses_c5_Q3_VeryGood | DC1: L_Ydses_c5_Q4_VeryGood | DD1: L_Ydses_c5_Q5_VeryGood | DE1: L_Dhhtp_c4_CoupleChildren_VeryGood | DF1: L_Dhhtp_c4_SingleNoChildren_VeryGood | DG1: L_Dlltsd01_VeryGood | DH1: demRgnUKE_VeryGood | DI1: demRgnUKF_VeryGood | DJ1: demRgnUKG_VeryGood | DK1: demRgnUKH_VeryGood | DL1: demRgnUKJ_VeryGood | DM1: demRgnUKK_VeryGood | DN1: demRgnUKN_VeryGood | DO1: Year_transformed_VeryGood | DP1: Y2021_VeryGood | DQ1: demEthnC4Asian_VeryGood | DR1: Constant_VeryGood
A2: Ded_Poor | B2: 0.072841292 | C2: 0.017241825 | D2: 0.0001118737 | E2: 0.00022274706 | F2: -1.7346691e-06 | G2: 3.0476841e-06 | H2: 1.0773934e-06 | I2: 0.0010911597 | J2: 0.00098785883 | K2: 0.0010436886 | L2: 0.00019343044 | M2: 0.00025284006 | N2: 0.00055678272 | O2: 0.00068589126 | P2: 0.0011459521 | Q2: 0.00022454434 | R2: 0.00030172186 | S2: 7.9274682e-05 | T2: -0.00038254926 | U2: 2.3352462e-05 | V2: -3.3722836e-06 | W2: -8.1695868e-05 | X2: -2.6013177e-05 | Y2: -0.00020214031 | Z2: -0.00014616095 | AA2: 3.588013e-05 | AB2: -9.6789514e-05 | AC2: -1.7893842e-05 | AD2: 1.0271111e-05 | AE2: -0.00017724103 | AF2: -7.4330763e-06 | AG2: 6.5408734e-06 | AH2: -5.6733123e-05 | AI2: -0.00022908864 | AJ2: -3.6032793e-05 | AK2: -5.1640684e-05 | AL2: -0.0085011904 | AM2: 0.0019995856 | AN2: -2.0223099e-06 | AO2: 3.4945473e-05 | AP2: -2.7250643e-07 | AQ2: 1.7144656e-06 | AR2: 5.5514675e-07 | AS2: 0.0001325212 | AT2: 0.00013344573 | AU2: 0.00016854116 | AV2: 6.2889801e-05 | AW2: 0.00011319607 | AX2: 0.00017001946 | AY2: 0.00020240047 | AZ2: 0.00027279853 | BA2: 8.5765094e-05 | BB2: 6.6910257e-05 | BC2: -3.0153112e-05 | BD2: -6.4251127e-05 | BE2: -2.4255813e-05 | BF2: -4.8991556e-05 | BG2: -3.8944999e-05 | BH2: -3.4690565e-05 | BI2: -3.1597728e-05 | BJ2: 4.3196455e-06 | BK2: -2.7743046e-06 | BL2: -8.2053818e-06 | BM2: -7.4450714e-05 | BN2: -0.0014421927 | BO2: 0.00041281955 | BP2: 3.1303959e-06 | BQ2: 8.2765906e-06 | BR2: -6.601818e-08 | BS2: 4.0470557e-07 | BT2: 7.3708342e-07 | BU2: 3.0150315e-05 | BV2: 2.9555907e-05 | BW2: 3.2096644e-05 | BX2: 2.009865e-05 | BY2: 2.4200416e-05 | BZ2: 3.196527e-05 | CA2: 4.9415005e-05 | CB2: 6.647347e-05 | CC2: 3.1842308e-05 | CD2: 2.8557791e-05 | CE2: -2.0341404e-05 | CF2: -3.728843e-06 | CG2: -4.1202013e-06 | CH2: -3.1623627e-05 | CI2: -6.1302924e-06 | CJ2: -3.7304614e-06 | CK2: -4.7308848e-06 | CL2: 2.603435e-06 | CM2: -1.029539e-06 | CN2: 3.2345813e-06 | CO2: 3.7402444e-06 | CP2: -0.00037124792 | CQ2: 0.00015580287 | CR2: 6.0319353e-07 | CS2: 4.172339e-06 | CT2: -3.5412135e-08 | CU2: 4.735201e-07 | CV2: 5.1162133e-07 | CW2: 4.0926766e-06 | CX2: 3.6992107e-06 | CY2: 9.5893984e-06 | CZ2: 1.1388186e-05 | DA2: 6.9173509e-06 | DB2: 1.746074e-05 | DC2: 2.2994872e-05 | DD2: 2.7868814e-05 | DE2: 9.8394993e-06 | DF2: 1.874515e-05 | DG2: -1.7290856e-05 | DH2: -1.5641629e-06 | DI2: -2.4207851e-06 | DJ2: -1.6755851e-05 | DK2: -3.9762475e-06 | DL2: -3.4199331e-06 | DM2: -2.8193637e-06 | DN2: -6.2894322e-07 | DO2: -1.0005373e-07 | DP2: -1.1082533e-06 | DQ2: 1.8764502e-05 | DR2: -0.00019917426
A3: Dgn_Poor | B3: -0.34580773 | C3: 0.0001118737 | D3: 0.00066476805 | E3: 3.3604426e-06 | F3: -5.3568777e-08 | G3: -4.2452106e-06 | H3: -1.7393572e-06 | I3: 4.1383846e-05 | J3: 9.3668925e-05 | K3: 7.3069158e-06 | L3: 2.0390753e-05 | M3: 2.1856864e-05 | N3: 2.901014e-05 | O3: 3.8955431e-05 | P3: 9.9726631e-05 | Q3: -3.5704935e-05 | R3: 8.3324017e-05 | S3: 2.6524092e-05 | T3: -4.4519411e-05 | U3: 5.0949505e-06 | V3: 2.1920063e-06 | W3: -2.2299412e-05 | X3: -4.3239438e-05 | Y3: -5.77844e-07 | Z3: 4.6211221e-06 | AA3: -4.2192108e-05 | AB3: -1.9442772e-05 | AC3: -3.7615998e-06 | AD3: 1.5355466e-05 | AE3: -6.5182607e-05 | AF3: 2.2668159e-06 | AG3: 2.2286413e-06 | AH3: 3.3581782e-06 | AI3: -6.7891936e-05 | AJ3: 1.092781e-05 | AK3: 1.3972928e-05 | AL3: -0.00018279548 | AM3: 3.7107641e-06 | AN3: 9.3525065e-05 | AO3: 1.0237674e-06 | AP3: -1.309803e-08 | AQ3: -5.8737476e-07 | AR3: -2.2612255e-07 | AS3: 4.5106376e-06 | AT3: 9.7634901e-06 | AU3: -2.8229282e-06 | AV3: 8.5962287e-06 | AW3: -2.697717e-06 | AX3: -2.454224e-06 | AY3: -9.1165376e-07 | AZ3: 3.115502e-06 | BA3: -3.8190222e-06 | BB3: 1.1881675e-05 | BC3: -1.0301137e-05 | BD3: 5.2710764e-06 | BE3: -2.4147084e-06 | BF3: 4.7938429e-06 | BG3: 6.3695351e-06 | BH3: 3.9957173e-07 | BI3: 3.2377579e-06 | BJ3: -1.7947567e-06 | BK3: 6.4265958e-07 | BL3: 3.6249396e-06 | BM3: -6.0596113e-06 | BN3: -4.3509863e-05 | BO3: 1.3899572e-06 | BP3: 2.1542464e-05 | BQ3: 3.5882863e-07 | BR3: -3.8929096e-09 | BS3: -1.1668469e-07 | BT3: 2.4310896e-08 | BU3: 2.6576477e-06 | BV3: 4.490751e-06 | BW3: 1.5535531e-06 | BX3: 4.6909018e-06 | BY3: -5.4427462e-07 | BZ3: -4.3929716e-07 | CA3: 2.4885597e-06 | CB3: 4.9425672e-06 | CC3: 3.0750747e-06 | CD3: 5.9074288e-06 | CE3: -3.2285555e-06 | CF3: 4.3840284e-06 | CG3: 3.6836178e-06 | CH3: 1.8187521e-06 | CI3: 5.7007918e-06 | CJ3: 5.0352896e-06 | CK3: 4.5619931e-06 | CL3: 3.2815595e-06 | CM3: 1.7731481e-07 | CN3: 9.2329288e-07 | CO3: 2.9729809e-06 | CP3: -2.9115888e-05 | CQ3: -1.7721251e-06 | CR3: 8.722458e-06 | CS3: 2.3043404e-08 | CT3: -1.8581083e-10 | CU3: -6.3930773e-08 | CV3: -3.4838427e-09 | CW3: 1.261447e-06 | CX3: 3.0365692e-06 | CY3: 3.0472814e-07 | CZ3: 3.1605917e-06 | DA3: -1.1774192e-06 | DB3: -2.814793e-07 | DC3: 2.3569036e-06 | DD3: 4.338128e-06 | DE3: 3.5785445e-06 | DF3: 4.7390673e-06 | DG3: -2.6770839e-06 | DH3: 4.8375275e-06 | DI3: 5.3441919e-06 | DJ3: 3.887243e-06 | DK3: 4.7373058e-06 | DL3: 5.1472169e-06 | DM3: 5.1959648e-06 | DN3: 4.8062386e-06 | DO3: 4.2512397e-08 | DP3: 5.7672249e-07 | DQ3: 1.2492501e-06 | DR3: -1.3752363e-05
A4: Dag_Poor | B4: -0.015830927 | C4: 0.00022274706 | D4: 3.3604426e-06 | E4: 2.3151908e-05 | F4: -2.043437e-07 | G4: 6.3601302e-07 | H4: 1.8844581e-07 | I4: 5.2232665e-06 | J4: 1.5565754e-06 | K4: 3.7747906e-06 | L4: 2.7617834e-06 | M4: -1.0755573e-06 | N4: -8.5416836e-06 | O4: -2.7315026e-05 | P4: -1.9136841e-05 | Q4: 1.5063623e-05 | R4: 2.1391824e-05 | S4: 6.5574133e-06 | T4: -3.1870643e-05 | U4: 1.9521921e-07 | V4: 2.9716914e-07 | W4: -1.2182145e-05 | X4: -2.6201115e-06 | Y4: -3.2906926e-06 | Z4: -7.1244962e-06 | AA4: 2.6538155e-06 | AB4: 3.0281535e-06 | AC4: 8.6515048e-07 | AD4: 1.2280423e-06 | AE4: -8.1085066e-06 | AF4: -2.88412e-07 | AG4: 1.2737144e-07 | AH4: -3.5544277e-06 | AI4: -1.0228014e-05 | AJ4: -1.1027717e-06 | AK4: 1.1797653e-05 | AL4: -0.00062216032 | AM4: 3.5992256e-05 | AN4: 8.844721e-07 | AO4: 3.8968021e-06 | AP4: -3.5003776e-08 | AQ4: 6.8338897e-08 | AR4: 6.0590228e-08 | AS4: -2.1834806e-07 | AT4: 6.3569277e-09 | AU4: -1.1206176e-07 | AV4: 3.4524822e-06 | AW4: 6.5498259e-07 | AX4: -8.0969691e-08 | AY4: -2.7582399e-06 | AZ4: -2.1837108e-06 | BA4: 3.0552907e-06 | BB4: 4.9234168e-06 | BC4: -3.5947632e-06 | BD4: -1.6213285e-06 | BE4: 2.8000414e-08 | BF4: 1.6039063e-07 | BG4: -3.7246151e-07 | BH4: 6.5706441e-08 | BI4: 1.4445723e-06 | BJ4: 1.5057225e-06 | BK4: -7.1031434e-08 | BL4: -4.0831218e-07 | BM4: -1.998672e-06 | BN4: -0.00010653027 | BO4: 7.8342499e-06 | BP4: 3.9841181e-07 | BQ4: 9.2474345e-07 | BR4: -8.5345379e-09 | BS4: 2.050623e-08 | BT4: 3.4945007e-08 | BU4: 2.3597386e-07 | BV4: 4.0229902e-07 | BW4: -6.4509768e-08 | BX4: 1.9151881e-06 | BY4: 1.2744102e-07 | BZ4: 7.6429121e-08 | CA4: 2.3629248e-08 | CB4: 4.0882994e-07 | CC4: 1.2945323e-06 | CD4: 1.8822543e-06 | CE4: -1.5849312e-06 | CF4: 3.3415836e-07 | CG4: 4.5614873e-07 | CH4: -1.0189019e-07 | CI4: 4.1099681e-07 | CJ4: 6.3404166e-07 | CK4: 8.3127719e-07 | CL4: 9.0960731e-07 | CM4: -4.2668992e-09 | CN4: -8.2938589e-08 | CO4: 1.1761525e-06 | CP4: -2.8262015e-05 | CQ4: 2.910185e-06 | CR4: 1.7393093e-07 | CS4: 3.7273942e-07 | CT4: -3.38817e-09 | CU4: 4.1112868e-08 | CV4: 3.5386224e-08 | CW4: -8.2793217e-08 | CX4: -2.2873364e-08 | CY4: 1.7543234e-11 | CZ4: 1.1156786e-06 | DA4: -6.6941907e-08 | DB4: 3.7045353e-07 | DC4: 5.7499596e-07 | DD4: 7.9697712e-07 | DE4: 8.7741478e-07 | DF4: 1.2710266e-06 | DG4: -1.0670512e-06 | DH4: 4.8091522e-07 | DI4: 5.3889608e-07 | DJ4: 1.7755867e-07 | DK4: 4.2107164e-07 | DL4: 4.4383171e-07 | DM4: 7.0620101e-07 | DN4: 7.7173979e-07 | DO4: -7.8351895e-09 | DP4: -5.9027145e-10 | DQ4: 8.9945112e-07 | DR4: -1.5541845e-05
A5: Dag_sq_Poor | B5: 0.00016030202 | C5: -1.7346691e-06 | D5: -5.3568777e-08 | E5: -2.043437e-07 | F5: 1.958976e-09 | G5: -2.1386448e-09 | H5: -3.0427196e-09 | I5: -5.058755e-08 | J5: -8.9054468e-08 | K5: -1.1394542e-08 | L5: -4.1256503e-07 | M5: -2.8715299e-08 | N5: 4.3707715e-08 | O5: 1.9749853e-07 | P5: 1.4074068e-07 | Q5: -4.1856094e-08 | R5: -1.9862664e-07 | S5: -3.9900183e-08 | T5: 2.5676618e-07 | U5: 2.99283e-09 | V5: 9.7968991e-10 | W5: 1.2520398e-07 | X5: 3.7516787e-08 | Y5: 1.4701614e-08 | Z5: 5.7214996e-08 | AA5: -2.2400968e-08 | AB5: -5.35401e-08 | AC5: -4.8026648e-09 | AD5: -3.6903213e-09 | AE5: 4.600957e-08 | AF5: 2.1145439e-09 | AG5: -5.530747e-09 | AH5: 7.2835216e-09 | AI5: 1.3262633e-07 | AJ5: 1.9761347e-08 | AK5: -7.5226574e-08 | AL5: 5.086527e-06 | AM5: -2.8427984e-07 | AN5: -1.1031217e-08 | AO5: -3.4908653e-08 | AP5: 3.3754418e-10 | AQ5: -1.3691047e-10 | AR5: -7.6172259e-10 | AS5: 3.2985875e-11 | AT5: -1.2489075e-08 | AU5: 1.0531995e-09 | AV5: -8.2672551e-08 | AW5: -1.2394848e-08 | AX5: -5.0632037e-09 | AY5: 1.9155907e-08 | AZ5: 1.6510662e-08 | BA5: -8.3914849e-09 | BB5: -4.1454398e-08 | BC5: 3.2049069e-08 | BD5: 1.9908564e-08 | BE5: 4.7076661e-09 | BF5: -6.3939513e-10 | BG5: 5.0764468e-09 | BH5: 7.5168739e-10 | BI5: -1.2664192e-08 | BJ5: -8.9461631e-09 | BK5: 4.6410087e-10 | BL5: 5.9668378e-10 | BM5: 2.7102645e-08 | BN5: 8.8520799e-07 | BO5: -6.5097493e-08 | BP5: -3.8417349e-09 | BQ5: -8.613523e-09 | BR5: 8.5711563e-11 | BS5: -1.1509393e-10 | BT5: -3.5817339e-10 | BU5: -2.1861764e-09 | BV5: -6.149128e-09 | BW5: -9.2448924e-11 | BX5: -2.8345759e-08 | BY5: -2.9341261e-09 | BZ5: -1.8970835e-09 | CA5: 2.2591627e-10 | CB5: -1.6815242e-09 | CC5: -5.0770614e-09 | CD5: -1.4457259e-08 | CE5: 1.263806e-08 | CF5: 2.2464054e-09 | CG5: 6.6637662e-10 | CH5: 3.5467026e-09 | CI5: 1.9105978e-10 | CJ5: -1.9049403e-09 | CK5: -3.502825e-09 | CL5: -3.345403e-09 | CM5: 4.7767975e-11 | CN5: -4.4261859e-10 | CO5: -3.8419775e-09 | CP5: 2.3751042e-07 | CQ5: -2.5835239e-08 | CR5: -1.487956e-09 | CS5: -3.5895839e-09 | CT5: 3.5643364e-11 | CU5: -3.2515701e-10 | CV5: -3.0324344e-10 | CW5: 4.1029609e-10 | CX5: -1.3067911e-09 | CY5: -4.1842382e-10 | CZ5: -1.4145204e-08 | DA5: -3.5516262e-10 | DB5: -3.1587102e-09 | DC5: -3.5339956e-09 | DD5: -4.539114e-09 | DE5: -3.8034529e-09 | DF5: -8.8567081e-09 | DG5: 7.4926017e-09 | DH5: 3.0574759e-10 | DI5: -3.2830339e-10 | DJ5: 2.1229135e-09 | DK5: 6.4552635e-11 | DL5: -3.2101559e-10 | DM5: -1.9284165e-09 | DN5: -2.0378374e-09 | DO5: 1.1107101e-10 | DP5: -8.8485935e-10 | DQ5: -3.9580799e-09 | DR5: 1.2663522e-07
A6: L_Dhe_pcs_Poor | B6: 0.12325572 | C6: 3.0476841e-06 | D6: -4.2452106e-06 | E6: 6.3601302e-07 | F6: -2.1386448e-09 | G6: 1.4033315e-06 | H6: 1.9388257e-07 | I6: 3.7521692e-06 | J6: 3.2503288e-06 | K6: 2.5322534e-06 | L6: 3.2050751e-06 | M6: 4.114053e-07 | N6: -1.2319152e-06 | O6: -3.3729747e-06 | P6: -3.2269092e-06 | Q6: -1.2950752e-06 | R6: 5.5660538e-08 | S6: 7.7156616e-07 | T6: 1.2716568e-05 | U6: 5.9229058e-07 | V6: 5.7036434e-07 | W6: 1.8356491e-06 | X6: -6.9360153e-07 | Y6: 4.0219182e-07 | Z6: -1.4900637e-06 | AA6: -1.6242707e-06 | AB6: -1.0378728e-06 | AC6: 8.5797881e-07 | AD6: 8.2953907e-07 | AE6: 2.3474716e-06 | AF6: 7.5017549e-08 | AG6: -1.605871e-07 | AH6: -1.9794683e-06 | AI6: 3.0919699e-06 | AJ6: -4.5939126e-07 | AK6: 3.6349704e-06 | AL6: -9.2898237e-05 | AM6: 2.5118648e-07 | AN6: -4.6350738e-07 | AO6: 2.2447898e-08 | AP6: 3.5639484e-10 | AQ6: 1.8978245e-07 | AR6: 2.4227329e-08 | AS6: 6.552011e-07 | AT6: 7.1444833e-07 | AU6: 7.6189529e-07 | AV6: 2.601318e-07 | AW6: 3.7951577e-08 | AX6: -2.5039892e-07 | AY6: -5.9564589e-07 | AZ6: -4.8384719e-07 | BA6: 7.3988715e-08 | BB6: 2.0646431e-07 | BC6: 2.7400511e-06 | BD6: 7.3301602e-07 | BE6: 4.3642035e-07 | BF6: 4.5628564e-07 | BG6: 2.5165222e-07 | BH6: 2.0787672e-07 | BI6: 5.0158358e-07 | BJ6: 6.7244548e-07 | BK6: -3.8860844e-08 | BL6: -2.5162733e-07 | BM6: 1.0044535e-06 | BN6: -1.1735501e-05 | BO6: -7.5147727e-08 | BP6: -2.320009e-08 | BQ6: -5.2961393e-10 | BR6: 1.7214608e-10 | BS6: 3.6979315e-08 | BT6: -5.501815e-09 | BU6: 1.1751718e-07 | BV6: 3.020817e-07 | BW6: 1.9096851e-07 | BX6: 5.6730489e-08 | BY6: -1.3168277e-07 | BZ6: -1.8574316e-07 | CA6: -2.2748337e-07 | CB6: -1.7693093e-07 | CC6: 5.9879582e-08 | CD6: 1.2717321e-07 | CE6: 1.184741e-06 | CF6: 5.7779621e-07 | CG6: 4.9618297e-07 | CH6: 5.9009853e-07 | CI6: 4.4758794e-07 | CJ6: 4.4843907e-07 | CK6: 5.4757903e-07 | CL6: 6.5701096e-07 | CM6: -1.6447094e-08 | CN6: -7.4130429e-08 | CO6: 4.1451886e-07 | CP6: -2.1734273e-06 | CQ6: -4.0446106e-09 | CR6: 2.0582699e-08 | CS6: 2.8111656e-09 | CT6: 5.8718936e-11 | CU6: 1.0710097e-08 | CV6: -7.613107e-09 | CW6: 6.7028338e-08 | CX6: 2.6486887e-07 | CY6: 1.3622999e-07 | CZ6: 6.267718e-08 | DA6: -5.5937128e-08 | DB6: -7.0397124e-08 | DC6: -5.2515692e-08 | DD6: 1.4860588e-08 | DE6: 1.1192518e-07 | DF6: 1.4420108e-07 | DG6: 7.5461376e-07 | DH6: 5.6070875e-07 | DI6: 5.1394091e-07 | DJ6: 5.0843331e-07 | DK6: 5.0579269e-07 | DL6: 5.1350489e-07 | DM6: 5.8030912e-07 | DN6: 5.8171636e-07 | DO6: -2.8900021e-09 | DP6: -6.3920705e-08 | DQ6: 3.5779029e-07 | DR6: -1.0527219e-06
A7: L_Dhe_mcs_Poor | B7: 0.068845052 | C7: 1.0773934e-06 | D7: -1.7393572e-06 | E7: 1.8844581e-07 | F7: -3.0427196e-09 | G7: 1.9388257e-07 | H7: 1.2751579e-06 | I7: 2.1159015e-06 | J7: 2.3806604e-06 | K7: 4.6053723e-06 | L7: 1.701017e-07 | M7: -2.4343472e-06 | N7: -3.5189115e-06 | O7: -4.3507815e-06 | P7: -4.9993061e-06 | Q7: -1.1924686e-06 | R7: 1.4770202e-06 | S7: 7.8312349e-08 | T7: 3.7571528e-06 | U7: -4.5845657e-08 | V7: 4.5472292e-08 | W7: -1.6050648e-06 | X7: -8.1380675e-07 | Y7: -5.3998352e-07 | Z7: -1.356202e-06 | AA7: -2.387531e-07 | AB7: -2.9553384e-08 | AC7: 2.5337611e-07 | AD7: 2.348504e-07 | AE7: -5.2324486e-07 | AF7: 4.5157482e-07 | AG7: 6.9509517e-08 | AH7: -6.7153146e-07 | AI7: 2.1347076e-06 | AJ7: -4.2322092e-07 | AK7: 1.0893152e-06 | AL7: -7.0086689e-05 | AM7: -1.1124356e-07 | AN7: -2.2775005e-07 | AO7: 2.5737386e-08 | AP7: -4.457045e-10 | AQ7: 1.8026592e-08 | AR7: 1.9386702e-07 | AS7: 2.9312538e-07 | AT7: 3.6883843e-07 | AU7: 1.1685808e-06 | AV7: -4.0204949e-08 | AW7: -6.1664579e-07 | AX7: -9.3326539e-07 | AY7: -1.0595883e-06 | AZ7: -1.1548096e-06 | BA7: 4.778258e-08 | BB7: 3.8006122e-07 | BC7: 7.6396157e-07 | BD7: -1.2218296e-07 | BE7: 5.190555e-08 | BF7: -1.7204298e-08 | BG7: -1.6519833e-07 | BH7: -9.136124e-08 | BI7: 8.7887504e-08 | BJ7: -9.9044113e-08 | BK7: 4.6328297e-08 | BL7: -8.0388383e-08 | BM7: 8.6952248e-07 | BN7: -9.878947e-06 | BO7: 2.756969e-08 | BP7: -2.0402898e-08 | BQ7: 7.186711e-09 | BR7: -1.0875322e-10 | BS7: -6.9714623e-09 | BT7: 4.7734936e-08 | BU7: 9.222178e-08 | BV7: 2.0506155e-07 | BW7: 2.565478e-07 | BX7: -1.6570574e-08 | BY7: -2.3959315e-07 | BZ7: -3.4825991e-07 | CA7: -3.2938756e-07 | CB7: -3.3678207e-07 | CC7: 3.8851773e-08 | CD7: 1.2750284e-07 | CE7: 5.0419718e-07 | CF7: -2.4154642e-09 | CG7: 8.3476107e-08 | CH7: -3.7077388e-08 | CI7: -1.0341818e-08 | CJ7: 4.3937281e-08 | CK7: 8.2764664e-08 | CL7: 6.2672985e-08 | CM7: -2.9796605e-09 | CN7: 5.1769746e-08 | CO7: 4.3868096e-08 | CP7: -1.7619554e-06 | CQ7: 1.0087029e-08 | CR7: 4.0601503e-09 | CS7: 1.1026958e-09 | CT7: -1.7788652e-11 | CU7: -1.7486144e-08 | CV7: 1.4624376e-08 | CW7: 5.1052571e-08 | CX7: 1.036236e-07 | CY7: 1.373827e-07 | CZ7: -1.970133e-08 | DA7: -9.7415766e-08 | DB7: -1.9198483e-07 | DC7: -1.8352307e-07 | DD7: -1.7362758e-07 | DE7: 6.3726231e-08 | DF7: 7.0412605e-08 | DG7: 3.5824424e-07 | DH7: 5.3668836e-08 | DI7: 1.0499865e-07 | DJ7: 7.699884e-08 | DK7: 5.4743511e-08 | DL7: 8.2986303e-08 | DM7: 1.0624012e-07 | DN7: 7.6564657e-08 | DO7: -4.0771131e-09 | DP7: 2.6826006e-08 | DQ7: -4.1397183e-08 | DR7: 3.3415874e-07
A8: Deh_c4_Medium_Poor | B8: -0.10917815 | C8: 0.0010911597 | D8: 4.1383846e-05 | E8: 5.2232665e-06 | F8: -5.058755e-08 | G8: 3.7521692e-06 | H8: 2.1159015e-06 | I8: 0.0014368412 | J8: 0.0011852858 | K8: -5.1081764e-05 | L8: 4.7331601e-05 | M8: -2.2439042e-05 | N8: 5.0175117e-05 | O8: 0.00015638643 | P8: 0.00047551564 | Q8: 9.4465414e-05 | R8: 9.7169731e-05 | S8: 3.0247023e-05 | T8: -1.4002007e-05 | U8: -1.0590116e-05 | V8: -1.315574e-05 | W8: -6.0082445e-05 | X8: -4.491878e-05 | Y8: -6.3681987e-05 | Z8: -6.3239724e-05 | AA8: 3.4603239e-05 | AB8: -0.00010215796 | AC8: -8.4315412e-06 | AD8: 1.8628378e-05 | AE8: -3.8865348e-06 | AF8: 1.1917337e-05 | AG8: -6.5151765e-06 | AH8: -3.3725231e-05 | AI8: 9.6104742e-05 | AJ8: -2.4823877e-05 | AK8: 8.2964915e-05 | AL8: -0.0017883812 | AM8: 0.00013234405 | AN8: 6.0068759e-06 | AO8: -2.1056981e-07 | AP8: 2.6834062e-10 | AQ8: 9.7017879e-07 | AR8: 4.3216225e-07 | AS8: 0.00018162941 | AT8: 0.00015143785 | AU8: 1.6651875e-05 | AV8: 2.0933093e-05 | AW8: 5.6495003e-06 | AX8: 1.5980783e-05 | AY8: 3.3571968e-05 | AZ8: 7.7766035e-05 | BA8: 1.2410502e-05 | BB8: 2.2528194e-05 | BC8: -1.6721018e-05 | BD8: -2.2935435e-05 | BE8: -1.223599e-05 | BF8: -2.1997295e-05 | BG8: -1.9669469e-05 | BH8: -3.3176589e-06 | BI8: -2.0132627e-05 | BJ8: -2.6912767e-06 | BK8: 1.1620709e-06 | BL8: -5.6664403e-06 | BM8: -2.9049216e-06 | BN8: -0.00024396296 | BO8: 2.600744e-05 | BP8: 3.4817647e-06 | BQ8: 1.5188706e-07 | BR8: -1.0371518e-09 | BS8: 2.3984553e-07 | BT8: 2.3126433e-07 | BU8: 3.7478902e-05 | BV8: 3.2364126e-05 | BW8: 2.7530106e-06 | BX8: 6.5849228e-06 | BY8: 5.080462e-07 | BZ8: 1.1738718e-06 | CA8: 8.1423194e-06 | CB8: 1.8272687e-05 | CC8: 8.5166966e-06 | CD8: 9.0180844e-06 | CE8: -3.6213483e-06 | CF8: -7.0948765e-06 | CG8: -4.9121832e-06 | CH8: -1.1150174e-05 | CI8: -7.5116682e-06 | CJ8: -2.9751439e-06 | CK8: -5.8972594e-06 | CL8: -2.2923328e-06 | CM8: 2.9297295e-07 | CN8: -1.3243392e-06 | CO8: 1.6438209e-06 | CP8: -7.1165517e-05 | CQ8: 4.1593362e-06 | CR8: 2.3421435e-06 | CS8: -1.7874436e-07 | CT8: 2.0575199e-09 | CU8: 5.3744657e-08 | CV8: 8.9223541e-08 | CW8: 1.2876668e-05 | CX8: 1.1682857e-05 | CY8: -7.2182901e-07 | CZ8: 3.1647224e-06 | DA8: -4.5290293e-07 | DB8: 9.3370476e-07 | DC8: 4.3027723e-06 | DD8: 8.4052635e-06 | DE8: 4.9356001e-06 | DF8: 4.4353725e-06 | DG8: -2.2701495e-06 | DH8: -3.8738413e-06 | DI8: -3.0532701e-06 | DJ8: -3.0312608e-06 | DK8: -3.9877467e-06 | DL8: -1.9675185e-06 | DM8: -2.7225782e-06 | DN8: -1.6905827e-06 | DO8: 3.8206335e-07 | DP8: -2.723218e-06 | DQ8: 2.0884723e-06 | DR8: -2.5322725e-05
A9: Deh_c4_Low_Poor | B9: -0.2491453 | C9: 0.00098785883 | D9: 9.3668925e-05 | E9: 1.5565754e-06 | F9: -8.9054468e-08 | G9: 3.2503288e-06 | H9: 2.3806604e-06 | I9: 0.0011852858 | J9: 0.0018384176 | K9: -2.5240122e-05 | L9: 8.4302734e-05 | M9: 1.4834999e-05 | N9: 0.00027694075 | O9: 0.0004044825 | P9: 0.00067961652 | Q9: 5.6209418e-05 | R9: 0.00010177677 | S9: 2.4654148e-05 | T9: -4.060118e-05 | U9: -1.390844e-05 | V9: -1.4483498e-05 | W9: -0.00010863366 | X9: -9.0552905e-05 | Y9: -8.6421429e-05 | Z9: -4.5668803e-05 | AA9: 2.0427769e-05 | AB9: -0.00010557195 | AC9: -1.9069246e-05 | AD9: 1.2620889e-05 | AE9: -4.5524056e-05 | AF9: 2.2983646e-05 | AG9: -3.5947709e-06 | AH9: -2.1717217e-05 | AI9: 0.00010245604 | AJ9: -2.3150495e-05 | AK9: 5.6508305e-05 | AL9: -0.0018471742 | AM9: 0.0001288377 | AN9: 1.0482082e-05 | AO9: -1.856856e-08 | AP9: -1.2796445e-08 | AQ9: 9.7657583e-07 | AR9: 4.7566852e-07 | AS9: 0.00014864657 | AT9: 0.00026095679 | AU9: 2.2146889e-05 | AV9: 2.5822245e-05 | AW9: 1.5247244e-05 | AX9: 5.3607198e-05 | AY9: 7.1724863e-05 | AZ9: 0.00011249551 | BA9: 4.6180799e-06 | BB9: 2.5373277e-05 | BC9: -2.2304114e-05 | BD9: -3.5668271e-05 | BE9: -2.2300045e-05 | BF9: -2.5905971e-05 | BG9: -2.0635598e-05 | BH9: -2.2197492e-06 | BI9: -2.2563273e-05 | BJ9: -1.6645228e-05 | BK9: 3.1806923e-06 | BL9: -3.4099809e-06 | BM9: -1.513281e-05 | BN9: -0.00028184531 | BO9: 2.4902803e-05 | BP9: 4.6118403e-06 | BQ9: 2.3421198e-07 | BR9: -4.9245708e-09 | BS9: 2.6201913e-07 | BT9: 2.3885307e-07 | BU9: 3.0048272e-05 | BV9: 6.4090172e-05 | BW9: 4.649538e-06 | BX9: 7.29766e-06 | BY9: 1.7157913e-06 | BZ9: 1.0463162e-05 | CA9: 1.6362797e-05 | CB9: 2.5049296e-05 | CC9: 6.00503e-06 | CD9: 9.3106833e-06 | CE9: -3.1762531e-06 | CF9: -1.2947013e-05 | CG9: -9.9956547e-06 | CH9: -1.3851714e-05 | CI9: -1.0945123e-05 | CJ9: -6.083862e-06 | CK9: -9.646514e-06 | CL9: -8.6908593e-06 | CM9: 8.6716176e-07 | CN9: -9.2365641e-07 | CO9: -3.9557456e-06 | CP9: -7.851142e-05 | CQ9: 4.0603505e-06 | CR9: 3.1255778e-06 | CS9: -1.4722266e-07 | CT9: 2.5647326e-10 | CU9: 8.4375505e-08 | CV9: 4.0949176e-08 | CW9: 1.0585906e-05 | CX9: 2.9297007e-05 | CY9: 1.3985343e-06 | CZ9: 3.9684526e-06 | DA9: -9.6210585e-07 | DB9: 4.119754e-06 | DC9: 6.8267494e-06 | DD9: 1.1045177e-05 | DE9: 3.7817389e-06 | DF9: 3.7850763e-06 | DG9: -7.4465716e-07 | DH9: -7.9229092e-06 | DI9: -6.4618367e-06 | DJ9: -6.8550337e-06 | DK9: -7.7523914e-06 | DL9: -4.2167384e-06 | DM9: -6.144184e-06 | DN9: -6.2686005e-06 | DO9: 6.1702241e-07 | DP9: -2.4037621e-06 | DQ9: -1.8101707e-06 | DR9: -2.4432243e-05
A10: L_Les_c4_NotEmployed_Poor | B10: -0.38112638 | C10: 0.0010436886 | D10: 7.3069158e-06 | E10: 3.7747906e-06 | F10: -1.1394542e-08 | G10: 2.5322534e-06 | H10: 4.6053723e-06 | I10: -5.1081764e-05 | J10: -2.5240122e-05 | K10: 0.0024517927 | L10: 0.00073883434 | M10: 0.00039832862 | N10: 0.00059763088 | O10: 0.00082072853 | P10: 0.0010078166 | Q10: 8.4119422e-05 | R10: 0.00018956599 | S10: -1.0992129e-05 | T10: -0.0010940979 | U10: 5.0440067e-06 | V10: 4.2253374e-06 | W10: 8.7799477e-05 | X10: 2.4615521e-05 | Y10: -2.8613577e-05 | Z10: 2.1928933e-05 | AA10: -9.5848801e-05 | AB10: 3.7871383e-05 | AC10: -1.126113e-05 | AD10: 3.1554921e-06 | AE10: -2.862703e-05 | AF10: 6.0200831e-06 | AG10: 1.816435e-06 | AH10: 1.9639446e-05 | AI10: -1.07242e-05 | AJ10: 2.0453208e-05 | AK10: -2.5820088e-05 | AL10: -0.0018436548 | AM10: 0.00016759553 | AN10: -9.8624929e-07 | AO10: 2.2802574e-07 | AP10: 6.487091e-10 | AQ10: 6.0978852e-07 | AR10: 1.1008381e-06 | AS10: 1.2188928e-05 | AT10: 1.8175857e-05 | AU10: 0.0004323188 | AV10: 9.2172316e-05 | AW10: 0.00010575076 | AX10: 0.0001280646 | AY10: 0.00016420456 | AZ10: 0.00019236213 | BA10: 4.4555024e-06 | BB10: 2.6469414e-05 | BC10: -0.0001877266 | BD10: -7.3266628e-06 | BE10: 1.2192298e-05 | BF10: -5.2241187e-06 | BG10: 9.4733825e-06 | BH10: -1.1849592e-05 | BI10: 1.0623971e-05 | BJ10: 2.1640167e-06 | BK10: 7.7408821e-07 | BL10: -1.8740005e-06 | BM10: 1.7340026e-06 | BN10: -0.00033518101 | BO10: 3.4966618e-05 | BP10: 1.295869e-06 | BQ10: 2.8399372e-07 | BR10: -2.2125357e-09 | BS10: 1.3015507e-07 | BT10: 2.5411015e-07 | BU10: 3.042589e-06 | BV10: 5.0763109e-06 | BW10: 0.00010097384 | BX10: 1.8266021e-05 | BY10: 2.0906657e-05 | BZ10: 2.3513297e-05 | CA10: 3.1982201e-05 | CB10: 3.7537394e-05 | CC10: -4.1925015e-07 | CD10: 5.7257934e-06 | CE10: -4.6121521e-05 | CF10: 1.7021786e-07 | CG10: 3.8099089e-06 | CH10: -6.9015448e-06 | CI10: 1.1874745e-06 | CJ10: -4.5593942e-07 | CK10: 2.8838658e-06 | CL10: 1.5944532e-06 | CM10: -1.8050798e-07 | CN10: 1.0358377e-06 | CO10: 1.9878844e-06 | CP10: -7.0131998e-05 | CQ10: 1.342489e-05 | CR10: -1.8973827e-07 | CS10: 3.5376736e-07 | CT10: -3.6104652e-09 | CU10: -1.5508512e-08 | CV10: 4.4239709e-08 | CW10: 3.7853434e-07 | CX10: 4.3625099e-06 | CY10: 4.4374304e-05 | CZ10: 6.9571866e-06 | DA10: 5.753436e-06 | DB10: 9.4193254e-06 | DC10: 1.0715905e-05 | DD10: 1.2362498e-05 | DE10: -1.2768759e-06 | DF10: 8.3282464e-07 | DG10: -2.3191688e-05 | DH10: 7.6848644e-07 | DI10: 2.8719723e-06 | DJ10: -1.0322483e-06 | DK10: 4.6121122e-07 | DL10: -1.9397224e-07 | DM10: 1.7771521e-06 | DN10: 1.7130139e-06 | DO10: -3.8812187e-08 | DP10: 2.5738137e-07 | DQ10: 1.920872e-06 | DR10: -2.3670443e-05
A11: L_Les_c4_Retired_Poor | B11: -0.23624978 | C11: 0.00019343044 | D11: 2.0390753e-05 | E11: 2.7617834e-06 | F11: -4.1256503e-07 | G11: 3.2050751e-06 | H11: 1.701017e-07 | I11: 4.7331601e-05 | J11: 8.4302734e-05 | K11: 0.00073883434 | L11: 0.0025097358 | M11: 0.00010647492 | N11: 0.00031158184 | O11: 0.00062704945 | P11: 0.00081187037 | Q11: 0.00022937356 | R11: 0.00014049912 | S11: 3.7682508e-05 | T11: 0.00055461438 | U11: 1.0331291e-06 | V11: 4.8639572e-06 | W11: 3.4527704e-05 | X11: 2.8718815e-05 | Y11: 3.4285718e-05 | Z11: 2.1934772e-05 | AA11: -2.2395504e-05 | AB11: 7.9115991e-05 | AC11: -6.6064659e-06 | AD11: -1.7215193e-05 | AE11: 0.00010339946 | AF11: -9.5072089e-06 | AG11: 1.284992e-05 | AH11: 5.9668415e-05 | AI11: 6.8966243e-05 | AJ11: 2.4135154e-05 | AK11: -0.00010486597 | AL11: -0.00051315435 | AM11: 5.23173e-05 | AN11: 5.6562217e-06 | AO11: 2.5915943e-06 | AP11: -7.4885468e-08 | AQ11: 3.8799928e-07 | AR11: 4.7579219e-08 | AS11: 1.6783687e-05 | AT11: 2.203966e-05 | AU11: 0.00010622481 | AV11: 0.00030805398 | AW11: 2.4655838e-05 | AX11: 5.4421208e-05 | AY11: 9.4822219e-05 | AZ11: 0.00012192256 | BA11: 1.884011e-05 | BB11: 2.0517888e-05 | BC11: 5.8473487e-05 | BD11: -9.1110345e-06 | BE11: 4.6627926e-06 | BF11: -6.1885339e-08 | BG11: 1.1981844e-06 | BH11: -4.0865493e-06 | BI11: 1.3983711e-05 | BJ11: 4.5539324e-06 | BK11: -1.6720439e-06 | BL11: 8.7917195e-06 | BM11: -1.2224531e-05 | BN11: -0.00011356173 | BO11: 1.1203926e-05 | BP11: 2.7115054e-06 | BQ11: 1.0581094e-06 | BR11: -2.1795289e-08 | BS11: 2.2213547e-07 | BT11: 1.6903707e-07 | BU11: 4.3274748e-06 | BV11: 4.8740769e-06 | BW11: 2.2648566e-05 | BX11: 7.2073868e-05 | BY11: 3.8868271e-06 | BZ11: 7.558067e-06 | CA11: 1.8892967e-05 | CB11: 2.6347955e-05 | CC11: 8.2754249e-06 | CD11: 8.9477568e-06 | CE11: 1.9282796e-05 | CF11: -5.1276207e-06 | CG11: -1.3070476e-06 | CH11: -8.0612667e-06 | CI11: -2.5931874e-06 | CJ11: -2.1385676e-06 | CK11: -3.7415361e-07 | CL11: -2.7582659e-06 | CM11: -3.5002042e-07 | CN11: 3.1992268e-06 | CO11: 6.468001e-07 | CP11: -5.0814054e-05 | CQ11: 7.939856e-07 | CR11: 2.5729842e-06 | CS11: 3.8404612e-07 | CT11: -8.4077164e-09 | CU11: 1.924248e-07 | CV11: 1.3890479e-07 | CW11: 4.6213569e-07 | CX11: 2.3386456e-06 | CY11: 8.927395e-06 | CZ11: 3.0199558e-05 | DA11: -1.9403311e-06 | DB11: 1.2048083e-06 | DC11: 6.3975187e-06 | DD11: 1.0214724e-05 | DE11: 6.2607448e-06 | DF11: 6.8546755e-06 | DG11: 1.0128791e-05 | DH11: -4.5824672e-06 | DI11: -1.4135208e-06 | DJ11: -4.0920187e-06 | DK11: -3.8976641e-06 | DL11: -3.2133443e-06 | DM11: -2.4895812e-06 | DN11: -3.8991763e-06 | DO11: -2.0740609e-07 | DP11: 2.3897193e-06 | DQ11: -5.8807829e-06 | DR11: -2.696801e-05
A12: L_Ydses_c5_Q2_Poor | B12: 0.2015064 | C12: 0.00025284006 | D12: 2.1856864e-05 | E12: -1.0755573e-06 | F12: -2.8715299e-08 | G12: 4.114053e-07 | H12: -2.4343472e-06 | I12: -2.2439042e-05 | J12: 1.4834999e-05 | K12: 0.00039832862 | L12: 0.00010647492 | M12: 0.0014115691 | N12: 0.00098863494 | O12: 0.0010085774 | P12: 0.0010618201 | Q12: -5.9574523e-05 | R12: 0.0002268091 | S12: -1.6544006e-06 | T12: 3.3540329e-05 | U12: 1.454825e-06 | V12: 2.5834242e-06 | W12: 8.253311e-05 | X12: -2.8800811e-05 | Y12: 1.0793807e-05 | Z12: -2.3944718e-05 | AA12: -3.1020066e-05 | AB12: -1.8745428e-05 | AC12: -7.5011508e-06 | AD12: 4.5384033e-06 | AE12: 0.00015056288 | AF12: -2.8193939e-06 | AG12: -3.0841364e-06 | AH12: 2.786895e-05 | AI12: 2.4932382e-05 | AJ12: 2.4858874e-05 | AK12: 5.6164738e-05 | AL12: -0.00084201067 | AM12: 7.5174134e-05 | AN12: -5.8795377e-07 | AO12: -6.4192337e-08 | AP12: -5.5712287e-09 | AQ12: 4.5064836e-07 | AR12: -2.408913e-07 | AS12: 3.9229736e-06 | AT12: 1.3948897e-05 | AU12: 0.0001015564 | AV12: 1.9028874e-05 | AW12: 0.00031028021 | AX12: 0.00024065597 | AY12: 0.00024761796 | AZ12: 0.00025517229 | BA12: -2.3496571e-05 | BB12: 3.8054189e-05 | BC12: 1.2489496e-05 | BD12: -1.0346613e-05 | BE12: -3.6714295e-06 | BF12: 2.1220033e-06 | BG12: -7.0596445e-07 | BH12: -5.602928e-06 | BI12: -2.345998e-06 | BJ12: 1.5730791e-05 | BK12: -9.941082e-07 | BL12: 7.4366017e-06 | BM12: -4.1584519e-05 | BN12: -0.00023589036 | BO12: 1.4893485e-05 | BP12: 3.2383314e-07 | BQ12: -8.3639248e-08 | BR12: -7.0960334e-10 | BS12: 1.0799637e-07 | BT12: -5.4902101e-08 | BU12: 1.3161373e-06 | BV12: 2.4423525e-06 | BW12: 2.110247e-05 | BX12: 4.3382902e-06 | BY12: 8.7156684e-05 | BZ12: 6.7709597e-05 | CA12: 6.8990056e-05 | CB12: 7.0297739e-05 | CC12: -4.9096206e-06 | CD12: 8.2285248e-06 | CE12: 1.0576248e-06 | CF12: 1.4543361e-06 | CG12: -1.0959708e-07 | CH12: 5.7882799e-08 | CI12: -1.269474e-07 | CJ12: 3.2502108e-07 | CK12: 9.6251031e-09 | CL12: 5.3114787e-06 | CM12: -1.1438628e-07 | CN12: 7.490857e-07 | CO12: 5.4266136e-07 | CP12: -6.8569662e-05 | CQ12: 5.4472478e-06 | CR12: 2.5966976e-07 | CS12: -4.5756357e-08 | CT12: 6.5100688e-11 | CU12: 5.3209146e-08 | CV12: -2.4411243e-08 | CW12: 9.6140605e-07 | CX12: 6.0942949e-07 | CY12: 7.1395003e-06 | CZ12: 1.3886988e-06 | DA12: 4.000614e-05 | DB12: 3.0077807e-05 | DC12: 3.0468961e-05 | DD12: 3.1048721e-05 | DE12: -1.4500975e-06 | DF12: 3.3218458e-06 | DG12: -2.0898706e-06 | DH12: 1.8844926e-06 | DI12: 1.2172042e-06 | DJ12: 1.2770763e-06 | DK12: 4.2584543e-07 | DL12: 9.3298462e-07 | DM12: 1.0039038e-06 | DN12: 3.4897342e-06 | DO12: -2.9207454e-08 | DP12: 3.2283158e-07 | DQ12: 2.649053e-06 | DR12: -3.3205529e-05
A13: L_Ydses_c5_Q3_Poor | B13: 0.33579278 | C13: 0.00055678272 | D13: 2.901014e-05 | E13: -8.5416836e-06 | F13: 4.3707715e-08 | G13: -1.2319152e-06 | H13: -3.5189115e-06 | I13: 5.0175117e-05 | J13: 0.00027694075 | K13: 0.00059763088 | L13: 0.00031158184 | M13: 0.00098863494 | N13: 0.0018735027 | O13: 0.0012751617 | P13: 0.0014075348 | Q13: -8.5722919e-05 | R13: 0.00031143229 | S13: 3.5363441e-05 | T13: 9.5845783e-05 | U13: 2.3258103e-06 | V13: 3.7765807e-06 | W13: 5.6427227e-05 | X13: -4.2075074e-05 | Y13: -4.1752995e-05 | Z13: 1.3926857e-05 | AA13: 8.7302235e-07 | AB13: -1.8510974e-05 | AC13: -6.2415249e-06 | AD13: 6.0178479e-06 | AE13: 0.00015446172 | AF13: -1.0992664e-06 | AG13: -1.5736664e-06 | AH13: -4.4050086e-05 | AI13: 0.00018582609 | AJ13: 4.3199466e-05 | AK13: 5.9010441e-05 | AL13: -0.0010524178 | AM13: 0.0001235559 | AN13: 5.0100821e-08 | AO13: -7.8391821e-07 | AP13: 1.7137562e-09 | AQ13: 3.8084953e-07 | AR13: -4.338004e-07 | AS13: 1.3316191e-05 | AT13: 5.2169261e-05 | AU13: 0.00012625001 | AV13: 5.3106144e-05 | AW13: 0.00024331105 | AX13: 0.00036691238 | AY13: 0.00029570774 | AZ13: 0.0003169256 | BA13: -2.6339259e-05 | BB13: 5.466845e-05 | BC13: 2.409606e-05 | BD13: -2.1686466e-05 | BE13: -4.3326944e-06 | BF13: -5.9580888e-06 | BG13: 2.4839195e-06 | BH13: -6.3330254e-07 | BI13: -2.9328119e-06 | BJ13: 1.8225685e-05 | BK13: -1.3904682e-06 | BL13: -3.4052341e-06 | BM13: -3.0750717e-05 | BN13: -0.0002771861 | BO13: 2.1017656e-05 | BP13: 1.3281748e-06 | BQ13: -3.1475552e-07 | BR13: 1.8919684e-09 | BS13: 2.175836e-08 | BT13: -1.1357484e-07 | BU13: 1.7070449e-06 | BV13: 1.1470991e-05 | BW13: 2.6620025e-05 | BX13: 1.259502e-05 | BY13: 6.8498552e-05 | BZ13: 9.7445553e-05 | CA13: 8.1754078e-05 | CB13: 8.6701638e-05 | CC13: -1.7212485e-06 | CD13: 1.4571251e-05 | CE13: 2.0991582e-06 | CF13: 3.0932374e-07 | CG13: 1.3637579e-06 | CH13: 9.4671988e-07 | CI13: 1.9847291e-06 | CJ13: 2.5526702e-06 | CK13: 1.67303e-06 | CL13: 6.4881395e-06 | CM13: 6.4000317e-08 | CN13: -2.231028e-06 | CO13: 7.4356991e-06 | CP13: -8.2139346e-05 | CQ13: 7.2640615e-06 | CR13: 1.2213014e-06 | CS13: -8.3766605e-08 | CT13: 1.3842389e-09 | CU13: 6.0988502e-08 | CV13: -2.4610076e-08 | CW13: 1.0736076e-06 | CX13: 5.8189987e-06 | CY13: 1.0662606e-05 | CZ13: 6.1109793e-06 | DA13: 2.8706058e-05 | DB13: 4.2006726e-05 | DC13: 3.7458161e-05 | DD13: 4.0569373e-05 | DE13: 3.3491232e-06 | DF13: 9.6418233e-06 | DG13: -3.866201e-06 | DH13: 2.4110351e-06 | DI13: 3.663416e-06 | DJ13: 3.2218838e-07 | DK13: 1.6132323e-06 | DL13: 2.8202895e-06 | DM13: 3.4459217e-06 | DN13: 5.6079905e-06 | DO13: -1.3001483e-07 | DP13: 3.7863037e-07 | DQ13: 6.3613094e-06 | DR13: -4.8564908e-05
... A121: Constant_VeryGood | B121: -12.783532 | C121: -0.00019917426 | D121: -1.3752363e-05 | E121: -1.5541845e-05 | F121: 1.2663522e-07 | G121: -1.0527219e-06 | H121: 3.3415874e-07 | I121: -2.5322725e-05 | J121: -2.4432243e-05 | K121: -2.3670443e-05 | L121: -2.696801e-05 | M121: -3.3205529e-05 | N121: -4.8564908e-05 | O121: -4.2913961e-05 | P121: -0.00011132428 | Q121: -3.276227e-05 | R121: -5.446336e-05 | S121: -0.00020881527 | T121: -2.0386146e-05 | U121: -0.00046744683 | V121: -0.00028540134 | W121: -0.00026051812 | X121: -0.00026084861 | Y121: -0.00024265996 | Z121: -0.00025909899 | AA121: -0.00027344364 | AB121: -0.00025479191 | AC121: -0.00029947205 | AD121: -0.00025856238 | AE121: -0.00026183627 | AF121: -1.1117085e-05 | AG121: 0.00014073488 | AH121: 5.0279418e-05 | AI121: -0.0001084394 | AJ121: -0.00022963606 | AK121: 0.00022546404 | AL121: 0.0010815143 | AM121: -0.00026660908 | AN121: 1.3622845e-05 | AO121: -2.1953871e-05 | AP121: 1.9141124e-07 | AQ121: -8.9977214e-06 | AR121: -3.6032697e-06 | AS121: -3.310769e-05 | AT121: -4.006911e-05 | AU121: -7.1535709e-05 | AV121: -6.9605521e-05 | AW121: -9.0509025e-05 | AX121: -9.8531932e-05 | AY121: -0.00010100524 | AZ121: -0.00011272128 | BA121: -2.9139921e-05 | BB121: -7.3535571e-05 | BC121: -2.9029744e-05 | BD121: -0.00028260507 | BE121: -0.00028739102 | BF121: -0.0002452311 | BG121: -0.00029074096 | BH121: -0.0002828587 | BI121: -0.00026931517 | BJ121: -0.00027536805 | BK121: -1.4851686e-05 | BL121: 4.5567939e-05 | BM121: -9.5148572e-05 | BN121: 0.0019579022 | BO121: -0.00055171738 | BP121: 1.3733483e-05 | BQ121: -4.6429024e-05 | BR121: 4.2351186e-07 | BS121: -5.0313762e-05 | BT121: -1.9730534e-05 | BU121: -4.2120138e-05 | BV121: -7.9323098e-05 | BW121: -0.00014465948 | BX121: -0.00017781532 | BY121: -0.00020757904 | BZ121: -0.00022348328 | CA121: -0.00022266624 | CB121: -0.00023489421 | CC121: -2.6772216e-05 | CD121: -0.00017684238 | CE121: -0.0001051078 | CF121: -0.00029949078 | CG121: -0.00029902455 | CH121: -0.00019413998 | CI121: -0.00028734878 | CJ121: -0.00030087478 | CK121: -0.00028715817 | CL121: -0.00030499944 | CM121: -2.3342641e-05 | CN121: 6.244593e-05 | CO121: -0.00014229555 | CP121: 0.0059426513 | CQ121: -0.0019516336 | CR121: 4.5414413e-05 | CS121: -0.00018875309 | CT121: 1.9103445e-06 | CU121: -0.00034257779 | CV121: -0.00014702371 | CW121: -0.00016932478 | CX121: -0.00054396308 | CY121: -0.00064154607 | CZ121: -0.00080369625 | DA121: -0.00088760008 | DB121: -0.00098815157 | DC121: -0.00086532228 | DD121: -0.00090801689 | DE121: 7.4701249e-05 | DF121: -0.0005826361 | DG121: -0.00052237553 | DH121: -0.00018186371 | DI121: -0.00030099846 | DJ121: 0.00012444017 | DK121: -0.00022522669 | DL121: -0.00031006598 | DM121: -0.00024125377 | DN121: -0.00026297941 | DO121: -0.00011514081 | DP121: 0.000451241 | DQ121: -0.0014428362 | DR121: 0.034455252

Sheet H2_orig
A1: REGRESSOR | B1: COEFFICIENT | C1: Dgn | D1: Dag | E1: Dag_sq | F1: Deh_c4_Medium | G1: Deh_c4_Low | H1: L_Ydses_c5_Q2 | I1: L_Ydses_c5_Q3 | J1: L_Ydses_c5_Q4 | K1: L_Ydses_c5_Q5 | L1: L_Dhe_pcs | M1: L_Dhe_mcs | N1: L_Dlltsd01 | O1: L_Dhhtp_c4_CoupleChildren | P1: L_Dhhtp_c4_SingleNoChildren | Q1: L_Dhhtp_c4_SingleChildren | R1: demRgnUKC | S1: demRgnUKD | T1: demRgnUKE | U1: demRgnUKF | V1: demRgnUKG | W1: demRgnUKH | X1: demRgnUKJ | Y1: demRgnUKK | Z1: demRgnUKL | AA1: demRgnUKM | AB1: demRgnUKN | AC1: Year_transformed | AD1: Y2020 | AE1: Y2021 | AF1: demEthnC4Asian | AG1: demEthnC4Black | AH1: demEthnC4Other | AI1: Constant
A2: Dgn | B2: -0.030671029 | C2: 0.00030286832 | D2: -2.252627e-06 | E2: 5.2870254e-08 | F2: -1.7045808e-05 | G2: -4.0511946e-05 | H2: -5.0476148e-06 | I2: -2.3535887e-05 | J2: -1.3698327e-06 | K2: 9.3085918e-05 | L2: 9.7428904e-07 | M2: 5.4945579e-07 | N2: -1.8414513e-05 | O2: 5.6296116e-05 | P2: 6.44096e-05 | Q2: 0.00017884283 | R2: 7.3251163e-06 | S2: -1.617751e-05 | T2: -1.0735741e-05 | U2: 1.7016284e-05 | V2: -1.3827736e-05 | W2: 0.00010473268 | X2: -8.8453584e-06 | Y2: -4.0794503e-07 | Z2: 8.6831591e-06 | AA2: 7.5764675e-05 | AB2: 2.2886927e-05 | AC2: 1.291558e-05 | AD2: -6.5529787e-05 | AE2: -5.5171666e-05 | AF2: 0.00024230941 | AG2: 2.3456275e-05 | AH2: 0.00023038484 | AI2: -0.00047252612
A3: Dag | B3: 0.12827825 | C3: -2.252627e-06 | D3: 1.5422931e-05 | E3: -1.652338e-07 | F3: 7.3083855e-07 | G3: 1.4528482e-06 | H3: -7.7059474e-06 | I3: -2.1627272e-05 | J3: -3.4347315e-05 | K3: -4.2353079e-05 | L3: 3.2824167e-08 | M3: -9.5800357e-08 | N3: -1.6090489e-05 | O3: -1.9021595e-05 | P3: 6.5716857e-06 | Q3: -2.436952e-05 | R3: -6.8589531e-06 | S3: -3.8554715e-06 | T3: -2.7262343e-06 | U3: -6.5954637e-06 | V3: -4.8792021e-06 | W3: -5.8017733e-06 | X3: -4.9534166e-06 | Y3: -4.2745698e-06 | Z3: -4.8161796e-06 | AA3: -3.5675792e-06 | AB3: -9.9586965e-08 | AC3: 8.4093963e-07 | AD3: 1.8355328e-06 | AE3: -5.1476466e-06 | AF3: -8.7457505e-06 | AG3: -4.046489e-06 | AH3: 7.446118e-06 | AI3: -0.00030695457
A4: Dag_sq | B4: -0.0015703749 | C4: 5.2870254e-08 | D4: -1.652338e-07 | E4: 1.8517087e-09 | F4: 1.7958636e-08 | G4: -5.7217555e-08 | H4: 2.7999877e-08 | I4: 2.1473953e-07 | J4: 3.6217164e-07 | K4: 4.9190362e-07 | L4: 2.7831821e-09 | M4: 1.0121766e-09 | N4: 1.7509997e-07 | O4: 2.8916651e-07 | P4: 1.5078857e-08 | Q4: 3.8188322e-07 | R4: 2.0076814e-08 | S4: -1.3776907e-08 | T4: -3.0592221e-08 | U4: 1.7177976e-08 | V4: -1.1191347e-08 | W4: 2.3011757e-08 | X4: -1.8738979e-08 | Y4: -1.8663494e-08 | Z4: -9.6156793e-09 | AA4: 1.5206144e-08 | AB4: -5.6483425e-08 | AC4: -4.6378056e-09 | AD4: -4.9734261e-08 | AE4: -2.1838026e-10 | AF4: 1.4176187e-07 | AG4: -9.0358128e-09 | AH4: 1.1182249e-07 | AI4: 2.86869e-06
A5: Deh_c4_Medium | B5: 0.22297852 | C5: -1.7045808e-05 | D5: 7.3083855e-07 | E5: 1.7958636e-08 | F5: 0.00055097478 | G5: 0.00043731059 | H5: -8.422051e-06 | I5: 3.1675924e-05 | J5: 4.8407206e-05 | K5: 0.00015818748 | L5: 1.8323465e-06 | M5: -4.0176447e-07 | N5: -4.621325e-06 | O5: 1.2125537e-06 | P5: 7.9739479e-05 | Q5: 3.2596644e-05 | R5: -2.3885961e-05 | S5: -2.2890792e-05 | T5: -4.4749e-05 | U5: -4.8844588e-05 | V5: -4.3923374e-05 | W5: -0.00020082018 | X5: -3.213685e-05 | Y5: -2.1199567e-05 | Z5: -5.2725452e-05 | AA5: 9.5744926e-05 | AB5: 4.3275312e-05 | AC5: 6.1335832e-06 | AD5: -1.9535575e-05 | AE5: -6.5780052e-05 | AF5: -0.00016314161 | AG5: 6.4526772e-05 | AH5: 0.00053166309 | AI5: -0.0006953381
A6: Deh_c4_Low | B6: 0.35541844 | C6: -4.0511946e-05 | D6: 1.4528482e-06 | E6: -5.7217555e-08 | F6: 0.00043731059 | G6: 0.00077079722 | H6: 6.8705859e-05 | I6: 0.00013638184 | J6: 0.00016493458 | K6: 0.00028057437 | L6: -5.3271989e-08 | M6: -6.6849468e-07 | N6: -4.1908252e-07 | O6: -7.1665449e-06 | P6: 5.9587571e-05 | Q6: 3.5305976e-05 | R6: 8.6133077e-05 | S6: 9.7206972e-05 | T6: 7.7928925e-05 | U6: 6.3106183e-05 | V6: 4.763169e-05 | W6: -6.2066021e-05 | X6: 8.4167245e-05 | Y6: 0.00010825077 | Z6: 5.5411528e-05 | AA6: 0.00019641346 | AB6: 5.8979526e-05 | AC6: 5.0886596e-06 | AD6: 2.1536358e-05 | AE6: -3.1974265e-05 | AF6: -0.00015451495 | AG6: 9.6616334e-05 | AH6: 0.00040313132 | AI6: -0.00062310127
A7: L_Ydses_c5_Q2 | B7: -0.26674911 | C7: -5.0476148e-06 | D7: -7.7059474e-06 | E7: 2.7999877e-08 | F7: -8.422051e-06 | G7: 6.8705859e-05 | H7: 0.00066976738 | I7: 0.00040283453 | J7: 0.00041624957 | K7: 0.00043346865 | L7: -2.5248944e-06 | M7: -5.81648e-07 | N7: 7.0297685e-05 | O7: -3.7203088e-05 | P7: 3.7588821e-05 | Q7: -3.9394529e-05 | R7: 0.00015259997 | S7: 0.00013816004 | T7: 0.00016152934 | U7: 0.00011923958 | V7: 0.00012192967 | W7: 0.0001072419 | X7: 0.0001625799 | Y7: 0.00014786701 | Z7: 0.00016139205 | AA7: 0.00019607533 | AB7: 0.00017133245 | AC7: -1.055153e-05 | AD7: 5.0490169e-05 | AE7: 7.4708052e-05 | AF7: -5.1603543e-05 | AG7: 0.00026886904 | AH7: 0.00011965347 | AI7: 5.0058928e-05
A8: L_Ydses_c5_Q3 | B8: -0.49654491 | C8: -2.3535887e-05 | D8: -2.1627272e-05 | E8: 2.1473953e-07 | F8: 3.1675924e-05 | G8: 0.00013638184 | H8: 0.00040283453 | I8: 0.00073566882 | J8: 0.00051475486 | K8: 0.00058077071 | L8: -2.9693502e-06 | M8: -1.3701283e-06 | N8: 0.00010786995 | O8: 4.7452503e-06 | P8: 0.00011756622 | Q8: 0.00013196272 | R8: 0.00019930009 | S8: 0.00018582746 | T8: 0.00019978022 | U8: 0.00015650791 | V8: 0.00017440284 | W8: 0.00014527111 | X8: 0.00019195448 | Y8: 0.00018396542 | Z8: 0.0002073168 | AA8: 0.00026364247 | AB8: 0.00020765012 | AC8: -1.1640646e-05 | AD8: 5.9492186e-05 | AE8: 4.7129094e-05 | AF8: -4.9678425e-07 | AG8: 0.00023519425 | AH8: 0.00036374486 | AI8: 0.00013800594
A9: L_Ydses_c5_Q4 | B9: -0.6516426 | C9: -1.3698327e-06 | D9: -3.4347315e-05 | E9: 3.6217164e-07 | F9: 4.8407206e-05 | G9: 0.00016493458 | H9: 0.00041624957 | I9: 0.00051475486 | J9: 0.00085800261 | K9: 0.00066744195 | L9: -3.5003927e-06 | M9: -1.991912e-06 | N9: 0.00013373229 | O9: 4.3390077e-05 | P9: 0.00013183754 | Q9: 0.00022671231 | R9: 0.00021241371 | S9: 0.00016996566 | T9: 0.00017116964 | U9: 0.00014529653 | V9: 0.00014203526 | W9: 0.00010916017 | X9: 0.00014353906 | Y9: 0.0001699869 | Z9: 0.00020052803 | AA9: 0.00025271033 | AB9: 0.00027470271 | AC9: -1.17271e-05 | AD9: 2.1283668e-05 | AE9: 2.8186536e-05 | AF9: 5.517365e-05 | AG9: 0.00025497523 | AH9: 0.00035347442 | AI9: 0.00036108672
A10: L_Ydses_c5_Q5 | B10: -0.82343239 | C10: 9.3085918e-05 | D10: -4.2353079e-05 | E10: 4.9190362e-07 | F10: 0.00015818748 | G10: 0.00028057437 | H10: 0.00043346865 | I10: 0.00058077071 | J10: 0.00066744195 | K10: 0.0014423872 | L10: -3.8416016e-06 | M10: 9.3993643e-07 | N10: 0.00016920329 | O10: 0.00025994743 | P10: 0.00036807521 | Q10: 0.000503653 | R10: 0.00052524147 | S10: 0.00044605514 | T10: 0.00048060145 | U10: 0.00042902316 | V10: 0.00039910406 | W10: 0.00072629136 | X10: 0.00034821951 | Y10: 0.00049300907 | Z10: 0.00052639711 | AA10: 0.00079089163 | AB10: 0.00054021823 | AC10: 5.4654959e-06 | AD10: -7.3843702e-05 | AE10: -0.00011795785 | AF10: 0.00074074968 | AG10: 0.00050638772 | AH10: 0.0012213229 | AI10: -0.00070931393
A11: L_Dhe_pcs | B11: -0.02061903 | C11: 9.7428904e-07 | D11: 3.2824167e-08 | E11: 2.7831821e-09 | F11: 1.8323465e-06 | G11: -5.3271989e-08 | H11: -2.5248944e-06 | I11: -2.9693502e-06 | J11: -3.5003927e-06 | K11: -3.8416016e-06 | L11: 5.439868e-07 | M11: 1.6632463e-10 | N11: 2.1384664e-06 | O11: 9.5908563e-07 | P11: 8.8581891e-07 | Q11: 7.6518945e-07 | R11: -3.8948974e-06 | S11: -3.6359743e-06 | T11: -4.0240428e-06 | U11: -3.6894943e-06 | V11: -3.5844804e-06 | W11: -3.1945395e-06 | X11: -3.421271e-06 | Y11: -3.7843266e-06 | Z11: -3.4215767e-06 | AA11: -3.0508379e-06 | AB11: -2.9637792e-06 | AC11: 1.9635697e-07 | AD11: -6.7941827e-07 | AE11: -2.2432787e-06 | AF11: 7.7959785e-07 | AG11: -5.546965e-06 | AH11: 2.6920687e-06 | AI11: -3.3020538e-05
A12: L_Dhe_mcs | B12: -0.011959765 | C12: 5.4945579e-07 | D12: -9.5800357e-08 | E12: 1.0121766e-09 | F12: -4.0176447e-07 | G12: -6.6849468e-07 | H12: -5.81648e-07 | I12: -1.3701283e-06 | J12: -1.991912e-06 | K12: 9.3993643e-07 | L12: 1.6632463e-10 | M12: 5.543472e-07 | N12: 1.5708369e-06 | O12: 1.1520322e-06 | P12: 1.0617811e-06 | Q12: 1.8894162e-06 | R12: 2.04869e-06 | S12: 2.5209779e-06 | T12: 2.1394664e-06 | U12: 2.1610697e-06 | V12: 1.7240385e-06 | W12: 6.6736941e-06 | X12: 2.1439272e-06 | Y12: 2.439937e-06 | Z12: 3.277394e-06 | AA12: 2.5162384e-06 | AB12: 2.5318512e-06 | AC12: 3.9865322e-07 | AD12: -9.751917e-07 | AE12: 1.3074877e-07 | AF12: 8.2383922e-06 | AG12: 2.2681936e-06 | AH12: 2.6828459e-06 | AI12: -3.2762876e-05
A13: L_Dlltsd01 | B13: 2.4323872 | C13: -1.8414513e-05 | D13: -1.6090489e-05 | E13: 1.7509997e-07 | F13: -4.621325e-06 | G13: -4.1908252e-07 | H13: 7.0297685e-05 | I13: 0.00010786995 | J13: 0.00013373229 | K13: 0.00016920329 | L13: 2.1384664e-06 | M13: 1.5708369e-06 | N13: 0.00036876145 | O13: 2.3067278e-05 | P13: -5.6286961e-06 | Q13: 4.7643884e-05 | R13: 6.2796927e-05 | S13: 6.9210746e-05 | T13: 6.1749384e-05 | U13: 6.1406293e-05 | V13: 6.4545385e-05 | W13: 8.1473542e-05 | X13: 5.6631707e-05 | Y13: 6.5380345e-05 | Z13: 7.8161106e-05 | AA13: 4.8871667e-05 | AB13: 5.5920063e-05 | AC13: -2.1392898e-06 | AD13: 9.4322936e-06 | AE13: 8.4487069e-06 | AF13: 5.1155193e-05 | AG13: 0.00010430822 | AH13: 2.4216555e-06 | AI13: -5.3469608e-05
... A34: Constant | B34: -2.8048153 | C34: -0.00047252612 | D34: -0.00030695457 | E34: 2.86869e-06 | F34: -0.0006953381 | G34: -0.00062310127 | H34: 5.0058928e-05 | I34: 0.00013800594 | J34: 0.00036108672 | K34: -0.00070931393 | L34: -3.3020538e-05 | M34: -3.2762876e-05 | N34: -5.3469608e-05 | O34: -0.00048846562 | P34: -0.0011353118 | Q34: -0.00094011223 | R34: -0.0013956528 | S34: -0.0014353849 | T34: -0.0012905104 | U34: -0.0012827849 | V34: -0.0011101138 | W34: -0.0020968352 | X34: -0.0011394819 | Y34: -0.0013603928 | Z34: -0.0014573897 | AA34: -0.0021221447 | AB34: -0.0017118718 | AC34: -0.00017201062 | AD34: 0.00055670127 | AE34: 0.00092014912 | AF34: -0.002208414 | AG34: -0.00075442752 | AH34: -0.0036522478 | AI34: 0.01617775

Sheet H1_raw
A1: CATEGORY | B1: REGRESSOR | C1: COEFFICIENT
A2: Poor | B2: eduSampleFlag | C2: 0.072841292
A3: Poor | B3: demMaleFlag | C3: -0.34580773
A4: Poor | B4: demAge | C4: -0.015830927
A5: Poor | B5: demAgeSq | C5: 0.00016030202
A6: Poor | B6: healthPhysicalPcsL1 | C6: 0.12325572
A7: Poor | B7: healthMentalMcsL1 | C7: 0.068845052
A8: Poor | B8: eduHighestC4Medium | C8: -0.10917815
A9: Poor | B9: eduHighestC4Low | C9: -0.2491453
A10: Poor | B10: labStatusC4NotEmployedL1 | C10: -0.38112638
A11: Poor | B11: labStatusC4RetiredL1 | C11: -0.23624978
A12: Poor | B12: yHhQuintilesMonthC5Q2L1 | C12: 0.2015064
A13: Poor | B13: yHhQuintilesMonthC5Q3L1 | C13: 0.33579278
... A149: VeryGood | B149: _cons | C149: -12.801401

Sheet H1
A1: REGRESSOR | B1: COEFFICIENT | C1: eduSampleFlag_Poor | D1: demMaleFlag_Poor | E1: demAge_Poor | F1: demAgeSq_Poor | G1: healthPhysicalPcsL1_Poor | H1: healthMentalMcsL1_Poor | I1: eduHighestC4Medium_Poor | J1: eduHighestC4Low_Poor | K1: labStatusC4NotEmployedL1_Poor | L1: labStatusC4RetiredL1_Poor | M1: yHhQuintilesMonthC5Q2L1_Poor | N1: yHhQuintilesMonthC5Q3L1_Poor | O1: yHhQuintilesMonthC5Q4L1_Poor | P1: yHhQuintilesMonthC5Q5L1_Poor | Q1: demCompHhC4CoupleChL1_Poor | R1: demCompHhC4SingleNoChL1_Poor | S1: demCompHhC4SingleChL1_ | T1: healthDsblLongtermFlagL1_Poor | U1: demRgnUKC_ | V1: demRgnUKD_ | W1: demRgnUKE_Poor | X1: demRgnUKF_Poor | Y1: demRgnUKG_Poor | Z1: demRgnUKH_Poor | AA1: demRgnUKJ_Poor | AB1: demRgnUKK_Poor | AC1: demRgnUKL_ | AD1: demRgnUKM_ | AE1: demRgnUKN_Poor | AF1: demYearTransformed_Poor | AG1: demYear2020_ | AH1: demYear2021_Poor | AI1: demEthnC4Asian_Poor | AJ1: demEthnC4Black_ | AK1: demEthnC4Other_ | AL1: Constant_Poor | AM1: eduSampleFlag_Fair | AN1: demMaleFlag_Fair | AO1: demAge_Fair | AP1: demAgeSq_Fair | AQ1: healthPhysicalPcsL1_Fair | AR1: healthMentalMcsL1_Fair | AS1: eduHighestC4Medium_Fair | AT1: eduHighestC4Low_Fair | AU1: labStatusC4NotEmployedL1_Fair | AV1: labStatusC4RetiredL1_Fair | AW1: yHhQuintilesMonthC5Q2L1_Fair | AX1: yHhQuintilesMonthC5Q3L1_Fair | AY1: yHhQuintilesMonthC5Q4L1_Fair | AZ1: yHhQuintilesMonthC5Q5L1_Fair | BA1: demCompHhC4CoupleChL1_Fair | BB1: demCompHhC4SingleNoChL1_Fair | BC1: healthDsblLongtermFlagL1_Fair | BD1: demRgnUKE_Fair | BE1: demRgnUKF_Fair | BF1: demRgnUKG_Fair | BG1: demRgnUKH_Fair | BH1: demRgnUKJ_Fair | BI1: demRgnUKK_Fair | BJ1: demRgnUKN_Fair | BK1: demYearTransformed_Fair | BL1: demYear2021_Fair | BM1: demEthnC4Asian_Fair | BN1: Constant_Fair | BO1: eduSampleFlag_Good | BP1: demMaleFlag_Good | BQ1: demAge_Good | BR1: demAgeSq_Good | BS1: healthPhysicalPcsL1_Good | BT1: healthMentalMcsL1_Good | BU1: eduHighestC4Medium_Good | BV1: eduHighestC4Low_Good | BW1: labStatusC4NotEmployedL1_Good | BX1: labStatusC4RetiredL1_Good | BY1: yHhQuintilesMonthC5Q2L1_Good | BZ1: yHhQuintilesMonthC5Q3L1_Good | CA1: yHhQuintilesMonthC5Q4L1_Good | CB1: yHhQuintilesMonthC5Q5L1_Good | CC1: demCompHhC4CoupleChL1_Good | CD1: demCompHhC4SingleNoChL1_Good | CE1: healthDsblLongtermFlagL1_Good | CF1: demRgnUKE_Good | CG1: demRgnUKF_Good | CH1: demRgnUKG_Good | CI1: demRgnUKH_Good | CJ1: demRgnUKJ_Good | CK1: demRgnUKK_Good | CL1: demRgnUKN_Good | CM1: demYearTransformed_Good | CN1: demYear2021_Good | CO1: demEthnC4Asian_Good | CP1: Constant_Good | CQ1: eduSampleFlag_VeryGood | CR1: demMaleFlag_VeryGood | CS1: demAge_VeryGood | CT1: demAgeSq_VeryGood | CU1: healthPhysicalPcsL1_VeryGood | CV1: healthMentalMcsL1_VeryGood | CW1: eduHighestC4Medium_VeryGood | CX1: eduHighestC4Low_VeryGood | CY1: labStatusC4NotEmployedL1_VeryGood | CZ1: labStatusC4RetiredL1_VeryGood | DA1: yHhQuintilesMonthC5Q2L1_VeryGood | DB1: yHhQuintilesMonthC5Q3L1_VeryGood | DC1: yHhQuintilesMonthC5Q4L1_VeryGood | DD1: yHhQuintilesMonthC5Q5L1_VeryGood | DE1: demCompHhC4CoupleChL1_VeryGood | DF1: demCompHhC4SingleNoChL1_VeryGood | DG1: healthDsblLongtermFlagL1_VeryGood | DH1: demRgnUKE_VeryGood | DI1: demRgnUKF_VeryGood | DJ1: demRgnUKG_VeryGood | DK1: demRgnUKH_VeryGood | DL1: demRgnUKJ_VeryGood | DM1: demRgnUKK_VeryGood | DN1: demRgnUKN_VeryGood | DO1: demYearTransformed_VeryGood | DP1: demYear2021_VeryGood | DQ1: demEthnC4Asian_VeryGood | DR1: Constant_VeryGood
