Workbook

Sheet E1a_comp
A1: =E1a!A1 -> REGRESSOR | B1: =E1a!B1 -> COEFFICIENT | D1: =E1a_orig!A1 -> REGRESSOR | E1: =E1a_orig!B1 -> COEFFICIENT | G1: comp
A2: =E1a!A2 -> demMaleFlag | B2: =E1a!B2 -> -0.013450267 | D2: =E1a_orig!A2 -> Dgn | E2: =E1a_orig!B2 -> -0.013450267 | G2: =B2-E2 -> -2.879641e-16
A3: =E1a!A3 -> demAge | B3: =E1a!B3 -> -1.1878096 | D3: =E1a_orig!A3 -> Dag | E3: =E1a_orig!B3 -> -1.1878096 | G3: =B3-E3 -> -1.2656542e-14
A4: =E1a!A4 -> demAgeSq | B4: =E1a!B4 -> 0.024709215 | D4: =E1a_orig!A4 -> Dag_sq | E4: =E1a_orig!B4 -> 0.024709215 | G4: =B4-E4 -> 2.810252e-16
A5: =E1a!A5 -> eduSampleFlagL1 | B5: =E1a!B5 -> 0.32099296 | D5: =E1a_orig!A5 -> Ded_L1 | E5: =E1a_orig!B5 -> 0.32099296 | G5: =B5-E5 -> -6.1062266e-16
A6: =E1a!A6 -> eduHighestParentC3MediumL1 | B6: =E1a!B6 -> -0.26246413 | D6: =E1a_orig!A6 -> Dehmf_c3_Medium_L1 | E6: =E1a_orig!B6 -> -0.26246413 | G6: =B6-E6 -> -1.0547119e-15
A7: =E1a!A7 -> eduHighestParentC3LowL1 | B7: =E1a!B7 -> -0.42167057 | D7: =E1a_orig!A7 -> Dehmf_c3_Low_L1 | E7: =E1a_orig!B7 -> -0.42167057 | G7: =B7-E7 -> -1.9428903e-15
A8: =E1a!A8 -> yHhQuintilesMonthC5Q2L1 | B8: =E1a!B8 -> -0.076391105 | D8: =E1a_orig!A8 -> Ydses_c5_Q2_L1 | E8: =E1a_orig!B8 -> -0.076391105 | G8: =B8-E8 -> -1.4849233e-15
A9: =E1a!A9 -> yHhQuintilesMonthC5Q3L1 | B9: =E1a!B9 -> -0.39833595 | D9: =E1a_orig!A9 -> Ydses_c5_Q3_L1 | E9: =E1a_orig!B9 -> -0.39833595 | G9: =B9-E9 -> -5.2180482e-15
A10: =E1a!A10 -> yHhQuintilesMonthC5Q4L1 | B10: =E1a!B10 -> -0.34339504 | D10: =E1a_orig!A10 -> Ydses_c5_Q4_L1 | E10: =E1a_orig!B10 -> -0.34339504 | G10: =B10-E10 -> -5.4400928e-15
A11: =E1a!A11 -> yHhQuintilesMonthC5Q5L1 | B11: =E1a!B11 -> -0.41007982 | D11: =E1a_orig!A11 -> Ydses_c5_Q5_L1 | E11: =E1a_orig!B11 -> -0.41007982 | G11: =B11-E11 -> -5.6066263e-15
A12: =E1a!A12 -> demRgnUKC | B12: =E1a!B12 -> 0.070957692 | D12: =E1a_orig!A12 -> demRgnUKC | E12: =E1a_orig!B12 -> 0.070957692 | G12: =B12-E12 -> -6.6613381e-16
A13: =E1a!A13 -> demRgnUKD | B13: =E1a!B13 -> 0.022964925 | D13: =E1a_orig!A13 -> demRgnUKD | E13: =E1a_orig!B13 -> 0.022964925 | G13: =B13-E13 -> -7.5633944e-16
... A29: =E1a!A29 -> Constant | B29: =E1a!B29 -> 14.504608 | D29: =E1a_orig!A29 -> Constant | E29: =E1a_orig!B29 -> 14.504608 | G29: =B29-E29 -> 1.4566126e-13

Sheet E1b_comp
A1: =E1b!A1 -> REGRESSOR | B1: =E1b!B1 -> COEFFICIENT | D1: =E1b_orig!A1 -> REGRESSOR | E1: =E1b_orig!B1 -> COEFFICIENT | G1: comp
A2: =E1b!A2 -> demMaleFlag | B2: =E1b!B2 -> -0.18352329 | D2: =E1b_orig!A2 -> Dgn | E2: =E1b_orig!B2 -> -0.18352329 | G2: =B2-E2 -> 0
A3: =E1b!A3 -> demAge | B3: =E1b!B3 -> -0.19078019 | D3: =E1b_orig!A3 -> Dag | E3: =E1b_orig!B3 -> -0.19078019 | G3: =B3-E3 -> 0
A4: =E1b!A4 -> demAgeSq | B4: =E1b!B4 -> 0.0018246601 | D4: =E1b_orig!A4 -> Dag_sq | E4: =E1b_orig!B4 -> 0.0018246601 | G4: =B4-E4 -> 0
A5: =E1b!A5 -> demPartnerStatusPartneredL1 | B5: =E1b!B5 -> -0.18198378 | D5: =E1b_orig!A5 -> Dcpst_Partnered_L1 | E5: =E1b_orig!B5 -> -0.18198378 | G5: =B5-E5 -> 0
A6: =E1b!A6 -> eduHighestC4HighL1 | B6: =E1b!B6 -> 0.055823343 | D6: =E1b_orig!A6 -> Deh_c4_High_L1 | E6: =E1b_orig!B6 -> 0.055823343 | G6: =B6-E6 -> 0
A7: =E1b!A7 -> eduHighestC4LowL1 | B7: =E1b!B7 -> -0.36602602 | D7: =E1b_orig!A7 -> Deh_c4_Low_L1 | E7: =E1b_orig!B7 -> -0.36602602 | G7: =B7-E7 -> 0
A8: =E1b!A8 -> eduHighestParentC3MediumL1 | B8: =E1b!B8 -> -0.39908167 | D8: =E1b_orig!A8 -> Dehmf_c3_Medium_L1 | E8: =E1b_orig!B8 -> -0.39908167 | G8: =B8-E8 -> 0
A9: =E1b!A9 -> eduHighestParentC3LowL1 | B9: =E1b!B9 -> -0.47489703 | D9: =E1b_orig!A9 -> Dehmf_c3_Low_L1 | E9: =E1b_orig!B9 -> -0.47489703 | G9: =B9-E9 -> 0
A10: =E1b!A10 -> labStatusC3NotEmployedL1 | B10: =E1b!B10 -> 0.24141222 | D10: =E1b_orig!A10 -> Les_c3_NotEmployed_L1 | E10: =E1b_orig!B10 -> 0.24141222 | G10: =B10-E10 -> 0
A11: =E1b!A11 -> demNChildL1 | B11: =E1b!B11 -> 0.080152375 | D11: =E1b_orig!A11 -> Dnc_L1 | E11: =E1b_orig!B11 -> 0.080152375 | G11: =B11-E11 -> 0
A12: =E1b!A12 -> demNChild0to2L1 | B12: =E1b!B12 -> -0.27954911 | D12: =E1b_orig!A12 -> Dnc02_L1 | E12: =E1b_orig!B12 -> -0.27954911 | G12: =B12-E12 -> 0
A13: =E1b!A13 -> demRgnUKC | B13: =E1b!B13 -> 0.24261062 | D13: =E1b_orig!A13 -> demRgnUKC | E13: =E1b_orig!B13 -> 0.24261062 | G13: =B13-E13 -> 0
... A30: =E1b!A30 -> Constant | B30: =E1b!B30 -> 2.181349 | D30: =E1b_orig!A30 -> Constant | E30: =E1b_orig!B30 -> 2.181349 | G30: =B30-E30 -> 0

Sheet E2_comp
A1: ='E2'!A1 -> REGRESSOR | B1: ='E2'!B1 -> COEFFICIENT | D1: =E2_orig!A1 -> REGRESSOR | E1: =E2_orig!B1 -> COEFFICIENT | G1: comp
A2: ='E2'!A2 -> demMaleFlag_Low | B2: ='E2'!B2 -> -0.70269446 | D2: =E2_orig!A2 -> Dgn_Low | E2: =E2_orig!B2 -> -0.70269446 | G2: =B2-E2 -> -1.0944579e-12
A3: ='E2'!A3 -> demAge_Low | B3: ='E2'!B3 -> 0.70218658 | D3: =E2_orig!A3 -> Dag_Low | E3: =E2_orig!B3 -> 0.70218658 | G3: =B3-E3 -> -2.8161917e-12
A4: ='E2'!A4 -> demAgeSq_Low | B4: ='E2'!B4 -> -0.0091555151 | D4: =E2_orig!A4 -> Dag_sq_Low | E4: =E2_orig!B4 -> -0.0091555151 | G4: =B4-E4 -> 6.9087097e-14
A5: ='E2'!A5 -> eduHighestParentC3MediumL1_ | B5: ='E2'!B5 -> -0.36235547 | D5: =E2_orig!A5 -> L_Dehmf_c3_Medium_ | E5: =E2_orig!B5 -> -0.36235547 | G5: =B5-E5 -> 4.6402882e-12
A6: ='E2'!A6 -> eduHighestParentC3LowL1_ | B6: ='E2'!B6 -> -1.1278756 | D6: =E2_orig!A6 -> L_Dehmf_c3_Low_ | E6: =E2_orig!B6 -> -1.1278756 | G6: =B6-E6 -> 9.7628572e-12
A7: ='E2'!A7 -> demRgnUKC_ | B7: ='E2'!B7 -> -0.34052897 | D7: =E2_orig!A7 -> demRgnUKC_ | E7: =E2_orig!B7 -> -0.34052897 | G7: =B7-E7 -> 3.6275427e-12
A8: ='E2'!A8 -> demRgnUKD_ | B8: ='E2'!B8 -> -0.20582816 | D8: =E2_orig!A8 -> demRgnUKD_ | E8: =E2_orig!B8 -> -0.20582816 | G8: =B8-E8 -> 1.9206026e-12
A9: ='E2'!A9 -> demRgnUKE_Low | B9: ='E2'!B9 -> 0.28530113 | D9: =E2_orig!A9 -> demRgnUKE_Low | E9: =E2_orig!B9 -> 0.28530113 | G9: =B9-E9 -> 2.1377899e-12
A10: ='E2'!A10 -> demRgnUKF_ | B10: ='E2'!B10 -> 0.072134082 | D10: =E2_orig!A10 -> demRgnUKF_ | E10: =E2_orig!B10 -> 0.072134082 | G10: =B10-E10 -> -3.5804693e-14
A11: ='E2'!A11 -> demRgnUKG_ | B11: ='E2'!B11 -> 0.001640279 | D11: =E2_orig!A11 -> demRgnUKG_ | E11: =E2_orig!B11 -> 0.001640279 | G11: =B11-E11 -> 4.0995115e-13
A12: ='E2'!A12 -> demRgnUKH_ | B12: ='E2'!B12 -> 0.093481552 | D12: =E2_orig!A12 -> demRgnUKH_ | E12: =E2_orig!B12 -> 0.093481552 | G12: =B12-E12 -> -4.7972737e-13
A13: ='E2'!A13 -> demRgnUKJ_ | B13: ='E2'!B13 -> 0.12025769 | D13: =E2_orig!A13 -> demRgnUKJ_ | E13: =E2_orig!B13 -> 0.12025769 | G13: =B13-E13 -> -5.8938965e-13
... A32: ='E2'!A32 -> Constant_Medium | B32: ='E2'!B32 -> -17.698016 | D32: =E2_orig!A32 -> Constant_Medium | E32: =E2_orig!B32 -> -17.698016 | G32: =B32-E32 -> 2.2384583e-10

Sheet Info
A1: Description: | B1: Model parameters governing projection of education status
A2: Authors: | B2: Patryk Bronka, Justin van de Ven, Daria Popova, Aleksandra Kolndrekaj, Ashley Burdett
A3: Last edit: | B3: 15 April 2026 (DP)
A5: Process: | B5: Description:
A6: E1a | B6: Prob. remain in education
A7: E1b | B7: Prob. retrun to education
A8: E2 | B8: Educational attainment when leave education
A9: E2_raw | B9: Raw attainment results
A11: Notes: | B11: Estimation sample: UK_ipop.dta with grossing up weight dwt
B12: Conditions for processes are defined as globals in master.do

Sheet Gof
A1: Goodness of fit
A3: E1a - Remain in education
A4: Pseudo R-squared | B4: 0.10295719 | E4: Chi^2 | F4: 1598.8036
A5: N | B5: 22095 | E5: Log likelihood | F5: -7381012.4
A7: E1b - Return to education
A8: Pseudo R-squared | B8: 0.30733103 | E8: Chi^2 | F8: 3169.3526
A9: N | B9: 225235 | E9: Log likelihood | F9: -5581873.3
A11: E2 - Education attainment
A12: Pseudo R-squared | B12: 0.30758642 | E12: Chi^2 | F12: 721.35354
A13: N | B13: 6423 | E13: Log likelihood | F13: -3537.3388

Sheet E1a_orig
A1: REGRESSOR | B1: COEFFICIENT | C1: Dgn | D1: Dag | E1: Dag_sq | F1: Ded_L1 | G1: Dehmf_c3_Medium_L1 | H1: Dehmf_c3_Low_L1 | I1: Ydses_c5_Q2_L1 | J1: Ydses_c5_Q3_L1 | K1: Ydses_c5_Q4_L1 | L1: Ydses_c5_Q5_L1 | M1: demRgnUKC | N1: demRgnUKD | O1: demRgnUKE | P1: demRgnUKF | Q1: demRgnUKG | R1: demRgnUKH | S1: demRgnUKJ | T1: demRgnUKK | U1: demRgnUKL | V1: demRgnUKM | W1: demRgnUKN | X1: Year_transformed | Y1: Y2020 | Z1: Y2021 | AA1: demEthnC4Asian | AB1: demEthnC4Black | AC1: demEthnC4Other | AD1: Constant
A2: Dgn | B2: -0.013450267 | C2: 0.00074882146 | D2: 0.00019883175 | E2: -6.0808293e-06 | F2: -2.2630387e-05 | G2: 0.00024630811 | H2: 0.00011751242 | I2: 0.00011307216 | J2: -0.000242621 | K2: -0.0001438881 | L2: -0.00011667989 | M2: 6.9992458e-05 | N2: 4.1800449e-05 | O2: 3.2535279e-05 | P2: 2.4765096e-05 | Q2: 0.00028722299 | R2: -1.1172609e-07 | S2: 1.1985222e-05 | T2: 3.5983686e-05 | U2: 4.10198e-05 | V2: 0.0001207553 | W2: 7.0332476e-05 | X2: 1.0523831e-05 | Y2: -1.717899e-05 | Z2: -1.689262e-05 | AA2: -4.8694361e-05 | AB2: 7.4015816e-05 | AC2: 0.00045068847 | AD2: -0.0022265494
A3: Dag | B3: -1.1878096 | C3: 0.00019883175 | D3: 0.0082922525 | E3: -0.0002049072 | F3: -0.00026702461 | G3: 0.0010041546 | H3: 0.0012185705 | I3: 0.00054071932 | J3: -0.00033497006 | K3: 0.0014508696 | L3: 0.001154746 | M3: -0.00015670448 | N3: -0.00055626667 | O3: -0.00066402617 | P3: -0.00078639849 | Q3: -0.0034195254 | R3: -0.0004180416 | S3: -0.00057259356 | T3: -0.00052946466 | U3: -0.00074130278 | V3: -0.00024903477 | W3: -0.000901616 | X3: -0.00011664901 | Y3: 0.00062169815 | Z3: 0.00083396681 | AA3: 0.00021932123 | AB3: 0.0001312797 | AC3: -0.0048710971 | AD3: -0.080709594
A4: Dag_sq | B4: 0.024709215 | C4: -6.0808293e-06 | D4: -0.0002049072 | E4: 5.1054099e-06 | F4: 8.7764806e-06 | G4: -2.666249e-05 | H4: -3.006456e-05 | I4: -1.3033552e-05 | J4: 1.5253603e-05 | K4: -3.0183287e-05 | L4: -2.304993e-05 | M4: 5.4307616e-06 | N4: 1.4578308e-05 | O4: 1.7576396e-05 | P4: 2.0445695e-05 | Q4: 8.5051663e-05 | R4: 1.1121726e-05 | S4: 1.4781329e-05 | T4: 1.3831264e-05 | U4: 1.9043532e-05 | V4: 6.4012249e-06 | W4: 2.2677045e-05 | X4: 2.9146758e-06 | Y4: -1.5684507e-05 | Z4: -2.0873506e-05 | AA4: -4.5863203e-06 | AB4: -3.9738079e-06 | AC4: 0.0001200066 | AD4: 0.0019747702
A5: Ded_L1 | B5: 0.32099296 | C5: -2.2630387e-05 | D5: -0.00026702461 | E5: 8.7764806e-06 | F5: 0.0013921945 | G5: 6.3599899e-05 | H5: 6.6234767e-05 | I5: 4.0477603e-05 | J5: 2.7179607e-05 | K5: -7.3058311e-07 | L5: 8.8113933e-06 | M5: 0.00029379412 | N5: 0.00013894614 | O5: 0.00013778609 | P5: 0.00015538067 | Q5: 0.00037287006 | R5: 0.00023347656 | S5: 0.00016039698 | T5: 0.00017332178 | U5: 0.00018591295 | V5: 0.00023194974 | W5: 0.0001303637 | X5: 3.3849538e-05 | Y5: -7.1747631e-05 | Z5: -9.5194835e-05 | AA5: 1.8124217e-05 | AB5: 4.0182337e-05 | AC5: 0.00038860827 | AD5: -7.9773937e-05
A6: Dehmf_c3_Medium_L1 | B6: -0.26246413 | C6: 0.00024630811 | D6: 0.0010041546 | E6: -2.666249e-05 | F6: 6.3599899e-05 | G6: 0.0015306513 | H6: 0.0012020306 | I6: 0.00026405406 | J6: -0.00065119706 | K6: -0.00016448699 | L6: 1.8250705e-05 | M6: -2.8684822e-06 | N6: -0.00011590208 | O6: -0.00017615971 | P6: -0.000184063 | Q6: -0.00027700733 | R6: -0.00017546188 | S6: -0.00010558532 | T6: -6.4714558e-05 | U6: -0.00019940525 | V6: 2.5335739e-05 | W6: -0.00014476789 | X6: 7.6651063e-06 | Y6: 3.4480918e-05 | Z6: 8.1103168e-05 | AA6: -3.9984435e-05 | AB6: 0.00014124012 | AC6: -0.00010772719 | AD6: -0.010545754
A7: Dehmf_c3_Low_L1 | B7: -0.42167057 | C7: 0.00011751242 | D7: 0.0012185705 | E7: -3.006456e-05 | F7: 6.6234767e-05 | G7: 0.0012020306 | H7: 0.0021998988 | I7: 0.00026464785 | J7: -0.00034352965 | K7: 0.00013060514 | L7: 0.00039836436 | M7: 5.4305503e-05 | N7: -6.3730794e-05 | O7: -0.00024545867 | P7: -0.00025154895 | Q7: -0.00061366537 | R7: -0.00022947175 | S7: -0.00011203363 | T7: -7.5165106e-05 | U7: -0.00028497768 | V7: -3.5515303e-06 | W7: -0.00034335488 | X7: 9.5205732e-06 | Y7: 7.4593468e-05 | Z7: 0.00011560222 | AA7: -0.00017922663 | AB7: 4.1752556e-05 | AC7: -0.00072096376 | AD7: -0.013393322
A8: Ydses_c5_Q2_L1 | B8: -0.076391105 | C8: 0.00011307216 | D8: 0.00054071932 | E8: -1.3033552e-05 | F8: 4.0477603e-05 | G8: 0.00026405406 | H8: 0.00026464785 | I8: 0.0016683442 | J8: 0.00032763873 | K8: 0.00053601793 | L8: 0.00056365944 | M8: 0.00047965979 | N8: 9.5451116e-05 | O8: -6.9903623e-06 | P8: 5.0935569e-05 | Q8: 0.0003100178 | R8: -3.4685519e-06 | S8: 8.6846805e-05 | T8: 1.6521936e-05 | U8: 7.8963806e-05 | V8: 0.0001250509 | W8: 0.00011190051 | X8: 3.0927037e-05 | Y8: -0.00011683992 | Z8: -0.00012083359 | AA8: 0.00019209077 | AB8: 0.00011836882 | AC8: 0.00054508384 | AD8: -0.0068764092
A9: Ydses_c5_Q3_L1 | B9: -0.39833595 | C9: -0.000242621 | D9: -0.00033497006 | E9: 1.5253603e-05 | F9: 2.7179607e-05 | G9: -0.00065119706 | H9: -0.00034352965 | I9: 0.00032763873 | J9: 0.003052476 | K9: 0.001348994 | L9: 0.0012915913 | M9: 0.00021664607 | N9: 0.00017401514 | O9: 0.00025261419 | P9: 0.00021329696 | Q9: 0.00054051809 | R9: 0.00012314392 | S9: 0.00017756323 | T9: 0.00012946508 | U9: 0.00016219014 | V9: 8.5529317e-05 | W9: 0.00022375137 | X9: 2.3310338e-05 | Y9: -0.00012998299 | Z9: -9.8802579e-05 | AA9: 0.0002204358 | AB9: 7.1117011e-05 | AC9: 0.00077676453 | AD9: -0.00018225812
A10: Ydses_c5_Q4_L1 | B10: -0.34339504 | C10: -0.0001438881 | D10: 0.0014508696 | E10: -3.0183287e-05 | F10: -7.3058311e-07 | G10: -0.00016448699 | H10: 0.00013060514 | I10: 0.00053601793 | J10: 0.001348994 | K10: 0.0026092095 | L10: 0.0013719017 | M10: 0.00012528863 | N10: -6.444739e-05 | O10: 2.1924802e-05 | P10: -0.0001134462 | Q10: -0.00057417155 | R10: -7.4974141e-06 | S10: -7.3720507e-05 | T10: -0.00019708814 | U10: -8.3924011e-05 | V10: -9.3580767e-05 | W10: -8.1171891e-05 | X10: -3.4886106e-06 | Y10: -2.5904905e-05 | Z10: -1.1188519e-05 | AA10: 0.00028762538 | AB10: 5.3221582e-05 | AC10: -0.00080661435 | AD10: -0.017054687
A11: Ydses_c5_Q5_L1 | B11: -0.41007982 | C11: -0.00011667989 | D11: 0.001154746 | E11: -2.304993e-05 | F11: 8.8113933e-06 | G11: 1.8250705e-05 | H11: 0.00039836436 | I11: 0.00056365944 | J11: 0.0012915913 | K11: 0.0013719017 | L11: 0.0023836088 | M11: 0.00030028063 | N11: 4.3439035e-05 | O11: 8.798877e-05 | P11: 7.3254201e-05 | Q11: -0.00032040202 | R11: -6.9031308e-05 | S11: -6.0481051e-06 | T11: 9.5202112e-06 | U11: 7.0117057e-05 | V11: 7.1359879e-06 | W11: 7.2547013e-05 | X11: -8.0013062e-06 | Y11: 5.0252998e-05 | Z11: 8.3623727e-05 | AA11: 0.00035553503 | AB11: 0.00021007066 | AC11: -0.00058573292 | AD11: -0.014262865
A12: demRgnUKC | B12: 0.070957692 | C12: 6.9992458e-05 | D12: -0.00015670448 | E12: 5.4307616e-06 | F12: 0.00029379412 | G12: -2.8684822e-06 | H12: 5.4305503e-05 | I12: 0.00047965979 | J12: 0.00021664607 | K12: 0.00012528863 | L12: 0.00030028063 | M12: 0.0072150569 | N12: 0.0021434567 | O12: 0.0021620851 | P12: 0.0021925159 | Q12: 0.002579383 | R12: 0.002176234 | S12: 0.002212925 | T12: 0.0022881413 | U12: 0.0023403682 | V12: 0.0022898312 | W12: 0.0023585834 | X12: 4.7241228e-05 | Y12: -0.00020086988 | Z12: -0.00037647882 | AA12: 0.0014516339 | AB12: 0.001526632 | AC12: 0.0016027372 | AD12: -0.0026312125
A13: demRgnUKD | B13: 0.022964925 | C13: 4.1800449e-05 | D13: -0.00055626667 | E13: 1.4578308e-05 | F13: 0.00013894614 | G13: -0.00011590208 | H13: -6.3730794e-05 | I13: 9.5451116e-05 | J13: 0.00017401514 | K13: -6.444739e-05 | L13: 4.3439035e-05 | M13: 0.0021434567 | N13: 0.0036742389 | O13: 0.0020721951 | P13: 0.0020731299 | Q13: 0.0025268261 | R13: 0.0020403371 | S13: 0.0020766636 | T13: 0.0021265357 | U13: 0.0021637011 | V13: 0.0021111611 | W13: 0.0021819385 | X13: 2.6687707e-05 | Y13: -0.00020297102 | Z13: -0.00028830312 | AA13: 0.00052664656 | AB13: 0.001352202 | AC13: 0.0016190327 | AD13: 0.0024985012
... A29: Constant | B29: 14.504608 | C29: -0.0022265494 | D29: -0.080709594 | E29: 0.0019747702 | F29: -7.9773937e-05 | G29: -0.010545754 | H29: -0.013393322 | I29: -0.0068764092 | J29: -0.00018225812 | K29: -0.017054687 | L29: -0.014262865 | M29: -0.0026312125 | N29: 0.0024985012 | O29: 0.003675627 | P29: 0.0048357356 | Q29: 0.028458489 | R29: 0.0012599836 | S29: 0.0028317451 | T29: 0.0022505341 | U29: 0.0041912773 | V29: -0.0006950537 | W29: 0.0060548255 | X29: 0.00069194656 | Y29: -0.0041486304 | Z29: -0.0058327486 | AA29: -0.0035780365 | AB29: -0.0031188073 | AC29: 0.042469196 | AD29: 0.80761444

Sheet E1b_orig
A1: REGRESSOR | B1: COEFFICIENT | C1: Dgn | D1: Dag | E1: Dag_sq | F1: Dcpst_Partnered_L1 | G1: Deh_c4_High_L1 | H1: Deh_c4_Low_L1 | I1: Dehmf_c3_Medium_L1 | J1: Dehmf_c3_Low_L1 | K1: Les_c3_NotEmployed_L1 | L1: Dnc_L1 | M1: Dnc02_L1 | N1: demRgnUKC | O1: demRgnUKD | P1: demRgnUKE | Q1: demRgnUKF | R1: demRgnUKG | S1: demRgnUKH | T1: demRgnUKJ | U1: demRgnUKK | V1: demRgnUKL | W1: demRgnUKM | X1: demRgnUKN | Y1: Year_transformed | Z1: Y2020 | AA1: Y2021 | AB1: demEthnC4Asian | AC1: demEthnC4Black | AD1: demEthnC4Other | AE1: Constant
A2: Dgn | B2: -0.18352329 | C2: 0.00082011818 | D2: 2.3175166e-05 | E2: -2.6689305e-07 | F2: -0.00017746121 | G2: 5.4401218e-05 | H2: 6.6734979e-06 | I2: 2.8575236e-06 | J2: 0.00015589917 | K2: -0.00012938632 | L2: 6.7894424e-05 | M2: -1.7525661e-05 | N2: 0.00097832084 | O2: 1.2166858e-05 | P2: 6.7025936e-05 | Q2: 3.7766338e-05 | R2: 9.3798558e-05 | S2: 0.00011995179 | T2: 1.8514358e-05 | U2: 3.8628074e-05 | V2: 5.1904106e-05 | W2: 0.00012448006 | X2: -1.2836201e-06 | Y2: 1.2632099e-05 | Z2: -3.181092e-06 | AA2: -3.447213e-05 | AB2: 0.00060477518 | AC2: 8.0695803e-05 | AD2: -2.1041596e-05 | AE2: -0.0010394015
A3: Dag | B3: -0.19078019 | C3: 2.3175166e-05 | D3: 4.7529227e-05 | E3: -5.3688774e-07 | F3: -6.3756375e-05 | G3: -1.8335123e-05 | H3: -4.4894216e-06 | I3: 2.0696412e-05 | J3: 9.741027e-06 | K3: 4.1874037e-05 | L3: -2.5672002e-05 | M3: 4.9322966e-05 | N3: -0.00014429373 | O3: -5.3057214e-06 | P3: -1.062872e-05 | Q3: -2.2119598e-05 | R3: -1.4951665e-05 | S3: -4.7538571e-06 | T3: -9.1328201e-06 | U3: -1.4082897e-07 | V3: -4.7302661e-05 | W3: -2.2908348e-05 | X3: -4.3565318e-05 | Y3: -2.7705036e-06 | Z3: 3.0542131e-05 | AA3: 2.7402657e-05 | AB3: -0.00011854956 | AC3: -5.6588287e-05 | AD3: -1.1926406e-05 | AE3: -0.00077764392
A4: Dag_sq | B4: 0.0018246601 | C4: -2.6689305e-07 | D4: -5.3688774e-07 | E4: 6.2162467e-09 | F4: 6.0299421e-07 | G4: 1.9863198e-07 | H4: -8.2770841e-09 | I4: -2.4540956e-07 | J4: -2.7594523e-07 | K4: -4.3121747e-07 | L4: 2.9618256e-07 | M4: -5.402874e-07 | N4: 1.4789624e-06 | O4: 5.1755879e-08 | P4: 1.5985484e-07 | Q4: 2.6410559e-07 | R4: 1.6923798e-07 | S4: 5.1621891e-08 | T4: 1.0958933e-07 | U4: 5.5238431e-08 | V4: 6.5455103e-07 | W4: 2.1667575e-07 | X4: 4.9662054e-07 | Y4: 1.7684337e-08 | Z4: -3.0624105e-07 | AA4: -3.0427678e-07 | AB4: 1.2692888e-06 | AC4: 6.2122068e-07 | AD4: 2.0044262e-07 | AE4: 8.9158207e-06
A5: Dcpst_Partnered_L1 | B5: -0.18198378 | C5: -0.00017746121 | D5: -6.3756375e-05 | E5: 6.0299421e-07 | F5: 0.0011337537 | G5: 2.1035299e-05 | H5: -2.540604e-05 | I5: -2.120262e-05 | J5: -2.7311155e-05 | K5: 0.00020370341 | L5: -6.2699391e-05 | M5: -0.00018939004 | N5: -0.00055918112 | O5: -9.5692528e-05 | P5: -0.00023273965 | Q5: -0.00016411936 | R5: -8.931934e-05 | S5: -0.00016652864 | T5: -3.8179486e-05 | U5: -0.00015288142 | V5: -7.570803e-05 | W5: -0.00011940017 | X5: 6.2980886e-05 | Y5: 1.0338858e-05 | Z5: -9.3587457e-05 | AA5: -9.3260744e-05 | AB5: -0.0004777306 | AC5: 1.6859178e-05 | AD5: -4.8213672e-05 | AE5: 0.00099202977
A6: Deh_c4_High_L1 | B6: 0.055823343 | C6: 5.4401218e-05 | D6: -1.8335123e-05 | E6: 1.9863198e-07 | F6: 2.1035299e-05 | G6: 0.0010945876 | H6: 0.00025491289 | I6: 0.00027448521 | J6: 0.00024033438 | K6: 0.0001940827 | L6: 5.3892757e-05 | M6: -9.3206975e-05 | N6: -0.00038038726 | O6: 0.00012846783 | P6: 0.00010721422 | Q6: 0.00026736303 | R6: 0.00015994191 | S6: 0.00022463541 | T6: 0.0002747711 | U6: 4.3778085e-05 | V6: 8.4535537e-05 | W6: 7.698278e-05 | X6: 3.9915074e-05 | Y6: -1.2775814e-05 | Z6: 2.6876951e-05 | AA6: 0.00011622452 | AB6: -0.00062858422 | AC6: 3.5445339e-05 | AD6: -0.00017365634 | AE6: -0.00017770263
A7: Deh_c4_Low_L1 | B7: -0.36602602 | C7: 6.6734979e-06 | D7: -4.4894216e-06 | E7: -8.2770841e-09 | F7: -2.540604e-05 | G7: 0.00025491289 | H7: 0.0035953635 | I7: -3.4198981e-05 | J7: -0.00021685418 | K7: -0.00013419765 | L7: -5.6133657e-05 | M7: -0.00015521744 | N7: -0.00072717737 | O7: 7.8681841e-05 | P7: -0.00013281784 | Q7: -8.4112105e-05 | R7: -0.00026080453 | S7: -0.00026047685 | T7: -0.00025710662 | U7: -0.00012440849 | V7: -0.00027218715 | W7: -0.00018854192 | X7: -0.00045425033 | Y7: -1.6901313e-05 | Z7: 5.9548364e-05 | AA7: 8.6695687e-05 | AB7: -0.00047673182 | AC7: -0.00019079493 | AD7: -0.00022315795 | AE7: 0.00055211871
A8: Dehmf_c3_Medium_L1 | B8: -0.39908167 | C8: 2.8575236e-06 | D8: 2.0696412e-05 | E8: -2.4540956e-07 | F8: -2.120262e-05 | G8: 0.00027448521 | H8: -3.4198981e-05 | I8: 0.0015633205 | J8: 0.0012895188 | K8: 4.5370815e-05 | L8: -5.18608e-06 | M8: -3.526231e-05 | N8: -0.00011486938 | O8: -0.00011240448 | P8: -0.00027899867 | Q8: -0.00011028701 | R8: -7.9999559e-05 | S8: -2.8332405e-05 | T8: 6.3480944e-05 | U8: -6.8676296e-05 | V8: -0.00012979113 | W8: -9.4582469e-05 | X8: -0.00014660338 | Y8: 8.6582451e-06 | Z8: -5.0928508e-05 | AA8: -2.4038318e-05 | AB8: 5.4203153e-05 | AC8: -0.00013320398 | AD8: -5.5563291e-05 | AE8: -0.0017721255
A9: Dehmf_c3_Low_L1 | B9: -0.47489703 | C9: 0.00015589917 | D9: 9.741027e-06 | E9: -2.7594523e-07 | F9: -2.7311155e-05 | G9: 0.00024033438 | H9: -0.00021685418 | I9: 0.0012895188 | J9: 0.0022374723 | K9: -0.00021113784 | L9: 8.3380346e-05 | M9: 2.2193793e-05 | N9: 0.0012557577 | O9: 0.00012796321 | P9: -1.9055723e-05 | Q9: 0.0001548661 | R9: 0.00015512041 | S9: 0.00028008596 | T9: 0.00024378701 | U9: 0.00013680473 | V9: 2.6857981e-05 | W9: 0.00015585588 | X9: 5.6874211e-05 | Y9: 4.9444503e-05 | Z9: -0.00028657959 | AA9: -0.00025445388 | AB9: 0.00082473368 | AC9: 2.7070077e-05 | AD9: -8.0195716e-05 | AE9: -0.0024294699
A10: Les_c3_NotEmployed_L1 | B10: 0.24141222 | C10: -0.00012938632 | D10: 4.1874037e-05 | E10: -4.3121747e-07 | F10: 0.00020370341 | G10: 0.0001940827 | H10: -0.00013419765 | I10: 4.5370815e-05 | J10: -0.00021113784 | K10: 0.0010932429 | L10: -0.00018569623 | M10: 0.00017509427 | N10: -0.0013853486 | O10: -2.4636229e-05 | P10: -0.00021412349 | Q10: -0.00019625818 | R10: -3.8573013e-05 | S10: -0.00012272142 | T10: -5.5982439e-05 | U10: -6.5231845e-05 | V10: -0.00022718876 | W10: -0.00014514181 | X10: -0.00025574937 | Y10: -2.4725191e-05 | Z10: 0.00010414506 | AA10: 9.7715183e-05 | AB10: -0.001029501 | AC10: -0.00015136788 | AD10: -0.00011811816 | AE10: -0.0004565815
A11: Dnc_L1 | B11: 0.080152375 | C11: 6.7894424e-05 | D11: -2.5672002e-05 | E11: 2.9618256e-07 | F11: -6.2699391e-05 | G11: 5.3892757e-05 | H11: -5.6133657e-05 | I11: -5.18608e-06 | J11: 8.3380346e-05 | K11: -0.00018569623 | L11: 0.0002364916 | M11: -0.0003584411 | N11: 0.00074189326 | O11: 0.00010237027 | P11: 0.00012315012 | Q11: 0.00012782872 | R11: 0.00011626642 | S11: 0.00010113057 | T11: 0.00022375385 | U11: 9.1563356e-05 | V11: 0.0001742851 | W11: 9.7337681e-05 | X11: 0.00015728635 | Y11: 1.8778524e-05 | Z11: -9.4259593e-05 | AA11: -8.8125714e-05 | AB11: 0.00041075428 | AC11: 4.7552025e-05 | AD11: 1.1075221e-05 | AE11: -0.00010217552
A12: Dnc02_L1 | B12: -0.27954911 | C12: -1.7525661e-05 | D12: 4.9322966e-05 | E12: -5.402874e-07 | F12: -0.00018939004 | G12: -9.3206975e-05 | H12: -0.00015521744 | I12: -3.526231e-05 | J12: 2.2193793e-05 | K12: 0.00017509427 | L12: -0.0003584411 | M12: 0.002658783 | N12: -0.00085156914 | O12: -2.7789283e-05 | P12: 2.4395639e-06 | Q12: -4.1352445e-05 | R12: 0.00014697064 | S12: -6.7778128e-05 | T12: -0.00032560688 | U12: 0.00021178663 | V12: -0.0002309877 | W12: -2.6938116e-05 | X12: -0.00026882194 | Y12: 3.1029077e-06 | Z12: 0.00026424818 | AA12: 9.1686937e-06 | AB12: -0.00040099038 | AC12: -0.00017181973 | AD12: -0.00018829145 | AE12: -0.00080184921
A13: demRgnUKC | B13: 0.24261062 | C13: 0.00097832084 | D13: -0.00014429373 | E13: 1.4789624e-06 | F13: -0.00055918112 | G13: -0.00038038726 | H13: -0.00072717737 | I13: -0.00011486938 | J13: 0.0012557577 | K13: -0.0013853486 | L13: 0.00074189326 | M13: -0.00085156914 | N13: 0.013317531 | O13: 0.0025970732 | P13: 0.0027405143 | Q13: 0.0028973797 | R13: 0.0024472875 | S13: 0.002778596 | T13: 0.002752813 | U13: 0.0032310413 | V13: 0.0031822674 | W13: 0.0031435547 | X13: 0.0030151696 | Y13: 0.0002082265 | Z13: -0.0010256555 | AA13: -0.00093677407 | AB13: 0.007059871 | AC13: 0.0021731995 | AD13: 0.0010532428 | AE13: -0.0042570895
... A30: Constant | B30: 2.181349 | C30: -0.0010394015 | D30: -0.00077764392 | E30: 8.9158207e-06 | F30: 0.00099202977 | G30: -0.00017770263 | H30: 0.00055211871 | I30: -0.0017721255 | J30: -0.0024294699 | K30: -0.0004565815 | L30: -0.00010217552 | M30: -0.00080184921 | N30: -0.0042570895 | O30: -0.0024542278 | P30: -0.0024034063 | Q30: -0.0022222198 | R30: -0.0023932416 | S30: -0.0025746409 | T30: -0.0032075575 | U30: -0.0032389986 | V30: -0.0020397633 | W30: -0.0025822635 | X30: -0.0017869744 | Y30: -0.0003243599 | Z30: 0.00088784809 | AA30: 0.0012270839 | AB30: -0.0015413884 | AC30: -0.00074039847 | AD30: -0.0002718525 | AE30: 0.023599902

Sheet E2_orig_raw
A1: CATEGORY | B1: REGRESSOR | C1: COEFFICIENT
A2: Low | B2: 0b.Dgn | C2: 0
A3: Low | B3: 1.Dgn | C3: -0.70269446
A4: Low | B4: Dag | C4: 0.70218658
A5: Low | B5: Dag_sq | C5: -0.0091555151
A6: Low | B6: 0b.L_Dehmf_c3_Medium | C6: 0
A7: Low | B7: 1.L_Dehmf_c3_Medium | C7: -0.36235547
A8: Low | B8: 0b.L_Dehmf_c3_Low | C8: 0
A9: Low | B9: 1.L_Dehmf_c3_Low | C9: -1.1278756
A10: Low | B10: demRgnUKC | C10: -0.34052897
A11: Low | B11: demRgnUKD | C11: -0.20582816
A12: Low | B12: demRgnUKE | C12: 0.28530113
A13: Low | B13: demRgnUKF | C13: 0.072134082
... A53: Medium | B53: _cons | C53: -17.698016

Sheet E2_orig
A1: REGRESSOR | B1: COEFFICIENT | C1: Dgn_Low | D1: Dag_Low | E1: Dag_sq_Low | F1: L_Dehmf_c3_Medium_ | G1: L_Dehmf_c3_Low_ | H1: demRgnUKC_ | I1: demRgnUKD_ | J1: demRgnUKE_Low | K1: demRgnUKF_ | L1: demRgnUKG_ | M1: demRgnUKH_ | N1: demRgnUKJ_ | O1: demRgnUKK_ | P1: demRgnUKL_ | Q1: demRgnUKM_Low | R1: demRgnUKN_Low | S1: Year_transformed_Low | T1: Y2020_ | U1: Y2021_ | V1: demEthnC4Asian_ | W1: demEthnC4Black_ | X1: demEthnC4Other_ | Y1: Constant_Low | Z1: Dgn_Medium | AA1: Dag_Medium | AB1: Dag_sq_Medium | AC1: demRgnUKE_Medium | AD1: demRgnUKM_Medium | AE1: demRgnUKN_Medium | AF1: Year_transformed_Medium | AG1: Constant_Medium
A2: Dgn_Low | B2: -0.70269446 | C2: 0.032208402 | D2: 0.0027407987 | E2: -3.1163251e-05 | F2: 0.00049847787 | G2: 0.0027391043 | H2: 0.0031834866 | I2: 0.0049504868 | J2: -0.0014791834 | K2: 0.0017945406 | L2: 0.0023315151 | M2: 0.0016109725 | N2: -0.00011145027 | O2: 0.0033125688 | P2: 0.0017907142 | Q2: 0.00054557074 | R2: -0.0014972689 | S2: 0.00060184678 | T2: -0.003563557 | U2: 0.00098041816 | V2: -0.00045977166 | W2: 0.002548586 | X2: 0.003738625 | Y2: -0.072169176 | Z2: 0.001296066 | AA2: 0.00014108071 | AB2: -2.2392803e-06 | AC2: 0.0016214221 | AD2: 0.0020130624 | AE2: 0.001934327 | AF2: 2.4415076e-05 | AG2: -0.0054443406
A3: Dag_Low | B3: 0.70218658 | C3: 0.0027407987 | D3: 0.0087989686 | E3: -0.00011781984 | F3: 0.00036402863 | G3: 0.001934758 | H3: -0.00028778366 | I3: 0.0027231583 | J3: 0.0011639782 | K3: 0.00059761463 | L3: 0.00083061414 | M3: 0.00084027759 | N3: 0.00048447733 | O3: 0.00081410184 | P3: 0.00094892192 | Q3: 0.0017837677 | R3: -0.0030577937 | S3: -0.00011293612 | T3: -0.00041795843 | U3: -0.00034500397 | V3: -0.0013589635 | W3: -0.0016498625 | X3: -0.001405092 | Y3: -0.12293404 | Z3: 0.00030497437 | AA3: 0.00098439902 | AB3: -1.2080898e-05 | AC3: 9.3142613e-05 | AD3: 2.7485515e-05 | AE3: 5.4043521e-05 | AF3: 5.2830964e-05 | AG3: -0.016776752
A4: Dag_sq_Low | B4: -0.0091555151 | C4: -3.1163251e-05 | D4: -0.00011781984 | E4: 1.6207162e-06 | F4: -4.7931049e-06 | G4: -2.6042618e-05 | H4: 4.8303736e-06 | I4: -3.4483675e-05 | J4: -1.4655703e-05 | K4: -6.8697255e-06 | L4: -8.3008945e-06 | M4: -9.7908584e-06 | N4: -5.7120083e-06 | O4: -1.0545461e-05 | P4: -1.4084719e-05 | Q4: -2.99085e-05 | R4: 4.1880505e-05 | S4: 1.3630681e-06 | T4: 2.9598751e-06 | U4: 7.7349166e-06 | V4: 2.0662264e-05 | W4: 2.0133772e-05 | X4: 1.8507136e-05 | Y4: 0.0016276532 | Z4: -3.8907545e-06 | AA4: -1.2660665e-05 | AB4: 1.6013524e-07 | AC4: -1.4683672e-06 | AD4: -2.7693475e-07 | AE4: -1.9349686e-07 | AF4: -7.349547e-07 | AG4: 0.00021417812
A5: L_Dehmf_c3_Medium_ | B5: -0.36235547 | C5: 0.00049847787 | D5: 0.00036402863 | E5: -4.7931049e-06 | F5: 0.010296423 | G5: 0.0081790533 | H5: -0.0016163781 | I5: -0.0015508914 | J5: -0.0011240083 | K5: -0.0014831153 | L5: -0.0018475611 | M5: -0.0013938392 | N5: -0.0024696333 | O5: -0.0017372613 | P5: -0.0017463059 | Q5: -0.00034934466 | R5: -0.0017154973 | S5: -0.00014315468 | T5: 0.00088219716 | U5: 0.00086466649 | V5: -4.4321659e-06 | W5: 0.00057092532 | X5: 0.0013621918 | Y5: -0.010245656 | Z5: 0.00020840633 | AA5: 0.00016125756 | AB5: -2.1310125e-06 | AC5: -0.0026049744 | AD5: -0.0010513496 | AE5: -0.0022312665 | AF5: 0.00011258852 | AG5: -0.0108331
A6: L_Dehmf_c3_Low_ | B6: -1.1278756 | C6: 0.0027391043 | D6: 0.001934758 | E6: -2.6042618e-05 | F6: 0.0081790533 | G6: 0.020066297 | H6: -0.0045136254 | I6: -0.0015312245 | J6: -0.0039665073 | K6: -0.0044304324 | L6: -0.0034544642 | M6: -0.0030880821 | N6: -0.004678421 | O6: -0.0032732261 | P6: -0.0023100352 | Q6: -0.0043231812 | R6: -0.0055637218 | S6: 0.00024531557 | T6: 0.0014314192 | U6: -8.8314197e-06 | V6: -0.0039281473 | W6: -0.0031815206 | X6: 0.0018775372 | Y6: -0.039504382 | Z6: 0.00058251317 | AA6: 7.4526145e-05 | AB6: -3.8387189e-06 | AC6: -0.0033271849 | AD6: -0.0031326169 | AE6: -0.0050464726 | AF6: 0.00017632231 | AG6: -0.0077013363
A7: demRgnUKC_ | B7: -0.34052897 | C7: 0.0031834866 | D7: -0.00028778366 | E7: 4.8303736e-06 | F7: -0.0016163781 | G7: -0.0045136254 | H7: 0.05762622 | I7: 0.022777251 | J7: 0.025194997 | K7: 0.023695861 | L7: 0.022336606 | M7: 0.02301091 | N7: 0.023080638 | O7: 0.023579558 | P7: 0.024069597 | Q7: 0.025488072 | R7: 0.026061252 | S7: -0.00031298881 | T7: -0.0029879194 | U7: -0.00086396309 | V7: 0.0087728127 | W7: 0.021999388 | X7: 0.0039831605 | Y7: -0.01633431 | Z7: 0.00086137508 | AA7: -0.00012833762 | AB7: 1.4208577e-06 | AC7: 0.021912015 | AD7: 0.024904118 | AE7: 0.024085959 | AF7: -0.0001371626 | AG7: -0.01767997
A8: demRgnUKD_ | B8: -0.20582816 | C8: 0.0049504868 | D8: 0.0027231583 | E8: -3.4483675e-05 | F8: -0.0015508914 | G8: -0.0015312245 | H8: 0.022777251 | I8: 0.036824146 | J8: 0.023208273 | K8: 0.022715995 | L8: 0.021764728 | M8: 0.022330298 | N8: 0.022146718 | O8: 0.022717851 | P8: 0.023128881 | Q8: 0.023344229 | R8: 0.022989978 | S8: 0.00019607036 | T8: -0.0043314904 | U8: 0.00039483487 | V8: 0.006177927 | W8: 0.019321753 | X8: 0.002683922 | Y8: -0.067088192 | Z8: 0.0005910539 | AA8: 6.1357701e-05 | AB8: -6.878877e-07 | AC8: 0.021326068 | AD8: 0.023931387 | AE8: 0.023012756 | AF8: -5.8930449e-05 | AG8: -0.021496533
A9: demRgnUKE_Low | B9: 0.28530113 | C9: -0.0014791834 | D9: 0.0011639782 | E9: -1.4655703e-05 | F9: -0.0011240083 | G9: -0.0039665073 | H9: 0.025194997 | I9: 0.023208273 | J9: 0.11288195 | K9: 0.024452728 | L9: 0.022707759 | M9: 0.02371768 | N9: 0.022967923 | O9: 0.024123851 | P9: 0.025332996 | Q9: 0.031860995 | R9: 0.031869452 | S9: -0.00067834954 | T9: -0.0044360405 | U9: 0.0042688123 | V9: 0.0074658635 | W9: 0.022513335 | X9: 0.0043090414 | Y9: -0.034252744 | Z9: 0.00022630764 | AA9: -3.2695561e-05 | AB9: 2.1261223e-07 | AC9: 0.023207632 | AD9: 0.023737886 | AE9: 0.022821583 | AF9: -0.00012295187 | AG9: -0.018593068
A10: demRgnUKF_ | B10: 0.072134082 | C10: 0.0017945406 | D10: 0.00059761463 | E10: -6.8697255e-06 | F10: -0.0014831153 | G10: -0.0044304324 | H10: 0.023695861 | I10: 0.022715995 | J10: 0.024452728 | K10: 0.038756142 | L10: 0.022333698 | M10: 0.022867729 | N10: 0.023104488 | O10: 0.023313745 | P10: 0.023755402 | Q10: 0.024601818 | R10: 0.024840267 | S10: -0.00022897899 | T10: -0.0039607475 | U10: 0.00040307101 | V10: 0.0077529441 | W10: 0.023109516 | X10: 0.0025840761 | Y10: -0.028406996 | Z10: -3.595644e-05 | AA10: 0.00015771143 | AB10: -1.4978714e-06 | AC10: 0.02167929 | AD10: 0.024197919 | AE10: 0.02368697 | AF10: -4.7570896e-05 | AG10: -0.02332394
A11: demRgnUKG_ | B11: 0.001640279 | C11: 0.0023315151 | D11: 0.00083061414 | E11: -8.3008945e-06 | F11: -0.0018475611 | G11: -0.0034544642 | H11: 0.022336606 | I11: 0.021764728 | J11: 0.022707759 | K11: 0.022333698 | L11: 0.038298126 | M11: 0.02189336 | N11: 0.021654094 | O11: 0.021973385 | P11: 0.022436808 | Q11: 0.022720304 | R11: 0.022776463 | S11: -8.8318991e-05 | T11: -0.003354449 | U11: 0.0038418635 | V11: 0.006420884 | W11: 0.018467932 | X11: -0.00055090897 | Y11: -0.03347005 | Z11: 0.00046634552 | AA11: -0.00016847281 | AB11: 3.7202298e-06 | AC11: 0.02097729 | AD11: 0.023070293 | AE11: 0.022458352 | AF11: -0.0001808093 | AG11: -0.015789504
A12: demRgnUKH_ | B12: 0.093481552 | C12: 0.0016109725 | D12: 0.00084027759 | E12: -9.7908584e-06 | F12: -0.0013938392 | G12: -0.0030880821 | H12: 0.02301091 | I12: 0.022330298 | J12: 0.02371768 | K12: 0.022867729 | L12: 0.02189336 | M12: 0.036416305 | N12: 0.022368294 | O12: 0.02269041 | P12: 0.023007121 | Q12: 0.023957868 | R12: 0.02379708 | S12: -0.00028040045 | T12: -0.003876703 | U12: 0.00085777956 | V12: 0.0071956577 | W12: 0.019492462 | X12: 0.0027638342 | Y12: -0.030609449 | Z12: 0.00066770002 | AA12: 0.00017645288 | AB12: -1.6243863e-06 | AC12: 0.021202458 | AD12: 0.023824463 | AE12: 0.022966314 | AF12: -0.00017285322 | AG12: -0.021493979
A13: demRgnUKJ_ | B13: 0.12025769 | C13: -0.00011145027 | D13: 0.00048447733 | E13: -5.7120083e-06 | F13: -0.0024696333 | G13: -0.004678421 | H13: 0.023080638 | I13: 0.022146718 | J13: 0.022967923 | K13: 0.023104488 | L13: 0.021654094 | M13: 0.022368294 | N13: 0.033999514 | O13: 0.022583578 | P13: 0.023379427 | Q13: 0.022892002 | R13: 0.023393739 | S13: 0.00019299754 | T13: -0.0038263641 | U13: -0.00068981191 | V13: 0.0071235481 | W13: 0.020240134 | X13: 0.0029008475 | Y13: -0.030577228 | Z13: -0.00032334538 | AA13: 0.00033688293 | AB13: -3.7219806e-06 | AC13: 0.021665135 | AD13: 0.024138334 | AE13: 0.023485665 | AF13: 1.1811042e-05 | AG13: -0.026055819
... A32: Constant_Medium | B32: -17.698016 | C32: -0.0054443406 | D32: -0.016776752 | E32: 0.00021417812 | F32: -0.0108331 | G32: -0.0077013363 | H32: -0.01767997 | I32: -0.021496533 | J32: -0.018593068 | K32: -0.02332394 | L32: -0.015789504 | M32: -0.021493979 | N32: -0.026055819 | O32: -0.02006196 | P32: -0.019456957 | Q32: -0.020370274 | R32: -0.010469143 | S32: -0.00092428775 | T32: 0.016703699 | U32: 0.011347514 | V32: 0.010212227 | W32: -0.016032295 | X32: 0.0046087979 | Y32: 0.28036207 | Z32: -0.003279382 | AA32: -0.045480008 | AB32: 0.00066897823 | AC32: -0.0050459804 | AD32: -0.013287455 | AE32: 0.00062016455 | AF32: -0.0041016079 | AG32: 0.74179492

Sheet E1a
A1: REGRESSOR | B1: COEFFICIENT | C1: demMaleFlag | D1: demAge | E1: demAgeSq | F1: eduSampleFlagL1 | G1: eduHighestParentC3MediumL1 | H1: eduHighestParentC3LowL1 | I1: yHhQuintilesMonthC5Q2L1 | J1: yHhQuintilesMonthC5Q3L1 | K1: yHhQuintilesMonthC5Q4L1 | L1: yHhQuintilesMonthC5Q5L1 | M1: demRgnUKC | N1: demRgnUKD | O1: demRgnUKE | P1: demRgnUKF | Q1: demRgnUKG | R1: demRgnUKH | S1: demRgnUKJ | T1: demRgnUKK | U1: demRgnUKL | V1: demRgnUKM | W1: demRgnUKN | X1: demYearTransformed | Y1: demYear2020 | Z1: demYear2021 | AA1: demEthnC4Asian | AB1: demEthnC4Black | AC1: demEthnC4Other | AD1: Constant
A2: demMaleFlag | B2: -0.013450267 | C2: 0.00074882146 | D2: 0.00019883175 | E2: -6.0808293e-06 | F2: -2.2630387e-05 | G2: 0.00024630811 | H2: 0.00011751242 | I2: 0.00011307216 | J2: -0.000242621 | K2: -0.0001438881 | L2: -0.00011667989 | M2: 6.9992458e-05 | N2: 4.1800449e-05 | O2: 3.2535279e-05 | P2: 2.4765096e-05 | Q2: 0.00028722299 | R2: -1.1172609e-07 | S2: 1.1985222e-05 | T2: 3.5983686e-05 | U2: 4.10198e-05 | V2: 0.0001207553 | W2: 7.0332476e-05 | X2: 1.0523831e-05 | Y2: -1.717899e-05 | Z2: -1.689262e-05 | AA2: -4.8694361e-05 | AB2: 7.4015816e-05 | AC2: 0.00045068847 | AD2: -0.0022265494
A3: demAge | B3: -1.1878096 | C3: 0.00019883175 | D3: 0.0082922525 | E3: -0.0002049072 | F3: -0.00026702461 | G3: 0.0010041546 | H3: 0.0012185705 | I3: 0.00054071932 | J3: -0.00033497006 | K3: 0.0014508696 | L3: 0.001154746 | M3: -0.00015670448 | N3: -0.00055626667 | O3: -0.00066402617 | P3: -0.00078639849 | Q3: -0.0034195254 | R3: -0.0004180416 | S3: -0.00057259356 | T3: -0.00052946466 | U3: -0.00074130278 | V3: -0.00024903477 | W3: -0.000901616 | X3: -0.00011664901 | Y3: 0.00062169815 | Z3: 0.00083396681 | AA3: 0.00021932123 | AB3: 0.0001312797 | AC3: -0.0048710971 | AD3: -0.080709594
A4: demAgeSq | B4: 0.024709215 | C4: -6.0808293e-06 | D4: -0.0002049072 | E4: 5.1054099e-06 | F4: 8.7764806e-06 | G4: -2.666249e-05 | H4: -3.006456e-05 | I4: -1.3033552e-05 | J4: 1.5253603e-05 | K4: -3.0183287e-05 | L4: -2.304993e-05 | M4: 5.4307616e-06 | N4: 1.4578308e-05 | O4: 1.7576396e-05 | P4: 2.0445695e-05 | Q4: 8.5051663e-05 | R4: 1.1121726e-05 | S4: 1.4781329e-05 | T4: 1.3831264e-05 | U4: 1.9043532e-05 | V4: 6.4012249e-06 | W4: 2.2677045e-05 | X4: 2.9146758e-06 | Y4: -1.5684507e-05 | Z4: -2.0873506e-05 | AA4: -4.5863203e-06 | AB4: -3.9738079e-06 | AC4: 0.0001200066 | AD4: 0.0019747702
A5: eduSampleFlagL1 | B5: 0.32099296 | C5: -2.2630387e-05 | D5: -0.00026702461 | E5: 8.7764806e-06 | F5: 0.0013921945 | G5: 6.3599899e-05 | H5: 6.6234767e-05 | I5: 4.0477603e-05 | J5: 2.7179607e-05 | K5: -7.305831e-07 | L5: 8.8113933e-06 | M5: 0.00029379412 | N5: 0.00013894614 | O5: 0.00013778609 | P5: 0.00015538067 | Q5: 0.00037287006 | R5: 0.00023347656 | S5: 0.00016039698 | T5: 0.00017332178 | U5: 0.00018591295 | V5: 0.00023194974 | W5: 0.0001303637 | X5: 3.3849538e-05 | Y5: -7.1747631e-05 | Z5: -9.5194835e-05 | AA5: 1.8124217e-05 | AB5: 4.0182337e-05 | AC5: 0.00038860827 | AD5: -7.9773937e-05
A6: eduHighestParentC3MediumL1 | B6: -0.26246413 | C6: 0.00024630811 | D6: 0.0010041546 | E6: -2.666249e-05 | F6: 6.3599899e-05 | G6: 0.0015306513 | H6: 0.0012020306 | I6: 0.00026405406 | J6: -0.00065119706 | K6: -0.00016448699 | L6: 1.8250705e-05 | M6: -2.8684822e-06 | N6: -0.00011590208 | O6: -0.00017615971 | P6: -0.000184063 | Q6: -0.00027700733 | R6: -0.00017546188 | S6: -0.00010558532 | T6: -6.4714558e-05 | U6: -0.00019940525 | V6: 2.5335739e-05 | W6: -0.00014476789 | X6: 7.6651063e-06 | Y6: 3.4480918e-05 | Z6: 8.1103168e-05 | AA6: -3.9984435e-05 | AB6: 0.00014124012 | AC6: -0.00010772719 | AD6: -0.010545754
A7: eduHighestParentC3LowL1 | B7: -0.42167057 | C7: 0.00011751242 | D7: 0.0012185705 | E7: -3.006456e-05 | F7: 6.6234767e-05 | G7: 0.0012020306 | H7: 0.0021998988 | I7: 0.00026464785 | J7: -0.00034352965 | K7: 0.00013060514 | L7: 0.00039836436 | M7: 5.4305503e-05 | N7: -6.3730794e-05 | O7: -0.00024545867 | P7: -0.00025154895 | Q7: -0.00061366537 | R7: -0.00022947175 | S7: -0.00011203363 | T7: -7.5165106e-05 | U7: -0.00028497768 | V7: -3.5515303e-06 | W7: -0.00034335488 | X7: 9.5205732e-06 | Y7: 7.4593468e-05 | Z7: 0.00011560222 | AA7: -0.00017922663 | AB7: 4.1752556e-05 | AC7: -0.00072096376 | AD7: -0.013393322
A8: yHhQuintilesMonthC5Q2L1 | B8: -0.076391105 | C8: 0.00011307216 | D8: 0.00054071932 | E8: -1.3033552e-05 | F8: 4.0477603e-05 | G8: 0.00026405406 | H8: 0.00026464785 | I8: 0.0016683442 | J8: 0.00032763873 | K8: 0.00053601793 | L8: 0.00056365944 | M8: 0.00047965979 | N8: 9.5451116e-05 | O8: -6.9903623e-06 | P8: 5.0935569e-05 | Q8: 0.0003100178 | R8: -3.4685519e-06 | S8: 8.6846805e-05 | T8: 1.6521936e-05 | U8: 7.8963806e-05 | V8: 0.0001250509 | W8: 0.00011190051 | X8: 3.0927037e-05 | Y8: -0.00011683992 | Z8: -0.00012083359 | AA8: 0.00019209077 | AB8: 0.00011836882 | AC8: 0.00054508384 | AD8: -0.0068764092
A9: yHhQuintilesMonthC5Q3L1 | B9: -0.39833595 | C9: -0.000242621 | D9: -0.00033497006 | E9: 1.5253603e-05 | F9: 2.7179607e-05 | G9: -0.00065119706 | H9: -0.00034352965 | I9: 0.00032763873 | J9: 0.003052476 | K9: 0.001348994 | L9: 0.0012915913 | M9: 0.00021664607 | N9: 0.00017401514 | O9: 0.00025261419 | P9: 0.00021329696 | Q9: 0.00054051809 | R9: 0.00012314392 | S9: 0.00017756323 | T9: 0.00012946508 | U9: 0.00016219014 | V9: 8.5529317e-05 | W9: 0.00022375137 | X9: 2.3310338e-05 | Y9: -0.00012998299 | Z9: -9.8802579e-05 | AA9: 0.0002204358 | AB9: 7.1117011e-05 | AC9: 0.00077676453 | AD9: -0.00018225812
A10: yHhQuintilesMonthC5Q4L1 | B10: -0.34339504 | C10: -0.0001438881 | D10: 0.0014508696 | E10: -3.0183287e-05 | F10: -7.305831e-07 | G10: -0.00016448699 | H10: 0.00013060514 | I10: 0.00053601793 | J10: 0.001348994 | K10: 0.0026092095 | L10: 0.0013719017 | M10: 0.00012528863 | N10: -6.444739e-05 | O10: 2.1924802e-05 | P10: -0.0001134462 | Q10: -0.00057417155 | R10: -7.4974141e-06 | S10: -7.3720507e-05 | T10: -0.00019708814 | U10: -8.3924011e-05 | V10: -9.3580767e-05 | W10: -8.1171891e-05 | X10: -3.4886106e-06 | Y10: -2.5904905e-05 | Z10: -1.1188519e-05 | AA10: 0.00028762538 | AB10: 5.3221582e-05 | AC10: -0.00080661435 | AD10: -0.017054687
A11: yHhQuintilesMonthC5Q5L1 | B11: -0.41007982 | C11: -0.00011667989 | D11: 0.001154746 | E11: -2.304993e-05 | F11: 8.8113933e-06 | G11: 1.8250705e-05 | H11: 0.00039836436 | I11: 0.00056365944 | J11: 0.0012915913 | K11: 0.0013719017 | L11: 0.0023836088 | M11: 0.00030028063 | N11: 4.3439035e-05 | O11: 8.798877e-05 | P11: 7.3254201e-05 | Q11: -0.00032040202 | R11: -6.9031308e-05 | S11: -6.0481051e-06 | T11: 9.5202112e-06 | U11: 7.0117057e-05 | V11: 7.1359879e-06 | W11: 7.2547013e-05 | X11: -8.0013062e-06 | Y11: 5.0252998e-05 | Z11: 8.3623727e-05 | AA11: 0.00035553503 | AB11: 0.00021007066 | AC11: -0.00058573292 | AD11: -0.014262865
A12: demRgnUKC | B12: 0.070957692 | C12: 6.9992458e-05 | D12: -0.00015670448 | E12: 5.4307616e-06 | F12: 0.00029379412 | G12: -2.8684822e-06 | H12: 5.4305503e-05 | I12: 0.00047965979 | J12: 0.00021664607 | K12: 0.00012528863 | L12: 0.00030028063 | M12: 0.0072150569 | N12: 0.0021434567 | O12: 0.0021620851 | P12: 0.0021925159 | Q12: 0.002579383 | R12: 0.002176234 | S12: 0.002212925 | T12: 0.0022881413 | U12: 0.0023403682 | V12: 0.0022898312 | W12: 0.0023585834 | X12: 4.7241228e-05 | Y12: -0.00020086988 | Z12: -0.00037647882 | AA12: 0.0014516339 | AB12: 0.001526632 | AC12: 0.0016027372 | AD12: -0.0026312125
A13: demRgnUKD | B13: 0.022964925 | C13: 4.1800449e-05 | D13: -0.00055626667 | E13: 1.4578308e-05 | F13: 0.00013894614 | G13: -0.00011590208 | H13: -6.3730794e-05 | I13: 9.5451116e-05 | J13: 0.00017401514 | K13: -6.444739e-05 | L13: 4.3439035e-05 | M13: 0.0021434567 | N13: 0.0036742389 | O13: 0.0020721951 | P13: 0.0020731299 | Q13: 0.0025268261 | R13: 0.0020403371 | S13: 0.0020766636 | T13: 0.0021265357 | U13: 0.0021637011 | V13: 0.0021111611 | W13: 0.0021819385 | X13: 2.6687707e-05 | Y13: -0.00020297102 | Z13: -0.00028830312 | AA13: 0.00052664656 | AB13: 0.001352202 | AC13: 0.0016190327 | AD13: 0.0024985012
... A29: Constant | B29: 14.504608 | C29: -0.0022265494 | D29: -0.080709594 | E29: 0.0019747702 | F29: -7.9773937e-05 | G29: -0.010545754 | H29: -0.013393322 | I29: -0.0068764092 | J29: -0.00018225812 | K29: -0.017054687 | L29: -0.014262865 | M29: -0.0026312125 | N29: 0.0024985012 | O29: 0.003675627 | P29: 0.0048357356 | Q29: 0.028458489 | R29: 0.0012599836 | S29: 0.0028317451 | T29: 0.0022505341 | U29: 0.0041912773 | V29: -0.0006950537 | W29: 0.0060548255 | X29: 0.00069194656 | Y29: -0.0041486304 | Z29: -0.0058327486 | AA29: -0.0035780365 | AB29: -0.0031188073 | AC29: 0.042469196 | AD29: 0.80761444

Sheet E1b
A1: REGRESSOR | B1: COEFFICIENT | C1: demMaleFlag | D1: demAge | E1: demAgeSq | F1: demPartnerStatusPartneredL1 | G1: eduHighestC4HighL1 | H1: eduHighestC4LowL1 | I1: eduHighestParentC3MediumL1 | J1: eduHighestParentC3LowL1 | K1: labStatusC3NotEmployedL1 | L1: demNChildL1 | M1: demNChild0to2L1 | N1: demRgnUKC | O1: demRgnUKD | P1: demRgnUKE | Q1: demRgnUKF | R1: demRgnUKG | S1: demRgnUKH | T1: demRgnUKJ | U1: demRgnUKK | V1: demRgnUKL | W1: demRgnUKM | X1: demRgnUKN | Y1: demYearTransformed | Z1: demYear2020 | AA1: demYear2021 | AB1: demEthnC4Asian | AC1: demEthnC4Black | AD1: demEthnC4Other | AE1: Constant
A2: demMaleFlag | B2: -0.18352329 | C2: 0.00082011818 | D2: 2.3175166e-05 | E2: -2.6689305e-07 | F2: -0.00017746121 | G2: 5.4401218e-05 | H2: 6.6734979e-06 | I2: 2.8575236e-06 | J2: 0.00015589917 | K2: -0.00012938632 | L2: 6.7894424e-05 | M2: -1.7525661e-05 | N2: 0.00097832084 | O2: 1.2166858e-05 | P2: 6.7025936e-05 | Q2: 3.7766338e-05 | R2: 9.3798558e-05 | S2: 0.00011995179 | T2: 1.8514358e-05 | U2: 3.8628074e-05 | V2: 5.1904106e-05 | W2: 0.00012448006 | X2: -1.2836201e-06 | Y2: 1.2632099e-05 | Z2: -3.181092e-06 | AA2: -3.447213e-05 | AB2: 0.00060477518 | AC2: 8.0695803e-05 | AD2: -2.1041596e-05 | AE2: -0.0010394015
A3: demAge | B3: -0.19078019 | C3: 2.3175166e-05 | D3: 4.7529227e-05 | E3: -5.3688774e-07 | F3: -6.3756375e-05 | G3: -1.8335123e-05 | H3: -4.4894216e-06 | I3: 2.0696412e-05 | J3: 9.741027e-06 | K3: 4.1874037e-05 | L3: -2.5672002e-05 | M3: 4.9322966e-05 | N3: -0.00014429373 | O3: -5.3057214e-06 | P3: -1.062872e-05 | Q3: -2.2119598e-05 | R3: -1.4951665e-05 | S3: -4.7538571e-06 | T3: -9.1328201e-06 | U3: -1.4082897e-07 | V3: -4.7302661e-05 | W3: -2.2908348e-05 | X3: -4.3565318e-05 | Y3: -2.7705036e-06 | Z3: 3.0542131e-05 | AA3: 2.7402657e-05 | AB3: -0.00011854956 | AC3: -5.6588287e-05 | AD3: -1.1926406e-05 | AE3: -0.00077764392
A4: demAgeSq | B4: 0.0018246601 | C4: -2.6689305e-07 | D4: -5.3688774e-07 | E4: 6.2162467e-09 | F4: 6.0299421e-07 | G4: 1.9863198e-07 | H4: -8.2770841e-09 | I4: -2.4540956e-07 | J4: -2.7594523e-07 | K4: -4.3121747e-07 | L4: 2.9618256e-07 | M4: -5.402874e-07 | N4: 1.4789624e-06 | O4: 5.1755879e-08 | P4: 1.5985484e-07 | Q4: 2.6410559e-07 | R4: 1.6923798e-07 | S4: 5.1621891e-08 | T4: 1.0958933e-07 | U4: 5.5238431e-08 | V4: 6.5455103e-07 | W4: 2.1667575e-07 | X4: 4.9662054e-07 | Y4: 1.7684337e-08 | Z4: -3.0624105e-07 | AA4: -3.0427678e-07 | AB4: 1.2692888e-06 | AC4: 6.2122068e-07 | AD4: 2.0044262e-07 | AE4: 8.9158207e-06
A5: demPartnerStatusPartneredL1 | B5: -0.18198378 | C5: -0.00017746121 | D5: -6.3756375e-05 | E5: 6.0299421e-07 | F5: 0.0011337537 | G5: 2.1035299e-05 | H5: -2.540604e-05 | I5: -2.120262e-05 | J5: -2.7311155e-05 | K5: 0.00020370341 | L5: -6.2699391e-05 | M5: -0.00018939004 | N5: -0.00055918112 | O5: -9.5692528e-05 | P5: -0.00023273965 | Q5: -0.00016411936 | R5: -8.931934e-05 | S5: -0.00016652864 | T5: -3.8179486e-05 | U5: -0.00015288142 | V5: -7.570803e-05 | W5: -0.00011940017 | X5: 6.2980886e-05 | Y5: 1.0338858e-05 | Z5: -9.3587457e-05 | AA5: -9.3260744e-05 | AB5: -0.0004777306 | AC5: 1.6859178e-05 | AD5: -4.8213672e-05 | AE5: 0.00099202977
A6: eduHighestC4HighL1 | B6: 0.055823343 | C6: 5.4401218e-05 | D6: -1.8335123e-05 | E6: 1.9863198e-07 | F6: 2.1035299e-05 | G6: 0.0010945876 | H6: 0.00025491289 | I6: 0.00027448521 | J6: 0.00024033438 | K6: 0.0001940827 | L6: 5.3892757e-05 | M6: -9.3206975e-05 | N6: -0.00038038726 | O6: 0.00012846783 | P6: 0.00010721422 | Q6: 0.00026736303 | R6: 0.00015994191 | S6: 0.00022463541 | T6: 0.0002747711 | U6: 4.3778085e-05 | V6: 8.4535537e-05 | W6: 7.698278e-05 | X6: 3.9915074e-05 | Y6: -1.2775814e-05 | Z6: 2.6876951e-05 | AA6: 0.00011622452 | AB6: -0.00062858422 | AC6: 3.5445339e-05 | AD6: -0.00017365634 | AE6: -0.00017770263
A7: eduHighestC4LowL1 | B7: -0.36602602 | C7: 6.6734979e-06 | D7: -4.4894216e-06 | E7: -8.2770841e-09 | F7: -2.540604e-05 | G7: 0.00025491289 | H7: 0.0035953635 | I7: -3.4198981e-05 | J7: -0.00021685418 | K7: -0.00013419765 | L7: -5.6133657e-05 | M7: -0.00015521744 | N7: -0.00072717737 | O7: 7.8681841e-05 | P7: -0.00013281784 | Q7: -8.4112105e-05 | R7: -0.00026080453 | S7: -0.00026047685 | T7: -0.00025710662 | U7: -0.00012440849 | V7: -0.00027218715 | W7: -0.00018854192 | X7: -0.00045425033 | Y7: -1.6901313e-05 | Z7: 5.9548364e-05 | AA7: 8.6695687e-05 | AB7: -0.00047673182 | AC7: -0.00019079493 | AD7: -0.00022315795 | AE7: 0.00055211871
A8: eduHighestParentC3MediumL1 | B8: -0.39908167 | C8: 2.8575236e-06 | D8: 2.0696412e-05 | E8: -2.4540956e-07 | F8: -2.120262e-05 | G8: 0.00027448521 | H8: -3.4198981e-05 | I8: 0.0015633205 | J8: 0.0012895188 | K8: 4.5370815e-05 | L8: -5.18608e-06 | M8: -3.526231e-05 | N8: -0.00011486938 | O8: -0.00011240448 | P8: -0.00027899867 | Q8: -0.00011028701 | R8: -7.9999559e-05 | S8: -2.8332405e-05 | T8: 6.3480944e-05 | U8: -6.8676296e-05 | V8: -0.00012979113 | W8: -9.4582469e-05 | X8: -0.00014660338 | Y8: 8.6582451e-06 | Z8: -5.0928508e-05 | AA8: -2.4038318e-05 | AB8: 5.4203153e-05 | AC8: -0.00013320398 | AD8: -5.5563291e-05 | AE8: -0.0017721255
A9: eduHighestParentC3LowL1 | B9: -0.47489703 | C9: 0.00015589917 | D9: 9.741027e-06 | E9: -2.7594523e-07 | F9: -2.7311155e-05 | G9: 0.00024033438 | H9: -0.00021685418 | I9: 0.0012895188 | J9: 0.0022374723 | K9: -0.00021113784 | L9: 8.3380346e-05 | M9: 2.2193793e-05 | N9: 0.0012557577 | O9: 0.00012796321 | P9: -1.9055723e-05 | Q9: 0.0001548661 | R9: 0.00015512041 | S9: 0.00028008596 | T9: 0.00024378701 | U9: 0.00013680473 | V9: 2.6857981e-05 | W9: 0.00015585588 | X9: 5.6874211e-05 | Y9: 4.9444503e-05 | Z9: -0.00028657959 | AA9: -0.00025445388 | AB9: 0.00082473368 | AC9: 2.7070077e-05 | AD9: -8.0195716e-05 | AE9: -0.0024294699
A10: labStatusC3NotEmployedL1 | B10: 0.24141222 | C10: -0.00012938632 | D10: 4.1874037e-05 | E10: -4.3121747e-07 | F10: 0.00020370341 | G10: 0.0001940827 | H10: -0.00013419765 | I10: 4.5370815e-05 | J10: -0.00021113784 | K10: 0.0010932429 | L10: -0.00018569623 | M10: 0.00017509427 | N10: -0.0013853486 | O10: -2.4636229e-05 | P10: -0.00021412349 | Q10: -0.00019625818 | R10: -3.8573013e-05 | S10: -0.00012272142 | T10: -5.5982439e-05 | U10: -6.5231845e-05 | V10: -0.00022718876 | W10: -0.00014514181 | X10: -0.00025574937 | Y10: -2.4725191e-05 | Z10: 0.00010414506 | AA10: 9.7715183e-05 | AB10: -0.001029501 | AC10: -0.00015136788 | AD10: -0.00011811816 | AE10: -0.0004565815
A11: demNChildL1 | B11: 0.080152375 | C11: 6.7894424e-05 | D11: -2.5672002e-05 | E11: 2.9618256e-07 | F11: -6.2699391e-05 | G11: 5.3892757e-05 | H11: -5.6133657e-05 | I11: -5.18608e-06 | J11: 8.3380346e-05 | K11: -0.00018569623 | L11: 0.0002364916 | M11: -0.0003584411 | N11: 0.00074189326 | O11: 0.00010237027 | P11: 0.00012315012 | Q11: 0.00012782872 | R11: 0.00011626642 | S11: 0.00010113057 | T11: 0.00022375385 | U11: 9.1563356e-05 | V11: 0.0001742851 | W11: 9.7337681e-05 | X11: 0.00015728635 | Y11: 1.8778524e-05 | Z11: -9.4259593e-05 | AA11: -8.8125714e-05 | AB11: 0.00041075428 | AC11: 4.7552025e-05 | AD11: 1.1075221e-05 | AE11: -0.00010217552
A12: demNChild0to2L1 | B12: -0.27954911 | C12: -1.7525661e-05 | D12: 4.9322966e-05 | E12: -5.402874e-07 | F12: -0.00018939004 | G12: -9.3206975e-05 | H12: -0.00015521744 | I12: -3.526231e-05 | J12: 2.2193793e-05 | K12: 0.00017509427 | L12: -0.0003584411 | M12: 0.002658783 | N12: -0.00085156914 | O12: -2.7789283e-05 | P12: 2.4395639e-06 | Q12: -4.1352445e-05 | R12: 0.00014697064 | S12: -6.7778128e-05 | T12: -0.00032560688 | U12: 0.00021178663 | V12: -0.0002309877 | W12: -2.6938116e-05 | X12: -0.00026882194 | Y12: 3.1029077e-06 | Z12: 0.00026424818 | AA12: 9.1686937e-06 | AB12: -0.00040099038 | AC12: -0.00017181973 | AD12: -0.00018829145 | AE12: -0.00080184921
A13: demRgnUKC | B13: 0.24261062 | C13: 0.00097832084 | D13: -0.00014429373 | E13: 1.4789624e-06 | F13: -0.00055918112 | G13: -0.00038038726 | H13: -0.00072717737 | I13: -0.00011486938 | J13: 0.0012557577 | K13: -0.0013853486 | L13: 0.00074189326 | M13: -0.00085156914 | N13: 0.013317531 | O13: 0.0025970732 | P13: 0.0027405143 | Q13: 0.0028973797 | R13: 0.0024472875 | S13: 0.002778596 | T13: 0.002752813 | U13: 0.0032310413 | V13: 0.0031822674 | W13: 0.0031435547 | X13: 0.0030151696 | Y13: 0.0002082265 | Z13: -0.0010256555 | AA13: -0.00093677407 | AB13: 0.007059871 | AC13: 0.0021731995 | AD13: 0.0010532428 | AE13: -0.0042570895
... A30: Constant | B30: 2.181349 | C30: -0.0010394015 | D30: -0.00077764392 | E30: 8.9158207e-06 | F30: 0.00099202977 | G30: -0.00017770263 | H30: 0.00055211871 | I30: -0.0017721255 | J30: -0.0024294699 | K30: -0.0004565815 | L30: -0.00010217552 | M30: -0.00080184921 | N30: -0.0042570895 | O30: -0.0024542278 | P30: -0.0024034063 | Q30: -0.0022222198 | R30: -0.0023932416 | S30: -0.0025746409 | T30: -0.0032075575 | U30: -0.0032389986 | V30: -0.0020397633 | W30: -0.0025822635 | X30: -0.0017869744 | Y30: -0.0003243599 | Z30: 0.00088784809 | AA30: 0.0012270839 | AB30: -0.0015413884 | AC30: -0.00074039847 | AD30: -0.0002718525 | AE30: 0.023599902

Sheet E2_raw
A1: CATEGORY | B1: REGRESSOR | C1: COEFFICIENT
A2: Low | B2: demMaleFlag | C2: -0.70269446
A3: Low | B3: demAge | C3: 0.70218658
A4: Low | B4: demAgeSq | C4: -0.0091555151
A5: Low | B5: eduHighestParentC3MediumL1 | C5: -0.36235547
A6: Low | B6: eduHighestParentC3LowL1 | C6: -1.1278756
A7: Low | B7: demRgnUKC | C7: -0.34052897
A8: Low | B8: demRgnUKD | C8: -0.20582816
A9: Low | B9: demRgnUKE | C9: 0.28530113
A10: Low | B10: demRgnUKF | C10: 0.072134082
A11: Low | B11: demRgnUKG | C11: 0.001640279
A12: Low | B12: demRgnUKH | C12: 0.093481552
A13: Low | B13: demRgnUKJ | C13: 0.12025769
... A53: Medium | B53: _cons | C53: -17.742276

Sheet E2
A1: REGRESSOR | B1: COEFFICIENT | C1: demMaleFlag_Low | D1: demAge_Low | E1: demAgeSq_Low | F1: eduHighestParentC3MediumL1_ | G1: eduHighestParentC3LowL1_ | H1: demRgnUKC_ | I1: demRgnUKD_ | J1: demRgnUKE_Low | K1: demRgnUKF_ | L1: demRgnUKG_ | M1: demRgnUKH_ | N1: demRgnUKJ_ | O1: demRgnUKK_ | P1: demRgnUKL_ | Q1: demRgnUKM_Low | R1: demRgnUKN_Low | S1: demYearTransformed_Low | T1: demYear2020_ | U1: demYear2021_ | V1: demEthnC4Asian_ | W1: demEthnC4Black_ | X1: demEthnC4Other_ | Y1: Constant_Low | Z1: demMaleFlag_Medium | AA1: demAge_Medium | AB1: demAgeSq_Medium | AC1: demRgnUKE_Medium | AD1: demRgnUKM_Medium | AE1: demRgnUKN_Medium | AF1: demYearTransformed_Medium | AG1: Constant_Medium
A2: demMaleFlag_Low | B2: -0.70269446 | C2: 0.032208402 | D2: 0.0027407987 | E2: -3.116325e-05 | F2: 0.00049847787 | G2: 0.0027391043 | H2: 0.0031834866 | I2: 0.0049504868 | J2: -0.0014791834 | K2: 0.0017945406 | L2: 0.0023315151 | M2: 0.0016109724 | N2: -0.00011145024 | O2: 0.0033125688 | P2: 0.0017907142 | Q2: 0.00054557069 | R2: -0.0014972689 | S2: 0.00060184678 | T2: -0.003563557 | U2: 0.00098041816 | V2: -0.00045977164 | W2: 0.002548586 | X2: 0.003738625 | Y2: -0.072169175 | Z2: 0.001296066 | AA2: 0.00014108071 | AB2: -2.2392802e-06 | AC2: 0.0016214221 | AD2: 0.0020130625 | AE2: 0.001934327 | AF2: 2.4415076e-05 | AG2: -0.0054443406
A3: demAge_Low | B3: 0.70218658 | C3: 0.0027407987 | D3: 0.0087989685 | E3: -0.00011781984 | F3: 0.00036402862 | G3: 0.001934758 | H3: -0.00028778368 | I3: 0.0027231583 | J3: 0.0011639782 | K3: 0.00059761462 | L3: 0.00083061412 | M3: 0.00084027757 | N3: 0.0004844773 | O3: 0.00081410182 | P3: 0.00094892191 | Q3: 0.0017837676 | R3: -0.0030577937 | S3: -0.00011293612 | T3: -0.00041795841 | U3: -0.00034500398 | V3: -0.0013589635 | W3: -0.0016498625 | X3: -0.001405092 | Y3: -0.12293404 | Z3: 0.00030497437 | AA3: 0.00098439902 | AB3: -1.2080898e-05 | AC3: 9.3142601e-05 | AD3: 2.7485496e-05 | AE3: 5.4043502e-05 | AF3: 5.2830963e-05 | AG3: -0.016776752
A4: demAgeSq_Low | B4: -0.0091555151 | C4: -3.116325e-05 | D4: -0.00011781984 | E4: 1.6207161e-06 | F4: -4.7931048e-06 | G4: -2.6042617e-05 | H4: 4.8303738e-06 | I4: -3.4483674e-05 | J4: -1.4655702e-05 | K4: -6.8697254e-06 | L4: -8.3008943e-06 | M4: -9.7908582e-06 | N4: -5.7120079e-06 | O4: -1.0545461e-05 | P4: -1.4084719e-05 | Q4: -2.9908499e-05 | R4: 4.1880505e-05 | S4: 1.3630681e-06 | T4: 2.9598749e-06 | U4: 7.7349167e-06 | V4: 2.0662264e-05 | W4: 2.0133772e-05 | X4: 1.8507137e-05 | Y4: 0.0016276532 | Z4: -3.8907545e-06 | AA4: -1.2660665e-05 | AB4: 1.6013524e-07 | AC4: -1.4683671e-06 | AD4: -2.7693451e-07 | AE4: -1.9349663e-07 | AF4: -7.349547e-07 | AG4: 0.00021417812
A5: eduHighestParentC3MediumL1_ | B5: -0.36235547 | C5: 0.00049847787 | D5: 0.00036402862 | E5: -4.7931048e-06 | F5: 0.010296423 | G5: 0.0081790532 | H5: -0.0016163782 | I5: -0.0015508915 | J5: -0.0011240083 | K5: -0.0014831153 | L5: -0.0018475611 | M5: -0.0013938392 | N5: -0.0024696333 | O5: -0.0017372613 | P5: -0.0017463059 | Q5: -0.00034934467 | R5: -0.0017154973 | S5: -0.00014315468 | T5: 0.00088219717 | U5: 0.0008646665 | V5: -4.4321677e-06 | W5: 0.0005709253 | X5: 0.0013621918 | Y5: -0.010245656 | Z5: 0.00020840633 | AA5: 0.00016125756 | AB5: -2.1310125e-06 | AC5: -0.0026049744 | AD5: -0.0010513496 | AE5: -0.0022312665 | AF5: 0.00011258852 | AG5: -0.0108331
A6: eduHighestParentC3LowL1_ | B6: -1.1278756 | C6: 0.0027391043 | D6: 0.001934758 | E6: -2.6042617e-05 | F6: 0.0081790532 | G6: 0.020066297 | H6: -0.0045136254 | I6: -0.0015312245 | J6: -0.0039665073 | K6: -0.0044304324 | L6: -0.0034544642 | M6: -0.0030880821 | N6: -0.004678421 | O6: -0.0032732262 | P6: -0.0023100352 | Q6: -0.0043231812 | R6: -0.0055637218 | S6: 0.00024531557 | T6: 0.0014314192 | U6: -8.8314176e-06 | V6: -0.0039281473 | W6: -0.0031815206 | X6: 0.0018775372 | Y6: -0.039504381 | Z6: 0.00058251318 | AA6: 7.4526142e-05 | AB6: -3.8387189e-06 | AC6: -0.0033271849 | AD6: -0.0031326169 | AE6: -0.0050464726 | AF6: 0.00017632231 | AG6: -0.0077013362
A7: demRgnUKC_ | B7: -0.34052897 | C7: 0.0031834866 | D7: -0.00028778368 | E7: 4.8303738e-06 | F7: -0.0016163782 | G7: -0.0045136254 | H7: 0.05762622 | I7: 0.022777251 | J7: 0.025194997 | K7: 0.023695861 | L7: 0.022336606 | M7: 0.02301091 | N7: 0.023080638 | O7: 0.023579558 | P7: 0.024069597 | Q7: 0.025488072 | R7: 0.026061252 | S7: -0.00031298881 | T7: -0.0029879194 | U7: -0.00086396308 | V7: 0.0087728127 | W7: 0.021999388 | X7: 0.0039831605 | Y7: -0.01633431 | Z7: 0.00086137507 | AA7: -0.00012833762 | AB7: 1.4208576e-06 | AC7: 0.021912015 | AD7: 0.024904118 | AE7: 0.024085959 | AF7: -0.0001371626 | AG7: -0.01767997
A8: demRgnUKD_ | B8: -0.20582816 | C8: 0.0049504868 | D8: 0.0027231583 | E8: -3.4483674e-05 | F8: -0.0015508915 | G8: -0.0015312245 | H8: 0.022777251 | I8: 0.036824146 | J8: 0.023208273 | K8: 0.022715995 | L8: 0.021764728 | M8: 0.022330298 | N8: 0.022146718 | O8: 0.022717851 | P8: 0.023128881 | Q8: 0.023344229 | R8: 0.022989978 | S8: 0.00019607036 | T8: -0.0043314904 | U8: 0.00039483487 | V8: 0.0061779271 | W8: 0.019321753 | X8: 0.002683922 | Y8: -0.067088191 | Z8: 0.0005910539 | AA8: 6.1357704e-05 | AB8: -6.8788775e-07 | AC8: 0.021326068 | AD8: 0.023931387 | AE8: 0.023012756 | AF8: -5.8930448e-05 | AG8: -0.021496533
A9: demRgnUKE_Low | B9: 0.28530113 | C9: -0.0014791834 | D9: 0.0011639782 | E9: -1.4655702e-05 | F9: -0.0011240083 | G9: -0.0039665073 | H9: 0.025194997 | I9: 0.023208273 | J9: 0.11288195 | K9: 0.024452728 | L9: 0.022707759 | M9: 0.02371768 | N9: 0.022967923 | O9: 0.024123851 | P9: 0.025332996 | Q9: 0.031860995 | R9: 0.031869452 | S9: -0.00067834954 | T9: -0.0044360405 | U9: 0.0042688123 | V9: 0.0074658635 | W9: 0.022513335 | X9: 0.0043090413 | Y9: -0.034252744 | Z9: 0.00022630764 | AA9: -3.2695559e-05 | AB9: 2.126122e-07 | AC9: 0.023207632 | AD9: 0.023737886 | AE9: 0.022821583 | AF9: -0.00012295187 | AG9: -0.018593068
A10: demRgnUKF_ | B10: 0.072134082 | C10: 0.0017945406 | D10: 0.00059761462 | E10: -6.8697254e-06 | F10: -0.0014831153 | G10: -0.0044304324 | H10: 0.023695861 | I10: 0.022715995 | J10: 0.024452728 | K10: 0.038756142 | L10: 0.022333698 | M10: 0.022867729 | N10: 0.023104488 | O10: 0.023313746 | P10: 0.023755402 | Q10: 0.024601818 | R10: 0.024840267 | S10: -0.00022897899 | T10: -0.0039607476 | U10: 0.00040307101 | V10: 0.0077529441 | W10: 0.023109516 | X10: 0.0025840761 | Y10: -0.028406996 | Z10: -3.5956443e-05 | AA10: 0.00015771143 | AB10: -1.4978715e-06 | AC10: 0.02167929 | AD10: 0.024197919 | AE10: 0.02368697 | AF10: -4.7570896e-05 | AG10: -0.02332394
