Workbook

Sheet Cover
B2: SimPaths Codebook
B4: Date: | C4: 45974
B5: Authors: | C5: David Sonnewald, Ashley Burdett
B7: Overview: | C7: This codebook accompanies the SimPaths microsimulation model, documenting the variables used within and produced by the model. It applies to both the UK and EU variants of SimPaths.
C8: The codebook provdes definitions of each variable, specififes where each variables is created in the code and idenitifies the output file in which it can be found. Where applicable, the codebook
C9: also lists the corresponding variables from the underlying survey datasets used to construct each variable.
C11: Potenitally add a line descibing the contents of each tab?
B14: Key: | C14: ** | D14: Replace with two letter country code for European model
C25: AB: UK initial populations information to be populated.

Sheet Variables
A1: SimPaths current name | B1: Local | C1: Mod | D1: Main attribute | E1: Level | F1: Measurement | G1: Other info | H1: Statistics type | I1: Periodicity | J1: New name | K1: Description | L1: Java class | M1: Initial population | N1: Original name UK (UKHLS) | O1: Do-file UK | P1: Original name EU (EU-SILC) | Q1: Do-file EU | R1: Output file name | S1: Module | T1: Model version introduced | U1: Notes
A2: aaconsToLeisRatio | C2: {=_xlfn.IFS(S2 = Modules!$A$2,Modules!$B$2,S2 = Modules!$A$3,Modules!$B$3,S2 = Modules!$A$4,Modules!$B$4,S2 = Modules!$A$5,Modules!$B$5,S2 = Modules!$A$6,Modules!$B$6,S2 = Modules!$A$7,Modules!$B$7,S2 = Modules!$A$8,Modules!$B$8,S2 = Modules!$A$9,Modules!$B$9,S2 = Modules!$A$10,Modules!$B$10,S2 = Modules!$A$11,Modules!$B$11,S2 = Modules!$A$12,Modules!$B$12, S2 = Modules!$A$13,Modules!$B$13)} -> x | D2: ToLeisure | H2: Ratio | J2: =CONCATENATE(B2, C2,D2,E2,F2,G2,H2,I2) -> xToLeisureRatio | K2: Consumption-Leisure ratio | L2: Statistics2.java | M2: =IF(OR(O2<>"", Q2<>""),"Yes","No") -> No | R2: File: Statistics2 | S2: Consumption
A3: aadisposableIncome18to29 | C3: {=_xlfn.IFS(S3 = Modules!$A$2,Modules!$B$2,S3 = Modules!$A$3,Modules!$B$3,S3 = Modules!$A$4,Modules!$B$4,S3 = Modules!$A$5,Modules!$B$5,S3 = Modules!$A$6,Modules!$B$6,S3 = Modules!$A$7,Modules!$B$7,S3 = Modules!$A$8,Modules!$B$8,S3 = Modules!$A$9,Modules!$B$9,S3 = Modules!$A$10,Modules!$B$10,S3 = Modules!$A$11,Modules!$B$11,S3 = Modules!$A$12,Modules!$B$12, S3 = Modules!$A$13,Modules!$B$13)} -> stat | F3: Disp | G3: 18to29 | H3: Avg | J3: =CONCATENATE(B3, C3,D3,E3,F3,G3,H3,I3) -> statDisp18to29Avg | K3: Average disposable income age 18-29 | L3: Statistics2.java | M3: =IF(OR(O3<>"", Q3<>""),"Yes","No") -> No | R3: File: Statistics2 | S3: Statistical display
A4: aadisposableIncome30to54 | C4: {=_xlfn.IFS(S4 = Modules!$A$2,Modules!$B$2,S4 = Modules!$A$3,Modules!$B$3,S4 = Modules!$A$4,Modules!$B$4,S4 = Modules!$A$5,Modules!$B$5,S4 = Modules!$A$6,Modules!$B$6,S4 = Modules!$A$7,Modules!$B$7,S4 = Modules!$A$8,Modules!$B$8,S4 = Modules!$A$9,Modules!$B$9,S4 = Modules!$A$10,Modules!$B$10,S4 = Modules!$A$11,Modules!$B$11,S4 = Modules!$A$12,Modules!$B$12, S4 = Modules!$A$13,Modules!$B$13)} -> stat | F4: Disp | G4: 30to54 | H4: Avg | J4: =CONCATENATE(B4, C4,D4,E4,F4,G4,H4,I4) -> statDisp30to54Avg | K4: Average disposable income age 30-54 | L4: Statistics2.java | M4: =IF(OR(O4<>"", Q4<>""),"Yes","No") -> No | R4: File: Statistics2 | S4: Statistical display
A5: aadisposableIncome55to74 | C5: {=_xlfn.IFS(S5 = Modules!$A$2,Modules!$B$2,S5 = Modules!$A$3,Modules!$B$3,S5 = Modules!$A$4,Modules!$B$4,S5 = Modules!$A$5,Modules!$B$5,S5 = Modules!$A$6,Modules!$B$6,S5 = Modules!$A$7,Modules!$B$7,S5 = Modules!$A$8,Modules!$B$8,S5 = Modules!$A$9,Modules!$B$9,S5 = Modules!$A$10,Modules!$B$10,S5 = Modules!$A$11,Modules!$B$11,S5 = Modules!$A$12,Modules!$B$12, S5 = Modules!$A$13,Modules!$B$13)} -> stat | F5: Disp | G5: 55to74 | H5: Avg | J5: =CONCATENATE(B5, C5,D5,E5,F5,G5,H5,I5) -> statDisp55to74Avg | K5: Average disposable income age 55-74 | L5: Statistics2.java | M5: =IF(OR(O5<>"", Q5<>""),"Yes","No") -> No | R5: File: Statistics2 | S5: Statistical display
A6: aaexpenditure18to29 | C6: {=_xlfn.IFS(S6 = Modules!$A$2,Modules!$B$2,S6 = Modules!$A$3,Modules!$B$3,S6 = Modules!$A$4,Modules!$B$4,S6 = Modules!$A$5,Modules!$B$5,S6 = Modules!$A$6,Modules!$B$6,S6 = Modules!$A$7,Modules!$B$7,S6 = Modules!$A$8,Modules!$B$8,S6 = Modules!$A$9,Modules!$B$9,S6 = Modules!$A$10,Modules!$B$10,S6 = Modules!$A$11,Modules!$B$11,S6 = Modules!$A$12,Modules!$B$12, S6 = Modules!$A$13,Modules!$B$13)} -> x | G6: 18to29 | H6: Avg | J6: =CONCATENATE(B6, C6,D6,E6,F6,G6,H6,I6) -> x18to29Avg | K6: Average expenditure age 18-29 | L6: Statistics2.java | M6: =IF(OR(O6<>"", Q6<>""),"Yes","No") -> No | R6: File: Statistics2 | S6: Consumption
A7: aaexpenditure18to54 | C7: {=_xlfn.IFS(S7 = Modules!$A$2,Modules!$B$2,S7 = Modules!$A$3,Modules!$B$3,S7 = Modules!$A$4,Modules!$B$4,S7 = Modules!$A$5,Modules!$B$5,S7 = Modules!$A$6,Modules!$B$6,S7 = Modules!$A$7,Modules!$B$7,S7 = Modules!$A$8,Modules!$B$8,S7 = Modules!$A$9,Modules!$B$9,S7 = Modules!$A$10,Modules!$B$10,S7 = Modules!$A$11,Modules!$B$11,S7 = Modules!$A$12,Modules!$B$12, S7 = Modules!$A$13,Modules!$B$13)} -> x | G7: 18to54 | H7: Avg | J7: =CONCATENATE(B7, C7,D7,E7,F7,G7,H7,I7) -> x18to54Avg | K7: Average expenditure age 18-54 | L7: Statistics2.java | M7: =IF(OR(O7<>"", Q7<>""),"Yes","No") -> No | R7: File: Statistics2 | S7: Consumption
A8: aaexpenditure30to54 | C8: {=_xlfn.IFS(S8 = Modules!$A$2,Modules!$B$2,S8 = Modules!$A$3,Modules!$B$3,S8 = Modules!$A$4,Modules!$B$4,S8 = Modules!$A$5,Modules!$B$5,S8 = Modules!$A$6,Modules!$B$6,S8 = Modules!$A$7,Modules!$B$7,S8 = Modules!$A$8,Modules!$B$8,S8 = Modules!$A$9,Modules!$B$9,S8 = Modules!$A$10,Modules!$B$10,S8 = Modules!$A$11,Modules!$B$11,S8 = Modules!$A$12,Modules!$B$12, S8 = Modules!$A$13,Modules!$B$13)} -> x | G8: 30to54 | H8: Avg | J8: =CONCATENATE(B8, C8,D8,E8,F8,G8,H8,I8) -> x30to54Avg | K8: Average expenditure age 30-54 | L8: Statistics2.java | M8: =IF(OR(O8<>"", Q8<>""),"Yes","No") -> No | R8: File: Statistics2 | S8: Consumption
A9: aaexpenditure55to74 | C9: {=_xlfn.IFS(S9 = Modules!$A$2,Modules!$B$2,S9 = Modules!$A$3,Modules!$B$3,S9 = Modules!$A$4,Modules!$B$4,S9 = Modules!$A$5,Modules!$B$5,S9 = Modules!$A$6,Modules!$B$6,S9 = Modules!$A$7,Modules!$B$7,S9 = Modules!$A$8,Modules!$B$8,S9 = Modules!$A$9,Modules!$B$9,S9 = Modules!$A$10,Modules!$B$10,S9 = Modules!$A$11,Modules!$B$11,S9 = Modules!$A$12,Modules!$B$12, S9 = Modules!$A$13,Modules!$B$13)} -> x | G9: 55to74 | H9: Avg | J9: =CONCATENATE(B9, C9,D9,E9,F9,G9,H9,I9) -> x55to74Avg | K9: Average expenditure age 55-74 | L9: Statistics2.java | M9: =IF(OR(O9<>"", Q9<>""),"Yes","No") -> No | R9: File: Statistics2 | S9: Consumption
A10: aaworkNone18to29 | C10: {=_xlfn.IFS(S10 = Modules!$A$2,Modules!$B$2,S10 = Modules!$A$3,Modules!$B$3,S10 = Modules!$A$4,Modules!$B$4,S10 = Modules!$A$5,Modules!$B$5,S10 = Modules!$A$6,Modules!$B$6,S10 = Modules!$A$7,Modules!$B$7,S10 = Modules!$A$8,Modules!$B$8,S10 = Modules!$A$9,Modules!$B$9,S10 = Modules!$A$10,Modules!$B$10,S10 = Modules!$A$11,Modules!$B$11,S10 = Modules!$A$12,Modules!$B$12, S10 = Modules!$A$13,Modules!$B$13)} -> lab | D10: NoWork | G10: 18to29 | H10: Share | J10: =CONCATENATE(B10, C10,D10,E10,F10,G10,H10,I10) -> labNoWork18to29Share | K10: Share not working age 18-29 | L10: Statistics2.java | M10: =IF(OR(O10<>"", Q10<>""),"Yes","No") -> No | R10: File: Statistics2 | S10: Labour
A11: aaworkNone18to74 | C11: {=_xlfn.IFS(S11 = Modules!$A$2,Modules!$B$2,S11 = Modules!$A$3,Modules!$B$3,S11 = Modules!$A$4,Modules!$B$4,S11 = Modules!$A$5,Modules!$B$5,S11 = Modules!$A$6,Modules!$B$6,S11 = Modules!$A$7,Modules!$B$7,S11 = Modules!$A$8,Modules!$B$8,S11 = Modules!$A$9,Modules!$B$9,S11 = Modules!$A$10,Modules!$B$10,S11 = Modules!$A$11,Modules!$B$11,S11 = Modules!$A$12,Modules!$B$12, S11 = Modules!$A$13,Modules!$B$13)} -> lab | D11: NoWork | G11: 18to54 | H11: Share | J11: =CONCATENATE(B11, C11,D11,E11,F11,G11,H11,I11) -> labNoWork18to54Share | K11: Share not working age 18-74 | L11: Statistics2.java | M11: =IF(OR(O11<>"", Q11<>""),"Yes","No") -> No | R11: File: Statistics2 | S11: Labour
A12: aaworkNone30to54 | C12: {=_xlfn.IFS(S12 = Modules!$A$2,Modules!$B$2,S12 = Modules!$A$3,Modules!$B$3,S12 = Modules!$A$4,Modules!$B$4,S12 = Modules!$A$5,Modules!$B$5,S12 = Modules!$A$6,Modules!$B$6,S12 = Modules!$A$7,Modules!$B$7,S12 = Modules!$A$8,Modules!$B$8,S12 = Modules!$A$9,Modules!$B$9,S12 = Modules!$A$10,Modules!$B$10,S12 = Modules!$A$11,Modules!$B$11,S12 = Modules!$A$12,Modules!$B$12, S12 = Modules!$A$13,Modules!$B$13)} -> lab | D12: NoWork | G12: 30to54 | H12: Share | J12: =CONCATENATE(B12, C12,D12,E12,F12,G12,H12,I12) -> labNoWork30to54Share | K12: Share not working age 30-54 | L12: Statistics2.java | M12: =IF(OR(O12<>"", Q12<>""),"Yes","No") -> No | R12: File: Statistics2 | S12: Labour
A13: aaworkNone55to74 | C13: {=_xlfn.IFS(S13 = Modules!$A$2,Modules!$B$2,S13 = Modules!$A$3,Modules!$B$3,S13 = Modules!$A$4,Modules!$B$4,S13 = Modules!$A$5,Modules!$B$5,S13 = Modules!$A$6,Modules!$B$6,S13 = Modules!$A$7,Modules!$B$7,S13 = Modules!$A$8,Modules!$B$8,S13 = Modules!$A$9,Modules!$B$9,S13 = Modules!$A$10,Modules!$B$10,S13 = Modules!$A$11,Modules!$B$11,S13 = Modules!$A$12,Modules!$B$12, S13 = Modules!$A$13,Modules!$B$13)} -> lab | D13: NoWork | G13: 55to74 | H13: Share | J13: =CONCATENATE(B13, C13,D13,E13,F13,G13,H13,I13) -> labNoWork55to74Share | K13: Share not working age 55-74 | L13: Statistics2.java | M13: =IF(OR(O13<>"", Q13<>""),"Yes","No") -> No | R13: File: Statistics2 | S13: Labour
A14: adultchildflag | C14: {=_xlfn.IFS(S14 = Modules!$A$2,Modules!$B$2,S14 = Modules!$A$3,Modules!$B$3,S14 = Modules!$A$4,Modules!$B$4,S14 = Modules!$A$5,Modules!$B$5,S14 = Modules!$A$6,Modules!$B$6,S14 = Modules!$A$7,Modules!$B$7,S14 = Modules!$A$8,Modules!$B$8,S14 = Modules!$A$9,Modules!$B$9,S14 = Modules!$A$10,Modules!$B$10,S14 = Modules!$A$11,Modules!$B$11,S14 = Modules!$A$12,Modules!$B$12, S14 = Modules!$A$13,Modules!$B$13)} -> dem | D14: AdultChild | H14: Flag | J14: =CONCATENATE(B14, C14,D14,E14,F14,G14,H14,I14) -> demAdultChildFlag | K14: Adult child 0 No 1 Yes | L14: Person.java | M14: =IF(OR(O14<>"", Q14<>""),"Yes","No") -> Yes | N14: dagmother; dagfather; dag; age_become_responsible; idpartner | O14: 02_create_ukhls_variables.do | P14: idmother (rb230; urtgrp); idfather (rb220; urtgrp); dag (rb080; rx010; pb110); les_c4 (pl030; pl031; pl032; rb210; rb211) | Q14: 02_00_create_variables_**.do | S14: Demography
A15: ageGroup | C15: {=_xlfn.IFS(S15 = Modules!$A$2,Modules!$B$2,S15 = Modules!$A$3,Modules!$B$3,S15 = Modules!$A$4,Modules!$B$4,S15 = Modules!$A$5,Modules!$B$5,S15 = Modules!$A$6,Modules!$B$6,S15 = Modules!$A$7,Modules!$B$7,S15 = Modules!$A$8,Modules!$B$8,S15 = Modules!$A$9,Modules!$B$9,S15 = Modules!$A$10,Modules!$B$10,S15 = Modules!$A$11,Modules!$B$11,S15 = Modules!$A$12,Modules!$B$12, S15 = Modules!$A$13,Modules!$B$13)} -> dem | D15: AgeGroup | J15: =CONCATENATE(B15, C15,D15,E15,F15,G15,H15,I15) -> demAgeGroup | K15: Age group 1 dag >= 18 && dag < 21 2 dag >= 21 && dag < 24 3 dag >= 24 && dag < 27 4 dag >= 27 && dag < 30 5 dag >= 30 && dag < 33 6 dag >= 33 && dag < 36 7 dag >= 36 && dag < 40 8 dag >= 40 && dag < 45 9 dag >= 45 && dag < 55 10 dag >= 55 && dag < 65 11 dag >= 65 | L15: Person.java | M15: =IF(OR(O15<>"", Q15<>""),"Yes","No") -> No | S15: Demography
A16: atRiskOfPoverty | C16: {=_xlfn.IFS(S16 = Modules!$A$2,Modules!$B$2,S16 = Modules!$A$3,Modules!$B$3,S16 = Modules!$A$4,Modules!$B$4,S16 = Modules!$A$5,Modules!$B$5,S16 = Modules!$A$6,Modules!$B$6,S16 = Modules!$A$7,Modules!$B$7,S16 = Modules!$A$8,Modules!$B$8,S16 = Modules!$A$9,Modules!$B$9,S16 = Modules!$A$10,Modules!$B$10,S16 = Modules!$A$11,Modules!$B$11,S16 = Modules!$A$12,Modules!$B$12, S16 = Modules!$A$13,Modules!$B$13)} -> y | D16: Pvrty | H16: Flag | J16: =CONCATENATE(B16, C16,D16,E16,F16,G16,H16,I16) -> yPvrtyFlag | K16: At risk of poverty 0 No 1 Yes | L16: BenefitUnit.java | M16: =IF(OR(O16<>"", Q16<>""),"Yes","No") -> No | S16: Income | U16: equivalisedDisposableIncomeYearly < 60% of median household's
A17: atRiskOfPoverty_lag1 | C17: {=_xlfn.IFS(S17 = Modules!$A$2,Modules!$B$2,S17 = Modules!$A$3,Modules!$B$3,S17 = Modules!$A$4,Modules!$B$4,S17 = Modules!$A$5,Modules!$B$5,S17 = Modules!$A$6,Modules!$B$6,S17 = Modules!$A$7,Modules!$B$7,S17 = Modules!$A$8,Modules!$B$8,S17 = Modules!$A$9,Modules!$B$9,S17 = Modules!$A$10,Modules!$B$10,S17 = Modules!$A$11,Modules!$B$11,S17 = Modules!$A$12,Modules!$B$12, S17 = Modules!$A$13,Modules!$B$13)} -> y | D17: Pvrty | H17: Flag | I17: L1 | J17: =CONCATENATE(B17, C17,D17,E17,F17,G17,H17,I17) -> yPvrtyFlagL1 | K17: Lag(1) of atRiskOfPoverty | L17: BenefitUnit.java | M17: =IF(OR(O17<>"", Q17<>""),"Yes","No") -> No | S17: Income
A18: avkids18to29 | C18: {=_xlfn.IFS(S18 = Modules!$A$2,Modules!$B$2,S18 = Modules!$A$3,Modules!$B$3,S18 = Modules!$A$4,Modules!$B$4,S18 = Modules!$A$5,Modules!$B$5,S18 = Modules!$A$6,Modules!$B$6,S18 = Modules!$A$7,Modules!$B$7,S18 = Modules!$A$8,Modules!$B$8,S18 = Modules!$A$9,Modules!$B$9,S18 = Modules!$A$10,Modules!$B$10,S18 = Modules!$A$11,Modules!$B$11,S18 = Modules!$A$12,Modules!$B$12, S18 = Modules!$A$13,Modules!$B$13)} -> dem | D18: NChild | G18: 18to29 | H18: Avg | J18: =CONCATENATE(B18, C18,D18,E18,F18,G18,H18,I18) -> demNChild18to29Avg | K18: Average number of children age 18-29 | L18: Statistics2.java | M18: =IF(OR(O18<>"", Q18<>""),"Yes","No") -> No | R18: File: Statistics2 | S18: Demography
A19: avkids30to54 | C19: {=_xlfn.IFS(S19 = Modules!$A$2,Modules!$B$2,S19 = Modules!$A$3,Modules!$B$3,S19 = Modules!$A$4,Modules!$B$4,S19 = Modules!$A$5,Modules!$B$5,S19 = Modules!$A$6,Modules!$B$6,S19 = Modules!$A$7,Modules!$B$7,S19 = Modules!$A$8,Modules!$B$8,S19 = Modules!$A$9,Modules!$B$9,S19 = Modules!$A$10,Modules!$B$10,S19 = Modules!$A$11,Modules!$B$11,S19 = Modules!$A$12,Modules!$B$12, S19 = Modules!$A$13,Modules!$B$13)} -> dem | D19: NChild | G19: 30to54 | H19: Avg | J19: =CONCATENATE(B19, C19,D19,E19,F19,G19,H19,I19) -> demNChild30to54Avg | K19: Average number of children age 30-54 | L19: Statistics2.java | M19: =IF(OR(O19<>"", Q19<>""),"Yes","No") -> No | R19: File: Statistics2 | S19: Demography
A20: avkids55to74 | C20: {=_xlfn.IFS(S20 = Modules!$A$2,Modules!$B$2,S20 = Modules!$A$3,Modules!$B$3,S20 = Modules!$A$4,Modules!$B$4,S20 = Modules!$A$5,Modules!$B$5,S20 = Modules!$A$6,Modules!$B$6,S20 = Modules!$A$7,Modules!$B$7,S20 = Modules!$A$8,Modules!$B$8,S20 = Modules!$A$9,Modules!$B$9,S20 = Modules!$A$10,Modules!$B$10,S20 = Modules!$A$11,Modules!$B$11,S20 = Modules!$A$12,Modules!$B$12, S20 = Modules!$A$13,Modules!$B$13)} -> dem | D20: NChild | G20: 55to74 | H20: Avg | J20: =CONCATENATE(B20, C20,D20,E20,F20,G20,H20,I20) -> demNChild55to74Avg | K20: Average number of children age 55-74 | L20: Statistics2.java | M20: =IF(OR(O20<>"", Q20<>""),"Yes","No") -> No | R20: File: Statistics2 | S20: Demography
A21: aworkFulltime18to29 | C21: {=_xlfn.IFS(S21 = Modules!$A$2,Modules!$B$2,S21 = Modules!$A$3,Modules!$B$3,S21 = Modules!$A$4,Modules!$B$4,S21 = Modules!$A$5,Modules!$B$5,S21 = Modules!$A$6,Modules!$B$6,S21 = Modules!$A$7,Modules!$B$7,S21 = Modules!$A$8,Modules!$B$8,S21 = Modules!$A$9,Modules!$B$9,S21 = Modules!$A$10,Modules!$B$10,S21 = Modules!$A$11,Modules!$B$11,S21 = Modules!$A$12,Modules!$B$12, S21 = Modules!$A$13,Modules!$B$13)} -> lab | D21: WorkFullTime | G21: 18to29 | H21: Share | J21: =CONCATENATE(B21, C21,D21,E21,F21,G21,H21,I21) -> labWorkFullTime18to29Share | K21: Share working full time age 18-29 | L21: Statistics2.java | M21: =IF(OR(O21<>"", Q21<>""),"Yes","No") -> No | R21: File: Statistics2 | S21: Labour
A22: aworkFulltime30to54 | C22: {=_xlfn.IFS(S22 = Modules!$A$2,Modules!$B$2,S22 = Modules!$A$3,Modules!$B$3,S22 = Modules!$A$4,Modules!$B$4,S22 = Modules!$A$5,Modules!$B$5,S22 = Modules!$A$6,Modules!$B$6,S22 = Modules!$A$7,Modules!$B$7,S22 = Modules!$A$8,Modules!$B$8,S22 = Modules!$A$9,Modules!$B$9,S22 = Modules!$A$10,Modules!$B$10,S22 = Modules!$A$11,Modules!$B$11,S22 = Modules!$A$12,Modules!$B$12, S22 = Modules!$A$13,Modules!$B$13)} -> lab | D22: WorkFullTime | G22: 30to54 | H22: Share | J22: =CONCATENATE(B22, C22,D22,E22,F22,G22,H22,I22) -> labWorkFullTime30to54Share | K22: Share working full time age 30-54 | L22: Statistics2.java | M22: =IF(OR(O22<>"", Q22<>""),"Yes","No") -> No | R22: File: Statistics2 | S22: Labour
A23: aworkFulltime55to74 | C23: {=_xlfn.IFS(S23 = Modules!$A$2,Modules!$B$2,S23 = Modules!$A$3,Modules!$B$3,S23 = Modules!$A$4,Modules!$B$4,S23 = Modules!$A$5,Modules!$B$5,S23 = Modules!$A$6,Modules!$B$6,S23 = Modules!$A$7,Modules!$B$7,S23 = Modules!$A$8,Modules!$B$8,S23 = Modules!$A$9,Modules!$B$9,S23 = Modules!$A$10,Modules!$B$10,S23 = Modules!$A$11,Modules!$B$11,S23 = Modules!$A$12,Modules!$B$12, S23 = Modules!$A$13,Modules!$B$13)} -> lab | D23: WorkFullTime | G23: 55to74 | H23: Share | J23: =CONCATENATE(B23, C23,D23,E23,F23,G23,H23,I23) -> labWorkFullTime55to74Share | K23: Share working full time age 55-74 | L23: Statistics2.java | M23: =IF(OR(O23<>"", Q23<>""),"Yes","No") -> No | R23: File: Statistics2 | S23: Labour
A24: aworkParttime18to29 | C24: {=_xlfn.IFS(S24 = Modules!$A$2,Modules!$B$2,S24 = Modules!$A$3,Modules!$B$3,S24 = Modules!$A$4,Modules!$B$4,S24 = Modules!$A$5,Modules!$B$5,S24 = Modules!$A$6,Modules!$B$6,S24 = Modules!$A$7,Modules!$B$7,S24 = Modules!$A$8,Modules!$B$8,S24 = Modules!$A$9,Modules!$B$9,S24 = Modules!$A$10,Modules!$B$10,S24 = Modules!$A$11,Modules!$B$11,S24 = Modules!$A$12,Modules!$B$12, S24 = Modules!$A$13,Modules!$B$13)} -> lab | D24: WorkPartTime | G24: 18to29 | H24: Share | J24: =CONCATENATE(B24, C24,D24,E24,F24,G24,H24,I24) -> labWorkPartTime18to29Share | K24: Share working part time age 18-29 | L24: Statistics2.java | M24: =IF(OR(O24<>"", Q24<>""),"Yes","No") -> No | R24: File: Statistics2 | S24: Labour
A25: aworkParttime30to54 | C25: {=_xlfn.IFS(S25 = Modules!$A$2,Modules!$B$2,S25 = Modules!$A$3,Modules!$B$3,S25 = Modules!$A$4,Modules!$B$4,S25 = Modules!$A$5,Modules!$B$5,S25 = Modules!$A$6,Modules!$B$6,S25 = Modules!$A$7,Modules!$B$7,S25 = Modules!$A$8,Modules!$B$8,S25 = Modules!$A$9,Modules!$B$9,S25 = Modules!$A$10,Modules!$B$10,S25 = Modules!$A$11,Modules!$B$11,S25 = Modules!$A$12,Modules!$B$12, S25 = Modules!$A$13,Modules!$B$13)} -> lab | D25: WorkPartTime | G25: 30to54 | H25: Share | J25: =CONCATENATE(B25, C25,D25,E25,F25,G25,H25,I25) -> labWorkPartTime30to54Share | K25: Share working part time age 30-54 | L25: Statistics2.java | M25: =IF(OR(O25<>"", Q25<>""),"Yes","No") -> No | R25: File: Statistics2 | S25: Labour
A26: aworkParttime55to74 | C26: {=_xlfn.IFS(S26 = Modules!$A$2,Modules!$B$2,S26 = Modules!$A$3,Modules!$B$3,S26 = Modules!$A$4,Modules!$B$4,S26 = Modules!$A$5,Modules!$B$5,S26 = Modules!$A$6,Modules!$B$6,S26 = Modules!$A$7,Modules!$B$7,S26 = Modules!$A$8,Modules!$B$8,S26 = Modules!$A$9,Modules!$B$9,S26 = Modules!$A$10,Modules!$B$10,S26 = Modules!$A$11,Modules!$B$11,S26 = Modules!$A$12,Modules!$B$12, S26 = Modules!$A$13,Modules!$B$13)} -> lab | D26: WorkPartTime | G26: 55to74 | H26: Share | J26: =CONCATENATE(B26, C26,D26,E26,F26,G26,H26,I26) -> labWorkPartTime55to74Share | K26: Share working part time age 55-74 | L26: Statistics2.java | M26: =IF(OR(O26<>"", Q26<>""),"Yes","No") -> No | R26: File: Statistics2 | S26: Labour
A27: benefitsReceivedPerMonth | C27: {=_xlfn.IFS(S27 = Modules!$A$2,Modules!$B$2,S27 = Modules!$A$3,Modules!$B$3,S27 = Modules!$A$4,Modules!$B$4,S27 = Modules!$A$5,Modules!$B$5,S27 = Modules!$A$6,Modules!$B$6,S27 = Modules!$A$7,Modules!$B$7,S27 = Modules!$A$8,Modules!$B$8,S27 = Modules!$A$9,Modules!$B$9,S27 = Modules!$A$10,Modules!$B$10,S27 = Modules!$A$11,Modules!$B$11,S27 = Modules!$A$12,Modules!$B$12, S27 = Modules!$A$13,Modules!$B$13)} -> y | D27: Ben | F27: Amount | I27: Month | J27: =CONCATENATE(B27, C27,D27,E27,F27,G27,H27,I27) -> yBenAmountMonth | K27: Amount of benefits received per month | L27: BenefitUnit.java | M27: =IF(OR(O27<>"", Q27<>""),"Yes","No") -> No | S27: Income
A28: bornInSimulation | C28: {=_xlfn.IFS(S28 = Modules!$A$2,Modules!$B$2,S28 = Modules!$A$3,Modules!$B$3,S28 = Modules!$A$4,Modules!$B$4,S28 = Modules!$A$5,Modules!$B$5,S28 = Modules!$A$6,Modules!$B$6,S28 = Modules!$A$7,Modules!$B$7,S28 = Modules!$A$8,Modules!$B$8,S28 = Modules!$A$9,Modules!$B$9,S28 = Modules!$A$10,Modules!$B$10,S28 = Modules!$A$11,Modules!$B$11,S28 = Modules!$A$12,Modules!$B$12, S28 = Modules!$A$13,Modules!$B$13)} -> dem | D28: BornInSim | H28: Flag | J28: =CONCATENATE(B28, C28,D28,E28,F28,G28,H28,I28) -> demBornInSimFlag | K28: Flag to keep track of newborns TRUE FALSE | L28: Person.java | M28: =IF(OR(O28<>"", Q28<>""),"Yes","No") -> No | S28: Demography
A29: careFormalExpenditureWeekly | C29: {=_xlfn.IFS(S29 = Modules!$A$2,Modules!$B$2,S29 = Modules!$A$3,Modules!$B$3,S29 = Modules!$A$4,Modules!$B$4,S29 = Modules!$A$5,Modules!$B$5,S29 = Modules!$A$6,Modules!$B$6,S29 = Modules!$A$7,Modules!$B$7,S29 = Modules!$A$8,Modules!$B$8,S29 = Modules!$A$9,Modules!$B$9,S29 = Modules!$A$10,Modules!$B$10,S29 = Modules!$A$11,Modules!$B$11,S29 = Modules!$A$12,Modules!$B$12, S29 = Modules!$A$13,Modules!$B$13)} -> x | D29: Care | G29: Formal | I29: Week | J29: =CONCATENATE(B29, C29,D29,E29,F29,G29,H29,I29) -> xCareFormalWeek | K29: Cost for weekly formal social care received | L29: Person.java | M29: =IF(OR(O29<>"", Q29<>""),"Yes","No") -> No | S29: Consumption
A30: careHoursFromDaughterWeekly | C30: {=_xlfn.IFS(S30 = Modules!$A$2,Modules!$B$2,S30 = Modules!$A$3,Modules!$B$3,S30 = Modules!$A$4,Modules!$B$4,S30 = Modules!$A$5,Modules!$B$5,S30 = Modules!$A$6,Modules!$B$6,S30 = Modules!$A$7,Modules!$B$7,S30 = Modules!$A$8,Modules!$B$8,S30 = Modules!$A$9,Modules!$B$9,S30 = Modules!$A$10,Modules!$B$10,S30 = Modules!$A$11,Modules!$B$11,S30 = Modules!$A$12,Modules!$B$12, S30 = Modules!$A$13,Modules!$B$13)} -> care | D30: Hrs | G30: FromDaughter | I30: Week | J30: =CONCATENATE(B30, C30,D30,E30,F30,G30,H30,I30) -> careHrsFromDaughterWeek | K30: Weekly hours of social care received from the daughter | L30: Person.java | M30: =IF(OR(O30<>"", Q30<>""),"Yes","No") -> No | S30: Social care
A31: careHoursFromDaughterWeekly_lag1 | C31: {=_xlfn.IFS(S31 = Modules!$A$2,Modules!$B$2,S31 = Modules!$A$3,Modules!$B$3,S31 = Modules!$A$4,Modules!$B$4,S31 = Modules!$A$5,Modules!$B$5,S31 = Modules!$A$6,Modules!$B$6,S31 = Modules!$A$7,Modules!$B$7,S31 = Modules!$A$8,Modules!$B$8,S31 = Modules!$A$9,Modules!$B$9,S31 = Modules!$A$10,Modules!$B$10,S31 = Modules!$A$11,Modules!$B$11,S31 = Modules!$A$12,Modules!$B$12, S31 = Modules!$A$13,Modules!$B$13)} -> care | D31: Hrs | G31: FromDaughter | I31: WeekL1 | J31: =CONCATENATE(B31, C31,D31,E31,F31,G31,H31,I31) -> careHrsFromDaughterWeekL1 | K31: Lag(1) of careHoursFromDaughterWeekly | L31: Person.java | M31: =IF(OR(O31<>"", Q31<>""),"Yes","No") -> No | S31: Social care
A32: careHoursFromFormalWeekly | C32: {=_xlfn.IFS(S32 = Modules!$A$2,Modules!$B$2,S32 = Modules!$A$3,Modules!$B$3,S32 = Modules!$A$4,Modules!$B$4,S32 = Modules!$A$5,Modules!$B$5,S32 = Modules!$A$6,Modules!$B$6,S32 = Modules!$A$7,Modules!$B$7,S32 = Modules!$A$8,Modules!$B$8,S32 = Modules!$A$9,Modules!$B$9,S32 = Modules!$A$10,Modules!$B$10,S32 = Modules!$A$11,Modules!$B$11,S32 = Modules!$A$12,Modules!$B$12, S32 = Modules!$A$13,Modules!$B$13)} -> care | D32: Hrs | G32: Formal | I32: Week | J32: =CONCATENATE(B32, C32,D32,E32,F32,G32,H32,I32) -> careHrsFormalWeek | K32: Weekly hours of formal social care received | L32: Person.java | M32: =IF(OR(O32<>"", Q32<>""),"Yes","No") -> No | S32: Social care
A33: careHoursFromFormalWeekly_lag1 | C33: {=_xlfn.IFS(S33 = Modules!$A$2,Modules!$B$2,S33 = Modules!$A$3,Modules!$B$3,S33 = Modules!$A$4,Modules!$B$4,S33 = Modules!$A$5,Modules!$B$5,S33 = Modules!$A$6,Modules!$B$6,S33 = Modules!$A$7,Modules!$B$7,S33 = Modules!$A$8,Modules!$B$8,S33 = Modules!$A$9,Modules!$B$9,S33 = Modules!$A$10,Modules!$B$10,S33 = Modules!$A$11,Modules!$B$11,S33 = Modules!$A$12,Modules!$B$12, S33 = Modules!$A$13,Modules!$B$13)} -> care | D33: Hrs | G33: Formal | I33: WeekL1 | J33: =CONCATENATE(B33, C33,D33,E33,F33,G33,H33,I33) -> careHrsFormalWeekL1 | K33: Lag(1) of careHoursFromFormalWeekly | L33: Person.java | M33: =IF(OR(O33<>"", Q33<>""),"Yes","No") -> No | S33: Social care
A34: careHoursFromOtherWeekly | C34: {=_xlfn.IFS(S34 = Modules!$A$2,Modules!$B$2,S34 = Modules!$A$3,Modules!$B$3,S34 = Modules!$A$4,Modules!$B$4,S34 = Modules!$A$5,Modules!$B$5,S34 = Modules!$A$6,Modules!$B$6,S34 = Modules!$A$7,Modules!$B$7,S34 = Modules!$A$8,Modules!$B$8,S34 = Modules!$A$9,Modules!$B$9,S34 = Modules!$A$10,Modules!$B$10,S34 = Modules!$A$11,Modules!$B$11,S34 = Modules!$A$12,Modules!$B$12, S34 = Modules!$A$13,Modules!$B$13)} -> care | D34: Hrs | G34: FromOther | I34: Week | J34: =CONCATENATE(B34, C34,D34,E34,F34,G34,H34,I34) -> careHrsFromOtherWeek | K34: Weekly hours of social care received from others | L34: Person.java | M34: =IF(OR(O34<>"", Q34<>""),"Yes","No") -> No | S34: Social care
A35: careHoursFromOtherWeekly_lag1 | C35: {=_xlfn.IFS(S35 = Modules!$A$2,Modules!$B$2,S35 = Modules!$A$3,Modules!$B$3,S35 = Modules!$A$4,Modules!$B$4,S35 = Modules!$A$5,Modules!$B$5,S35 = Modules!$A$6,Modules!$B$6,S35 = Modules!$A$7,Modules!$B$7,S35 = Modules!$A$8,Modules!$B$8,S35 = Modules!$A$9,Modules!$B$9,S35 = Modules!$A$10,Modules!$B$10,S35 = Modules!$A$11,Modules!$B$11,S35 = Modules!$A$12,Modules!$B$12, S35 = Modules!$A$13,Modules!$B$13)} -> care | D35: Hrs | G35: FromOther | I35: WeekL1 | J35: =CONCATENATE(B35, C35,D35,E35,F35,G35,H35,I35) -> careHrsFromOtherWeekL1 | K35: Lag(1) of careHoursFromOtherWeekly | L35: Person.java | M35: =IF(OR(O35<>"", Q35<>""),"Yes","No") -> No | S35: Social care
A36: careHoursFromParentWeekly | C36: {=_xlfn.IFS(S36 = Modules!$A$2,Modules!$B$2,S36 = Modules!$A$3,Modules!$B$3,S36 = Modules!$A$4,Modules!$B$4,S36 = Modules!$A$5,Modules!$B$5,S36 = Modules!$A$6,Modules!$B$6,S36 = Modules!$A$7,Modules!$B$7,S36 = Modules!$A$8,Modules!$B$8,S36 = Modules!$A$9,Modules!$B$9,S36 = Modules!$A$10,Modules!$B$10,S36 = Modules!$A$11,Modules!$B$11,S36 = Modules!$A$12,Modules!$B$12, S36 = Modules!$A$13,Modules!$B$13)} -> care | D36: Hrs | G36: FromParent | I36: Week | J36: =CONCATENATE(B36, C36,D36,E36,F36,G36,H36,I36) -> careHrsFromParentWeek | K36: Weekly hours of social care received from the parents | L36: Person.java | M36: =IF(OR(O36<>"", Q36<>""),"Yes","No") -> No | S36: Social care
A37: careHoursFromParentWeekly_lag1 | C37: {=_xlfn.IFS(S37 = Modules!$A$2,Modules!$B$2,S37 = Modules!$A$3,Modules!$B$3,S37 = Modules!$A$4,Modules!$B$4,S37 = Modules!$A$5,Modules!$B$5,S37 = Modules!$A$6,Modules!$B$6,S37 = Modules!$A$7,Modules!$B$7,S37 = Modules!$A$8,Modules!$B$8,S37 = Modules!$A$9,Modules!$B$9,S37 = Modules!$A$10,Modules!$B$10,S37 = Modules!$A$11,Modules!$B$11,S37 = Modules!$A$12,Modules!$B$12, S37 = Modules!$A$13,Modules!$B$13)} -> care | D37: Hrs | G37: FromParent | I37: WeekL1 | J37: =CONCATENATE(B37, C37,D37,E37,F37,G37,H37,I37) -> careHrsFromParentWeekL1 | K37: Lag(1) of careHoursFromParentWeekly | L37: Person.java | M37: =IF(OR(O37<>"", Q37<>""),"Yes","No") -> No | S37: Social care
A38: careHoursFromPartnerWeekly | C38: {=_xlfn.IFS(S38 = Modules!$A$2,Modules!$B$2,S38 = Modules!$A$3,Modules!$B$3,S38 = Modules!$A$4,Modules!$B$4,S38 = Modules!$A$5,Modules!$B$5,S38 = Modules!$A$6,Modules!$B$6,S38 = Modules!$A$7,Modules!$B$7,S38 = Modules!$A$8,Modules!$B$8,S38 = Modules!$A$9,Modules!$B$9,S38 = Modules!$A$10,Modules!$B$10,S38 = Modules!$A$11,Modules!$B$11,S38 = Modules!$A$12,Modules!$B$12, S38 = Modules!$A$13,Modules!$B$13)} -> care | D38: Hrs | G38: FromPartner | I38: Week | J38: =CONCATENATE(B38, C38,D38,E38,F38,G38,H38,I38) -> careHrsFromPartnerWeek | K38: Weekly hours of social care received from the partner | L38: Person.java | M38: =IF(OR(O38<>"", Q38<>""),"Yes","No") -> No | S38: Social care
A39: careHoursFromPartnerWeekly_lag1 | C39: {=_xlfn.IFS(S39 = Modules!$A$2,Modules!$B$2,S39 = Modules!$A$3,Modules!$B$3,S39 = Modules!$A$4,Modules!$B$4,S39 = Modules!$A$5,Modules!$B$5,S39 = Modules!$A$6,Modules!$B$6,S39 = Modules!$A$7,Modules!$B$7,S39 = Modules!$A$8,Modules!$B$8,S39 = Modules!$A$9,Modules!$B$9,S39 = Modules!$A$10,Modules!$B$10,S39 = Modules!$A$11,Modules!$B$11,S39 = Modules!$A$12,Modules!$B$12, S39 = Modules!$A$13,Modules!$B$13)} -> care | D39: Hrs | G39: FromPartner | I39: WeekL1 | J39: =CONCATENATE(B39, C39,D39,E39,F39,G39,H39,I39) -> careHrsFromPartnerWeekL1 | K39: Lag(1) of careHoursFromPartnerWeekly | L39: Person.java | M39: =IF(OR(O39<>"", Q39<>""),"Yes","No") -> No | S39: Social care
A40: careHoursFromSonWeekly | C40: {=_xlfn.IFS(S40 = Modules!$A$2,Modules!$B$2,S40 = Modules!$A$3,Modules!$B$3,S40 = Modules!$A$4,Modules!$B$4,S40 = Modules!$A$5,Modules!$B$5,S40 = Modules!$A$6,Modules!$B$6,S40 = Modules!$A$7,Modules!$B$7,S40 = Modules!$A$8,Modules!$B$8,S40 = Modules!$A$9,Modules!$B$9,S40 = Modules!$A$10,Modules!$B$10,S40 = Modules!$A$11,Modules!$B$11,S40 = Modules!$A$12,Modules!$B$12, S40 = Modules!$A$13,Modules!$B$13)} -> care | D40: Hrs | G40: FromSon | I40: Week | J40: =CONCATENATE(B40, C40,D40,E40,F40,G40,H40,I40) -> careHrsFromSonWeek | K40: Weekly hours of social care received from the son | L40: Person.java | M40: =IF(OR(O40<>"", Q40<>""),"Yes","No") -> No | S40: Social care
...

Sheet Rules
A1: 0. Local/temporary variables: i_
A2: 1. Module name. Example: Income (y)
A3: 2. Main attribute (if necessary). Example: Employment income (Emp)
A4: 3. Level (if applicable). Example: Household (hh)
A5: 4. Measurement (if applicable). Example: Gross/net/equivalised
A6: 5. Other information
A7: 6. Statistics type (if applicable). Example: Median/mean
B8: Number | C8: n
B9: Flag | C9: flag
B10: Mean | C10: avg
B11: Median | C11: p50
B12: Pctiles | C12: p##
B13: Categories | C13: c#
B14: Squared | C14: sq
B15: Share | C15: share
B16: Ratio | C16: ratio
A17: 7. Periodicity (if applicable). Example: Yearly/monthly
B18: Lag# | C18: l#

Sheet Modules
A1: Modules | B1: Acronym
A2: Demography | B2: dem
A3: Education | B3: edu
A4: Health | B4: health
A5: Social care | B5: care
A6: Labour | B6: lab
A7: Income | B7: y
A8: Consumption | B8: x
A9: Statistical display | B9: stat
A10: Covid | B10: covid
A11: Wealth | B11: wealth
A12: ID | B12: id
A13: Weight | B13: wgt

Sheet Abbreviations
A1: Word | B1: Abbreviation
A2: Activity | B2: ---
A3: Adjustment | B3: adj
A4: Age | B4: age
A5: Alignment | B5: align
A6: Benefit | B6: ben
A7: Benefit unit | B7: bu
A8: Children | B8: child
A9: Cohabiting | B9: --> partnership
A10: Composition | B10: comp
A11: Couple | B11: couple
A12: Cross-sectional | B12: cross
... A79: Yearly | B79: yrly

Sheet Coding Style
A1: Style | B1: Applicable to
A2: camelCase | B2: global, updated variables
A3: PascalCase | B3: Java Classes
A4: snake_case | B4: local, temporary variables | D4: start with i_

Sheet Country Specific Vars
A1: Country Specific Variables
A2: drgn / demRegion
B3: UK | C3: Region : NUTS Level 1 1 "North East" 2 "North West" 4 "Yorkshire and the Humber 5 "East Midlands" 6 "West Midlands" 7 "East of England" 8 "London" 9 "South East" 10 "South West" 11 "Wales" 12 "Scotland" 13 "Northern Ireland"
B4: PL | C4: Region: NUTS 1 2 "Poludniowy" 4 "Polnocno-Zachodni" 5 "Poludniowo-Zachodni" 6 "Polnocy" 10 "Central and East"
B5: IT | C5: Region: NUTS 1 3 "Northwest" 6 "South" 7 "Islands" 8 "Northeast" 9 "Central"
B6: HU | C6: Region: NUTS1 1 "Central Hungary" 2 "Transdanubia" 3 "Great Plain and North "
B7: EL | C7: Region: NUTS1 3 "Attica" 4 "Aegean Islands" 7 "Central and Northern Greece"
